#VRML_SIM R2025a utf8

EXTERNPROTO "https://raw.githubusercontent.com/cyberbotics/webots/R2025a/projects/objects/backgrounds/protos/TexturedBackground.proto"
EXTERNPROTO "https://raw.githubusercontent.com/cyberbotics/webots/R2025a/projects/objects/backgrounds/protos/TexturedBackgroundLight.proto"
EXTERNPROTO "https://raw.githubusercontent.com/cyberbotics/webots/R2025a/projects/objects/floors/protos/RectangleArena.proto"
EXTERNPROTO "https://raw.githubusercontent.com/cyberbotics/webots/R2025a/projects/appearances/protos/Parquetry.proto"
EXTERNPROTO "../protos/ConveyorBelt.proto"
EXTERNPROTO "../protos/Pioneer3at.proto"
EXTERNPROTO "../protos/WoodenPallet.proto"
EXTERNPROTO "https://raw.githubusercontent.com/cyberbotics/webots/R2025a/projects/objects/factory/containers/protos/CardboardBox.proto"
EXTERNPROTO "https://raw.githubusercontent.com/cyberbotics/webots/R2025a/projects/objects/factory/containers/protos/PlasticFruitBox.proto"
EXTERNPROTO "https://raw.githubusercontent.com/cyberbotics/webots/R2025a/projects/objects/factory/manhole/protos/SquareManhole.proto"
EXTERNPROTO "https://raw.githubusercontent.com/cyberbotics/webots/R2025a/projects/objects/traffic/protos/SignPole.proto"
EXTERNPROTO "https://raw.githubusercontent.com/cyberbotics/webots/R2025a/projects/objects/traffic/protos/DirectionPanel.proto"
EXTERNPROTO "https://raw.githubusercontent.com/cyberbotics/webots/R2025a/projects/humans/pedestrian/protos/Pedestrian.proto"
EXTERNPROTO "https://raw.githubusercontent.com/cyberbotics/webots/R2025a/projects/appearances/protos/Plastic.proto"
EXTERNPROTO "https://raw.githubusercontent.com/cyberbotics/webots/R2025a/projects/robots/mir/mir100/protos/Mir100UltrasonicSensor.proto"
EXTERNPROTO "https://raw.githubusercontent.com/cyberbotics/webots/R2025a/projects/appearances/protos/CorrodedMetal.proto"
EXTERNPROTO "https://raw.githubusercontent.com/cyberbotics/webots/R2025a/projects/objects/solids/protos/SolidTorus.proto"
EXTERNPROTO "https://raw.githubusercontent.com/cyberbotics/webots/R2025a/projects/appearances/protos/CorrugatedMetal.proto"
EXTERNPROTO "https://raw.githubusercontent.com/cyberbotics/webots/R2025a/projects/appearances/protos/Rubber.proto"

WorldInfo {
}
Viewpoint {
  orientation -0.45508226714879063 0.45455550955631946 0.7656888525104122 1.835777379094399
  position 6.496449621251185 -4.95711209885523 28.004345390246062
  followType "None"
}
TexturedBackground {
}
TexturedBackgroundLight {
}
DEF rectangle_arena RectangleArena {
  translation 15.1304 9.85552 0
  floorSize 30 20
  floorTileSize 1 1
  floorAppearance Parquetry {
    type "dark strip"
  }
}
Pedestrian {
  translation 11.06 7.31002 1.27
  rotation 0 0 1 -3.1415853071795863
}
Pedestrian {
  translation 16.3842 17.72 1.28
  rotation 0 0 1 -0.523595307179586
  name "pedestrian(1)"
}
Pedestrian {
  translation 26.7331 5.34865 1.28
  rotation 0 0 -1 1.5708
  name "pedestrian(2)"
}
SignPole {
  translation 25.3498 15.6897 0
  rotation 0 0 1 3.14159
  height 1
  signBoards [
    DirectionPanel {
      translation 0 0 -0.86
      width 0.4
      height 0.2
    }
  ]
}
PlasticFruitBox {
  translation 28.2254 1.86879 0.63
  rotation 0 0 1 0.261799
  color 0.371527 0.966171 0.557473
}
DEF left_big_conveyor_belt_5 ConveyorBelt {
  hidden translation_1 0 0 1.1213672312337615
  translation 17.8 15 0
  rotation 0 0 -1 0
  size 1 5 1.5
}
DEF left_big_conveyor_belt_6 ConveyorBelt {
  hidden translation_1 7.105427357601002e-15 -3.552713678800501e-15 1.12136723123376
  translation 21 15 0
  rotation 0 0 -1 0
  name "conveyor belt(11)"
  size 1 5 1.5
}
DEF left_big_conveyor_belt_6 ConveyorBelt {
  hidden translation_1 -0.0003848911937467392 2.1388581966874654e-05 1.146411672360298
  hidden rotation_1 -0.007108017828594725 0.999974682844138 -0.0003312903771018675 0.006046461441891239
  translation 28.88 15 0
  rotation 0 0 -1 0
  name "conveyor belt(25)"
  size 1 5 1.5
}
DEF left_small_conveyor_belt_4 ConveyorBelt {
  hidden translation_1 0 0 0.7463672314251913
  translation 13.33 14.5 0
  rotation 0 0 -1 0
  name "conveyor belt(3)"
  size 1 4 1
}
DEF left_big_conveyor_belt_4 ConveyorBelt {
  hidden translation_1 0 0 1.1213672312337615
  translation 14.5 15 0
  rotation 0 0 -1 0
  name "conveyor belt(4)"
  size 1 5 1.5
}
DEF left_small_conveyor_belt_5 ConveyorBelt {
  hidden translation_1 0 0 0.746367231234008
  translation 16.6 14.5 0
  rotation 0 0 -1 0
  name "conveyor belt(1)"
  size 1 4 1
}
DEF left_small_conveyor_belt_6 ConveyorBelt {
  hidden translation_1 0 0 0.7463672312337536
  translation 19.8 14.5 0
  rotation 0 0 -1 0
  name "conveyor belt(10)"
  size 1 4 1
}
DEF right_small_conveyor_belt_6 ConveyorBelt {
  hidden translation_1 0 0 0.7463672312337536
  translation 23 6 0
  rotation 0 0 -1 0
  name "conveyor belt(2)"
  size 1 4 1
}
DEF right_big_conveyor_belt_6 ConveyorBelt {
  hidden translation_1 0 0 1.1213672312337615
  translation 21.8 5.5 0
  rotation 0 0 -1 0
  name "conveyor belt(5)"
  size 1 5 1.5
}
ConveyorBelt {
  hidden translation_1 0 0 0.44636723123374844
  translation 27.8449 2.58127 0
  rotation 0 0 -1 0
  name "conveyor belt(12)"
  size 4 4 0.6
}
DEF right_small_conveyor_belt_5 ConveyorBelt {
  hidden translation_1 0 0 0.7463672312337536
  translation 19.8 6 0
  rotation 0 0 -1 0
  name "conveyor belt(6)"
  size 1 4 1
}
WoodenPallet {
  translation 22.5 8.7 0
  size 2 1 0.1
}
WoodenPallet {
  translation 19 8.7 0
  name "wooden pallet(1)"
  size 2 1 0.1
}
WoodenPallet {
  translation 9.4 8.7 0
  name "wooden pallet(6)"
  size 2 1 0.1
}
WoodenPallet {
  translation 17 11.9 0
  name "wooden pallet(2)"
  size 2 1 0.1
}
WoodenPallet {
  translation 10.73 11.9 0
  name "wooden pallet(3)"
  size 2 1 0.1
}
WoodenPallet {
  translation 7.5 11.9 0
  name "wooden pallet(5)"
  size 2 1 0.1
}
WoodenPallet {
  translation 4.5 11.9 0
  name "wooden pallet(4)"
  size 2 1 0.1
}
DEF right_big_conveyor_belt_5 ConveyorBelt {
  hidden translation_1 0 0 1.1213672312337615
  translation 18.5 5.5 0
  rotation 0 0 -1 0
  name "conveyor belt(7)"
  window "<none>"
  size 1 5 1.5
}
DEF right_small_conveyor_belt_4 ConveyorBelt {
  hidden translation_1 0 0 0.7463672312337536
  translation 16.46 6 0
  rotation 0 0 -1 0
  name "conveyor belt(8)"
  window "<none>"
  size 1 4 1
}
DEF right_small_conveyor_belt_3 ConveyorBelt {
  hidden translation_1 0 0 0.7463672313983676
  translation 13.22 6 0
  rotation 0 0 -1 0
  name "conveyor belt(14)"
  window "<none>"
  size 1 4 1
}
DEF left_small_conveyor_belt_2 ConveyorBelt {
  hidden translation_1 0 0 0.7463672312337536
  translation 6.9 14.5 0
  rotation 0 0 -1 0
  name "conveyor belt(21)"
  size 1 4 1
}
DEF left_small_conveyor_belt_1 ConveyorBelt {
  hidden translation_1 0 0 0.7463672312337536
  translation 3.7 14.5 0
  rotation 0 0 -1 0
  name "conveyor belt(23)"
  size 1 4 1
}
DEF left_small_conveyor_belt_3 ConveyorBelt {
  hidden translation_1 0 0 0.7463672312337536
  translation 10.1 14.5 0
  rotation 0 0 -1 0
  name "conveyor belt(19)"
  size 1 4 1
}
DEF right_small_conveyor_belt_2 ConveyorBelt {
  hidden translation_1 0 0 0.7463672312337536
  translation 10 6 0
  rotation 0 0 -1 0
  name "conveyor belt(15)"
  size 1 4 1
}
DEF right_small_conveyor_belt_1 ConveyorBelt {
  hidden translation_1 1.7763568394002505e-15 1.7763568394002505e-15 0.7463672312337531
  translation 7 6 0
  rotation 0 0 -1 0
  name "conveyor belt(17)"
  size 1 4 1
}
DEF right_big_conveyor_belt_4 ConveyorBelt {
  hidden translation_1 0 0 1.1213672312337615
  translation 15.3 5.5 0
  rotation 0 0 -1 0
  name "conveyor belt(9)"
  size 1 5 1.5
}
DEF right_big_conveyor_belt_3 ConveyorBelt {
  hidden translation_1 0 0 1.1213672312337615
  translation 12 5.5 0
  rotation 0 0 -1 0
  name "conveyor belt(13)"
  size 1 5 1.5
}
DEF left_big_conveyor_belt_3 ConveyorBelt {
  hidden translation_1 0 0 1.1213672312337615
  translation 11.3 15 0
  rotation 0 0 -1 0
  name "conveyor belt(20)"
  size 1 5 1.5
}
DEF left_big_conveyor_belt_2 ConveyorBelt {
  hidden translation_1 0 0 1.1213672312337615
  translation 8.1 15 0
  rotation 0 0 -1 0
  name "conveyor belt(22)"
  size 1 5 1.5
}
DEF left_big_conveyor_belt_1 ConveyorBelt {
  hidden translation_1 0 0 1.1213672312337615
  translation 4.9 15 0
  rotation 0 0 -1 0
  name "conveyor belt(24)"
  size 1 5 1.5
}
DEF right_big_conveyor_belt_2 ConveyorBelt {
  hidden translation_1 0 0 1.1213672312337615
  translation 8.8 5.5 0
  rotation 0 0 -1 0
  name "conveyor belt(16)"
  size 1 5 1.5
}
DEF right_big_conveyor_belt_1 Robot {
  translation 5.8 5.5 0
  rotation 0 0 -1 0
  children [
    Track {
      translation -9.488717160177629e-05 -0.0008011680417192579 1.129294778681529
      rotation 0.9966346016118166 -0.08196245748030113 0.0012753171548224409 0.007025254798688431
      children [
        Shape {
          appearance Rubber {
            type "dotted"
            textureTransform TextureTransform {
              scale 4 20
            }
          }
          geometry DEF BELT_BO Box {
            size 1 5 0.75
          }
        }
      ]
      boundingObject USE BELT_BO
      physics Physics {
        density -1
        mass 1
      }
      device [
        LinearMotor {
          name "belt_motor"
          maxVelocity 0.5
          sound ""
        }
      ]
      textureAnimation 1 0
      linearVelocity 0 0 -1.2139209724183647e-07
    }
    Shape {
      appearance CorrugatedMetal {
        textureTransform TextureTransform {
          scale 2 2
        }
      }
      geometry IndexedFaceSet {
        coord Coordinate {
          point [
            0.53 -2.53 0
            0.53 -2.53 1.51
            -0.53 -2.53 1.51
            -0.53 -2.53 0
            0.53 2.53 0
            0.53 2.53 1.51
            -0.53 2.53 1.51
            -0.53 2.53 0
            0.5 -2.5 1.51
            0.5 2.5 1.51
            -0.5 2.5 1.51
            -0.5 -2.5 1.51
            0.5 -2.5 1.5
            0.5 2.5 1.5
            -0.5 2.5 1.5
            -0.5 -2.5 1.5
          ]
        }
        texCoord TextureCoordinate {
          point [
            0 0
            1 0
            1 1
            0 1
            0 2.849056603773585
            1 2.849056603773585
            0 2.849056603773585
            4.7735849056603765 2.849056603773585
            4.7735849056603765 0
            0 0
            0.001 0
            0.001 0.001
            0 0.001
          ]
        }
        coordIndex [
          0, 1, 2, 3, -1, 4, 7, 6, 5, -1, 0, 4, 5, 1, -1, 7, 3, 2, 6, -1, 1, 5, 9, 8, -1, 5, 6, 10, 9, -1, 6, 2, 11, 10, -1, 2, 1, 8, 11, -1, 0, 3, 7, 4, -1, 8, 9, 13, 12, -1, 9, 10, 14, 13, -1, 10, 11, 15, 14, -1, 11, 8, 12, 15, -1
        ]
        texCoordIndex [
          1, 5, 4, 0, -1, 0, 1, 5, 4, -1, 0, 8, 7, 6, -1, 0, 8, 7, 6, -1, 9, 10, 11, 12, -1, 9, 10, 11, 12, -1, 9, 10, 11, 12, -1, 9, 10, 11, 12, -1, 9, 10, 11, 12, -1, 9, 10, 11, 12, -1, 9, 10, 11, 12, -1, 9, 10, 11, 12, -1, 9, 10, 11, 12, -1
        ]
      }
    }
    Pose {
      translation -0.53 -2.93845e-06 0.17
      rotation 0 0 1 -3.14159
      children [
        Shape {
          appearance Appearance {
            material Material {
              diffuseColor 1 1 1
            }
            texture ImageTexture {
              url [
                "/Users/nguyenquangnhat/Documents/ARM_project/protos/textures/april_tag.png"
              ]
              repeatS FALSE
              repeatT FALSE
            }
          }
          geometry Box {
            size 0.0005 0.05 0.05
          }
        }
      ]
    }
  ]
  name "conveyor belt(18)"
  boundingObject Group {
    children [
      Pose {
        translation 0.515 0 0.755
        children [
          Box {
            size 0.03 5.06 1.51
          }
        ]
      }
      Pose {
        translation -0.515 0 0.755
        children [
          Box {
            size 0.03 5.06 1.51
          }
        ]
      }
      Pose {
        translation 0 -2.515 0.755
        children [
          Box {
            size 1 0.03 1.51
          }
        ]
      }
      Pose {
        translation 0 2.515 0.755
        children [
          Box {
            size 1 0.03 1.51
          }
        ]
      }
    ]
  }
  controllerArgs [
    "0.5"
    "0"
  ]
}
CardboardBox {
  translation 27.8384 3.01098 0.71
  rotation 0 0 1 0.261799
  size 0.2 0.2 0.2
}
CardboardBox {
  translation 28.0224 3.48865 0.71
  rotation 0 0 1 0.785398
  name "cardboard box(1)"
  size 0.2 0.2 0.2
}
CardboardBox {
  translation 21.6903 3.22499 1.6
  rotation 0 0 1 1.309
  name "cardboard box(6)"
  size 0.2 0.2 0.2
}
CardboardBox {
  translation 7.98736 14.1014 1.6
  rotation 0 0 1 1.309
  name "cardboard box(7)"
  size 0.2 0.2 0.2
}
CardboardBox {
  translation 15.3336 4.18682 1.6
  rotation 0 0 1 2.0944
  name "cardboard box(10)"
  size 0.2 0.2 0.2
}
CardboardBox {
  translation 11.2185 13.9355 1.6
  rotation 0 0 1 2.0944
  name "cardboard box(11)"
  size 0.2 0.2 0.2
}
CardboardBox {
  translation 4.6953 16.4739 1.6
  rotation 0 0 1 2.0944
  name "cardboard box(12)"
  size 0.2 0.2 0.2
}
CardboardBox {
  translation 5.94515 4.74132 1.6
  rotation 0 0 1 1.309
  name "cardboard box(9)"
  size 0.2 0.2 0.2
}
CardboardBox {
  translation 26.2061 1.6839 0.71
  rotation 0 0 1 1.309
  name "cardboard box(8)"
  size 0.2 0.2 0.2
}
CardboardBox {
  translation 28.3211 1.96902 0.77
  rotation 0 0 1 4.692820414042842e-06
  name "cardboard box(5)"
  size 0.2 0.2 0.2
}
CardboardBox {
  translation 28.0496 3.95362 0.71
  rotation 0 0 1 0.261803
  name "cardboard box(2)"
  size 0.2 0.2 0.2
}
CardboardBox {
  translation 18.9049 8.5223 0.11
  rotation 0 0 1 1.5708
  name "cardboard box(4)"
  size 0.2 0.2 0.2
}
CardboardBox {
  translation 20.9849 7.7223 0.11
  rotation 0 0 1 1.5708
  name "cardboard box(13)"
  size 0.2 0.2 0.2
}
CardboardBox {
  translation 17.3949 8.2323 0.11
  rotation 0 0 1 1.5708
  name "cardboard box(16)"
  size 0.2 0.2 0.2
}
CardboardBox {
  translation 18.6349 12.5223 0.11
  rotation 0 0 1 1.5708
  name "cardboard box(17)"
  size 0.2 0.2 0.2
}
CardboardBox {
  translation 17.0749 12.4123 0.11
  rotation 0 0 1 1.5708
  name "cardboard box(18)"
  size 0.2 0.2 0.2
}
CardboardBox {
  translation 24.9049 4.5023 0.11
  rotation 0 0 1 1.5708
  name "cardboard box(15)"
  size 0.2 0.2 0.2
}
CardboardBox {
  translation 24.3649 4.5123 0.11
  rotation 0 0 1 1.5708
  name "cardboard box(14)"
  size 0.2 0.2 0.2
}
CardboardBox {
  translation 22.6249 18.7445 0.15
  rotation 0 0 1 4.07987e-06
  name "cardboard box(3)"
  size 0.2 0.2 0.2
}
Pose {
}
DEF SUPERVISOR Robot {
  rotation 0 0 1 -2.8797853071795863
  controller "floor_mapper"
  supervisor TRUE
}
DEF Pioneer_3-AT Pioneer3at {
  hidden position_0_0 17180.781317374345
  hidden position_0_1 14902.012851972204
  hidden position_0_2 17201.443176472498
  hidden position_0_3 14923.747407570921
  hidden linearVelocity_0 2.2244134135858848e-14 -2.204008755804762e-15 -1.5502750598402187e-16
  hidden angularVelocity_0 -1.054163645790784e-16 -1.0866734165081566e-15 3.0572106151246705e-15
  hidden rotation_1 0.5773516024134749 -0.5773476024162304 -0.5773516027299337 2.094404999683543
  hidden translation_2 4.390430234023778e-13 2.1847962280823109e-13 0.04999999999999215
  hidden rotation_2 -0.42526537133496617 0.425258256650912 -0.7989397843977734 1.7934126943521096
  hidden rotation_3 0.6930329821963311 -0.6930264970215477 -0.1985435972629246 2.7496115792719635
  hidden linearVelocity_3 1.85540095808794e-14 3.720062157032704e-16 7.105260307674532e-17
  hidden angularVelocity_3 7.320478712633599e-15 2.418650624438192e-15 -2.6976566159867537e-17
  hidden rotation_4 -0.16753941184003418 0.167540988633279 0.971524864637071 4.683493665386912
  hidden linearVelocity_4 -1.45763231488652e-14 -1.2619106443438053e-15 -2.842283223098736e-16
  hidden angularVelocity_4 3.913643325612396e-15 2.3872710144546404e-15 -6.703369288432648e-18
  hidden rotation_5 0.16398691637382773 -0.1639819097437611 0.9727374900429162 4.684741716412891
  hidden linearVelocity_5 -3.8458474392537246e-15 2.0025944330971301e-16 -1.4213143275452658e-16
  hidden angularVelocity_5 9.555233999381112e-15 8.815050979792354e-17 -3.67673648198989e-17
  hidden rotation_6 0.07773587598801582 -0.07773168840995452 0.9939390917965314 4.70629960106549
  hidden linearVelocity_6 -1.915995447212206e-16 -2.5949892112954486e-15 1.4211966942233164e-16
  hidden angularVelocity_6 9.381095733547806e-15 -2.2646102658576037e-15 -2.574676811073036e-17
  translation 12.981299877569555 1.1346399975520371 -0.0023889310687115473
  rotation -2.473697390029517e-05 2.482305495026674e-05 0.999999999385949 1.5554670108890136
  name "Pioneer 3-AT_1"
  controller "pioneer_controller_1"
}
DEF Pioneer_3-AT Pioneer3at {
  hidden position_0_0 17180.781317379937
  hidden position_0_1 14902.012851965772
  hidden position_0_2 17201.44317648103
  hidden position_0_3 14923.74740756774
  hidden linearVelocity_0 1.3489932135854508e-14 -2.6947178705610305e-15 -2.0670334131202914e-16
  hidden angularVelocity_0 5.786790281852153e-16 -1.0715986217597613e-15 -3.875209406050431e-15
  hidden rotation_1 0.5773516024134749 -0.5773476024162304 -0.5773516027299337 2.094404999683543
  hidden translation_2 4.390430234023778e-13 2.1847962280823109e-13 0.04999999999999215
  hidden rotation_2 -0.42526537133496617 0.425258256650912 -0.7989397843977734 1.7934126943521096
  hidden rotation_3 0.6930329819078426 -0.6930264967330674 -0.19854359927687315 2.749611575396854
  hidden linearVelocity_3 1.8755024063279898e-14 -3.2679488050955976e-17 2.842114195022034e-16
  hidden angularVelocity_3 7.268398570858012e-15 -4.63531109017428e-15 8.173896863772785e-17
  hidden rotation_4 -0.16753941487673268 0.167540991669942 0.971524863589715 4.683493664309299
  hidden linearVelocity_4 -1.4249117976354204e-14 -1.4112699567045191e-15 4.2630371893370196e-16
  hidden angularVelocity_4 3.505389053612636e-15 1.2079240806852612e-15 3.3707130791694354e-17
  hidden rotation_5 0.16398692041149363 -0.1639819137813901 0.9727374886815802 4.684741715013951
  hidden linearVelocity_5 -2.8952228056345294e-15 1.465658513358092e-15 7.10604965685181e-17
  hidden angularVelocity_5 8.926959621913118e-15 -3.4443856760153542e-15 8.10304780891613e-17
  hidden rotation_6 0.07773587441650424 -0.07773168683845841 0.993939092042339 4.706299601312786
  hidden linearVelocity_6 -3.1524514014154625e-15 -3.2809591623544356e-15 7.104023300615182e-17
  hidden angularVelocity_6 1.0030784416822383e-14 -6.960936338389624e-15 4.500445973999682e-17
  translation 14.481299987170779 1.1131699989811175 -0.0023889310687115195
  rotation -2.4736973900354237e-05 2.4823054933496082e-05 0.999999999385949 1.5554670115527376
  name "Pioneer 3-AT_1(1)"
  controller "pioneer_controller_2"
}
DEF Pioneer_3-AT Pioneer3at {
  hidden position_0_0 17180.781317379257
  hidden position_0_1 14902.012851964286
  hidden position_0_2 17201.44317648571
  hidden position_0_3 14923.74740757173
  hidden linearVelocity_0 3.859517326155395e-14 -2.059164076624724e-15 0
  hidden angularVelocity_0 7.818734304485857e-16 6.95110952199404e-18 3.767271072053521e-15
  hidden rotation_1 0.5773516024134749 -0.5773476024162304 -0.5773516027299337 2.094404999683543
  hidden translation_2 4.390430234023778e-13 2.1847962280823109e-13 0.04999999999999215
  hidden rotation_2 -0.42526537133496617 0.425258256650912 -0.7989397843977734 1.7934126943521096
  hidden rotation_3 0.6930329819429413 -0.6930264967681664 -0.19854359903184401 2.749611575868322
  hidden linearVelocity_3 3.454083990105304e-14 -2.693554298627915e-16 6.395139565607367e-16
  hidden angularVelocity_3 6.771019425392197e-15 -9.342217638553243e-15 -1.286349231052108e-16
  hidden rotation_4 -0.16753941557836766 0.16754099237156947 0.9715248633477214 4.683493664060314
  hidden linearVelocity_4 -3.1407361906055537e-14 -1.1760094946712462e-15 -1.421042718050478e-16
  hidden angularVelocity_4 3.985088850618976e-15 -1.1388097252172207e-15 -1.3090949756144401e-16
  hidden rotation_5 0.16398692262747372 -0.16398191599735187 0.9727374879344418 4.6847417142461705
  hidden linearVelocity_5 -2.3049757890355018e-15 6.841982875087568e-16 -4.973476894915351e-16
  hidden angularVelocity_5 9.523445444124102e-15 -3.4388829025139686e-15 -1.5846727252738056e-16
  hidden rotation_6 0.07773587638695867 -0.07773168880889257 0.9939390917341309 4.70629960100271
  hidden linearVelocity_6 -2.2777583925972674e-15 -2.5220518926711162e-15 -5.684437755117859e-16
  hidden angularVelocity_6 9.52759490434624e-15 1.2634813755889191e-15 -1.376101370800044e-16
  translation 16.431299990933564 1.084789998887374 -0.002388931068711575
  rotation -2.4736973900253677e-05 2.482305489167198e-05 0.9999999993859491 1.555467013218015
  name "Pioneer 3-AT_1(2)"
  controller "pioneer_controller_3"
}
SquareManhole {
  translation 25 19 0
}
SquareManhole {
  translation 19.092 9.85948 -0.04
  rotation 0 0 1 0.523602
  name "manhole(16)"
}
SquareManhole {
  translation 19.2812 12.146 -0.04
  rotation 0 0 1 0.785401
  name "manhole(17)"
}
SquareManhole {
  translation 9.00273 12.0778 -0.02
  rotation 0 0 1 1.5708
  name "manhole(12)"
}
SquareManhole {
  translation 6.19714 8.34714 -0.04
  rotation 9.58978e-09 3.57898e-08 1 -0.523595307179586
  name "manhole(11)"
}
WoodenPallet {
  translation 6.46 8.7 0
  name "wooden pallet(7)"
  size 2 1 0.1
}
WoodenPallet {
  translation 12.72 8.7 0
  name "wooden pallet(8)"
  size 2 1 0.1
}
WoodenPallet {
  translation 15.74 8.7 0
  name "wooden pallet(9)"
  size 2 1 0.1
}
WoodenPallet {
  translation 13.93 11.89 0
  name "wooden pallet(10)"
  size 2 1 0.1
}
WoodenPallet {
  translation 20.37 11.89 0
  name "wooden pallet(11)"
  size 2 1 0.1
}
Robot {
  translation 7.447143621246269 10.684600322628883 -0.008594794620149254
  rotation 0.0009121398694184405 -0.0015267105047615628 0.9999984185766961 3.1415748618759225
  children [
    Camera {
      translation 0.044 -0.28 0.18
      rotation 0 0 1 -1.5707953071795862
      fieldOfView 2.05949
      width 1280
      height 720
    }
    InertialUnit {
      rotation 0 0 1 -1.5707953071795862
    }
    GPS {
      rotation 0 0 -1 -5.307179586466759e-06
    }
    Pose {
      translation 0.037646 0 0
      children [
        Shape {
          appearance DEF WHITE Plastic {
          }
          geometry Mesh {
            url [
              "https://raw.githubusercontent.com/cyberbotics/webots/R2025a/projects/robots/mir/mir100/protos/meshes/mir_100_base.obj"
            ]
          }
        }
        Shape {
          appearance USE WHITE
          geometry Mesh {
            url [
              "https://raw.githubusercontent.com/cyberbotics/webots/R2025a/projects/robots/mir/mir100/protos/meshes/mir_100_inside.obj"
            ]
          }
        }
        Shape {
          appearance Plastic {
            colorOverride 0.93 0.93 0.93
          }
          geometry Mesh {
            url [
              "https://raw.githubusercontent.com/cyberbotics/webots/R2025a/projects/robots/mir/mir100/protos/meshes/mir_100_logos.dae"
            ]
          }
        }
        Shape {
          appearance DEF BLACK Plastic {
            colorOverride 0 0 0
          }
          geometry Mesh {
            url [
              "https://raw.githubusercontent.com/cyberbotics/webots/R2025a/projects/robots/mir/mir100/protos/meshes/mir_100_base_corners.dae"
            ]
          }
        }
        Shape {
          appearance DEF BLACK Plastic {
            colorOverride 0 0 0
          }
          geometry Mesh {
            url [
              "https://raw.githubusercontent.com/cyberbotics/webots/R2025a/projects/robots/mir/mir100/protos/meshes/mir_100_top_plugs.dae"
            ]
          }
        }
      ]
    }
    DEF IMU Pose {
      translation 0 0 0.25
      children [
        Accelerometer {
          name "imu_data accelerometer"
          lookupTable [
            -100 -100 -0.002
            100 100 0.002
          ]
        }
        Gyro {
          name "imu_data gyro"
          lookupTable [
            -100 -100 -0.002
            100 100 0.002
          ]
        }
        Compass {
          name "imu_data compass"
          lookupTable [
            -1 -1 -0.2
            1 1 0.2
          ]
        }
      ]
    }
    Pose {
      translation 0.4288 0.2358 0.188
      rotation -0.9238797538373538 -0.38268289803626016 0 -3.14159
    }
    Pose {
      translation -0.3548 -0.2352 0.188
      rotation 0.38268289803626016 -0.9238797538373538 0 -3.14159
    }
    Pose {
      translation 0.037646 0 0.349
    }
    DEF DEPTH_CAMERA Transform {
      translation 0.042224 -0.273014 0.141194
      rotation 1 0 0 1.5708
      scale 4.00035 3.92893 3.92893
      children [
        Shape {
          appearance Appearance {
            material Material {
              emissiveColor 1 1 1
            }
            texture ImageTexture {
              url [
                "https://raw.githubusercontent.com/cyberbotics/webots/R2025a/projects/robots/mir/mir100/protos/textures/camera.png"
              ]
            }
            textureTransform TextureTransform {
              rotation 3.1415926
            }
          }
          geometry Plane {
            size 0.08 0.015
          }
        }
      ]
    }
    Mir100UltrasonicSensor {
      translation 0.415448 -0.108238 0.08
      rotation 0.8628559982596194 -0.35740699927911007 -0.35740699927911007 1.71777
      name "ds0"
      lookupTable [
        0.2 1000 0
        0.3 0 0
      ]
    }
    Mir100UltrasonicSensor {
      translation -0.3844 -0.1328 0.156
      rotation 0 0 1 3.141592653589793
      name "ds1"
    }
    Mir100UltrasonicSensor {
      translation -0.3844 0.1328 0.156
      rotation 0 0 1 3.141592653589793
      name "ds2"
    }
    Mir100UltrasonicSensor {
      translation 0.415448 0.108238 0.08
      rotation 0.8628559982596194 0.35740699927911007 0.35740699927911007 1.71777
      name "ds3"
      lookupTable [
        0.2 1000 0
        0.3 0 0
      ]
    }
    RangeFinder {
      translation 0.044 -0.28 0.18
      rotation 0 0 1 -1.5707953071795862
      name "depth_camera"
      fieldOfView 2.05949
      near 0.001
      maxRange 1.95
    }
    Pose {
      translation 0.03733 0.0005 0.2085
      children [
        DEF LIGHT_FRONT Pose {
          translation 0.392 0 0
          children [
            DEF LIGHT_WIDTH_SHAPE Shape {
              appearance PBRAppearance {
                transparency 0.5
                emissiveColor 0 0.9 1
              }
              geometry Box {
                size 0.001 0.4723 0.053
              }
            }
          ]
        }
        DEF LIGHT_BACK Pose {
          translation -0.392 0 0
          children [
            USE LIGHT_WIDTH_SHAPE
          ]
        }
        DEF LIGHT_LEFT Pose {
          translation 0 0.2355 0
          children [
            DEF LIGHT_WIDTH_SHAPE Shape {
              appearance PBRAppearance {
                transparency 0.5
                emissiveColor 0 0.9 1
              }
              geometry Box {
                size 0.783 0.001 0.053
              }
            }
          ]
        }
        DEF LIGHT_RIGHT Pose {
          translation 0 -0.2355 0
          children [
            USE LIGHT_WIDTH_SHAPE
          ]
        }
      ]
    }
    DEF US_1_FRAME Solid {
      translation 0.45 -0.12 0.16
      name "us_1_frame"
    }
    DEF US_2_FRAME Solid {
      translation 0.45 0.12 0.16
      name "us_2_frame"
    }
    DEF FL_CASTER_ROTATION_JOINT HingeJoint {
      jointParameters HingeJointParameters {
        position 2.493966917362607e-05
        axis 0 0 1
        anchor 0.341346 0 0.154
        dampingConstant 0.01
      }
      device [
        RotationalMotor {
          name "front_wheel_joint"
          maxVelocity 100
          maxTorque 20
        }
        PositionSensor {
          name "front_caster_joint_sensor"
        }
      ]
      endPoint DEF FL_CASTER_ROTATION_LINK Solid {
        translation 0.3408593618547467 0.0005417687717419614 0.16104314252205185
        rotation 0 0 1 2.3013780965963073e-05
        children [
          DEF CASTER_WHEEL_BASE Shape {
            appearance PBRAppearance {
              baseColor 0.35 0.35 0.35
              roughness 1
              metalness 0
            }
            geometry Mesh {
              url [
                "https://raw.githubusercontent.com/cyberbotics/webots/R2025a/projects/robots/mir/mir100/protos/meshes/caster_wheel_base.dae"
              ]
            }
          }
          DEF FL_CASTER_WHEEL_JOINT HingeJoint {
            jointParameters HingeJointParameters {
              position 657.0119049735135
              axis 0 1 0
              anchor -0.0382 0 -0.094
            }
            device [
              RotationalMotor {
                name "front_wheel"
                maxVelocity 100
                maxTorque 20
              }
              PositionSensor {
                name "front_left_wheel_joint_sensor"
              }
            ]
            endPoint DEF FL_CASTER_WHEEL_LINK Solid {
              translation -0.03784277238668186 -5.553783064016242e-05 -0.0939007598933172
              rotation 0.8124149960923129 -0.41229968720003746 -0.4122994567775689 4.5061192081287835
              children [
                Group {
                  children [
                    DEF RIM Shape {
                      appearance CorrodedMetal {
                      }
                      geometry Cylinder {
                        height 0.032
                        radius 0.0465
                      }
                    }
                    SolidTorus {
                      translation 0 0 0
                      majorRadius 0.0465
                      minorRadius 0.016
                      appearance DEF WHEEL_RUBBER PBRAppearance {
                        baseColor 0 0 0
                        roughness 1
                        metalness 0
                      }
                      enableBoundingObject FALSE
                    }
                  ]
                }
              ]
              name "fl_caster_wheel_link"
              contactMaterial "wheel"
              boundingObject DEF WHEEL_BO Cylinder {
                height 0.01
                radius 0.0625
              }
              physics Physics {
                density -1
                mass 1
                centerOfMass [
                  0 0 0
                ]
                inertiaMatrix [
                  0.001061895 0.001953125 0.001061895
                  0 0 5.457207e-20
                ]
              }
              linearVelocity 1.4134299405988547e-08 -4.98355659816142e-10 1.2028618809528033e-10
              angularVelocity 1.3714320531926146e-10 1.102391505653804e-07 3.969014974627436e-08
            }
          }
        ]
        name "fl_caster_rotation_link"
        boundingObject Pose {
          translation 0 0 -0.028
          children [
            DEF SWIVEL Cylinder {
              height 0.055
              radius 0.0298
            }
          ]
        }
        physics Physics {
          density -1
          mass 0.309754
          centerOfMass [
            0 0 -0.0425
          ]
          inertiaMatrix [
            0.0005287255 0.000517415 0.0002462724
            -7.734275e-21 -1.120566e-20 -0.0001505672
          ]
        }
        linearVelocity 7.926777751893104e-09 -2.0093385724282367e-09 -5.370644129278645e-10
        angularVelocity 1.358944921456385e-10 -3.15067769582822e-09 3.9344290309532525e-08
      }
    }
    DEF BL_CASTER_ROTATION_JOINT HingeJoint {
      jointParameters HingeJointParameters {
        position 1.3275467921718875e-05
        axis 0 0 1
        anchor -0.270154 0.203 0.1565
        dampingConstant 0.01
      }
      device [
        RotationalMotor {
          name "back_left_wheel_joint"
          maxVelocity 100
          maxTorque 20
        }
        PositionSensor {
          name "back_left_caster_joint_sensor"
        }
      ]
      endPoint DEF BL_CASTER_ROTATION_LINK Solid {
        translation -0.2701497508991513 0.2030071130952407 0.16440597262302642
        rotation 0 0 0.9999999999999999 1.2445779534355491e-05
        children [
          USE CASTER_WHEEL_BASE
          DEF BL_CASTER_WHEEL_JOINT HingeJoint {
            jointParameters HingeJointParameters {
              position 742.7851761856537
              axis 0 1 0
              anchor -0.0382 0 -0.094
            }
            device [
              RotationalMotor {
                name "back_left_wheel"
                maxVelocity 100
                maxTorque 20
              }
              PositionSensor {
                name "back_left_wheel_joint_sensor"
              }
            ]
            endPoint DEF BL_CASTER_WHEEL_LINK Solid {
              translation -0.03808994988676162 -2.948096799570955e-06 -0.09404284402472593
              rotation -0.6547034163515421 0.5344909623365885 0.534493075538053 1.9822469450259004
              children [
                Group {
                  children [
                    USE RIM
                    SolidTorus {
                      translation 0 0 0
                      majorRadius 0.0465
                      minorRadius 0.016
                      appearance USE WHEEL_RUBBER
                      enableBoundingObject FALSE
                    }
                  ]
                }
              ]
              name "bl_caster_wheel_link"
              contactMaterial "wheel"
              boundingObject USE WHEEL_BO
              physics Physics {
                density -1
                mass 1
                centerOfMass [
                  0 0 0
                ]
                inertiaMatrix [
                  0.001061895 0.001953125 0.001061895
                  0 0 5.457207e-20
                ]
              }
              linearVelocity -3.572018304915228e-09 2.3272533590791872e-10 7.149599241466032e-10
              angularVelocity 9.255467069805906e-11 1.2737091896719838e-08 1.855509239358677e-08
            }
          }
        ]
        name "bl_caster_rotation_link"
        boundingObject Pose {
          translation 0 0 -0.028
          children [
            USE SWIVEL
          ]
        }
        physics Physics {
          density -1
          mass 0.309754
          centerOfMass [
            0 0 -0.0425
          ]
          inertiaMatrix [
            0.0005287255 0.000517415 0.0002462724
            -7.734275e-21 -1.120566e-20 -0.0001505672
          ]
        }
        linearVelocity -6.575817699059944e-10 -4.623160935596499e-10 4.4609932592255633e-10
        angularVelocity 9.319630975480374e-11 -1.7266422024079604e-09 1.8510902367232763e-08
      }
    }
    DEF BR_CASTER_ROTATION_JOINT HingeJoint {
      jointParameters HingeJointParameters {
        position 6.101126153156614e-06
        axis 0 0 1
        anchor -0.270154 -0.203 0.1565
        dampingConstant 0.01
      }
      device [
        RotationalMotor {
          name "back_right_wheel_joint"
          maxVelocity 100
          maxTorque 20
        }
        PositionSensor {
          name "back_right_caster_joint_sensor"
        }
      ]
      endPoint DEF BR_CASTER_ROTATION_LINK Solid {
        translation -0.2701443195720145 -0.20305818992191613 0.16301604855217966
        rotation 0 0 1 5.2822462130135185e-06
        children [
          USE CASTER_WHEEL_BASE
          DEF BR_CASTER_WHEEL_JOINT HingeJoint {
            jointParameters HingeJointParameters {
              position 728.8493111168093
              axis 0 1 0
              anchor -0.0382 0 -0.094
            }
            device [
              RotationalMotor {
                name "back_right_wheel"
                maxVelocity 100
                maxTorque 20
              }
              PositionSensor {
                name "back_right_wheel_joint_sensor"
              }
            ]
            endPoint DEF BR_CASTER_WHEEL_LINK Solid {
              translation -0.03840694620490053 -1.0658529570051044e-07 -0.09387012644179725
              rotation -0.9999999914884908 -9.225581020903982e-05 -9.225987237845966e-05 1.5708000106770543
              children [
                Group {
                  children [
                    USE RIM
                    SolidTorus {
                      translation 0 0 0
                      majorRadius 0.0465
                      minorRadius 0.016
                      appearance USE WHEEL_RUBBER
                      enableBoundingObject FALSE
                    }
                  ]
                }
              ]
              name "br_caster_wheel_link"
              contactMaterial "wheel"
              boundingObject USE WHEEL_BO
              physics Physics {
                density -1
                mass 1
                centerOfMass [
                  0 0 0
                ]
                inertiaMatrix [
                  0.001061895 0.001953125 0.001061895
                  0 0 5.457207e-20
                ]
              }
              linearVelocity -4.72336100148729e-09 2.4658096357322573e-10 7.368159345000644e-10
              angularVelocity 9.32000238633284e-11 -2.9762166089137508e-08 1.8253127674625206e-08
            }
          }
        ]
        name "br_caster_rotation_link"
        boundingObject Pose {
          translation 0 0 -0.028
          children [
            USE SWIVEL
          ]
        }
        physics Physics {
          density -1
          mass 0.309754
          centerOfMass [
            0 0 -0.0425
          ]
          inertiaMatrix [
            0.0005287255 0.000517415 0.0002462724
            -7.734275e-21 -1.120566e-20 -0.0001505672
          ]
        }
        linearVelocity -1.7629683140199639e-09 -4.550515972608849e-10 4.682607242963877e-10
        angularVelocity 9.39679191467791e-11 -1.7160105889067167e-09 1.8338747807112584e-08
      }
    }
    DEF SURFACE Solid {
      translation 0.037646 0 0.352
      name "surface"
    }
  ]
  name "Mir100"
  model "Mobile Industrial Robots' MiR100"
  boundingObject Group {
    children [
      DEF TOP Pose {
        translation 0.0375 0.0005 0.334
        children [
          Box {
            size 0.774 0.461 0.04
          }
        ]
      }
      DEF MIDDLE_CENTER Pose {
        translation 0.0375 0.0005 0.262
        children [
          Box {
            size 0.857 0.44 0.096
          }
        ]
      }
      DEF MIDDLE_RIGHT_SIDE Pose {
        translation 0.0375 -0.25 0.262
        children [
          Box {
            size 0.774 0.041 0.096
          }
        ]
      }
      DEF MIDDLE_LEFT_SIDE Pose {
        translation 0.0375 0.25 0.262
        children [
          Box {
            size 0.774 0.041 0.096
          }
        ]
      }
      DEF CYL_BR Pose {
        translation -0.3555 -0.2353 0.262
        children [
          Cylinder {
            height 0.096
            radius 0.054
          }
        ]
      }
      DEF CYL_FL Pose {
        translation 0.4306 0.2364 0.262
        children [
          Cylinder {
            height 0.096
            radius 0.054
          }
        ]
      }
      DEF CYL_FR Pose {
        translation 0.415 -0.221 0.262
        children [
          Cylinder {
            height 0.096
            radius 0.049
          }
        ]
      }
      DEF CYL_BL Pose {
        translation -0.341 0.222 0.262
        children [
          Cylinder {
            height 0.096
            radius 0.049
          }
        ]
      }
      DEF MIDLOW Pose {
        translation 0.03733 0.0005 0.204
        children [
          Box {
            size 0.7806 0.4665 0.04
          }
        ]
      }
      DEF LOW Pose {
        translation 0.0374 0.0005 0.16
        children [
          Box {
            size 0.85 0.536 0.039
          }
        ]
      }
      DEF BOTTOM_LEFT Pose {
        translation 0.0374 0.2586 0.09425
        children [
          Box {
            size 0.35 0.04 0.0925
          }
        ]
      }
      DEF BOTTOM_RIGHT Pose {
        translation 0.0374 -0.2476 0.09425
        children [
          Box {
            size 0.35 0.04 0.0925
          }
        ]
      }
      DEF BOTTOM_CENTER Pose {
        translation 0.0375 0.0005 0.094
        children [
          Box {
            size 0.857 0.2 0.092
          }
        ]
      }
    ]
  }
  physics Physics {
    density -1
    mass 5
  }
  controller "mir100"
  linearVelocity 1.6218721226759897e-09 -1.2587754311758134e-09 -3.4609209296163503e-10
  angularVelocity 6.604342782359281e-11 -2.1165878214102567e-09 2.61411559996733e-09
}
