#VRML_SIM R2025a utf8

EXTERNPROTO "https://raw.githubusercontent.com/cyberbotics/webots/R2025a/projects/objects/backgrounds/protos/TexturedBackground.proto"
EXTERNPROTO "https://raw.githubusercontent.com/cyberbotics/webots/R2025a/projects/objects/backgrounds/protos/TexturedBackgroundLight.proto"
EXTERNPROTO "https://raw.githubusercontent.com/cyberbotics/webots/R2025a/projects/objects/floors/protos/RectangleArena.proto"
EXTERNPROTO "https://raw.githubusercontent.com/cyberbotics/webots/R2025a/projects/appearances/protos/Parquetry.proto"
EXTERNPROTO "../protos/ConveyorBelt.proto"
EXTERNPROTO "../protos/Pioneer3at.proto"
EXTERNPROTO "../protos/WoodenPallet.proto"
EXTERNPROTO "https://raw.githubusercontent.com/cyberbotics/webots/R2025a/projects/objects/factory/containers/protos/CardboardBox.proto"
EXTERNPROTO "https://raw.githubusercontent.com/cyberbotics/webots/R2025a/projects/objects/factory/containers/protos/PlasticFruitBox.proto"
EXTERNPROTO "https://raw.githubusercontent.com/cyberbotics/webots/R2025a/projects/objects/factory/manhole/protos/SquareManhole.proto"
EXTERNPROTO "https://raw.githubusercontent.com/cyberbotics/webots/R2025a/projects/objects/traffic/protos/SignPole.proto"
EXTERNPROTO "https://raw.githubusercontent.com/cyberbotics/webots/R2025a/projects/objects/traffic/protos/DirectionPanel.proto"
EXTERNPROTO "https://raw.githubusercontent.com/cyberbotics/webots/R2025a/projects/humans/pedestrian/protos/Pedestrian.proto"
EXTERNPROTO "https://raw.githubusercontent.com/cyberbotics/webots/R2025a/projects/appearances/protos/Plastic.proto"
EXTERNPROTO "https://raw.githubusercontent.com/cyberbotics/webots/R2025a/projects/robots/mir/mir100/protos/Mir100UltrasonicSensor.proto"
EXTERNPROTO "https://raw.githubusercontent.com/cyberbotics/webots/R2025a/projects/appearances/protos/CorrodedMetal.proto"
EXTERNPROTO "https://raw.githubusercontent.com/cyberbotics/webots/R2025a/projects/objects/solids/protos/SolidTorus.proto"

WorldInfo {
}
Viewpoint {
  orientation -0.4021469955194004 -0.576088687543899 0.7116176066390343 4.731617152252108
  position 1.1772307582037875 1.5788092147718626 1.5006745823925995
  follow "Pioneer 3-AT_0"
  followType "None"
}
TexturedBackground {
}
TexturedBackgroundLight {
}
DEF rectangle_arena RectangleArena {
  translation 15 10 0
  floorSize 30 20
  floorTileSize 1 1
  floorAppearance Parquetry {
    type "dark strip"
  }
}
Pedestrian {
  translation 11.06 7.31002 1.27
  rotation 0 0 1 -3.1415853071795863
}
Pedestrian {
  translation 16.3842 17.72 1.28
  rotation 0 0 1 -0.523595307179586
  name "pedestrian(1)"
}
Pedestrian {
  translation 26.7331 5.34865 1.28
  rotation 0 0 -1 1.5708
  name "pedestrian(2)"
}
SignPole {
  translation 25.3498 15.6897 0
  rotation 0 0 1 3.14159
  height 1
  signBoards [
    DirectionPanel {
      translation 0 0 -0.86
      width 0.4
      height 0.2
    }
  ]
}
PlasticFruitBox {
  translation 28.2254 1.86879 0.63
  rotation 0 0 1 0.261799
  color 0.371527 0.966171 0.557473
}
DEF left_big_conveyor_belt_5 ConveyorBelt {
  hidden translation_1 0 0 1.122088874261258
  translation 17.8 15 0
  rotation 0 0 -1 0
  size 1 5 1.5
}
DEF left_big_conveyor_belt_6 ConveyorBelt {
  hidden translation_1 7.105427357601002e-15 -3.552713678800501e-15 1.1220888742612565
  translation 21 15 0
  rotation 0 0 -1 0
  name "conveyor belt(11)"
  size 1 5 1.5
}
DEF left_big_conveyor_belt_6 ConveyorBelt {
  hidden translation_1 -0.0003848911937467392 2.1388581966874654e-05 1.1471333153877945
  hidden rotation_1 -0.007108017828594725 0.999974682844138 -0.0003312903771018675 0.006046461441891239
  translation 28.88 15 0
  rotation 0 0 -1 0
  name "conveyor belt(25)"
  size 1 5 1.5
}
DEF left_small_conveyor_belt_4 ConveyorBelt {
  hidden translation_1 0 0 0.7470888744526875
  translation 13.33 14.5 0
  rotation 0 0 -1 0
  name "conveyor belt(3)"
  size 1 4 1
}
DEF left_big_conveyor_belt_4 ConveyorBelt {
  hidden translation_1 0 0 1.122088874261258
  translation 14.5 15 0
  rotation 0 0 -1 0
  name "conveyor belt(4)"
  size 1 5 1.5
}
DEF left_small_conveyor_belt_5 ConveyorBelt {
  hidden translation_1 0 0 0.7470888742615042
  translation 16.6 14.5 0
  rotation 0 0 -1 0
  name "conveyor belt(1)"
  size 1 4 1
}
DEF left_small_conveyor_belt_6 ConveyorBelt {
  hidden translation_1 0 0 0.7470888742612497
  translation 19.8 14.5 0
  rotation 0 0 -1 0
  name "conveyor belt(10)"
  size 1 4 1
}
DEF right_small_conveyor_belt_6 ConveyorBelt {
  hidden translation_1 0 0 0.7470888742612497
  translation 23 6 0
  rotation 0 0 -1 0
  name "conveyor belt(2)"
  size 1 4 1
}
DEF right_big_conveyor_belt_6 ConveyorBelt {
  hidden translation_1 0 0 1.122088874261258
  translation 21.8 5.5 0
  rotation 0 0 -1 0
  name "conveyor belt(5)"
  size 1 5 1.5
}
ConveyorBelt {
  hidden translation_1 0 0 0.4470888742612439
  translation 27.8449 2.58127 0
  rotation 0 0 -1 0
  name "conveyor belt(12)"
  size 4 4 0.6
}
DEF right_small_conveyor_belt_5 ConveyorBelt {
  hidden translation_1 0 0 0.7470888742612497
  translation 19.8 6 0
  rotation 0 0 -1 0
  name "conveyor belt(6)"
  size 1 4 1
}
WoodenPallet {
  translation 22.5 8.7 0
  size 2 1 0.1
}
WoodenPallet {
  translation 19 8.7 0
  name "wooden pallet(1)"
  size 2 1 0.1
}
WoodenPallet {
  translation 9.4 8.7 0
  name "wooden pallet(6)"
  size 2 1 0.1
}
WoodenPallet {
  translation 17 11.9 0
  name "wooden pallet(2)"
  size 2 1 0.1
}
WoodenPallet {
  translation 10.73 11.9 0
  name "wooden pallet(3)"
  size 2 1 0.1
}
WoodenPallet {
  translation 7.5 11.9 0
  name "wooden pallet(5)"
  size 2 1 0.1
}
WoodenPallet {
  translation 4.5 11.9 0
  name "wooden pallet(4)"
  size 2 1 0.1
}
DEF right_big_conveyor_belt_5 ConveyorBelt {
  hidden translation_1 0 0 1.122088874261258
  translation 18.5 5.5 0
  rotation 0 0 -1 0
  name "conveyor belt(7)"
  window "<none>"
  size 1 5 1.5
}
DEF right_small_conveyor_belt_4 ConveyorBelt {
  hidden translation_1 0 0 0.7470888742612497
  translation 16.46 6 0
  rotation 0 0 -1 0
  name "conveyor belt(8)"
  window "<none>"
  size 1 4 1
}
DEF right_small_conveyor_belt_3 ConveyorBelt {
  hidden translation_1 0 0 0.7470888744258637
  translation 13.22 6 0
  rotation 0 0 -1 0
  name "conveyor belt(14)"
  window "<none>"
  size 1 4 1
}
DEF left_small_conveyor_belt_2 ConveyorBelt {
  hidden translation_1 0 0 0.7470888742612497
  translation 6.9 14.5 0
  rotation 0 0 -1 0
  name "conveyor belt(21)"
  size 1 4 1
}
DEF left_small_conveyor_belt_1 ConveyorBelt {
  hidden translation_1 0 0 0.7470888742612497
  translation 3.7 14.5 0
  rotation 0 0 -1 0
  name "conveyor belt(23)"
  size 1 4 1
}
DEF left_small_conveyor_belt_3 ConveyorBelt {
  hidden translation_1 0 0 0.7470888742612497
  translation 10.1 14.5 0
  rotation 0 0 -1 0
  name "conveyor belt(19)"
  size 1 4 1
}
DEF right_small_conveyor_belt_2 ConveyorBelt {
  hidden translation_1 0 0 0.7470888742612497
  translation 10 6 0
  rotation 0 0 -1 0
  name "conveyor belt(15)"
  size 1 4 1
}
DEF right_small_conveyor_belt_1 ConveyorBelt {
  hidden translation_1 0 0 0.7470888742612497
  translation 7 6 0
  rotation 0 0 -1 0
  name "conveyor belt(17)"
  size 1 4 1
}
DEF right_big_conveyor_belt_4 ConveyorBelt {
  hidden translation_1 0 0 1.122088874261258
  translation 15.3 5.5 0
  rotation 0 0 -1 0
  name "conveyor belt(9)"
  size 1 5 1.5
}
DEF right_big_conveyor_belt_3 ConveyorBelt {
  hidden translation_1 0 0 1.122088874261258
  translation 12 5.5 0
  rotation 0 0 -1 0
  name "conveyor belt(13)"
  size 1 5 1.5
}
DEF left_big_conveyor_belt_3 ConveyorBelt {
  hidden translation_1 0 0 1.122088874261258
  translation 11.3 15 0
  rotation 0 0 -1 0
  name "conveyor belt(20)"
  size 1 5 1.5
}
DEF left_big_conveyor_belt_2 ConveyorBelt {
  hidden translation_1 0 0 1.122088874261258
  translation 8.1 15 0
  rotation 0 0 -1 0
  name "conveyor belt(22)"
  size 1 5 1.5
}
DEF left_big_conveyor_belt_1 ConveyorBelt {
  hidden translation_1 0 0 1.122088874261258
  translation 4.9 15 0
  rotation 0 0 -1 0
  name "conveyor belt(24)"
  size 1 5 1.5
}
DEF right_big_conveyor_belt_2 ConveyorBelt {
  hidden translation_1 0 0 1.122088874261258
  translation 8.8 5.5 0
  rotation 0 0 -1 0
  name "conveyor belt(16)"
  size 1 5 1.5
}
DEF right_big_conveyor_belt_1 ConveyorBelt {
  hidden translation_1 0 0 1.122088874261258
  translation 5.8 5.5 0
  rotation 0 0 -1 0
  name "conveyor belt(18)"
  size 1 5 1.5
}
CardboardBox {
  translation 27.8384 3.01098 0.71
  rotation 0 0 1 0.261799
  size 0.2 0.2 0.2
}
CardboardBox {
  translation 28.0224 3.48865 0.71
  rotation 0 0 1 0.785398
  name "cardboard box(1)"
  size 0.2 0.2 0.2
}
CardboardBox {
  translation 21.6903 3.22499 1.6
  rotation 0 0 1 1.309
  name "cardboard box(6)"
  size 0.2 0.2 0.2
}
CardboardBox {
  translation 7.98736 14.1014 1.6
  rotation 0 0 1 1.309
  name "cardboard box(7)"
  size 0.2 0.2 0.2
}
CardboardBox {
  translation 15.3336 4.18682 1.6
  rotation 0 0 1 2.0944
  name "cardboard box(10)"
  size 0.2 0.2 0.2
}
CardboardBox {
  translation 11.2185 13.9355 1.6
  rotation 0 0 1 2.0944
  name "cardboard box(11)"
  size 0.2 0.2 0.2
}
CardboardBox {
  translation 4.6953 16.4739 1.6
  rotation 0 0 1 2.0944
  name "cardboard box(12)"
  size 0.2 0.2 0.2
}
CardboardBox {
  translation 5.94515 4.74132 1.6
  rotation 0 0 1 1.309
  name "cardboard box(9)"
  size 0.2 0.2 0.2
}
CardboardBox {
  translation 26.2061 1.6839 0.71
  rotation 0 0 1 1.309
  name "cardboard box(8)"
  size 0.2 0.2 0.2
}
CardboardBox {
  translation 28.3211 1.96902 0.77
  rotation 0 0 1 4.692820414042842e-06
  name "cardboard box(5)"
  size 0.2 0.2 0.2
}
CardboardBox {
  translation 28.0496 3.95362 0.71
  rotation 0 0 1 0.261803
  name "cardboard box(2)"
  size 0.2 0.2 0.2
}
CardboardBox {
  translation 18.9049 8.5223 0.11
  rotation 0 0 1 1.5708
  name "cardboard box(4)"
  size 0.2 0.2 0.2
}
CardboardBox {
  translation 20.9849 7.7223 0.11
  rotation 0 0 1 1.5708
  name "cardboard box(13)"
  size 0.2 0.2 0.2
}
CardboardBox {
  translation 17.3949 8.2323 0.11
  rotation 0 0 1 1.5708
  name "cardboard box(16)"
  size 0.2 0.2 0.2
}
CardboardBox {
  translation 18.6349 12.5223 0.11
  rotation 0 0 1 1.5708
  name "cardboard box(17)"
  size 0.2 0.2 0.2
}
CardboardBox {
  translation 17.0749 12.4123 0.11
  rotation 0 0 1 1.5708
  name "cardboard box(18)"
  size 0.2 0.2 0.2
}
CardboardBox {
  translation 24.9049 4.5023 0.11
  rotation 0 0 1 1.5708
  name "cardboard box(15)"
  size 0.2 0.2 0.2
}
CardboardBox {
  translation 24.3649 4.5123 0.11
  rotation 0 0 1 1.5708
  name "cardboard box(14)"
  size 0.2 0.2 0.2
}
CardboardBox {
  translation 22.6249 18.7445 0.15
  rotation 0 0 1 4.07987e-06
  name "cardboard box(3)"
  size 0.2 0.2 0.2
}
Pose {
}
DEF SUPERVISOR Robot {
  rotation 0 0 1 -2.8797853071795863
  controller "floor_mapper"
  supervisor TRUE
}
DEF Pioneer_3-AT Pioneer3at {
  hidden position_0_0 17181.675597810736
  hidden position_0_1 14901.686214389332
  hidden position_0_2 17201.273777642607
  hidden position_0_3 14922.746012564687
  hidden linearVelocity_0 -1.5990157682792146e-12 2.57159835566219e-14 5.1675835328007286e-17
  hidden angularVelocity_0 -9.385881861374117e-15 3.6775984836760854e-15 -4.900083807417035e-15
  hidden rotation_1 0.5773516024134749 -0.5773476024162304 -0.5773516027299337 2.094404999683543
  hidden translation_2 4.390430234023778e-13 2.1847962280823109e-13 0.04999999999999215
  hidden rotation_2 -0.42526537133496617 0.425258256650912 -0.7989397843977734 1.7934126943521096
  hidden rotation_3 0.5988398786453055 -0.5988355014271939 -0.531777060406442 2.1641145754326065
  hidden linearVelocity_3 -1.5720075919803437e-12 2.4048383264126736e-14 1.4210911258239135e-15
  hidden angularVelocity_3 -1.2077591751468197e-14 -3.5352418785971452e-12 3.701884873857105e-14
  hidden rotation_4 -0.3115849445168318 0.31158478142933627 0.8976802027069972 4.604645138172588
  hidden linearVelocity_4 -1.6066873138595288e-12 2.5785898280147293e-14 -1.6341943818046008e-15
  hidden angularVelocity_4 -3.2433264990658384e-14 -2.2212292881608795e-11 2.653474329225191e-13
  hidden rotation_5 0.08194373227322942 -0.08193950351883317 0.9932628768378593 4.705619059790349
  hidden linearVelocity_5 -1.571979681973879e-12 -1.798126967390488e-14 1.7763049745950311e-15
  hidden angularVelocity_5 -4.3079620383315425e-14 -1.8097436839127538e-11 2.1439006259561794e-13
  hidden rotation_6 -0.37949243221473694 0.37949138391661935 0.8437842042991753 4.543329733525855
  hidden linearVelocity_6 -1.6062818907074148e-12 -1.9816967234067145e-14 -1.3500223745350025e-15
  hidden angularVelocity_6 -1.1075623215856544e-14 -2.5615890167774184e-12 2.6688469134212227e-14
  translation 21.474789389970336 10.903091970329594 0.0003579822304023428
  rotation 0.009578648359298994 0.006087279264806389 0.9999355951893908 3.1400405392354465
  name "Pioneer 3-AT_0"
  controller "pioneer_controller"
}
DEF Pioneer_3-AT Pioneer3at {
  hidden position_0_0 17180.781322602295
  hidden position_0_1 14902.012855460223
  hidden position_0_2 17201.44317876107
  hidden position_0_3 14923.74740811703
  hidden linearVelocity_0 2.234210707953716e-14 4.5869408334751265e-15 -5.1675835328007286e-17
  hidden angularVelocity_0 8.847244901237641e-16 7.332209661723786e-16 1.5107146720043142e-16
  hidden rotation_1 0.5773516024134749 -0.5773476024162304 -0.5773516027299337 2.094404999683543
  hidden translation_2 4.390430234023778e-13 2.1847962280823109e-13 0.04999999999999215
  hidden rotation_2 -0.42526537133496617 0.425258256650912 -0.7989397843977734 1.7934126943521096
  hidden rotation_3 0.6930327124662691 -0.693026227300684 -0.1985454802432583 2.7496079561646787
  hidden linearVelocity_3 2.6605221703809686e-14 6.6188795289401276e-15 1.4209939977901663e-16
  hidden angularVelocity_3 6.716677500789046e-15 7.115436604918209e-15 3.6499577602415463e-16
  hidden rotation_4 -0.16753776504962492 0.1675393418618175 0.9715254326113577 4.683494249770281
  hidden linearVelocity_4 -3.583648624846736e-15 -8.11102458571661e-15 -2.1319248405913649e-16
  hidden angularVelocity_4 5.6457524476261616e-15 2.4032802418080004e-15 3.3866113676387243e-16
  hidden rotation_5 0.16398799953183937 -0.16398299289182086 0.9727371248450356 4.684741341127175
  hidden linearVelocity_5 -1.4869048851745115e-14 6.4379994971874066e-15 -4.973721356743585e-16
  hidden angularVelocity_5 8.889923941302523e-15 8.205605462539453e-17 3.613022665719214e-16
  hidden rotation_6 0.07773614574708375 -0.0777319581663731 0.993939049602142 4.706299558615522
  hidden linearVelocity_6 -7.245771136192793e-15 -8.584257060298134e-15 2.1311965553608272e-16
  hidden angularVelocity_6 1.2099685559537431e-14 -2.2394693822308815e-15 3.8034052205550655e-16
  translation 14.256699999296933 5.304799941431381 -0.0023889310687115195
  rotation -2.4736974944312665e-05 2.4823257165708656e-05 0.999999999385944 1.5554589192107413
  name "Pioneer 3-AT_1"
  controller "pioneer_controller_1"
}
DEF Pioneer_3-AT Pioneer3at {
  hidden position_0_0 17180.454441604186
  hidden position_0_1 14901.654045764164
  hidden position_0_2 17201.22296917776
  hidden position_0_3 14923.432880804237
  hidden linearVelocity_0 4.849059916227235e-15 1.6658310242695522e-14 -1.0335167065601457e-16
  hidden angularVelocity_0 -1.8079151168379758e-15 7.999757342955065e-20 3.653750622634451e-15
  hidden rotation_1 0.5773516024134749 -0.5773476024162304 -0.5773516027299337 2.094404999683543
  hidden translation_2 4.390430234023778e-13 2.1847962280823109e-13 0.04999999999999215
  hidden rotation_2 -0.42526537133496617 0.425258256650912 -0.7989397843977734 1.7934126943521096
  hidden rotation_3 0.7047397682804863 -0.704732764679641 -0.08181435932008528 2.978334010360019
  hidden linearVelocity_3 1.5780409589124605e-14 -2.4324547309020542e-14 3.5529319044117684e-16
  hidden angularVelocity_3 -1.1757670614213433e-15 -5.652043891330636e-15 5.083629371285264e-15
  hidden rotation_4 -0.3244966544389927 0.32449632662075334 0.8884841333797348 4.594413538132474
  hidden linearVelocity_4 -1.6712358853064853e-14 -2.4201506032158367e-14 -4.2631690492717365e-16
  hidden angularVelocity_4 5.8049912311603295e-21 -1.1145461579945906e-15 3.809113572830143e-15
  hidden rotation_5 0.056786419890742505 -0.0567824391477218 0.9967703131215472 4.709143933295925
  hidden linearVelocity_5 1.5761072983327084e-14 2.4237392907181328e-14 5.684082534260334e-16
  hidden angularVelocity_5 -1.1757204880119642e-15 -5.8861758192202486e-15 4.237873850041803e-15
  hidden rotation_6 -0.07888296150006355 0.07888553009617458 0.993757793190285 4.706116647194325
  hidden linearVelocity_6 -1.736716774513364e-14 2.408282836123446e-14 5.684538680253726e-16
  hidden angularVelocity_6 2.351544397059944e-15 -1.0257232001659233e-14 4.6964369953794516e-15
  translation 10.682299346961068 9.696709999980968 -0.0023889310679025
  rotation -0.007212864466455892 0.9999538074744647 -0.006352755583994139 4.918019781223578e-05
  name "Pioneer 3-AT_2"
  controller "pioneer_controller_2"
}
DEF Pioneer_3-AT Pioneer3at {
  hidden position_0_0 17180.454404988628
  hidden position_0_1 14901.654010969487
  hidden position_0_2 17201.223057057512
  hidden position_0_3 14923.432970219175
  hidden linearVelocity_0 6.342826358837509e-15 1.638243773406938e-14 1.0335167065601457e-16
  hidden angularVelocity_0 3.6108554853097344e-16 4.885366346215359e-16 -2.475958675224498e-16
  hidden rotation_1 0.5773516024134749 -0.5773476024162304 -0.5773516027299337 2.094404999683543
  hidden translation_2 4.390430234023778e-13 2.1847962280823109e-13 0.04999999999999215
  hidden rotation_2 -0.42526537133496617 0.425258256650912 -0.7989397843977734 1.7934126943521096
  hidden rotation_3 0.7047405221819186 -0.7047335185290585 -0.08180137074896712 2.9783598145573755
  hidden linearVelocity_3 1.0932326862390608e-14 -2.4328491934572463e-14 1.4210357408574697e-16
  hidden angularVelocity_3 2.351473632858342e-15 -6.043804223700176e-15 -2.530053773893831e-15
  hidden rotation_4 -0.3245104839510334 0.3245101559554968 0.8884740314086874 4.594402247146985
  hidden linearVelocity_4 -1.2659712312554203e-14 -2.4139893126027644e-14 -4.263411444909699e-16
  hidden angularVelocity_4 1.1757447079791985e-15 2.948702783141041e-16 -1.147645028899433e-15
  hidden rotation_5 0.05683007641276318 -0.056826095235579056 0.9967653371356752 4.709138941351068
  hidden linearVelocity_5 2.033110437488418e-14 2.3983901716092615e-14 7.104767258977283e-17
  hidden angularVelocity_5 2.1208088235164872e-20 -4.341983303173351e-15 -2.8593093421023463e-15
  hidden rotation_6 -0.07883880925667264 0.07884137833287436 0.9937648007539625 4.7061236987652
  hidden linearVelocity_6 -2.0860111685582612e-14 2.3730778247356152e-14 -3.5524395268354314e-16
  hidden angularVelocity_6 3.5272967983311956e-15 -1.044458324396381e-14 -2.0651159908501347e-15
  translation 7.89171174144434 9.700530025629593 -0.0023889310679026388
  rotation -0.00721041653058904 0.9997153476879935 -0.02274276787309578 4.9191928795114106e-05
  name "Pioneer 3-AT_3"
  controller "pioneer_controller_3"
}
SquareManhole {
  translation 25 19 0
}
SquareManhole {
  translation 19.092 9.85948 -0.04
  rotation 0 0 1 0.523602
  name "manhole(16)"
}
SquareManhole {
  translation 20.7736 10.6536 -0.04
  rotation 0 0 1 0.785401
  name "manhole(17)"
}
SquareManhole {
  translation 9.00273 10.7778 -0.02
  rotation 0 0 1 1.5708
  name "manhole(12)"
}
SquareManhole {
  translation 4.9337 9.8387 -0.04
  rotation 9.58978e-09 3.57898e-08 1 -0.523595307179586
  name "manhole(11)"
}
WoodenPallet {
  translation 6 8.7 0
  name "wooden pallet(7)"
  size 2 1 0.1
}
WoodenPallet {
  translation 12.72 8.7 0
  name "wooden pallet(8)"
  size 2 1 0.1
}
WoodenPallet {
  translation 15.74 8.7 0
  name "wooden pallet(9)"
  size 2 1 0.1
}
WoodenPallet {
  translation 13.93 11.89 0
  name "wooden pallet(10)"
  size 2 1 0.1
}
WoodenPallet {
  translation 20.37 11.89 0
  name "wooden pallet(11)"
  size 2 1 0.1
}
Robot {
  translation 1.6005415523978745 1.4133712482196292 -0.010404290991913423
  rotation -0.6710453124584536 0.6696805047149582 -0.318160667324318 0.00477737686241638
  children [
    Pose {
      translation 0.037646 0 0
      children [
        Shape {
          appearance DEF WHITE Plastic {
          }
          geometry Mesh {
            url [
              "https://raw.githubusercontent.com/cyberbotics/webots/R2025a/projects/robots/mir/mir100/protos/meshes/mir_100_base.obj"
            ]
          }
        }
        Shape {
          appearance USE WHITE
          geometry Mesh {
            url [
              "https://raw.githubusercontent.com/cyberbotics/webots/R2025a/projects/robots/mir/mir100/protos/meshes/mir_100_inside.obj"
            ]
          }
        }
        Shape {
          appearance Plastic {
            colorOverride 0.93 0.93 0.93
          }
          geometry Mesh {
            url [
              "https://raw.githubusercontent.com/cyberbotics/webots/R2025a/projects/robots/mir/mir100/protos/meshes/mir_100_logos.dae"
            ]
          }
        }
        Shape {
          appearance DEF BLACK Plastic {
            colorOverride 0 0 0
          }
          geometry Mesh {
            url [
              "https://raw.githubusercontent.com/cyberbotics/webots/R2025a/projects/robots/mir/mir100/protos/meshes/mir_100_base_corners.dae"
            ]
          }
        }
        Shape {
          appearance DEF BLACK Plastic {
            colorOverride 0 0 0
          }
          geometry Mesh {
            url [
              "https://raw.githubusercontent.com/cyberbotics/webots/R2025a/projects/robots/mir/mir100/protos/meshes/mir_100_top_plugs.dae"
            ]
          }
        }
      ]
    }
    DEF IMU Pose {
      translation 0 0 0.25
      children [
        Accelerometer {
          name "imu_data accelerometer"
          lookupTable [
            -100 -100 -0.002
            100 100 0.002
          ]
        }
        Gyro {
          name "imu_data gyro"
          lookupTable [
            -100 -100 -0.002
            100 100 0.002
          ]
        }
        Compass {
          name "imu_data compass"
          lookupTable [
            -1 -1 -0.2
            1 1 0.2
          ]
        }
      ]
    }
    Pose {
      translation 0.4288 0.2358 0.188
      rotation -0.9238797538373538 -0.38268289803626016 0 -3.14159
    }
    Pose {
      translation -0.3548 -0.2352 0.188
      rotation 0.38268289803626016 -0.9238797538373538 0 -3.14159
    }
    Pose {
      translation 0.037646 0 0.349
    }
    DEF CAMERA_RIGHT Transform {
      translation 0.448325 -0.063463 0.110114
      rotation 0.23089800552792925 -0.8463170202616761 -0.48003501149251837 -1.480875307179586
      scale 1.0003465485345713 0.92893 0.92893
      children [
        Shape {
          appearance Appearance {
            material Material {
              emissiveColor 1 1 1
            }
            texture ImageTexture {
              url [
                "https://raw.githubusercontent.com/cyberbotics/webots/R2025a/projects/robots/mir/mir100/protos/textures/camera.png"
              ]
            }
            textureTransform TextureTransform {
              rotation 3.1415926
            }
          }
          geometry Plane {
            size 0.08 0.015
          }
        }
      ]
    }
    DEF CAMERA_LEFT Transform {
      translation 0.448325 0.063463 0.110114
      rotation 0.6034542780292518 -0.1646370758531751 0.7802163594687759 2.48203
      scale 1.0003465485345713 0.92893 0.92893
      children [
        Shape {
          appearance Appearance {
            material Material {
              emissiveColor 1 1 1
            }
            texture ImageTexture {
              url [
                "https://raw.githubusercontent.com/cyberbotics/webots/R2025a/projects/robots/mir/mir100/protos/textures/camera.png"
              ]
            }
          }
          geometry Plane {
            size 0.08 0.015
          }
        }
      ]
    }
    Mir100UltrasonicSensor {
      translation 0.415448 -0.108238 0.08
      rotation 0.8628559982596194 -0.35740699927911007 -0.35740699927911007 1.71777
      name "ds0"
      lookupTable [
        0.2 1000 0
        0.3 0 0
      ]
    }
    Mir100UltrasonicSensor {
      translation -0.3844 -0.1328 0.156
      rotation 0 0 1 3.141592653589793
      name "ds1"
    }
    Mir100UltrasonicSensor {
      translation -0.3844 0.1328 0.156
      rotation 0 0 1 3.141592653589793
      name "ds2"
    }
    Mir100UltrasonicSensor {
      translation 0.415448 0.108238 0.08
      rotation 0.8628559982596194 0.35740699927911007 0.35740699927911007 1.71777
      name "ds3"
      lookupTable [
        0.2 1000 0
        0.3 0 0
      ]
    }
    RangeFinder {
      translation 0.004 -0.28 0.18
      rotation 0 0 1 1.01416e-06
      name "depth_camera"
      fieldOfView 2.05949
      width 1280
      height 720
      minRange 0.18
      maxRange 1.95
    }
    Pose {
      translation 0.03733 0.0005 0.2085
      children [
        DEF LIGHT_FRONT Pose {
          translation 0.392 0 0
          children [
            DEF LIGHT_WIDTH_SHAPE Shape {
              appearance PBRAppearance {
                transparency 0.5
                emissiveColor 0 0.9 1
              }
              geometry Box {
                size 0.001 0.4723 0.053
              }
            }
          ]
        }
        DEF LIGHT_BACK Pose {
          translation -0.392 0 0
          children [
            USE LIGHT_WIDTH_SHAPE
          ]
        }
        DEF LIGHT_LEFT Pose {
          translation 0 0.2355 0
          children [
            DEF LIGHT_WIDTH_SHAPE Shape {
              appearance PBRAppearance {
                transparency 0.5
                emissiveColor 0 0.9 1
              }
              geometry Box {
                size 0.783 0.001 0.053
              }
            }
          ]
        }
        DEF LIGHT_RIGHT Pose {
          translation 0 -0.2355 0
          children [
            USE LIGHT_WIDTH_SHAPE
          ]
        }
      ]
    }
    DEF US_1_FRAME Solid {
      translation 0.45 -0.12 0.16
      name "us_1_frame"
    }
    DEF US_2_FRAME Solid {
      translation 0.45 0.12 0.16
      name "us_2_frame"
    }
    DEF LEFT_WHEEL_JOINT HingeJoint {
      jointParameters HingeJointParameters {
        position -5.007777195537513e-05
        axis 0 1 0
        anchor 0 0.222604 0.0625
      }
      device [
        RotationalMotor {
          name "middle_left_wheel_joint"
          maxVelocity 20
          maxTorque 100
        }
        PositionSensor {
          name "middle_left_wheel_joint_sensor"
        }
      ]
      endPoint DEF LEFT_WHEEL_LINK Solid {
        translation 0 0.222604 0.0625
        rotation -0.9999999993730565 -2.5038793994427508e-05 -2.503888596722228e-05 1.5708000006269411
        children [
          Group {
            children [
              DEF RIM Shape {
                appearance CorrodedMetal {
                }
                geometry Cylinder {
                  height 0.032
                  radius 0.0465
                }
              }
              SolidTorus {
                translation 0 0 0
                majorRadius 0.0465
                minorRadius 0.016
                appearance DEF WHEEL_RUBBER PBRAppearance {
                  baseColor 0 0 0
                  roughness 1
                  metalness 0
                }
                enableBoundingObject FALSE
              }
            ]
          }
        ]
        name "left_wheel_link"
        contactMaterial "wheel"
        boundingObject DEF WHEEL_BO Cylinder {
          height 0.01
          radius 0.0625
        }
        physics Physics {
          density -1
          mass 1
          centerOfMass [
            0 0 0
          ]
          inertiaMatrix [
            0.001061895 0.001953125 0.001061895
            0 0 5.457207e-20
          ]
        }
        linearVelocity 3.724945716315986e-06 2.4196365604378662e-06 -1.2278426771672462e-07
        angularVelocity -4.953173601747368e-07 7.363838333349969e-07 -7.070839331771038e-06
      }
    }
    DEF RIGHT_WHEEL_JOINT HingeJoint {
      jointParameters HingeJointParameters {
        position -2.285609818354346e-05
        axis 0 1 0
        anchor 0 -0.222604 0.0625
      }
      device [
        RotationalMotor {
          name "middle_right_wheel_joint"
          maxVelocity 20
          maxTorque 100
        }
        PositionSensor {
          name "middle_right_wheel_joint_sensor"
        }
      ]
      endPoint DEF RIGHT_WHEEL_LINK Solid {
        translation 0 -0.222604 0.0625
        rotation -0.9999999998694002 -1.1428007113285604e-05 -1.1428049090776728e-05 1.5708000001305973
        children [
          Group {
            children [
              USE RIM
              SolidTorus {
                translation 0 0 0
                majorRadius 0.0465
                minorRadius 0.016
                appearance USE WHEEL_RUBBER
                enableBoundingObject FALSE
              }
            ]
          }
        ]
        name "right_wheel_link"
        contactMaterial "wheel"
        boundingObject USE WHEEL_BO
        physics Physics {
          density -1
          mass 1
          centerOfMass [
            0 0 0
          ]
          inertiaMatrix [
            0.001061895 0.001953125 0.001061895
            0 0 5.457207e-20
          ]
        }
        linearVelocity 5.782326763525971e-07 2.425116007629847e-06 9.389534255888065e-08
        angularVelocity -4.95906112251945e-07 3.4609571624610863e-07 -7.0695871457544805e-06
      }
    }
    DEF FL_CASTER_ROTATION_JOINT HingeJoint {
      jointParameters HingeJointParameters {
        position 1.994973334658577
        axis 0 0 1
        anchor 0.341346 0.203 0.1565
        dampingConstant 0.01
      }
      device [
        PositionSensor {
          name "front_left_caster_joint_sensor"
        }
      ]
      endPoint DEF FL_CASTER_ROTATION_LINK Solid {
        translation 0.341346 0.203 0.1565
        rotation 0 0 1 1.994973334658577
        children [
          DEF CASTER_WHEEL_BASE Shape {
            appearance PBRAppearance {
              baseColor 0.35 0.35 0.35
              roughness 1
              metalness 0
            }
            geometry Mesh {
              url [
                "https://raw.githubusercontent.com/cyberbotics/webots/R2025a/projects/robots/mir/mir100/protos/meshes/caster_wheel_base.dae"
              ]
            }
          }
          DEF FL_CASTER_WHEEL_JOINT HingeJoint {
            jointParameters HingeJointParameters {
              position -0.15097301160775012
              axis 0 1 0
              anchor -0.0382 0 -0.094
            }
            device [
              PositionSensor {
                name "front_left_wheel_joint_sensor"
              }
            ]
            endPoint DEF FL_CASTER_WHEEL_LINK Solid {
              translation -0.0382 0 -0.094
              rotation -0.9943287047375641 -0.07520101525046151 -0.0752012914797218 1.576487407399207
              children [
                Group {
                  children [
                    USE RIM
                    SolidTorus {
                      translation 0 0 0
                      majorRadius 0.0465
                      minorRadius 0.016
                      appearance USE WHEEL_RUBBER
                      enableBoundingObject FALSE
                    }
                  ]
                }
              ]
              name "fl_caster_wheel_link"
              contactMaterial "wheel"
              boundingObject USE WHEEL_BO
              physics Physics {
                density -1
                mass 1
                centerOfMass [
                  0 0 0
                ]
                inertiaMatrix [
                  0.001061895 0.001953125 0.001061895
                  0 0 5.457207e-20
                ]
              }
              linearVelocity -1.9158257075178036e-06 -2.4670951489031983e-06 -1.6589075636375123e-07
              angularVelocity 2.0668134975722923e-05 9.530138415455933e-06 -0.00015792920812741592
            }
          }
        ]
        name "fl_caster_rotation_link"
        boundingObject Pose {
          translation 0 0 -0.028
          children [
            DEF SWIVEL Cylinder {
              height 0.055
              radius 0.0298
            }
          ]
        }
        physics Physics {
          density -1
          mass 0.309754
          centerOfMass [
            0 0 -0.0425
          ]
          inertiaMatrix [
            0.0005287255 0.000517415 0.0002462724
            -7.734275e-21 -1.120566e-20 -0.0001505672
          ]
        }
        linearVelocity 3.5980625929503936e-06 3.041919854447676e-08 -2.0666226775725629e-07
        angularVelocity -9.788410343777202e-07 -2.058538506744377e-07 -0.00015782871070302545
      }
    }
    DEF FR_CASTER_ROTATION_JOINT HingeJoint {
      jointParameters HingeJointParameters {
        position 0.24451512662474525
        axis 0 0 1
        anchor 0.341346 -0.203 0.1565
        dampingConstant 0.01
      }
      device [
        PositionSensor {
          name "front_right_caster_joint_sensor"
        }
      ]
      endPoint DEF FR_CASTER_ROTATION_LINK Solid {
        translation 0.341346 -0.203 0.1565
        rotation 0 0 1 0.24451512662474606
        children [
          USE CASTER_WHEEL_BASE
          DEF FR_CASTER_WHEEL_JOINT HingeJoint {
            jointParameters HingeJointParameters {
              position 0.07406088341898165
              axis 0 1 0
              anchor -0.0382 0 -0.094
            }
            device [
              PositionSensor {
                name "front_right_wheel_joint_sensor"
              }
            ]
            endPoint DEF FR_CASTER_WHEEL_LINK Solid {
              translation -0.0382 0 -0.094
              rotation -0.9986303160948325 0.03699649794889982 0.03699663384487445 1.572170622346969
              children [
                Group {
                  children [
                    USE RIM
                    SolidTorus {
                      translation 0 0 0
                      majorRadius 0.0465
                      minorRadius 0.016
                      appearance USE WHEEL_RUBBER
                      enableBoundingObject FALSE
                    }
                  ]
                }
              ]
              name "fr_caster_wheel_link"
              contactMaterial "wheel"
              boundingObject USE WHEEL_BO
              physics Physics {
                density -1
                mass 1
                centerOfMass [
                  0 0 0
                ]
                inertiaMatrix [
                  0.001061895 0.001953125 0.001061895
                  0 0 5.457207e-20
                ]
              }
              linearVelocity 1.0004622066176472e-06 -1.149210908165444e-06 9.576372065112081e-09
              angularVelocity -2.949672527835077e-06 1.0793504836790307e-05 3.127444046818903e-05
            }
          }
        ]
        name "fr_caster_rotation_link"
        boundingObject Pose {
          translation 0 0 -0.028
          children [
            USE SWIVEL
          ]
        }
        physics Physics {
          density -1
          mass 0.309754
          centerOfMass [
            0 0 -0.0425
          ]
          inertiaMatrix [
            0.0005287255 0.000517415 0.0002462724
            -7.734275e-21 -1.120566e-20 -0.0001505672
          ]
        }
        linearVelocity 7.281896179701388e-07 3.558264948474711e-08 -8.622180627512261e-09
        angularVelocity -3.731621152758441e-07 4.00064392683468e-07 3.129948562934131e-05
      }
    }
    DEF BL_CASTER_ROTATION_JOINT HingeJoint {
      jointParameters HingeJointParameters {
        position 1.9845481757804206
        axis 0 0 1
        anchor -0.270154 0.203 0.1565
        dampingConstant 0.01
      }
      device [
        PositionSensor {
          name "back_left_caster_joint_sensor"
        }
      ]
      endPoint DEF BL_CASTER_ROTATION_LINK Solid {
        translation -0.270154 0.203 0.1565
        rotation 0 0 1 1.9845481757804206
        children [
          USE CASTER_WHEEL_BASE
          DEF BL_CASTER_WHEEL_JOINT HingeJoint {
            jointParameters HingeJointParameters {
              position -0.14270106150671358
              axis 0 1 0
              anchor -0.0382 0 -0.094
            }
            device [
              PositionSensor {
                name "back_left_wheel_joint_sensor"
              }
            ]
            endPoint DEF BL_CASTER_WHEEL_LINK Solid {
              translation -0.0382 0 -0.094
              rotation -0.9949306027822674 -0.07110927682039643 -0.07110953801983452 1.5758822682770592
              children [
                Group {
                  children [
                    USE RIM
                    SolidTorus {
                      translation 0 0 0
                      majorRadius 0.0465
                      minorRadius 0.016
                      appearance USE WHEEL_RUBBER
                      enableBoundingObject FALSE
                    }
                  ]
                }
              ]
              name "bl_caster_wheel_link"
              contactMaterial "wheel"
              boundingObject USE WHEEL_BO
              physics Physics {
                density -1
                mass 1
                centerOfMass [
                  0 0 0
                ]
                inertiaMatrix [
                  0.001061895 0.001953125 0.001061895
                  0 0 5.457207e-20
                ]
              }
              linearVelocity -3.0605937965209053e-06 1.4216726110891641e-06 1.6836478948789573e-09
              angularVelocity -3.786518626262212e-05 -1.6393798004888922e-05 -0.00018984105343147753
            }
          }
        ]
        name "bl_caster_rotation_link"
        boundingObject Pose {
          translation 0 0 -0.028
          children [
            USE SWIVEL
          ]
        }
        physics Physics {
          density -1
          mass 0.309754
          centerOfMass [
            0 0 -0.0425
          ]
          inertiaMatrix [
            0.0005287255 0.000517415 0.0002462724
            -7.734275e-21 -1.120566e-20 -0.0001505672
          ]
        }
        linearVelocity 3.6051652395182046e-06 4.354275739583224e-06 -4.0998893042879684e-08
        angularVelocity -1.0817604053469028e-06 -3.0889247338798173e-07 -0.00019001035240242398
      }
    }
    DEF BR_CASTER_ROTATION_JOINT HingeJoint {
      jointParameters HingeJointParameters {
        position 0.016795549842387014
        axis 0 0 1
        anchor -0.270154 -0.203 0.1565
        dampingConstant 0.01
      }
      device [
        PositionSensor {
          name "back_right_caster_joint_sensor"
        }
      ]
      endPoint DEF BR_CASTER_ROTATION_LINK Solid {
        translation -0.270154 -0.203 0.1565
        rotation 0 0 1 0.016795549842381446
        children [
          USE CASTER_WHEEL_BASE
          DEF BR_CASTER_WHEEL_JOINT HingeJoint {
            jointParameters HingeJointParameters {
              position 0.09734499433673453
              axis 0 1 0
              anchor -0.0382 0 -0.094
            }
            device [
              PositionSensor {
                name "back_right_wheel_joint_sensor"
              }
            ]
            endPoint DEF BR_CASTER_WHEEL_LINK Solid {
              translation -0.0382 0 -0.094
              rotation -0.9976356618817641 0.048595621165236254 0.04859579966724773 1.573167135358105
              children [
                Group {
                  children [
                    USE RIM
                    SolidTorus {
                      translation 0 0 0
                      majorRadius 0.0465
                      minorRadius 0.016
                      appearance USE WHEEL_RUBBER
                      enableBoundingObject FALSE
                    }
                  ]
                }
              ]
              name "br_caster_wheel_link"
              contactMaterial "wheel"
              boundingObject USE WHEEL_BO
              physics Physics {
                density -1
                mass 1
                centerOfMass [
                  0 0 0
                ]
                inertiaMatrix [
                  0.001061895 0.001953125 0.001061895
                  0 0 5.457207e-20
                ]
              }
              linearVelocity 8.075000155933764e-07 -1.403213166355499e-06 1.8320734073995477e-07
              angularVelocity -1.798112267662763e-07 1.3048643772600464e-05 0.0001501925669882149
            }
          }
        ]
        name "br_caster_rotation_link"
        boundingObject Pose {
          translation 0 0 -0.028
          children [
            USE SWIVEL
          ]
        }
        physics Physics {
          density -1
          mass 0.309754
          centerOfMass [
            0 0 -0.0425
          ]
          inertiaMatrix [
            0.0005287255 0.000517415 0.0002462724
            -7.734275e-21 -1.120566e-20 -0.0001505672
          ]
        }
        linearVelocity 7.352859318430793e-07 4.359356574750618e-06 1.5692063584481603e-07
        angularVelocity 7.632692373294907e-09 7.809213489242115e-07 0.00015023126532567096
      }
    }
    DEF SURFACE Solid {
      translation 0.037646 0 0.352
      name "surface"
    }
  ]
  name "Mir100"
  model "Mobile Industrial Robots' MiR100"
  boundingObject Group {
    children [
      DEF TOP Pose {
        translation 0.0375 0.0005 0.334
        children [
          Box {
            size 0.774 0.461 0.04
          }
        ]
      }
      DEF MIDDLE_CENTER Pose {
        translation 0.0375 0.0005 0.262
        children [
          Box {
            size 0.857 0.44 0.096
          }
        ]
      }
      DEF MIDDLE_RIGHT_SIDE Pose {
        translation 0.0375 -0.25 0.262
        children [
          Box {
            size 0.774 0.041 0.096
          }
        ]
      }
      DEF MIDDLE_LEFT_SIDE Pose {
        translation 0.0375 0.25 0.262
        children [
          Box {
            size 0.774 0.041 0.096
          }
        ]
      }
      DEF CYL_BR Pose {
        translation -0.3555 -0.2353 0.262
        children [
          Cylinder {
            height 0.096
            radius 0.054
          }
        ]
      }
      DEF CYL_FL Pose {
        translation 0.4306 0.2364 0.262
        children [
          Cylinder {
            height 0.096
            radius 0.054
          }
        ]
      }
      DEF CYL_FR Pose {
        translation 0.415 -0.221 0.262
        children [
          Cylinder {
            height 0.096
            radius 0.049
          }
        ]
      }
      DEF CYL_BL Pose {
        translation -0.341 0.222 0.262
        children [
          Cylinder {
            height 0.096
            radius 0.049
          }
        ]
      }
      DEF MIDLOW Pose {
        translation 0.03733 0.0005 0.204
        children [
          Box {
            size 0.7806 0.4665 0.04
          }
        ]
      }
      DEF LOW Pose {
        translation 0.0374 0.0005 0.16
        children [
          Box {
            size 0.85 0.536 0.039
          }
        ]
      }
      DEF BOTTOM_LEFT Pose {
        translation 0.0374 0.2486 0.09425
        children [
          Box {
            size 0.35 0.04 0.0925
          }
        ]
      }
      DEF BOTTOM_RIGHT Pose {
        translation 0.0374 -0.2476 0.09425
        children [
          Box {
            size 0.35 0.04 0.0925
          }
        ]
      }
      DEF BOTTOM_CENTER Pose {
        translation 0.0375 0.0005 0.094
        children [
          Box {
            size 0.857 0.2 0.092
          }
        ]
      }
    ]
  }
  physics Physics {
    density -1
    mass 70
  }
  controller "mir100"
  linearVelocity 2.201557535679816e-06 2.2317538261405206e-06 -2.5703241168928684e-08
  angularVelocity -4.96010358132349e-07 2.7715168094412815e-07 -7.069365924429525e-06
}
