#VRML_SIM R2025a utf8

EXTERNPROTO "https://raw.githubusercontent.com/cyberbotics/webots/R2025a/projects/objects/backgrounds/protos/TexturedBackground.proto"
EXTERNPROTO "https://raw.githubusercontent.com/cyberbotics/webots/R2025a/projects/objects/backgrounds/protos/TexturedBackgroundLight.proto"
EXTERNPROTO "https://raw.githubusercontent.com/cyberbotics/webots/R2025a/projects/objects/floors/protos/RectangleArena.proto"
EXTERNPROTO "https://raw.githubusercontent.com/cyberbotics/webots/R2025a/projects/appearances/protos/Parquetry.proto"
EXTERNPROTO "../protos/ConveyorBelt.proto"
EXTERNPROTO "../protos/Pioneer3at.proto"
EXTERNPROTO "../protos/WoodenPallet.proto"
EXTERNPROTO "https://raw.githubusercontent.com/cyberbotics/webots/R2025a/projects/objects/factory/containers/protos/CardboardBox.proto"
EXTERNPROTO "https://raw.githubusercontent.com/cyberbotics/webots/R2025a/projects/objects/factory/containers/protos/PlasticFruitBox.proto"
EXTERNPROTO "https://raw.githubusercontent.com/cyberbotics/webots/R2025a/projects/objects/factory/manhole/protos/SquareManhole.proto"
EXTERNPROTO "https://raw.githubusercontent.com/cyberbotics/webots/R2025a/projects/objects/traffic/protos/SignPole.proto"
EXTERNPROTO "https://raw.githubusercontent.com/cyberbotics/webots/R2025a/projects/objects/traffic/protos/DirectionPanel.proto"
EXTERNPROTO "https://raw.githubusercontent.com/cyberbotics/webots/R2025a/projects/humans/pedestrian/protos/Pedestrian.proto"
EXTERNPROTO "https://raw.githubusercontent.com/cyberbotics/webots/R2025a/projects/appearances/protos/Plastic.proto"
EXTERNPROTO "https://raw.githubusercontent.com/cyberbotics/webots/R2025a/projects/robots/mir/mir100/protos/Mir100UltrasonicSensor.proto"
EXTERNPROTO "https://raw.githubusercontent.com/cyberbotics/webots/R2025a/projects/appearances/protos/CorrodedMetal.proto"
EXTERNPROTO "https://raw.githubusercontent.com/cyberbotics/webots/R2025a/projects/objects/solids/protos/SolidTorus.proto"

WorldInfo {
}
Viewpoint {
  orientation 0.04248451663717981 0.011253176935231162 0.9990337491070909 3.658976149503901
  position 4.080821578952575 3.8973633191876322 0.07456503777248269
  follow "Pioneer 3-AT_0"
  followType "None"
}
TexturedBackground {
}
TexturedBackgroundLight {
}
DEF rectangle_arena RectangleArena {
  translation 15.1304 9.85552 0
  floorSize 30 20
  floorTileSize 1 1
  floorAppearance Parquetry {
    type "dark strip"
  }
}
Pedestrian {
  translation 11.06 7.31002 1.27
  rotation 0 0 1 -3.1415853071795863
}
Pedestrian {
  translation 16.3842 17.72 1.28
  rotation 0 0 1 -0.523595307179586
  name "pedestrian(1)"
}
Pedestrian {
  translation 26.7331 5.34865 1.28
  rotation 0 0 -1 1.5708
  name "pedestrian(2)"
}
SignPole {
  translation 25.3498 15.6897 0
  rotation 0 0 1 3.14159
  height 1
  signBoards [
    DirectionPanel {
      translation 0 0 -0.86
      width 0.4
      height 0.2
    }
  ]
}
PlasticFruitBox {
  translation 28.2254 1.86879 0.63
  rotation 0 0 1 0.261799
  color 0.371527 0.966171 0.557473
}
DEF left_big_conveyor_belt_5 ConveyorBelt {
  hidden translation_1 0 0 1.1218065171954423
  translation 17.8 15 0
  rotation 0 0 -1 0
  size 1 5 1.5
}
DEF left_big_conveyor_belt_6 ConveyorBelt {
  hidden translation_1 7.105427357601002e-15 -3.552713678800501e-15 1.1218065171954408
  translation 21 15 0
  rotation 0 0 -1 0
  name "conveyor belt(11)"
  size 1 5 1.5
}
DEF left_big_conveyor_belt_6 ConveyorBelt {
  hidden translation_1 -0.0003848911937467392 2.1388581966874654e-05 1.1468509583219788
  hidden rotation_1 -0.007108017828594725 0.999974682844138 -0.0003312903771018675 0.006046461441891239
  translation 28.88 15 0
  rotation 0 0 -1 0
  name "conveyor belt(25)"
  size 1 5 1.5
}
DEF left_small_conveyor_belt_4 ConveyorBelt {
  hidden translation_1 0 0 0.7468065173868723
  translation 13.33 14.5 0
  rotation 0 0 -1 0
  name "conveyor belt(3)"
  size 1 4 1
}
DEF left_big_conveyor_belt_4 ConveyorBelt {
  hidden translation_1 0 0 1.1218065171954423
  translation 14.5 15 0
  rotation 0 0 -1 0
  name "conveyor belt(4)"
  size 1 5 1.5
}
DEF left_small_conveyor_belt_5 ConveyorBelt {
  hidden translation_1 0 0 0.746806517195689
  translation 16.6 14.5 0
  rotation 0 0 -1 0
  name "conveyor belt(1)"
  size 1 4 1
}
DEF left_small_conveyor_belt_6 ConveyorBelt {
  hidden translation_1 0 0 0.7468065171954346
  translation 19.8 14.5 0
  rotation 0 0 -1 0
  name "conveyor belt(10)"
  size 1 4 1
}
DEF right_small_conveyor_belt_6 ConveyorBelt {
  hidden translation_1 0 0 0.7468065171954346
  translation 23 6 0
  rotation 0 0 -1 0
  name "conveyor belt(2)"
  size 1 4 1
}
DEF right_big_conveyor_belt_6 ConveyorBelt {
  hidden translation_1 0 0 1.1218065171954423
  translation 21.8 5.5 0
  rotation 0 0 -1 0
  name "conveyor belt(5)"
  size 1 5 1.5
}
ConveyorBelt {
  hidden translation_1 0 0 0.44680651719542935
  translation 27.8449 2.58127 0
  rotation 0 0 -1 0
  name "conveyor belt(12)"
  size 4 4 0.6
}
DEF right_small_conveyor_belt_5 ConveyorBelt {
  hidden translation_1 0 0 0.7468065171954346
  translation 19.8 6 0
  rotation 0 0 -1 0
  name "conveyor belt(6)"
  size 1 4 1
}
WoodenPallet {
  translation 22.5 8.7 0
  size 2 1 0.1
}
WoodenPallet {
  translation 19 8.7 0
  name "wooden pallet(1)"
  size 2 1 0.1
}
WoodenPallet {
  translation 9.4 8.7 0
  name "wooden pallet(6)"
  size 2 1 0.1
}
WoodenPallet {
  translation 17 11.9 0
  name "wooden pallet(2)"
  size 2 1 0.1
}
WoodenPallet {
  translation 10.73 11.9 0
  name "wooden pallet(3)"
  size 2 1 0.1
}
WoodenPallet {
  translation 7.5 11.9 0
  name "wooden pallet(5)"
  size 2 1 0.1
}
WoodenPallet {
  translation 4.5 11.9 0
  name "wooden pallet(4)"
  size 2 1 0.1
}
DEF right_big_conveyor_belt_5 ConveyorBelt {
  hidden translation_1 0 0 1.1218065171954423
  translation 18.5 5.5 0
  rotation 0 0 -1 0
  name "conveyor belt(7)"
  window "<none>"
  size 1 5 1.5
}
DEF right_small_conveyor_belt_4 ConveyorBelt {
  hidden translation_1 0 0 0.7468065171954346
  translation 16.46 6 0
  rotation 0 0 -1 0
  name "conveyor belt(8)"
  window "<none>"
  size 1 4 1
}
DEF right_small_conveyor_belt_3 ConveyorBelt {
  hidden translation_1 0 0 0.7468065173600485
  translation 13.22 6 0
  rotation 0 0 -1 0
  name "conveyor belt(14)"
  window "<none>"
  size 1 4 1
}
DEF left_small_conveyor_belt_2 ConveyorBelt {
  hidden translation_1 0 0 0.7468065171954346
  translation 6.9 14.5 0
  rotation 0 0 -1 0
  name "conveyor belt(21)"
  size 1 4 1
}
DEF left_small_conveyor_belt_1 ConveyorBelt {
  hidden translation_1 0 0 0.7468065171954346
  translation 3.7 14.5 0
  rotation 0 0 -1 0
  name "conveyor belt(23)"
  size 1 4 1
}
DEF left_small_conveyor_belt_3 ConveyorBelt {
  hidden translation_1 0 0 0.7468065171954346
  translation 10.1 14.5 0
  rotation 0 0 -1 0
  name "conveyor belt(19)"
  size 1 4 1
}
DEF right_small_conveyor_belt_2 ConveyorBelt {
  hidden translation_1 0 0 0.7468065171954346
  translation 10 6 0
  rotation 0 0 -1 0
  name "conveyor belt(15)"
  size 1 4 1
}
DEF right_small_conveyor_belt_1 ConveyorBelt {
  hidden translation_1 1.7763568394002505e-15 1.7763568394002505e-15 0.7468065171954341
  translation 7 6 0
  rotation 0 0 -1 0
  name "conveyor belt(17)"
  size 1 4 1
}
DEF right_big_conveyor_belt_4 ConveyorBelt {
  hidden translation_1 0 0 1.1218065171954423
  translation 15.3 5.5 0
  rotation 0 0 -1 0
  name "conveyor belt(9)"
  size 1 5 1.5
}
DEF right_big_conveyor_belt_3 ConveyorBelt {
  hidden translation_1 0 0 1.1218065171954423
  translation 12 5.5 0
  rotation 0 0 -1 0
  name "conveyor belt(13)"
  size 1 5 1.5
}
DEF left_big_conveyor_belt_3 ConveyorBelt {
  hidden translation_1 0 0 1.1218065171954423
  translation 11.3 15 0
  rotation 0 0 -1 0
  name "conveyor belt(20)"
  size 1 5 1.5
}
DEF left_big_conveyor_belt_2 ConveyorBelt {
  hidden translation_1 0 0 1.1218065171954423
  translation 8.1 15 0
  rotation 0 0 -1 0
  name "conveyor belt(22)"
  size 1 5 1.5
}
DEF left_big_conveyor_belt_1 ConveyorBelt {
  hidden translation_1 0 0 1.1218065171954423
  translation 4.9 15 0
  rotation 0 0 -1 0
  name "conveyor belt(24)"
  size 1 5 1.5
}
DEF right_big_conveyor_belt_2 ConveyorBelt {
  hidden translation_1 0 0 1.1218065171954423
  translation 8.8 5.5 0
  rotation 0 0 -1 0
  name "conveyor belt(16)"
  size 1 5 1.5
}
DEF right_big_conveyor_belt_1 ConveyorBelt {
  hidden translation_1 -9.488717160177629e-05 -0.0008011680417192579 1.1297340646432126
  hidden rotation_1 0.9966346016118166 -0.08196245748030113 0.0012753171548224409 0.007025254798688431
  translation 5.8 5.5 0
  rotation 0 0 -1 0
  name "conveyor belt(18)"
  size 1 5 1.5
}
CardboardBox {
  translation 27.8384 3.01098 0.71
  rotation 0 0 1 0.261799
  size 0.2 0.2 0.2
}
CardboardBox {
  translation 28.0224 3.48865 0.71
  rotation 0 0 1 0.785398
  name "cardboard box(1)"
  size 0.2 0.2 0.2
}
CardboardBox {
  translation 21.6903 3.22499 1.6
  rotation 0 0 1 1.309
  name "cardboard box(6)"
  size 0.2 0.2 0.2
}
CardboardBox {
  translation 7.98736 14.1014 1.6
  rotation 0 0 1 1.309
  name "cardboard box(7)"
  size 0.2 0.2 0.2
}
CardboardBox {
  translation 15.3336 4.18682 1.6
  rotation 0 0 1 2.0944
  name "cardboard box(10)"
  size 0.2 0.2 0.2
}
CardboardBox {
  translation 11.2185 13.9355 1.6
  rotation 0 0 1 2.0944
  name "cardboard box(11)"
  size 0.2 0.2 0.2
}
CardboardBox {
  translation 4.6953 16.4739 1.6
  rotation 0 0 1 2.0944
  name "cardboard box(12)"
  size 0.2 0.2 0.2
}
CardboardBox {
  translation 5.94515 4.74132 1.6
  rotation 0 0 1 1.309
  name "cardboard box(9)"
  size 0.2 0.2 0.2
}
CardboardBox {
  translation 26.2061 1.6839 0.71
  rotation 0 0 1 1.309
  name "cardboard box(8)"
  size 0.2 0.2 0.2
}
CardboardBox {
  translation 28.3211 1.96902 0.77
  rotation 0 0 1 4.692820414042842e-06
  name "cardboard box(5)"
  size 0.2 0.2 0.2
}
CardboardBox {
  translation 28.0496 3.95362 0.71
  rotation 0 0 1 0.261803
  name "cardboard box(2)"
  size 0.2 0.2 0.2
}
CardboardBox {
  translation 18.9049 8.5223 0.11
  rotation 0 0 1 1.5708
  name "cardboard box(4)"
  size 0.2 0.2 0.2
}
CardboardBox {
  translation 20.9849 7.7223 0.11
  rotation 0 0 1 1.5708
  name "cardboard box(13)"
  size 0.2 0.2 0.2
}
CardboardBox {
  translation 17.3949 8.2323 0.11
  rotation 0 0 1 1.5708
  name "cardboard box(16)"
  size 0.2 0.2 0.2
}
CardboardBox {
  translation 18.6349 12.5223 0.11
  rotation 0 0 1 1.5708
  name "cardboard box(17)"
  size 0.2 0.2 0.2
}
CardboardBox {
  translation 17.0749 12.4123 0.11
  rotation 0 0 1 1.5708
  name "cardboard box(18)"
  size 0.2 0.2 0.2
}
CardboardBox {
  translation 24.9049 4.5023 0.11
  rotation 0 0 1 1.5708
  name "cardboard box(15)"
  size 0.2 0.2 0.2
}
CardboardBox {
  translation 24.3649 4.5123 0.11
  rotation 0 0 1 1.5708
  name "cardboard box(14)"
  size 0.2 0.2 0.2
}
CardboardBox {
  translation 22.6249 18.7445 0.15
  rotation 0 0 1 4.07987e-06
  name "cardboard box(3)"
  size 0.2 0.2 0.2
}
Pose {
}
DEF SUPERVISOR Robot {
  rotation 0 0 1 -2.8797853071795863
  controller "floor_mapper"
  supervisor TRUE
}
DEF Pioneer_3-AT Pioneer3at {
  hidden position_0_0 17181.675598126873
  hidden position_0_1 14901.686230805095
  hidden position_0_2 17201.27376675018
  hidden position_0_3 14922.74601288468
  hidden linearVelocity_0 2.771787058137516e-15 -8.428119828143476e-16 -7.23461694592102e-16
  hidden angularVelocity_0 7.969339443812887e-15 2.591375752614254e-14 -7.309572265498457e-17
  hidden rotation_1 0.5773516024134749 -0.5773476024162304 -0.5773516027299337 2.094404999683543
  hidden translation_2 4.390430234023778e-13 2.1847962280823109e-13 0.04999999999999215
  hidden rotation_2 -0.42526537133496617 0.425258256650912 -0.7989397843977734 1.7934126943521096
  hidden rotation_3 0.5988398247311807 -0.5988354475140398 -0.5317771818314401 2.164114386118724
  hidden linearVelocity_3 2.7040591986727713e-14 -1.2497780588273561e-14 2.8421681460990786e-15
  hidden angularVelocity_3 8.945026625098566e-15 2.5282257791688358e-14 3.113851353379555e-16
  hidden rotation_4 -0.3115782917519234 0.31157812874889695 0.897684820966852 4.604650253019825
  hidden linearVelocity_4 2.707833957234032e-14 -1.2509993039414141e-14 2.8776929689112385e-15
  hidden angularVelocity_4 7.313537137927088e-15 2.5711305198525086e-14 9.595186187068305e-16
  hidden rotation_5 0.0819383590674099 -0.08193413036551764 0.993263763355226 4.705619952281285
  hidden linearVelocity_5 2.6620927685966295e-14 -1.3222756224268583e-15 -4.511955505609782e-15
  hidden angularVelocity_5 7.48313496335353e-15 2.5855753680728798e-14 2.016109838132138e-15
  hidden rotation_6 -0.37949231665424893 0.3794912683576789 0.8437843082451056 4.543329854960415
  hidden linearVelocity_6 2.6636470812319463e-14 -1.3233858452374025e-15 -4.511951420164575e-15
  hidden angularVelocity_6 6.313867212209385e-15 2.622868812877368e-14 3.0285684910669966e-16
  translation 21.977027207539106 10.648583967116107 0.28828544279339585
  rotation 0.9904762543001602 -0.1343220254412261 -0.030238768971160367 -3.133102367105844
  name "Pioneer 3-AT_0"
  controller "pioneer_controller"
}
DEF Pioneer_3-AT Pioneer3at {
  hidden position_0_0 17180.78132187774
  hidden position_0_1 14902.012854876544
  hidden position_0_2 17201.443179344125
  hidden position_0_3 14923.747408840876
  hidden linearVelocity_0 1.654338331807569e-14 1.8301025152393663e-15 1.0335167065601457e-16
  hidden angularVelocity_0 3.8067406978803163e-16 -1.4411236786501789e-15 3.0186895605080448e-15
  hidden rotation_1 0.5773516024134749 -0.5773476024162304 -0.5773516027299337 2.094404999683543
  hidden translation_2 4.390430234023778e-13 2.1847962280823109e-13 0.04999999999999215
  hidden rotation_2 -0.42526537133496617 0.425258256650912 -0.7989397843977734 1.7934126943521096
  hidden rotation_3 0.693032749848983 -0.6930262646821231 -0.1985452192763675 2.7496084582999023
  hidden linearVelocity_3 2.4052333851284698e-14 5.465734430003355e-15 2.1315842615216592e-16
  hidden angularVelocity_3 6.931044687641117e-15 -3.46281266254941e-15 4.560125437294338e-15
  hidden rotation_4 -0.16753804062081032 0.16753961742983242 0.9715253375678913 4.683494151980981
  hidden linearVelocity_4 -5.427765131778087e-15 -6.996275369300137e-15 -2.1313386737022205e-16
  hidden angularVelocity_4 5.7745394769391765e-15 -1.1222748097908784e-15 4.525052692535344e-15
  hidden rotation_5 0.1639882754858081 -0.16398326884325676 0.9727370318039049 4.684741245515953
  hidden linearVelocity_5 -9.653420300074945e-15 5.3192817894674286e-15 -2.1314937142009487e-16
  hidden angularVelocity_5 8.899303794926149e-15 -2.2690239862960346e-15 4.5735328883852264e-15
  hidden rotation_6 0.07773650330320012 -0.07773231571898712 0.9939389936747401 4.706299502349365
  hidden linearVelocity_6 -9.472496107745357e-15 -7.426007024313237e-15 -1.421245466201217e-16
  hidden angularVelocity_6 1.1649700628195031e-14 1.2831073821650589e-15 4.5282541202206825e-15
  translation 14.256700033508164 5.304822308346285 -0.0023889310687115473
  rotation -2.4736974707837447e-05 2.482322415919871e-05 0.9999999993859447 1.5554602425612096
  name "Pioneer 3-AT_1"
  controller "pioneer_controller_1"
}
DEF Pioneer_3-AT Pioneer3at {
  hidden position_0_0 17180.454440888985
  hidden position_0_1 14901.654045170671
  hidden position_0_2 17201.222969771174
  hidden position_0_3 14923.432881519406
  hidden linearVelocity_0 1.604334326373151e-14 5.455222884437504e-15 5.1675835328007286e-17
  hidden angularVelocity_0 -3.034102771757171e-18 -2.9319902466445643e-16 3.5010077677524726e-15
  hidden rotation_1 0.5773516024134749 -0.5773476024162304 -0.5773516027299337 2.094404999683543
  hidden translation_2 4.390430234023778e-13 2.1847962280823109e-13 0.04999999999999215
  hidden rotation_2 -0.42526537133496617 0.425258256650912 -0.7989397843977734 1.7934126943521096
  hidden rotation_3 0.7047397830073873 -0.7047327794055265 -0.0818141056179318 2.9783345143857205
  hidden linearVelocity_3 1.5846363663090957e-14 -2.4180493514417696e-14 -1.4210440002509783e-16
  hidden angularVelocity_3 -2.3515153096526117e-15 -5.188410755797679e-15 2.088035723426952e-15
  hidden rotation_4 -0.3244968903313731 0.3244965625101099 0.8884839610732379 4.59441334554624
  hidden linearVelocity_4 -1.6677007058812856e-14 -2.423584759014756e-14 2.9603401217496275e-20
  hidden angularVelocity_4 2.3514964886655013e-15 -8.183510308041687e-16 2.5302297895917607e-15
  hidden rotation_5 0.05678671468511826 -0.05678273393916686 0.9967702795336872 4.709143899600425
  hidden linearVelocity_5 1.579906900356668e-14 2.3779397595537567e-14 -2.6252533891246058e-20
  hidden angularVelocity_5 7.054499188657413e-15 -5.605512272453955e-15 1.5059195466825014e-15
  hidden rotation_6 -0.07888260835918016 0.07888517695913007 0.9937578492543234 4.706116703610642
  hidden linearVelocity_6 -1.7342863727214916e-14 2.4141779520571022e-14 -3.5525349905822054e-16
  hidden angularVelocity_6 1.1757889023010587e-15 -9.773321558822234e-15 2.180338420640527e-15
  translation 10.682321711769378 9.6967100962006 -0.0023889310679025
  rotation -0.007212573583976896 0.9998354098863458 0.01664727964860206 4.918602138638272e-05
  name "Pioneer 3-AT_2"
  controller "pioneer_controller_2"
}
DEF Pioneer_3-AT Pioneer3at {
  hidden position_0_0 17180.454404272998
  hidden position_0_1 14901.654010376
  hidden position_0_2 17201.22305765175
  hidden position_0_3 14923.43297093435
  hidden linearVelocity_0 7.822105494891363e-15 5.734241839491999e-15 -2.583791766400364e-16
  hidden angularVelocity_0 -3.141910612016299e-18 1.9536160920888935e-16 3.5416025776617154e-15
  hidden rotation_1 0.5773516024134749 -0.5773476024162304 -0.5773516027299337 2.094404999683543
  hidden translation_2 4.390430234023778e-13 2.1847962280823109e-13 0.04999999999999215
  hidden rotation_2 -0.42526537133496617 0.425258256650912 -0.7989397843977734 1.7934126943521096
  hidden rotation_3 0.7047405369152885 -0.7047335332614124 -0.081801116894799 2.978360318886144
  hidden linearVelocity_3 1.1212966210426037e-14 -2.3904797747114454e-14 -3.5532021515714147e-16
  hidden angularVelocity_3 -3.5272598329768665e-15 -5.3701176458327636e-15 4.9601732358929816e-15
  hidden rotation_4 -0.3245107198361968 0.3245103918376366 0.8884738590981598 4.594402054554311
  hidden linearVelocity_4 -1.0035147993635634e-14 -2.40320087383714e-14 7.10659072819982e-17
  hidden angularVelocity_4 -3.52724558524603e-15 1.2811984018426297e-15 4.6758108419365624e-15
  hidden rotation_5 0.056830371614446165 -0.05682639043432767 0.9967653034753814 4.70913890758273
  hidden linearVelocity_5 2.0571228540832413e-14 2.4508780605112626e-14 7.105992704406606e-17
  hidden angularVelocity_5 -3.52722171836642e-15 -4.15262359016628e-15 3.589210286753094e-15
  hidden rotation_6 -0.07883845610812973 0.078841025188171 0.9937648567874419 4.706123755150368
  hidden linearVelocity_6 -2.3889268373796536e-14 2.4184661281485726e-14 -2.1321336808890683e-16
  hidden angularVelocity_6 1.1758001467112532e-15 -1.1117876127758841e-14 3.944816350265849e-15
  translation 7.8917341062527875 9.700530121884906 -0.002388931067902611
  rotation -0.007212844995732479 0.9999739543367014 0.00025595954356370256 4.917920690312289e-05
  name "Pioneer 3-AT_3"
  controller "pioneer_controller_3"
}
SquareManhole {
  translation 25 19 0
}
SquareManhole {
  translation 19.092 9.85948 -0.04
  rotation 0 0 1 0.523602
  name "manhole(16)"
}
SquareManhole {
  translation 20.7736 10.6536 -0.04
  rotation 0 0 1 0.785401
  name "manhole(17)"
}
SquareManhole {
  translation 9.00273 10.7778 -0.02
  rotation 0 0 1 1.5708
  name "manhole(12)"
}
SquareManhole {
  translation 4.9337 9.8387 -0.04
  rotation 9.58978e-09 3.57898e-08 1 -0.523595307179586
  name "manhole(11)"
}
WoodenPallet {
  translation 6 8.7 0
  name "wooden pallet(7)"
  size 2 1 0.1
}
WoodenPallet {
  translation 12.72 8.7 0
  name "wooden pallet(8)"
  size 2 1 0.1
}
WoodenPallet {
  translation 15.74 8.7 0
  name "wooden pallet(9)"
  size 2 1 0.1
}
WoodenPallet {
  translation 13.93 11.89 0
  name "wooden pallet(10)"
  size 2 1 0.1
}
WoodenPallet {
  translation 20.37 11.89 0
  name "wooden pallet(11)"
  size 2 1 0.1
}
Robot {
  translation 1.7905771261222982 2.5868815069400077 -0.005520854127749858
  rotation -0.012117256567175954 -0.016749520014734422 -0.9997862900002987 0.7491289988627333
  children [
    Pose {
      translation 0.037646 0 0
      children [
        Shape {
          appearance DEF WHITE Plastic {
          }
          geometry Mesh {
            url [
              "https://raw.githubusercontent.com/cyberbotics/webots/R2025a/projects/robots/mir/mir100/protos/meshes/mir_100_base.obj"
            ]
          }
        }
        Shape {
          appearance USE WHITE
          geometry Mesh {
            url [
              "https://raw.githubusercontent.com/cyberbotics/webots/R2025a/projects/robots/mir/mir100/protos/meshes/mir_100_inside.obj"
            ]
          }
        }
        Shape {
          appearance Plastic {
            colorOverride 0.93 0.93 0.93
          }
          geometry Mesh {
            url [
              "https://raw.githubusercontent.com/cyberbotics/webots/R2025a/projects/robots/mir/mir100/protos/meshes/mir_100_logos.dae"
            ]
          }
        }
        Shape {
          appearance DEF BLACK Plastic {
            colorOverride 0 0 0
          }
          geometry Mesh {
            url [
              "https://raw.githubusercontent.com/cyberbotics/webots/R2025a/projects/robots/mir/mir100/protos/meshes/mir_100_base_corners.dae"
            ]
          }
        }
        Shape {
          appearance DEF BLACK Plastic {
            colorOverride 0 0 0
          }
          geometry Mesh {
            url [
              "https://raw.githubusercontent.com/cyberbotics/webots/R2025a/projects/robots/mir/mir100/protos/meshes/mir_100_top_plugs.dae"
            ]
          }
        }
      ]
    }
    DEF IMU Pose {
      translation 0 0 0.25
      children [
        Accelerometer {
          name "imu_data accelerometer"
          lookupTable [
            -100 -100 -0.002
            100 100 0.002
          ]
        }
        Gyro {
          name "imu_data gyro"
          lookupTable [
            -100 -100 -0.002
            100 100 0.002
          ]
        }
        Compass {
          name "imu_data compass"
          lookupTable [
            -1 -1 -0.2
            1 1 0.2
          ]
        }
      ]
    }
    Pose {
      translation 0.4288 0.2358 0.188
      rotation -0.9238797538373538 -0.38268289803626016 0 -3.14159
    }
    Pose {
      translation -0.3548 -0.2352 0.188
      rotation 0.38268289803626016 -0.9238797538373538 0 -3.14159
    }
    Pose {
      translation 0.037646 0 0.349
    }
    DEF DEPTH_CAMERA Transform {
      translation 0.042224 -0.273014 0.141194
      rotation 1 0 0 1.5708
      scale 4.00035 3.92893 3.92893
      children [
        Shape {
          appearance Appearance {
            material Material {
              emissiveColor 1 1 1
            }
            texture ImageTexture {
              url [
                "https://raw.githubusercontent.com/cyberbotics/webots/R2025a/projects/robots/mir/mir100/protos/textures/camera.png"
              ]
            }
            textureTransform TextureTransform {
              rotation 3.1415926
            }
          }
          geometry Plane {
            size 0.08 0.015
          }
        }
      ]
    }
    Mir100UltrasonicSensor {
      translation 0.415448 -0.108238 0.08
      rotation 0.8628559982596194 -0.35740699927911007 -0.35740699927911007 1.71777
      name "ds0"
      lookupTable [
        0.2 1000 0
        0.3 0 0
      ]
    }
    Mir100UltrasonicSensor {
      translation -0.3844 -0.1328 0.156
      rotation 0 0 1 3.141592653589793
      name "ds1"
    }
    Mir100UltrasonicSensor {
      translation -0.3844 0.1328 0.156
      rotation 0 0 1 3.141592653589793
      name "ds2"
    }
    Mir100UltrasonicSensor {
      translation 0.415448 0.108238 0.08
      rotation 0.8628559982596194 0.35740699927911007 0.35740699927911007 1.71777
      name "ds3"
      lookupTable [
        0.2 1000 0
        0.3 0 0
      ]
    }
    RangeFinder {
      translation 0.044 -0.28 0.18
      rotation 0 0 1 -1.5707953071795862
      name "depth_camera"
      fieldOfView 2.05949
      width 1280
      height 720
      minRange 0.18
      maxRange 1.95
    }
    Pose {
      translation 0.03733 0.0005 0.2085
      children [
        DEF LIGHT_FRONT Pose {
          translation 0.392 0 0
          children [
            DEF LIGHT_WIDTH_SHAPE Shape {
              appearance PBRAppearance {
                transparency 0.5
                emissiveColor 0 0.9 1
              }
              geometry Box {
                size 0.001 0.4723 0.053
              }
            }
          ]
        }
        DEF LIGHT_BACK Pose {
          translation -0.392 0 0
          children [
            USE LIGHT_WIDTH_SHAPE
          ]
        }
        DEF LIGHT_LEFT Pose {
          translation 0 0.2355 0
          children [
            DEF LIGHT_WIDTH_SHAPE Shape {
              appearance PBRAppearance {
                transparency 0.5
                emissiveColor 0 0.9 1
              }
              geometry Box {
                size 0.783 0.001 0.053
              }
            }
          ]
        }
        DEF LIGHT_RIGHT Pose {
          translation 0 -0.2355 0
          children [
            USE LIGHT_WIDTH_SHAPE
          ]
        }
      ]
    }
    DEF US_1_FRAME Solid {
      translation 0.45 -0.12 0.16
      name "us_1_frame"
    }
    DEF US_2_FRAME Solid {
      translation 0.45 0.12 0.16
      name "us_2_frame"
    }
    DEF FL_CASTER_ROTATION_JOINT HingeJoint {
      jointParameters HingeJointParameters {
        position -12.510918378861156
        axis 0 0 1
        anchor 0.341346 0 0.154
        dampingConstant 0.01
      }
      device [
        PositionSensor {
          name "front_left_caster_joint_sensor"
        }
      ]
      endPoint DEF FL_CASTER_ROTATION_LINK Solid {
        translation 0.34094584163605646 -3.7475987226394725e-05 0.15416044596262188
        rotation -0.0002663210696631671 0.0026134340149305568 0.9999965495119159 0.05544494535904892
        children [
          DEF CASTER_WHEEL_BASE Shape {
            appearance PBRAppearance {
              baseColor 0.35 0.35 0.35
              roughness 1
              metalness 0
            }
            geometry Mesh {
              url [
                "https://raw.githubusercontent.com/cyberbotics/webots/R2025a/projects/robots/mir/mir100/protos/meshes/caster_wheel_base.dae"
              ]
            }
          }
          DEF FL_CASTER_WHEEL_JOINT HingeJoint {
            jointParameters HingeJointParameters {
              position 536.6286188654358
              axis 0 1 0
              anchor -0.0382 0 -0.094
            }
            device [
              PositionSensor {
                name "front_left_wheel_joint_sensor"
              }
            ]
            endPoint DEF FL_CASTER_WHEEL_LINK Solid {
              translation -0.038029532529413546 -5.000259708154428e-05 -0.09365021624567767
              rotation 0.9825953177113699 -0.13135203684510613 -0.1313509955361361 4.694828454091532
              children [
                Group {
                  children [
                    DEF RIM Shape {
                      appearance CorrodedMetal {
                      }
                      geometry Cylinder {
                        height 0.032
                        radius 0.0465
                      }
                    }
                    SolidTorus {
                      translation 0 0 0
                      majorRadius 0.0465
                      minorRadius 0.016
                      appearance DEF WHEEL_RUBBER PBRAppearance {
                        baseColor 0 0 0
                        roughness 1
                        metalness 0
                      }
                      enableBoundingObject FALSE
                    }
                  ]
                }
              ]
              name "fl_caster_wheel_link"
              contactMaterial "wheel"
              boundingObject DEF WHEEL_BO Cylinder {
                height 0.01
                radius 0.0625
              }
              physics Physics {
                density -1
                mass 1
                centerOfMass [
                  0 0 0
                ]
                inertiaMatrix [
                  0.001061895 0.001953125 0.001061895
                  0 0 5.457207e-20
                ]
              }
              linearVelocity -5.159392547565004e-07 -1.056782082053287e-07 1.4408405317553581e-06
              angularVelocity -9.56730967526343e-06 -6.3556796914383075e-06 2.4369150041146354e-05
            }
          }
        ]
        name "fl_caster_rotation_link"
        boundingObject Pose {
          translation 0 0 -0.028
          children [
            DEF SWIVEL Cylinder {
              height 0.055
              radius 0.0298
            }
          ]
        }
        physics Physics {
          density -1
          mass 0.309754
          centerOfMass [
            0 0 -0.0425
          ]
          inertiaMatrix [
            0.0005287255 0.000517415 0.0002462724
            -7.734275e-21 -1.120566e-20 -0.0001505672
          ]
        }
        linearVelocity -1.6599739831878735e-07 9.468552030361738e-07 1.6995606365178303e-06
        angularVelocity -2.7943165921542054e-06 -3.33093847017241e-06 3.070019486560343e-05
      }
    }
    DEF BL_CASTER_ROTATION_JOINT HingeJoint {
      jointParameters HingeJointParameters {
        position -21.95029120942775
        axis 0 0 1
        anchor -0.270154 0.203 0.1565
        dampingConstant 0.01
      }
      device [
        RotationalMotor {
          name "back_left_wheel_joint"
          maxVelocity 100
          maxTorque 20
        }
        PositionSensor {
          name "back_left_caster_joint_sensor"
        }
      ]
      endPoint DEF BL_CASTER_ROTATION_LINK Solid {
        translation -0.27015719303676505 0.20299260219699083 0.16422307121557253
        rotation 2.7962369094868507e-05 1.1658112135641244e-06 -0.9999999996083735 3.1007712768160536
        children [
          USE CASTER_WHEEL_BASE
          DEF BL_CASTER_WHEEL_JOINT HingeJoint {
            jointParameters HingeJointParameters {
              position 605.6238197987237
              axis 0 1 0
              anchor -0.0382 0 -0.094
            }
            device [
              RotationalMotor {
                name "back_left_wheel"
                maxVelocity 100
                maxTorque 20
              }
              PositionSensor {
                name "back_left_wheel_joint_sensor"
              }
            ]
            endPoint DEF BL_CASTER_WHEEL_LINK Solid {
              translation -0.038184595234020575 -2.9480967995709783e-06 -0.09411708685265055
              rotation -0.25121932046855217 0.6844286810027465 0.684431321349454 2.649342454988598
              children [
                Group {
                  children [
                    USE RIM
                    SolidTorus {
                      translation 0 0 0
                      majorRadius 0.0465
                      minorRadius 0.016
                      appearance USE WHEEL_RUBBER
                      enableBoundingObject FALSE
                    }
                  ]
                }
              ]
              name "bl_caster_wheel_link"
              contactMaterial "wheel"
              boundingObject USE WHEEL_BO
              physics Physics {
                density -1
                mass 1
                centerOfMass [
                  0 0 0
                ]
                inertiaMatrix [
                  0.001061895 0.001953125 0.001061895
                  0 0 5.457207e-20
                ]
              }
              linearVelocity -8.754732220608296e-07 9.11900189759951e-07 -6.318131790976622e-07
              angularVelocity -2.6205378128433493e-06 -3.757106978963919e-06 1.2768865874885882e-06
            }
          }
        ]
        name "bl_caster_rotation_link"
        boundingObject Pose {
          translation 0 0 -0.028
          children [
            USE SWIVEL
          ]
        }
        physics Physics {
          density -1
          mass 0.309754
          centerOfMass [
            0 0 -0.0425
          ]
          inertiaMatrix [
            0.0005287255 0.000517415 0.0002462724
            -7.734275e-21 -1.120566e-20 -0.0001505672
          ]
        }
        linearVelocity -9.244241056783395e-07 8.413489940596064e-07 -8.350007242443097e-07
        angularVelocity -2.5021412812436756e-06 -3.701065594681827e-06 1.2533604029343143e-06
      }
    }
    DEF BR_CASTER_ROTATION_JOINT HingeJoint {
      jointParameters HingeJointParameters {
        position -21.950289520956105
        axis 0 0 1
        anchor -0.270154 -0.203 0.1565
        dampingConstant 0.01
      }
      device [
        RotationalMotor {
          name "back_right_wheel_joint"
          maxVelocity 100
          maxTorque 20
        }
        PositionSensor {
          name "back_right_caster_joint_sensor"
        }
      ]
      endPoint DEF BR_CASTER_ROTATION_LINK Solid {
        translation -0.2701634726078615 -0.20294224454453128 0.16285703034018398
        rotation 3.0979923283280256e-05 1.0419187315706514e-06 -0.9999999995195795 3.100785500341405
        children [
          USE CASTER_WHEEL_BASE
          DEF BR_CASTER_WHEEL_JOINT HingeJoint {
            jointParameters HingeJointParameters {
              position 607.292111812863
              axis 0 1 0
              anchor -0.0382 0 -0.094
            }
            device [
              RotationalMotor {
                name "back_right_wheel"
                maxVelocity 100
                maxTorque 20
              }
              PositionSensor {
                name "back_right_wheel_joint_sensor"
              }
            ]
            endPoint DEF BR_CASTER_WHEEL_LINK Solid {
              translation -0.038188902811482885 -1.0658529570051185e-07 -0.09424407114792618
              rotation 0.3472201819933353 0.6631119480301176 0.6631143865097616 3.809982827373826
              children [
                Group {
                  children [
                    USE RIM
                    SolidTorus {
                      translation 0 0 0
                      majorRadius 0.0465
                      minorRadius 0.016
                      appearance USE WHEEL_RUBBER
                      enableBoundingObject FALSE
                    }
                  ]
                }
              ]
              name "br_caster_wheel_link"
              contactMaterial "wheel"
              boundingObject USE WHEEL_BO
              physics Physics {
                density -1
                mass 1
                centerOfMass [
                  0 0 0
                ]
                inertiaMatrix [
                  0.001061895 0.001953125 0.001061895
                  0 0 5.457207e-20
                ]
              }
              linearVelocity 5.233966375972621e-07 1.1674640933317937e-07 -8.800381821743031e-07
              angularVelocity -2.518408024712559e-06 -3.6914717430971757e-06 1.2544702342031456e-06
            }
          }
        ]
        name "br_caster_rotation_link"
        boundingObject Pose {
          translation 0 0 -0.028
          children [
            USE SWIVEL
          ]
        }
        physics Physics {
          density -1
          mass 0.309754
          centerOfMass [
            0 0 -0.0425
          ]
          inertiaMatrix [
            0.0005287255 0.000517415 0.0002462724
            -7.734275e-21 -1.120566e-20 -0.0001505672
          ]
        }
        linearVelocity -2.786741563956746e-08 2.6162071161725485e-07 -1.1078138809338904e-06
        angularVelocity -2.5352253794326155e-06 -3.777780062163132e-06 1.2317629596809078e-06
      }
    }
    DEF SURFACE Solid {
      translation 0.037646 0 0.352
      name "surface"
    }
  ]
  name "Mir100"
  model "Mobile Industrial Robots' MiR100"
  boundingObject Group {
    children [
      DEF TOP Pose {
        translation 0.0375 0.0005 0.334
        children [
          Box {
            size 0.774 0.461 0.04
          }
        ]
      }
      DEF MIDDLE_CENTER Pose {
        translation 0.0375 0.0005 0.262
        children [
          Box {
            size 0.857 0.44 0.096
          }
        ]
      }
      DEF MIDDLE_RIGHT_SIDE Pose {
        translation 0.0375 -0.25 0.262
        children [
          Box {
            size 0.774 0.041 0.096
          }
        ]
      }
      DEF MIDDLE_LEFT_SIDE Pose {
        translation 0.0375 0.25 0.262
        children [
          Box {
            size 0.774 0.041 0.096
          }
        ]
      }
      DEF CYL_BR Pose {
        translation -0.3555 -0.2353 0.262
        children [
          Cylinder {
            height 0.096
            radius 0.054
          }
        ]
      }
      DEF CYL_FL Pose {
        translation 0.4306 0.2364 0.262
        children [
          Cylinder {
            height 0.096
            radius 0.054
          }
        ]
      }
      DEF CYL_FR Pose {
        translation 0.415 -0.221 0.262
        children [
          Cylinder {
            height 0.096
            radius 0.049
          }
        ]
      }
      DEF CYL_BL Pose {
        translation -0.341 0.222 0.262
        children [
          Cylinder {
            height 0.096
            radius 0.049
          }
        ]
      }
      DEF MIDLOW Pose {
        translation 0.03733 0.0005 0.204
        children [
          Box {
            size 0.7806 0.4665 0.04
          }
        ]
      }
      DEF LOW Pose {
        translation 0.0374 0.0005 0.16
        children [
          Box {
            size 0.85 0.536 0.039
          }
        ]
      }
      DEF BOTTOM_LEFT Pose {
        translation 0.0374 0.2586 0.09425
        children [
          Box {
            size 0.35 0.04 0.0925
          }
        ]
      }
      DEF BOTTOM_RIGHT Pose {
        translation 0.0374 -0.2476 0.09425
        children [
          Box {
            size 0.35 0.04 0.0925
          }
        ]
      }
      DEF BOTTOM_CENTER Pose {
        translation 0.0375 0.0005 0.094
        children [
          Box {
            size 0.857 0.2 0.092
          }
        ]
      }
    ]
  }
  physics Physics {
    density -1
    mass 5
  }
  controller "mir100"
  linearVelocity -6.792444849533474e-07 1.0551949909733898e-06 3.7348886216188075e-07
  angularVelocity -2.5243116973601555e-06 -3.723669431917567e-06 1.2902388443761074e-06
}
