#VRML_SIM R2025a utf8

EXTERNPROTO "https://raw.githubusercontent.com/cyberbotics/webots/R2025a/projects/objects/backgrounds/protos/TexturedBackground.proto"
EXTERNPROTO "https://raw.githubusercontent.com/cyberbotics/webots/R2025a/projects/objects/backgrounds/protos/TexturedBackgroundLight.proto"
EXTERNPROTO "https://raw.githubusercontent.com/cyberbotics/webots/R2025a/projects/objects/floors/protos/RectangleArena.proto"
EXTERNPROTO "https://raw.githubusercontent.com/cyberbotics/webots/R2025a/projects/appearances/protos/Parquetry.proto"
EXTERNPROTO "../protos/ConveyorBelt.proto"
EXTERNPROTO "../protos/Pioneer3at.proto"
EXTERNPROTO "../protos/WoodenPallet.proto"
EXTERNPROTO "https://raw.githubusercontent.com/cyberbotics/webots/R2025a/projects/objects/factory/containers/protos/CardboardBox.proto"
EXTERNPROTO "https://raw.githubusercontent.com/cyberbotics/webots/R2025a/projects/objects/factory/containers/protos/PlasticFruitBox.proto"
EXTERNPROTO "https://raw.githubusercontent.com/cyberbotics/webots/R2025a/projects/objects/factory/manhole/protos/SquareManhole.proto"
EXTERNPROTO "https://raw.githubusercontent.com/cyberbotics/webots/R2025a/projects/objects/traffic/protos/SignPole.proto"
EXTERNPROTO "https://raw.githubusercontent.com/cyberbotics/webots/R2025a/projects/objects/traffic/protos/DirectionPanel.proto"
EXTERNPROTO "https://raw.githubusercontent.com/cyberbotics/webots/R2025a/projects/humans/pedestrian/protos/Pedestrian.proto"
EXTERNPROTO "https://raw.githubusercontent.com/cyberbotics/webots/R2025a/projects/appearances/protos/Plastic.proto"
EXTERNPROTO "https://raw.githubusercontent.com/cyberbotics/webots/R2025a/projects/robots/mir/mir100/protos/Mir100UltrasonicSensor.proto"
EXTERNPROTO "https://raw.githubusercontent.com/cyberbotics/webots/R2025a/projects/appearances/protos/CorrodedMetal.proto"
EXTERNPROTO "https://raw.githubusercontent.com/cyberbotics/webots/R2025a/projects/objects/solids/protos/SolidTorus.proto"

WorldInfo {
}
Viewpoint {
  orientation -0.2816451651870676 -0.0281956108681907 -0.9591042740257802 2.950146905482687
  position 3.81896785712824 1.8826668756379035 -1.1651934948590326
  follow "Pioneer 3-AT_0"
  followType "None"
}
TexturedBackground {
}
TexturedBackgroundLight {
}
DEF rectangle_arena RectangleArena {
  translation 15 10 0
  floorSize 30 20
  floorTileSize 1 1
  floorAppearance Parquetry {
    type "dark strip"
  }
}
Pedestrian {
  translation 11.06 7.31002 1.27
  rotation 0 0 1 -3.1415853071795863
}
Pedestrian {
  translation 16.3842 17.72 1.28
  rotation 0 0 1 -0.523595307179586
  name "pedestrian(1)"
}
Pedestrian {
  translation 26.7331 5.34865 1.28
  rotation 0 0 -1 1.5708
  name "pedestrian(2)"
}
SignPole {
  translation 25.3498 15.6897 0
  rotation 0 0 1 3.14159
  height 1
  signBoards [
    DirectionPanel {
      translation 0 0 -0.86
      width 0.4
      height 0.2
    }
  ]
}
PlasticFruitBox {
  translation 28.2254 1.86879 0.63
  rotation 0 0 1 0.261799
  color 0.371527 0.966171 0.557473
}
DEF left_big_conveyor_belt_5 ConveyorBelt {
  hidden translation_1 0 0 1.1220574822766523
  translation 17.8 15 0
  rotation 0 0 -1 0
  size 1 5 1.5
}
DEF left_big_conveyor_belt_6 ConveyorBelt {
  hidden translation_1 7.105427357601002e-15 -3.552713678800501e-15 1.1220574822766507
  translation 21 15 0
  rotation 0 0 -1 0
  name "conveyor belt(11)"
  size 1 5 1.5
}
DEF left_big_conveyor_belt_6 ConveyorBelt {
  hidden translation_1 -0.0003848911937467392 2.1388581966874654e-05 1.1471019234031887
  hidden rotation_1 -0.007108017828594725 0.999974682844138 -0.0003312903771018675 0.006046461441891239
  translation 28.88 15 0
  rotation 0 0 -1 0
  name "conveyor belt(25)"
  size 1 5 1.5
}
DEF left_small_conveyor_belt_4 ConveyorBelt {
  hidden translation_1 0 0 0.7470574824680817
  translation 13.33 14.5 0
  rotation 0 0 -1 0
  name "conveyor belt(3)"
  size 1 4 1
}
DEF left_big_conveyor_belt_4 ConveyorBelt {
  hidden translation_1 0 0 1.1220574822766523
  translation 14.5 15 0
  rotation 0 0 -1 0
  name "conveyor belt(4)"
  size 1 5 1.5
}
DEF left_small_conveyor_belt_5 ConveyorBelt {
  hidden translation_1 0 0 0.7470574822768984
  translation 16.6 14.5 0
  rotation 0 0 -1 0
  name "conveyor belt(1)"
  size 1 4 1
}
DEF left_small_conveyor_belt_6 ConveyorBelt {
  hidden translation_1 0 0 0.7470574822766439
  translation 19.8 14.5 0
  rotation 0 0 -1 0
  name "conveyor belt(10)"
  size 1 4 1
}
DEF right_small_conveyor_belt_6 ConveyorBelt {
  hidden translation_1 0 0 0.7470574822766439
  translation 23 6 0
  rotation 0 0 -1 0
  name "conveyor belt(2)"
  size 1 4 1
}
DEF right_big_conveyor_belt_6 ConveyorBelt {
  hidden translation_1 0 0 1.1220574822766523
  translation 21.8 5.5 0
  rotation 0 0 -1 0
  name "conveyor belt(5)"
  size 1 5 1.5
}
ConveyorBelt {
  hidden translation_1 0 0 0.44705748227663805
  translation 27.8449 2.58127 0
  rotation 0 0 -1 0
  name "conveyor belt(12)"
  size 4 4 0.6
}
DEF right_small_conveyor_belt_5 ConveyorBelt {
  hidden translation_1 0 0 0.7470574822766439
  translation 19.8 6 0
  rotation 0 0 -1 0
  name "conveyor belt(6)"
  size 1 4 1
}
WoodenPallet {
  translation 22.5 8.7 0
  size 2 1 0.1
}
WoodenPallet {
  translation 19 8.7 0
  name "wooden pallet(1)"
  size 2 1 0.1
}
WoodenPallet {
  translation 9.4 8.7 0
  name "wooden pallet(6)"
  size 2 1 0.1
}
WoodenPallet {
  translation 17 11.9 0
  name "wooden pallet(2)"
  size 2 1 0.1
}
WoodenPallet {
  translation 10.73 11.9 0
  name "wooden pallet(3)"
  size 2 1 0.1
}
WoodenPallet {
  translation 7.5 11.9 0
  name "wooden pallet(5)"
  size 2 1 0.1
}
WoodenPallet {
  translation 4.5 11.9 0
  name "wooden pallet(4)"
  size 2 1 0.1
}
DEF right_big_conveyor_belt_5 ConveyorBelt {
  hidden translation_1 0 0 1.1220574822766523
  translation 18.5 5.5 0
  rotation 0 0 -1 0
  name "conveyor belt(7)"
  window "<none>"
  size 1 5 1.5
}
DEF right_small_conveyor_belt_4 ConveyorBelt {
  hidden translation_1 0 0 0.7470574822766439
  translation 16.46 6 0
  rotation 0 0 -1 0
  name "conveyor belt(8)"
  window "<none>"
  size 1 4 1
}
DEF right_small_conveyor_belt_3 ConveyorBelt {
  hidden translation_1 0 0 0.7470574824412579
  translation 13.22 6 0
  rotation 0 0 -1 0
  name "conveyor belt(14)"
  window "<none>"
  size 1 4 1
}
DEF left_small_conveyor_belt_2 ConveyorBelt {
  hidden translation_1 0 0 0.7470574822766439
  translation 6.9 14.5 0
  rotation 0 0 -1 0
  name "conveyor belt(21)"
  size 1 4 1
}
DEF left_small_conveyor_belt_1 ConveyorBelt {
  hidden translation_1 0 0 0.7470574822766439
  translation 3.7 14.5 0
  rotation 0 0 -1 0
  name "conveyor belt(23)"
  size 1 4 1
}
DEF left_small_conveyor_belt_3 ConveyorBelt {
  hidden translation_1 0 0 0.7470574822766439
  translation 10.1 14.5 0
  rotation 0 0 -1 0
  name "conveyor belt(19)"
  size 1 4 1
}
DEF right_small_conveyor_belt_2 ConveyorBelt {
  hidden translation_1 0 0 0.7470574822766439
  translation 10 6 0
  rotation 0 0 -1 0
  name "conveyor belt(15)"
  size 1 4 1
}
DEF right_small_conveyor_belt_1 ConveyorBelt {
  hidden translation_1 0 0 0.7470574822766439
  translation 7 6 0
  rotation 0 0 -1 0
  name "conveyor belt(17)"
  size 1 4 1
}
DEF right_big_conveyor_belt_4 ConveyorBelt {
  hidden translation_1 0 0 1.1220574822766523
  translation 15.3 5.5 0
  rotation 0 0 -1 0
  name "conveyor belt(9)"
  size 1 5 1.5
}
DEF right_big_conveyor_belt_3 ConveyorBelt {
  hidden translation_1 0 0 1.1220574822766523
  translation 12 5.5 0
  rotation 0 0 -1 0
  name "conveyor belt(13)"
  size 1 5 1.5
}
DEF left_big_conveyor_belt_3 ConveyorBelt {
  hidden translation_1 0 0 1.1220574822766523
  translation 11.3 15 0
  rotation 0 0 -1 0
  name "conveyor belt(20)"
  size 1 5 1.5
}
DEF left_big_conveyor_belt_2 ConveyorBelt {
  hidden translation_1 0 0 1.1220574822766523
  translation 8.1 15 0
  rotation 0 0 -1 0
  name "conveyor belt(22)"
  size 1 5 1.5
}
DEF left_big_conveyor_belt_1 ConveyorBelt {
  hidden translation_1 0 0 1.1220574822766523
  translation 4.9 15 0
  rotation 0 0 -1 0
  name "conveyor belt(24)"
  size 1 5 1.5
}
DEF right_big_conveyor_belt_2 ConveyorBelt {
  hidden translation_1 0 0 1.1220574822766523
  translation 8.8 5.5 0
  rotation 0 0 -1 0
  name "conveyor belt(16)"
  size 1 5 1.5
}
DEF right_big_conveyor_belt_1 ConveyorBelt {
  hidden translation_1 0 0 1.1220574822766523
  translation 5.8 5.5 0
  rotation 0 0 -1 0
  name "conveyor belt(18)"
  size 1 5 1.5
}
CardboardBox {
  translation 27.8384 3.01098 0.71
  rotation 0 0 1 0.261799
  size 0.2 0.2 0.2
}
CardboardBox {
  translation 28.0224 3.48865 0.71
  rotation 0 0 1 0.785398
  name "cardboard box(1)"
  size 0.2 0.2 0.2
}
CardboardBox {
  translation 21.6903 3.22499 1.6
  rotation 0 0 1 1.309
  name "cardboard box(6)"
  size 0.2 0.2 0.2
}
CardboardBox {
  translation 7.98736 14.1014 1.6
  rotation 0 0 1 1.309
  name "cardboard box(7)"
  size 0.2 0.2 0.2
}
CardboardBox {
  translation 15.3336 4.18682 1.6
  rotation 0 0 1 2.0944
  name "cardboard box(10)"
  size 0.2 0.2 0.2
}
CardboardBox {
  translation 11.2185 13.9355 1.6
  rotation 0 0 1 2.0944
  name "cardboard box(11)"
  size 0.2 0.2 0.2
}
CardboardBox {
  translation 4.6953 16.4739 1.6
  rotation 0 0 1 2.0944
  name "cardboard box(12)"
  size 0.2 0.2 0.2
}
CardboardBox {
  translation 5.94515 4.74132 1.6
  rotation 0 0 1 1.309
  name "cardboard box(9)"
  size 0.2 0.2 0.2
}
CardboardBox {
  translation 26.2061 1.6839 0.71
  rotation 0 0 1 1.309
  name "cardboard box(8)"
  size 0.2 0.2 0.2
}
CardboardBox {
  translation 28.3211 1.96902 0.77
  rotation 0 0 1 4.692820414042842e-06
  name "cardboard box(5)"
  size 0.2 0.2 0.2
}
CardboardBox {
  translation 28.0496 3.95362 0.71
  rotation 0 0 1 0.261803
  name "cardboard box(2)"
  size 0.2 0.2 0.2
}
CardboardBox {
  translation 18.9049 8.5223 0.11
  rotation 0 0 1 1.5708
  name "cardboard box(4)"
  size 0.2 0.2 0.2
}
CardboardBox {
  translation 20.9849 7.7223 0.11
  rotation 0 0 1 1.5708
  name "cardboard box(13)"
  size 0.2 0.2 0.2
}
CardboardBox {
  translation 17.3949 8.2323 0.11
  rotation 0 0 1 1.5708
  name "cardboard box(16)"
  size 0.2 0.2 0.2
}
CardboardBox {
  translation 18.6349 12.5223 0.11
  rotation 0 0 1 1.5708
  name "cardboard box(17)"
  size 0.2 0.2 0.2
}
CardboardBox {
  translation 17.0749 12.4123 0.11
  rotation 0 0 1 1.5708
  name "cardboard box(18)"
  size 0.2 0.2 0.2
}
CardboardBox {
  translation 24.9049 4.5023 0.11
  rotation 0 0 1 1.5708
  name "cardboard box(15)"
  size 0.2 0.2 0.2
}
CardboardBox {
  translation 24.3649 4.5123 0.11
  rotation 0 0 1 1.5708
  name "cardboard box(14)"
  size 0.2 0.2 0.2
}
CardboardBox {
  translation 22.6249 18.7445 0.15
  rotation 0 0 1 4.07987e-06
  name "cardboard box(3)"
  size 0.2 0.2 0.2
}
Pose {
}
DEF SUPERVISOR Robot {
  rotation 0 0 1 -2.8797853071795863
  controller "floor_mapper"
  supervisor TRUE
}
DEF Pioneer_3-AT Pioneer3at {
  hidden position_0_0 17181.675598177524
  hidden position_0_1 14901.686214389418
  hidden position_0_2 17201.273778493785
  hidden position_0_3 14922.746012564696
  hidden linearVelocity_0 -1.6032085255317115e-12 -8.934286588640028e-15 1.0335167065601457e-16
  hidden angularVelocity_0 -2.5036037988382804e-15 -2.0048343206404603e-14 -4.312973912665168e-15
  hidden rotation_1 0.5773516024134749 -0.5773476024162304 -0.5773516027299337 2.094404999683543
  hidden translation_2 4.390430234023778e-13 2.1847962280823109e-13 0.04999999999999215
  hidden rotation_2 -0.42526537133496617 0.425258256650912 -0.7989397843977734 1.7934126943521096
  hidden rotation_3 0.5988398160930318 -0.5988354388760464 -0.5317772012862122 2.164114355786763
  hidden linearVelocity_3 -1.5744075414754968e-12 2.3310381020596967e-14 3.268497020447559e-15
  hidden angularVelocity_3 -7.648700143454101e-15 -3.5581247465814747e-12 3.8700081428813965e-14
  hidden rotation_4 -0.3115849444821848 0.31158478139468976 0.897680202731049 4.604645138199225
  hidden linearVelocity_4 -1.6092187665815529e-12 2.4671455663338434e-14 1.8473994076361137e-15
  hidden angularVelocity_4 -3.0061610614614135e-14 -2.223529776814859e-11 2.6706743313857196e-13
  hidden rotation_5 0.08194415215659957 -0.08193992339810056 0.9932628075594342 4.705618990045076
  hidden linearVelocity_5 -1.5744478024076984e-12 -1.949972493609369e-14 -2.84221909916879e-15
  hidden angularVelocity_5 -2.4248169397022513e-14 -1.811977851424944e-11 2.15733120626604e-13
  hidden rotation_6 -0.3794924322114524 0.3794913839133349 0.8437842043021297 4.543329733529307
  hidden linearVelocity_6 -1.6088393662230106e-12 -2.0641666143687055e-14 -3.0553297711227797e-15
  hidden angularVelocity_6 -5.434144058746035e-15 -2.5845385640559544e-12 2.6835661341852795e-14
  translation 21.47478938905279 10.903091899178712 0.00035798223039743005
  rotation 0.009578648395676148 0.006087279207739027 0.9999355951893897 3.1400405273090453
  name "Pioneer 3-AT_0"
  controller "pioneer_controller"
}
DEF Pioneer_3-AT Pioneer3at {
  hidden position_0_0 17180.781322602295
  hidden position_0_1 14902.012855460096
  hidden position_0_2 17201.44317876107
  hidden position_0_3 14923.747408116593
  hidden linearVelocity_0 1.4264946645789478e-14 3.635476547328684e-15 -5.1675835328007286e-17
  hidden angularVelocity_0 -1.26024531116781e-15 1.4259737873508324e-15 1.0732809473203562e-15
  hidden rotation_1 0.5773516024134749 -0.5773476024162304 -0.5773516027299337 2.094404999683543
  hidden translation_2 4.390430234023778e-13 2.1847962280823109e-13 0.04999999999999215
  hidden rotation_2 -0.42526537133496617 0.425258256650912 -0.7989397843977734 1.7934126943521096
  hidden rotation_3 0.6930327124662691 -0.693026227300684 -0.1985454802432583 2.7496079561646787
  hidden linearVelocity_3 2.3376941259288497e-14 6.321816598750906e-15 -1.4213287282261155e-16
  hidden angularVelocity_3 4.28540474922577e-15 1.2151096348617435e-15 -4.020507577793974e-16
  hidden rotation_4 -0.1675377651097405 0.16753934192193234 0.9715254325906241 4.683494249748948
  hidden linearVelocity_4 -2.474467105758071e-15 -6.377438015779403e-15 5.684313638715155e-16
  hidden angularVelocity_4 3.0236168547543477e-15 1.2034933151752091e-15 -4.428263655072009e-16
  hidden rotation_5 0.16398799953183937 -0.16398299289182125 0.9727371248450356 4.684741341127175
  hidden linearVelocity_5 -9.92218008849005e-15 6.1762855985681315e-15 -4.263152212069432e-16
  hidden angularVelocity_5 6.519618848713844e-15 4.762497021728437e-15 -4.008650605141228e-16
  hidden rotation_6 0.0777361455314389 -0.07773195795073054 0.9939390496358721 4.706299558649457
  hidden linearVelocity_6 -9.549226647051717e-15 -8.684994733396037e-15 -4.2634017064562793e-16
  hidden angularVelocity_6 9.377949990508856e-15 7.140045432380787e-15 -4.072160004581812e-16
  translation 14.256699999311204 5.304799941431153 -0.0023889310687114917
  rotation -2.4736974944209527e-05 2.482325716781857e-05 0.9999999993859439 1.5554589191221189
  name "Pioneer 3-AT_1"
  controller "pioneer_controller_1"
}
DEF Pioneer_3-AT Pioneer3at {
  hidden position_0_0 17180.454441604186
  hidden position_0_1 14901.654045764051
  hidden position_0_2 17201.22296917776
  hidden position_0_3 14923.432880803986
  hidden linearVelocity_0 5.032507712322453e-15 1.670596875280253e-14 2.583791766400364e-16
  hidden angularVelocity_0 -3.1726645172447664e-18 -9.77767009987579e-17 3.6259923119131754e-15
  hidden rotation_1 0.5773516024134749 -0.5773476024162304 -0.5773516027299337 2.094404999683543
  hidden translation_2 4.390430234023778e-13 2.1847962280823109e-13 0.04999999999999215
  hidden rotation_2 -0.42526537133496617 0.425258256650912 -0.7989397843977734 1.7934126943521096
  hidden rotation_3 0.7047397682804865 -0.704732764679641 -0.08181435932008523 2.978334010360019
  hidden linearVelocity_3 1.5918919359534782e-14 -2.420003511230866e-14 4.263137014586946e-16
  hidden angularVelocity_3 -3.5272544810920176e-15 -4.18154262329314e-15 4.368871628441003e-15
  hidden rotation_4 -0.3244966544838178 0.3244963266655777 0.8884841333469925 4.594413538095878
  hidden linearVelocity_4 -1.6594553638434202e-14 -2.4236448394723592e-14 4.2632507168141745e-16
  hidden angularVelocity_4 1.175747133170642e-15 -1.43047052981914e-16 4.728492264621716e-15
  hidden rotation_5 0.056786419890742436 -0.056782439147721964 0.9967703131215472 4.709143933295925
  hidden linearVelocity_5 1.5837058827436006e-14 2.4374523952633637e-14 2.84204733253531e-16
  hidden angularVelocity_5 -1.1757226652199344e-15 -5.394149713055787e-15 5.350059469912851e-15
  hidden rotation_6 -0.07888296162401433 0.07888553022012385 0.9937577931706065 4.706116647174524
  hidden linearVelocity_6 -1.725434108462018e-14 2.4160468717490957e-14 -9.2369968377487e-16
  hidden angularVelocity_6 3.5272853412596143e-15 -9.177134295829185e-15 3.4932558055133527e-15
  translation 10.68229934696105 9.696709999977253 -0.0023889310679025277
  rotation -0.007212864361259533 0.9999537976381473 -0.006354303797676063 4.9180198296015445e-05
  name "Pioneer 3-AT_2"
  controller "pioneer_controller_2"
}
DEF Pioneer_3-AT Pioneer3at {
  hidden position_0_0 17180.454404988628
  hidden position_0_1 14901.654010969374
  hidden position_0_2 17201.223057057512
  hidden position_0_3 14923.432970218924
  hidden linearVelocity_0 6.517667560959869e-15 1.6445363458096678e-14 2.583791766400364e-16
  hidden angularVelocity_0 -3.6109826600628907e-16 8.794390168774966e-16 3.0176101230376306e-17
  hidden rotation_1 0.5773516024134749 -0.5773476024162304 -0.5773516027299337 2.094404999683543
  hidden translation_2 4.390430234023778e-13 2.1847962280823109e-13 0.04999999999999215
  hidden rotation_2 -0.42526537133496617 0.425258256650912 -0.7989397843977734 1.7934126943521096
  hidden rotation_3 0.7047405221819184 -0.7047335185290586 -0.08180137074896703 2.9783598145573755
  hidden linearVelocity_3 1.1008241397791424e-14 -2.464290763726222e-14 -8.526605147055565e-16
  hidden angularVelocity_3 5.87871525039357e-15 -5.271397784877655e-15 -2.8125143408560305e-17
  hidden rotation_4 -0.3245104839958574 0.3245101560003205 0.8884740313759442 4.594402247110388
  hidden linearVelocity_4 -1.2583873400212153e-14 -2.3861037822251076e-14 -7.106778251895626e-17
  hidden angularVelocity_4 -2.3514980398857004e-15 9.224778222570012e-16 -3.0422939567036193e-15
  hidden rotation_5 0.05683007641276309 -0.05682609523557897 0.9967653371356752 4.709138941351067
  hidden linearVelocity_5 2.0396991385180026e-14 2.412069898120603e-14 -2.842468975785826e-16
  hidden angularVelocity_5 -2.351475231755942e-15 -3.591541279147109e-15 -2.8279567032348793e-15
  hidden rotation_6 -0.07883880938062515 0.07884137845682544 0.9937648007342951 4.706123698745409
  hidden linearVelocity_6 -2.0742941587551985e-14 2.3809662430723266e-14 -6.395055653247863e-16
  hidden angularVelocity_6 4.7030373081206325e-15 -9.378933596013406e-15 -2.498191957231105e-15
  translation 7.891711741444327 9.700530025625875 -0.002388931067902611
  rotation -0.007210416238567645 0.9997153124835209 -0.022744315413809685 4.919193052710101e-05
  name "Pioneer 3-AT_3"
  controller "pioneer_controller_3"
}
SquareManhole {
  translation 25 19 0
}
SquareManhole {
  translation 19.092 9.85948 -0.04
  rotation 0 0 1 0.523602
  name "manhole(16)"
}
SquareManhole {
  translation 20.7736 10.6536 -0.04
  rotation 0 0 1 0.785401
  name "manhole(17)"
}
SquareManhole {
  translation 9.00273 10.7778 -0.02
  rotation 0 0 1 1.5708
  name "manhole(12)"
}
SquareManhole {
  translation 4.9337 9.8387 -0.04
  rotation 9.58978e-09 3.57898e-08 1 -0.523595307179586
  name "manhole(11)"
}
WoodenPallet {
  translation 6 8.7 0
  name "wooden pallet(7)"
  size 2 1 0.1
}
WoodenPallet {
  translation 12.72 8.7 0
  name "wooden pallet(8)"
  size 2 1 0.1
}
WoodenPallet {
  translation 15.74 8.7 0
  name "wooden pallet(9)"
  size 2 1 0.1
}
WoodenPallet {
  translation 13.93 11.89 0
  name "wooden pallet(10)"
  size 2 1 0.1
}
WoodenPallet {
  translation 20.37 11.89 0
  name "wooden pallet(11)"
  size 2 1 0.1
}
Robot {
  translation 1.600553390234323 1.4133845612295841 -0.010404376032822599
  rotation -0.6694272193183372 0.6678268031680872 -0.3253837104189635 0.00479315609876027
  children [
    Pose {
      translation 0.037646 0 0
      children [
        Shape {
          appearance DEF WHITE Plastic {
          }
          geometry Mesh {
            url [
              "https://raw.githubusercontent.com/cyberbotics/webots/R2025a/projects/robots/mir/mir100/protos/meshes/mir_100_base.obj"
            ]
          }
        }
        Shape {
          appearance USE WHITE
          geometry Mesh {
            url [
              "https://raw.githubusercontent.com/cyberbotics/webots/R2025a/projects/robots/mir/mir100/protos/meshes/mir_100_inside.obj"
            ]
          }
        }
        Shape {
          appearance Plastic {
            colorOverride 0.93 0.93 0.93
          }
          geometry Mesh {
            url [
              "https://raw.githubusercontent.com/cyberbotics/webots/R2025a/projects/robots/mir/mir100/protos/meshes/mir_100_logos.dae"
            ]
          }
        }
        Shape {
          appearance DEF BLACK Plastic {
            colorOverride 0 0 0
          }
          geometry Mesh {
            url [
              "https://raw.githubusercontent.com/cyberbotics/webots/R2025a/projects/robots/mir/mir100/protos/meshes/mir_100_base_corners.dae"
            ]
          }
        }
        Shape {
          appearance DEF BLACK Plastic {
            colorOverride 0 0 0
          }
          geometry Mesh {
            url [
              "https://raw.githubusercontent.com/cyberbotics/webots/R2025a/projects/robots/mir/mir100/protos/meshes/mir_100_top_plugs.dae"
            ]
          }
        }
      ]
    }
    DEF IMU Pose {
      translation 0 0 0.25
      children [
        Accelerometer {
          name "imu_data accelerometer"
          lookupTable [
            -100 -100 -0.002
            100 100 0.002
          ]
        }
        Gyro {
          name "imu_data gyro"
          lookupTable [
            -100 -100 -0.002
            100 100 0.002
          ]
        }
        Compass {
          name "imu_data compass"
          lookupTable [
            -1 -1 -0.2
            1 1 0.2
          ]
        }
      ]
    }
    Pose {
      translation 0.4288 0.2358 0.188
      rotation -0.9238797538373538 -0.38268289803626016 0 -3.14159
    }
    Pose {
      translation -0.3548 -0.2352 0.188
      rotation 0.38268289803626016 -0.9238797538373538 0 -3.14159
    }
    Pose {
      translation 0.037646 0 0.349
    }
    DEF DEPTH_CAMERA Transform {
      translation 0.042224 -0.273014 0.141194
      rotation 1 0 0 1.5708
      scale 4.00035 3.92893 3.92893
      children [
        Shape {
          appearance Appearance {
            material Material {
              emissiveColor 1 1 1
            }
            texture ImageTexture {
              url [
                "https://raw.githubusercontent.com/cyberbotics/webots/R2025a/projects/robots/mir/mir100/protos/textures/camera.png"
              ]
            }
            textureTransform TextureTransform {
              rotation 3.1415926
            }
          }
          geometry Plane {
            size 0.08 0.015
          }
        }
      ]
    }
    Mir100UltrasonicSensor {
      translation 0.415448 -0.108238 0.08
      rotation 0.8628559982596194 -0.35740699927911007 -0.35740699927911007 1.71777
      name "ds0"
      lookupTable [
        0.2 1000 0
        0.3 0 0
      ]
    }
    Mir100UltrasonicSensor {
      translation -0.3844 -0.1328 0.156
      rotation 0 0 1 3.141592653589793
      name "ds1"
    }
    Mir100UltrasonicSensor {
      translation -0.3844 0.1328 0.156
      rotation 0 0 1 3.141592653589793
      name "ds2"
    }
    Mir100UltrasonicSensor {
      translation 0.415448 0.108238 0.08
      rotation 0.8628559982596194 0.35740699927911007 0.35740699927911007 1.71777
      name "ds3"
      lookupTable [
        0.2 1000 0
        0.3 0 0
      ]
    }
    RangeFinder {
      translation 0.004 -0.28 0.18
      rotation 0 0 1 -1.5707953071795862
      name "depth_camera"
      fieldOfView 2.05949
      width 1280
      height 720
      minRange 0.18
      maxRange 1.95
    }
    Pose {
      translation 0.03733 0.0005 0.2085
      children [
        DEF LIGHT_FRONT Pose {
          translation 0.392 0 0
          children [
            DEF LIGHT_WIDTH_SHAPE Shape {
              appearance PBRAppearance {
                transparency 0.5
                emissiveColor 0 0.9 1
              }
              geometry Box {
                size 0.001 0.4723 0.053
              }
            }
          ]
        }
        DEF LIGHT_BACK Pose {
          translation -0.392 0 0
          children [
            USE LIGHT_WIDTH_SHAPE
          ]
        }
        DEF LIGHT_LEFT Pose {
          translation 0 0.2355 0
          children [
            DEF LIGHT_WIDTH_SHAPE Shape {
              appearance PBRAppearance {
                transparency 0.5
                emissiveColor 0 0.9 1
              }
              geometry Box {
                size 0.783 0.001 0.053
              }
            }
          ]
        }
        DEF LIGHT_RIGHT Pose {
          translation 0 -0.2355 0
          children [
            USE LIGHT_WIDTH_SHAPE
          ]
        }
      ]
    }
    DEF US_1_FRAME Solid {
      translation 0.45 -0.12 0.16
      name "us_1_frame"
    }
    DEF US_2_FRAME Solid {
      translation 0.45 0.12 0.16
      name "us_2_frame"
    }
    DEF LEFT_WHEEL_JOINT HingeJoint {
      jointParameters HingeJointParameters {
        position -4.778071108220045e-05
        axis 0 1 0
        anchor 0 0.222604 0.0625
      }
      device [
        RotationalMotor {
          name "middle_left_wheel_joint"
          maxVelocity 20
          maxTorque 100
        }
        PositionSensor {
          name "middle_left_wheel_joint_sensor"
        }
      ]
      endPoint DEF LEFT_WHEEL_LINK Solid {
        translation 0 0.222604 0.0625
        rotation -0.9999999994292529 -2.3890267777995354e-05 -2.389035553201002e-05 1.5708000005707436
        children [
          Group {
            children [
              DEF RIM Shape {
                appearance CorrodedMetal {
                }
                geometry Cylinder {
                  height 0.032
                  radius 0.0465
                }
              }
              SolidTorus {
                translation 0 0 0
                majorRadius 0.0465
                minorRadius 0.016
                appearance DEF WHEEL_RUBBER PBRAppearance {
                  baseColor 0 0 0
                  roughness 1
                  metalness 0
                }
                enableBoundingObject FALSE
              }
            ]
          }
        ]
        name "left_wheel_link"
        contactMaterial "wheel"
        boundingObject DEF WHEEL_BO Cylinder {
          height 0.01
          radius 0.0625
        }
        physics Physics {
          density -1
          mass 1
          centerOfMass [
            0 0 0
          ]
          inertiaMatrix [
            0.001061895 0.001953125 0.001061895
            0 0 5.457207e-20
          ]
        }
        linearVelocity 3.727530965978332e-06 2.4178298576025265e-06 -1.2265116589560417e-07
        angularVelocity -4.946779050077452e-07 7.368603027163379e-07 -7.078468468692992e-06
      }
    }
    DEF RIGHT_WHEEL_JOINT HingeJoint {
      jointParameters HingeJointParameters {
        position -2.2468212662364168e-05
        axis 0 1 0
        anchor 0 -0.222604 0.0625
      }
      device [
        RotationalMotor {
          name "middle_right_wheel_joint"
          maxVelocity 20
          maxTorque 100
        }
        PositionSensor {
          name "middle_right_wheel_joint_sensor"
        }
      ]
      endPoint DEF RIGHT_WHEEL_LINK Solid {
        translation 0 -0.222604 0.0625
        rotation -0.9999999998737953 -1.123406506513599e-05 -1.1234106330236887e-05 1.570800000126201
        children [
          Group {
            children [
              USE RIM
              SolidTorus {
                translation 0 0 0
                majorRadius 0.0465
                minorRadius 0.016
                appearance USE WHEEL_RUBBER
                enableBoundingObject FALSE
              }
            ]
          }
        ]
        name "right_wheel_link"
        contactMaterial "wheel"
        boundingObject USE WHEEL_BO
        physics Physics {
          density -1
          mass 1
          centerOfMass [
            0 0 0
          ]
          inertiaMatrix [
            0.001061895 0.001953125 0.001061895
            0 0 5.457207e-20
          ]
        }
        linearVelocity 5.774228852373221e-07 2.4234424273226207e-06 9.376214296707984e-08
        angularVelocity -4.952825529521457e-07 3.4615109641415773e-07 -7.077213799546935e-06
      }
    }
    DEF FL_CASTER_ROTATION_JOINT HingeJoint {
      jointParameters HingeJointParameters {
        position 1.9940836966356457
        axis 0 0 1
        anchor 0.341346 0.203 0.1565
        dampingConstant 0.01
      }
      device [
        PositionSensor {
          name "front_left_caster_joint_sensor"
        }
      ]
      endPoint DEF FL_CASTER_ROTATION_LINK Solid {
        translation 0.341346 0.203 0.1565
        rotation 0 0 0.9999999999999999 1.9940836966356454
        children [
          DEF CASTER_WHEEL_BASE Shape {
            appearance PBRAppearance {
              baseColor 0.35 0.35 0.35
              roughness 1
              metalness 0
            }
            geometry Mesh {
              url [
                "https://raw.githubusercontent.com/cyberbotics/webots/R2025a/projects/robots/mir/mir100/protos/meshes/caster_wheel_base.dae"
              ]
            }
          }
          DEF FL_CASTER_WHEEL_JOINT HingeJoint {
            jointParameters HingeJointParameters {
              position -0.15114841273753865
              axis 0 1 0
              anchor -0.0382 0 -0.094
            }
            device [
              PositionSensor {
                name "front_left_wheel_joint_sensor"
              }
            ]
            endPoint DEF FL_CASTER_WHEEL_LINK Solid {
              translation -0.0382 0 -0.094
              rotation -0.9943155815131474 -0.07528772382929579 -0.07528800037705499 1.5765006053466675
              children [
                Group {
                  children [
                    USE RIM
                    SolidTorus {
                      translation 0 0 0
                      majorRadius 0.0465
                      minorRadius 0.016
                      appearance USE WHEEL_RUBBER
                      enableBoundingObject FALSE
                    }
                  ]
                }
              ]
              name "fl_caster_wheel_link"
              contactMaterial "wheel"
              boundingObject USE WHEEL_BO
              physics Physics {
                density -1
                mass 1
                centerOfMass [
                  0 0 0
                ]
                inertiaMatrix [
                  0.001061895 0.001953125 0.001061895
                  0 0 5.457207e-20
                ]
              }
              linearVelocity -1.918355909197977e-06 -2.4675402121863145e-06 -1.6580993593606765e-07
              angularVelocity 2.0705316526480955e-05 9.522119718799313e-06 -0.00015800308104520268
            }
          }
        ]
        name "fl_caster_rotation_link"
        boundingObject Pose {
          translation 0 0 -0.028
          children [
            DEF SWIVEL Cylinder {
              height 0.055
              radius 0.0298
            }
          ]
        }
        physics Physics {
          density -1
          mass 0.309754
          centerOfMass [
            0 0 -0.0425
          ]
          inertiaMatrix [
            0.0005287255 0.000517415 0.0002462724
            -7.734275e-21 -1.120566e-20 -0.0001505672
          ]
        }
        linearVelocity 3.600408515797001e-06 2.598253341528693e-08 -2.0659124734155076e-07
        angularVelocity -9.786951123527898e-07 -2.0631401016770544e-07 -0.0001579024246944569
      }
    }
    DEF FR_CASTER_ROTATION_JOINT HingeJoint {
      jointParameters HingeJointParameters {
        position 0.244753245225302
        axis 0 0 1
        anchor 0.341346 -0.203 0.1565
        dampingConstant 0.01
      }
      device [
        PositionSensor {
          name "front_right_caster_joint_sensor"
        }
      ]
      endPoint DEF FR_CASTER_ROTATION_LINK Solid {
        translation 0.341346 -0.203 0.1565
        rotation 0 0 1 0.2447532452253025
        children [
          USE CASTER_WHEEL_BASE
          DEF FR_CASTER_WHEEL_JOINT HingeJoint {
            jointParameters HingeJointParameters {
              position 0.07408183416916912
              axis 0 1 0
              anchor -0.0382 0 -0.094
            }
            device [
              PositionSensor {
                name "front_right_wheel_joint_sensor"
              }
            ]
            endPoint DEF FR_CASTER_WHEEL_LINK Solid {
              translation -0.0382 0 -0.094
              rotation -0.9986295419423802 0.037006944611140354 0.03700708054548776 1.5721713975607874
              children [
                Group {
                  children [
                    USE RIM
                    SolidTorus {
                      translation 0 0 0
                      majorRadius 0.0465
                      minorRadius 0.016
                      appearance USE WHEEL_RUBBER
                      enableBoundingObject FALSE
                    }
                  ]
                }
              ]
              name "fr_caster_wheel_link"
              contactMaterial "wheel"
              boundingObject USE WHEEL_BO
              physics Physics {
                density -1
                mass 1
                centerOfMass [
                  0 0 0
                ]
                inertiaMatrix [
                  0.001061895 0.001953125 0.001061895
                  0 0 5.457207e-20
                ]
              }
              linearVelocity 9.991754285563206e-07 -1.1503884632588772e-06 9.408722178250173e-09
              angularVelocity -2.944314256746991e-06 1.0764931332451303e-05 3.1192235984849014e-05
            }
          }
        ]
        name "fr_caster_rotation_link"
        boundingObject Pose {
          translation 0 0 -0.028
          children [
            USE SWIVEL
          ]
        }
        physics Physics {
          density -1
          mass 0.309754
          centerOfMass [
            0 0 -0.0425
          ]
          inertiaMatrix [
            0.0005287255 0.000517415 0.0002462724
            -7.734275e-21 -1.120566e-20 -0.0001505672
          ]
        }
        linearVelocity 7.274401606474802e-07 3.1264518437169236e-08 -8.79394004407173e-09
        angularVelocity -3.727133259501843e-07 4.0010016600828966e-07 3.121722928849219e-05
      }
    }
    DEF BL_CASTER_ROTATION_JOINT HingeJoint {
      jointParameters HingeJointParameters {
        position 1.9834882463245922
        axis 0 0 1
        anchor -0.270154 0.203 0.1565
        dampingConstant 0.01
      }
      device [
        PositionSensor {
          name "back_left_caster_joint_sensor"
        }
      ]
      endPoint DEF BL_CASTER_ROTATION_LINK Solid {
        translation -0.270154 0.203 0.1565
        rotation 0 0 0.9999999999999999 1.983488246324592
        children [
          USE CASTER_WHEEL_BASE
          DEF BL_CASTER_WHEEL_JOINT HingeJoint {
            jointParameters HingeJointParameters {
              position -0.14251095429127522
              axis 0 1 0
              anchor -0.0382 0 -0.094
            }
            device [
              PositionSensor {
                name "back_left_wheel_joint_sensor"
              }
            ]
            endPoint DEF BL_CASTER_WHEEL_LINK Solid {
              translation -0.0382 0 -0.094
              rotation -0.9949440440043374 -0.07101518235935735 -0.0710154432131665 1.575868758834428
              children [
                Group {
                  children [
                    USE RIM
                    SolidTorus {
                      translation 0 0 0
                      majorRadius 0.0465
                      minorRadius 0.016
                      appearance USE WHEEL_RUBBER
                      enableBoundingObject FALSE
                    }
                  ]
                }
              ]
              name "bl_caster_wheel_link"
              contactMaterial "wheel"
              boundingObject USE WHEEL_BO
              physics Physics {
                density -1
                mass 1
                centerOfMass [
                  0 0 0
                ]
                inertiaMatrix [
                  0.001061895 0.001953125 0.001061895
                  0 0 5.457207e-20
                ]
              }
              linearVelocity -3.061473987321151e-06 1.429159447876138e-06 1.8434840853842579e-09
              angularVelocity -3.7952461491190035e-05 -1.638415668691491e-05 -0.00018984642137067937
            }
          }
        ]
        name "bl_caster_rotation_link"
        boundingObject Pose {
          translation 0 0 -0.028
          children [
            USE SWIVEL
          ]
        }
        physics Physics {
          density -1
          mass 0.309754
          centerOfMass [
            0 0 -0.0425
          ]
          inertiaMatrix [
            0.0005287255 0.000517415 0.0002462724
            -7.734275e-21 -1.120566e-20 -0.0001505672
          ]
        }
        linearVelocity 3.607690446956861e-06 4.354501948554234e-06 -4.0837890335967065e-08
        angularVelocity -1.0814531909836593e-06 -3.092238282669194e-07 -0.0001900160777556152
      }
    }
    DEF BR_CASTER_ROTATION_JOINT HingeJoint {
      jointParameters HingeJointParameters {
        position 0.01769873898841037
        axis 0 0 1
        anchor -0.270154 -0.203 0.1565
        dampingConstant 0.01
      }
      device [
        PositionSensor {
          name "back_right_caster_joint_sensor"
        }
      ]
      endPoint DEF BR_CASTER_ROTATION_LINK Solid {
        translation -0.270154 -0.203 0.1565
        rotation 0 0 1 0.01769873898839831
        children [
          USE CASTER_WHEEL_BASE
          DEF BR_CASTER_WHEEL_JOINT HingeJoint {
            jointParameters HingeJointParameters {
              position 0.09738240012866556
              axis 0 1 0
              anchor -0.0382 0 -0.094
            }
            device [
              PositionSensor {
                name "back_right_wheel_joint_sensor"
              }
            ]
            endPoint DEF BR_CASTER_WHEEL_LINK Solid {
              translation -0.0382 0 -0.094
              rotation -0.9976338480710889 0.04861423567595063 0.04861441424633713 1.573168953463944
              children [
                Group {
                  children [
                    USE RIM
                    SolidTorus {
                      translation 0 0 0
                      majorRadius 0.0465
                      minorRadius 0.016
                      appearance USE WHEEL_RUBBER
                      enableBoundingObject FALSE
                    }
                  ]
                }
              ]
              name "br_caster_wheel_link"
              contactMaterial "wheel"
              boundingObject USE WHEEL_BO
              physics Physics {
                density -1
                mass 1
                centerOfMass [
                  0 0 0
                ]
                inertiaMatrix [
                  0.001061895 0.001953125 0.001061895
                  0 0 5.457207e-20
                ]
              }
              linearVelocity 8.118671973842415e-07 -1.4023250299661787e-06 1.8314883453740537e-07
              angularVelocity -1.9032659115922155e-07 1.3098990771675828e-05 0.00015018109526734272
            }
          }
        ]
        name "br_caster_rotation_link"
        boundingObject Pose {
          translation 0 0 -0.028
          children [
            USE SWIVEL
          ]
        }
        physics Physics {
          density -1
          mass 0.309754
          centerOfMass [
            0 0 -0.0425
          ]
          inertiaMatrix [
            0.0005287255 0.000517415 0.0002462724
            -7.734275e-21 -1.120566e-20 -0.0001505672
          ]
        }
        linearVelocity 7.347157961588512e-07 4.359701081770187e-06 1.5683827735505518e-07
        angularVelocity 8.516757562789722e-09 7.815140080332174e-07 0.00015021995026673948
      }
    }
    DEF SURFACE Solid {
      translation 0.037646 0 0.352
      name "surface"
    }
  ]
  name "Mir100"
  model "Mobile Industrial Robots' MiR100"
  boundingObject Group {
    children [
      DEF TOP Pose {
        translation 0.0375 0.0005 0.334
        children [
          Box {
            size 0.774 0.461 0.04
          }
        ]
      }
      DEF MIDDLE_CENTER Pose {
        translation 0.0375 0.0005 0.262
        children [
          Box {
            size 0.857 0.44 0.096
          }
        ]
      }
      DEF MIDDLE_RIGHT_SIDE Pose {
        translation 0.0375 -0.25 0.262
        children [
          Box {
            size 0.774 0.041 0.096
          }
        ]
      }
      DEF MIDDLE_LEFT_SIDE Pose {
        translation 0.0375 0.25 0.262
        children [
          Box {
            size 0.774 0.041 0.096
          }
        ]
      }
      DEF CYL_BR Pose {
        translation -0.3555 -0.2353 0.262
        children [
          Cylinder {
            height 0.096
            radius 0.054
          }
        ]
      }
      DEF CYL_FL Pose {
        translation 0.4306 0.2364 0.262
        children [
          Cylinder {
            height 0.096
            radius 0.054
          }
        ]
      }
      DEF CYL_FR Pose {
        translation 0.415 -0.221 0.262
        children [
          Cylinder {
            height 0.096
            radius 0.049
          }
        ]
      }
      DEF CYL_BL Pose {
        translation -0.341 0.222 0.262
        children [
          Cylinder {
            height 0.096
            radius 0.049
          }
        ]
      }
      DEF MIDLOW Pose {
        translation 0.03733 0.0005 0.204
        children [
          Box {
            size 0.7806 0.4665 0.04
          }
        ]
      }
      DEF LOW Pose {
        translation 0.0374 0.0005 0.16
        children [
          Box {
            size 0.85 0.536 0.039
          }
        ]
      }
      DEF BOTTOM_LEFT Pose {
        translation 0.0374 0.2486 0.09425
        children [
          Box {
            size 0.35 0.04 0.0925
          }
        ]
      }
      DEF BOTTOM_RIGHT Pose {
        translation 0.0374 -0.2476 0.09425
        children [
          Box {
            size 0.35 0.04 0.0925
          }
        ]
      }
      DEF BOTTOM_CENTER Pose {
        translation 0.0375 0.0005 0.094
        children [
          Box {
            size 0.857 0.2 0.092
          }
        ]
      }
    ]
  }
  physics Physics {
    density -1
    mass 70
  }
  controller "mir100"
  linearVelocity 2.202471040206411e-06 2.2296245203787332e-06 -2.5710149037931222e-08
  angularVelocity -4.953895075650082e-07 2.7732062142494513e-07 -7.076992742898255e-06
}
