#VRML_SIM R2025a utf8

EXTERNPROTO "https://raw.githubusercontent.com/cyberbotics/webots/R2025a/projects/objects/backgrounds/protos/TexturedBackground.proto"
EXTERNPROTO "https://raw.githubusercontent.com/cyberbotics/webots/R2025a/projects/objects/backgrounds/protos/TexturedBackgroundLight.proto"
EXTERNPROTO "https://raw.githubusercontent.com/cyberbotics/webots/R2025a/projects/objects/floors/protos/RectangleArena.proto"
EXTERNPROTO "https://raw.githubusercontent.com/cyberbotics/webots/R2025a/projects/appearances/protos/Parquetry.proto"
EXTERNPROTO "../protos/ConveyorBelt.proto"
EXTERNPROTO "../protos/Pioneer3at.proto"
EXTERNPROTO "../protos/WoodenPallet.proto"
EXTERNPROTO "https://raw.githubusercontent.com/cyberbotics/webots/R2025a/projects/objects/factory/containers/protos/CardboardBox.proto"
EXTERNPROTO "https://raw.githubusercontent.com/cyberbotics/webots/R2025a/projects/objects/factory/containers/protos/PlasticFruitBox.proto"
EXTERNPROTO "https://raw.githubusercontent.com/cyberbotics/webots/R2025a/projects/objects/factory/manhole/protos/SquareManhole.proto"
EXTERNPROTO "https://raw.githubusercontent.com/cyberbotics/webots/R2025a/projects/objects/traffic/protos/SignPole.proto"
EXTERNPROTO "https://raw.githubusercontent.com/cyberbotics/webots/R2025a/projects/objects/traffic/protos/DirectionPanel.proto"
EXTERNPROTO "https://raw.githubusercontent.com/cyberbotics/webots/R2025a/projects/humans/pedestrian/protos/Pedestrian.proto"
EXTERNPROTO "https://raw.githubusercontent.com/cyberbotics/webots/R2025a/projects/appearances/protos/Plastic.proto"
EXTERNPROTO "https://raw.githubusercontent.com/cyberbotics/webots/R2025a/projects/robots/mir/mir100/protos/Mir100UltrasonicSensor.proto"
EXTERNPROTO "https://raw.githubusercontent.com/cyberbotics/webots/R2025a/projects/appearances/protos/CorrodedMetal.proto"
EXTERNPROTO "https://raw.githubusercontent.com/cyberbotics/webots/R2025a/projects/objects/solids/protos/SolidTorus.proto"

WorldInfo {
}
Viewpoint {
  orientation -0.4021469955194004 -0.576088687543899 0.7116176066390343 4.731617152252108
  position 1.1772307582037875 1.5788092147718626 1.5006745823925995
  follow "Pioneer 3-AT_0"
  followType "None"
}
TexturedBackground {
}
TexturedBackgroundLight {
}
DEF rectangle_arena RectangleArena {
  translation 15 10 0
  floorSize 30 20
  floorTileSize 1 1
  floorAppearance Parquetry {
    type "dark strip"
  }
}
Pedestrian {
  translation 11.06 7.31002 1.27
  rotation 0 0 1 -3.1415853071795863
}
Pedestrian {
  translation 16.3842 17.72 1.28
  rotation 0 0 1 -0.523595307179586
  name "pedestrian(1)"
}
Pedestrian {
  translation 26.7331 5.34865 1.28
  rotation 0 0 -1 1.5708
  name "pedestrian(2)"
}
SignPole {
  translation 25.3498 15.6897 0
  rotation 0 0 1 3.14159
  height 1
  signBoards [
    DirectionPanel {
      translation 0 0 -0.86
      width 0.4
      height 0.2
    }
  ]
}
PlasticFruitBox {
  translation 28.2254 1.86879 0.63
  rotation 0 0 1 0.261799
  color 0.371527 0.966171 0.557473
}
DEF left_big_conveyor_belt_5 ConveyorBelt {
  hidden translation_1 0 0 1.1220731782766369
  translation 17.8 15 0
  rotation 0 0 -1 0
  size 1 5 1.5
}
DEF left_big_conveyor_belt_6 ConveyorBelt {
  hidden translation_1 7.105427357601002e-15 -3.552713678800501e-15 1.1220731782766353
  translation 21 15 0
  rotation 0 0 -1 0
  name "conveyor belt(11)"
  size 1 5 1.5
}
DEF left_big_conveyor_belt_6 ConveyorBelt {
  hidden translation_1 -0.0003848911937467392 2.1388581966874654e-05 1.1471176194031734
  hidden rotation_1 -0.007108017828594725 0.999974682844138 -0.0003312903771018675 0.006046461441891239
  translation 28.88 15 0
  rotation 0 0 -1 0
  name "conveyor belt(25)"
  size 1 5 1.5
}
DEF left_small_conveyor_belt_4 ConveyorBelt {
  hidden translation_1 0 0 0.7470731784680664
  translation 13.33 14.5 0
  rotation 0 0 -1 0
  name "conveyor belt(3)"
  size 1 4 1
}
DEF left_big_conveyor_belt_4 ConveyorBelt {
  hidden translation_1 0 0 1.1220731782766369
  translation 14.5 15 0
  rotation 0 0 -1 0
  name "conveyor belt(4)"
  size 1 5 1.5
}
DEF left_small_conveyor_belt_5 ConveyorBelt {
  hidden translation_1 0 0 0.7470731782768831
  translation 16.6 14.5 0
  rotation 0 0 -1 0
  name "conveyor belt(1)"
  size 1 4 1
}
DEF left_small_conveyor_belt_6 ConveyorBelt {
  hidden translation_1 0 0 0.7470731782766287
  translation 19.8 14.5 0
  rotation 0 0 -1 0
  name "conveyor belt(10)"
  size 1 4 1
}
DEF right_small_conveyor_belt_6 ConveyorBelt {
  hidden translation_1 0 0 0.7470731782766287
  translation 23 6 0
  rotation 0 0 -1 0
  name "conveyor belt(2)"
  size 1 4 1
}
DEF right_big_conveyor_belt_6 ConveyorBelt {
  hidden translation_1 0 0 1.1220731782766369
  translation 21.8 5.5 0
  rotation 0 0 -1 0
  name "conveyor belt(5)"
  size 1 5 1.5
}
ConveyorBelt {
  hidden translation_1 0 0 0.44707317827662285
  translation 27.8449 2.58127 0
  rotation 0 0 -1 0
  name "conveyor belt(12)"
  size 4 4 0.6
}
DEF right_small_conveyor_belt_5 ConveyorBelt {
  hidden translation_1 0 0 0.7470731782766287
  translation 19.8 6 0
  rotation 0 0 -1 0
  name "conveyor belt(6)"
  size 1 4 1
}
WoodenPallet {
  translation 22.5 8.7 0
  size 2 1 0.1
}
WoodenPallet {
  translation 19 8.7 0
  name "wooden pallet(1)"
  size 2 1 0.1
}
WoodenPallet {
  translation 9.4 8.7 0
  name "wooden pallet(6)"
  size 2 1 0.1
}
WoodenPallet {
  translation 17 11.9 0
  name "wooden pallet(2)"
  size 2 1 0.1
}
WoodenPallet {
  translation 10.73 11.9 0
  name "wooden pallet(3)"
  size 2 1 0.1
}
WoodenPallet {
  translation 7.5 11.9 0
  name "wooden pallet(5)"
  size 2 1 0.1
}
WoodenPallet {
  translation 4.5 11.9 0
  name "wooden pallet(4)"
  size 2 1 0.1
}
DEF right_big_conveyor_belt_5 ConveyorBelt {
  hidden translation_1 0 0 1.1220731782766369
  translation 18.5 5.5 0
  rotation 0 0 -1 0
  name "conveyor belt(7)"
  window "<none>"
  size 1 5 1.5
}
DEF right_small_conveyor_belt_4 ConveyorBelt {
  hidden translation_1 0 0 0.7470731782766287
  translation 16.46 6 0
  rotation 0 0 -1 0
  name "conveyor belt(8)"
  window "<none>"
  size 1 4 1
}
DEF right_small_conveyor_belt_3 ConveyorBelt {
  hidden translation_1 0 0 0.7470731784412427
  translation 13.22 6 0
  rotation 0 0 -1 0
  name "conveyor belt(14)"
  window "<none>"
  size 1 4 1
}
DEF left_small_conveyor_belt_2 ConveyorBelt {
  hidden translation_1 0 0 0.7470731782766287
  translation 6.9 14.5 0
  rotation 0 0 -1 0
  name "conveyor belt(21)"
  size 1 4 1
}
DEF left_small_conveyor_belt_1 ConveyorBelt {
  hidden translation_1 0 0 0.7470731782766287
  translation 3.7 14.5 0
  rotation 0 0 -1 0
  name "conveyor belt(23)"
  size 1 4 1
}
DEF left_small_conveyor_belt_3 ConveyorBelt {
  hidden translation_1 0 0 0.7470731782766287
  translation 10.1 14.5 0
  rotation 0 0 -1 0
  name "conveyor belt(19)"
  size 1 4 1
}
DEF right_small_conveyor_belt_2 ConveyorBelt {
  hidden translation_1 0 0 0.7470731782766287
  translation 10 6 0
  rotation 0 0 -1 0
  name "conveyor belt(15)"
  size 1 4 1
}
DEF right_small_conveyor_belt_1 ConveyorBelt {
  hidden translation_1 0 0 0.7470731782766287
  translation 7 6 0
  rotation 0 0 -1 0
  name "conveyor belt(17)"
  size 1 4 1
}
DEF right_big_conveyor_belt_4 ConveyorBelt {
  hidden translation_1 0 0 1.1220731782766369
  translation 15.3 5.5 0
  rotation 0 0 -1 0
  name "conveyor belt(9)"
  size 1 5 1.5
}
DEF right_big_conveyor_belt_3 ConveyorBelt {
  hidden translation_1 0 0 1.1220731782766369
  translation 12 5.5 0
  rotation 0 0 -1 0
  name "conveyor belt(13)"
  size 1 5 1.5
}
DEF left_big_conveyor_belt_3 ConveyorBelt {
  hidden translation_1 0 0 1.1220731782766369
  translation 11.3 15 0
  rotation 0 0 -1 0
  name "conveyor belt(20)"
  size 1 5 1.5
}
DEF left_big_conveyor_belt_2 ConveyorBelt {
  hidden translation_1 0 0 1.1220731782766369
  translation 8.1 15 0
  rotation 0 0 -1 0
  name "conveyor belt(22)"
  size 1 5 1.5
}
DEF left_big_conveyor_belt_1 ConveyorBelt {
  hidden translation_1 0 0 1.1220731782766369
  translation 4.9 15 0
  rotation 0 0 -1 0
  name "conveyor belt(24)"
  size 1 5 1.5
}
DEF right_big_conveyor_belt_2 ConveyorBelt {
  hidden translation_1 0 0 1.1220731782766369
  translation 8.8 5.5 0
  rotation 0 0 -1 0
  name "conveyor belt(16)"
  size 1 5 1.5
}
DEF right_big_conveyor_belt_1 ConveyorBelt {
  hidden translation_1 0 0 1.1220731782766369
  translation 5.8 5.5 0
  rotation 0 0 -1 0
  name "conveyor belt(18)"
  size 1 5 1.5
}
CardboardBox {
  translation 27.8384 3.01098 0.71
  rotation 0 0 1 0.261799
  size 0.2 0.2 0.2
}
CardboardBox {
  translation 28.0224 3.48865 0.71
  rotation 0 0 1 0.785398
  name "cardboard box(1)"
  size 0.2 0.2 0.2
}
CardboardBox {
  translation 21.6903 3.22499 1.6
  rotation 0 0 1 1.309
  name "cardboard box(6)"
  size 0.2 0.2 0.2
}
CardboardBox {
  translation 7.98736 14.1014 1.6
  rotation 0 0 1 1.309
  name "cardboard box(7)"
  size 0.2 0.2 0.2
}
CardboardBox {
  translation 15.3336 4.18682 1.6
  rotation 0 0 1 2.0944
  name "cardboard box(10)"
  size 0.2 0.2 0.2
}
CardboardBox {
  translation 11.2185 13.9355 1.6
  rotation 0 0 1 2.0944
  name "cardboard box(11)"
  size 0.2 0.2 0.2
}
CardboardBox {
  translation 4.6953 16.4739 1.6
  rotation 0 0 1 2.0944
  name "cardboard box(12)"
  size 0.2 0.2 0.2
}
CardboardBox {
  translation 5.94515 4.74132 1.6
  rotation 0 0 1 1.309
  name "cardboard box(9)"
  size 0.2 0.2 0.2
}
CardboardBox {
  translation 26.2061 1.6839 0.71
  rotation 0 0 1 1.309
  name "cardboard box(8)"
  size 0.2 0.2 0.2
}
CardboardBox {
  translation 28.3211 1.96902 0.77
  rotation 0 0 1 4.692820414042842e-06
  name "cardboard box(5)"
  size 0.2 0.2 0.2
}
CardboardBox {
  translation 28.0496 3.95362 0.71
  rotation 0 0 1 0.261803
  name "cardboard box(2)"
  size 0.2 0.2 0.2
}
CardboardBox {
  translation 18.9049 8.5223 0.11
  rotation 0 0 1 1.5708
  name "cardboard box(4)"
  size 0.2 0.2 0.2
}
CardboardBox {
  translation 20.9849 7.7223 0.11
  rotation 0 0 1 1.5708
  name "cardboard box(13)"
  size 0.2 0.2 0.2
}
CardboardBox {
  translation 17.3949 8.2323 0.11
  rotation 0 0 1 1.5708
  name "cardboard box(16)"
  size 0.2 0.2 0.2
}
CardboardBox {
  translation 18.6349 12.5223 0.11
  rotation 0 0 1 1.5708
  name "cardboard box(17)"
  size 0.2 0.2 0.2
}
CardboardBox {
  translation 17.0749 12.4123 0.11
  rotation 0 0 1 1.5708
  name "cardboard box(18)"
  size 0.2 0.2 0.2
}
CardboardBox {
  translation 24.9049 4.5023 0.11
  rotation 0 0 1 1.5708
  name "cardboard box(15)"
  size 0.2 0.2 0.2
}
CardboardBox {
  translation 24.3649 4.5123 0.11
  rotation 0 0 1 1.5708
  name "cardboard box(14)"
  size 0.2 0.2 0.2
}
CardboardBox {
  translation 22.6249 18.7445 0.15
  rotation 0 0 1 4.07987e-06
  name "cardboard box(3)"
  size 0.2 0.2 0.2
}
Pose {
}
DEF SUPERVISOR Robot {
  rotation 0 0 1 -2.8797853071795863
  controller "floor_mapper"
  supervisor TRUE
}
DEF Pioneer_3-AT Pioneer3at {
  hidden position_0_0 17181.675597994126
  hidden position_0_1 14901.686213960887
  hidden position_0_2 17201.273778068164
  hidden position_0_3 14922.746012515978
  hidden linearVelocity_0 -1.5934203451644696e-12 4.501661137449269e-15 2.583791766400364e-16
  hidden angularVelocity_0 1.029309208303876e-15 -2.6530057002332883e-15 1.274730933400985e-14
  hidden rotation_1 0.5773516024134749 -0.5773476024162304 -0.5773516027299337 2.094404999683543
  hidden translation_2 4.390430234023778e-13 2.1847962280823109e-13 0.04999999999999215
  hidden rotation_2 -0.42526537133496617 0.425258256650912 -0.7989397843977734 1.7934126943521096
  hidden rotation_3 0.5988398473697922 -0.5988354701522437 -0.5317771308449296 2.1641144656118603
  hidden linearVelocity_3 -1.5671141298613943e-12 2.5585833749602766e-14 3.9079907220225917e-16
  hidden angularVelocity_3 -4.577568583334903e-15 -3.5403707386630695e-12 5.561643188611115e-14
  hidden rotation_4 -0.31158511815043644 0.3115849550607363 0.8976800821712474 4.604645004675682
  hidden linearVelocity_4 -1.6062124953111906e-12 2.6608960549105866e-14 9.237192883015506e-16
  hidden angularVelocity_4 -2.7724953609941394e-14 -2.2218127467171738e-11 2.8234306702931705e-13
  hidden rotation_5 0.08194394219877027 -0.08193971344232279 0.9932628422013553 4.70561902492044
  hidden linearVelocity_5 -1.5767251224586335e-12 -1.8970632740979816e-14 -2.1316060619724077e-16
  hidden angularVelocity_5 -3.131605531189096e-14 -1.8104195778543122e-11 2.3200528681333845e-13
  hidden rotation_6 -0.37949244980519575 0.3794914015068425 0.8437841884766646 4.5433297150412475
  hidden linearVelocity_6 -1.6049014364739275e-12 -2.6008865751809645e-14 -1.0657513904043939e-16
  hidden angularVelocity_6 -5.008013762158421e-15 -2.5673203921889753e-12 4.4723740719557385e-14
  translation 21.474789389812805 10.903091934754153 0.00035798223039962274
  rotation 0.009578648377454474 0.006087279236311468 0.9999355951893903 3.140040533272259
  name "Pioneer 3-AT_0"
  controller "pioneer_controller"
}
DEF Pioneer_3-AT Pioneer3at {
  hidden position_0_0 17180.78132260258
  hidden position_0_1 14902.01285546016
  hidden position_0_2 17201.443178761332
  hidden position_0_3 14923.747408116811
  hidden linearVelocity_0 1.3816369689058392e-14 3.372576839012386e-15 -1.0335167065601457e-16
  hidden angularVelocity_0 -5.812553733356003e-16 7.133838536694531e-16 8.151130413220226e-16
  hidden rotation_1 0.5773516024134749 -0.5773476024162304 -0.5773516027299337 2.094404999683543
  hidden translation_2 4.390430234023778e-13 2.1847962280823109e-13 0.04999999999999215
  hidden rotation_2 -0.42526537133496617 0.425258256650912 -0.7989397843977734 1.7934126943521096
  hidden rotation_3 0.6930327124516288 -0.6930262272860441 -0.19854548034546257 2.749607955968024
  hidden linearVelocity_3 2.2766028762311904e-14 6.163086351622575e-15 -1.4211632179666528e-16
  hidden angularVelocity_3 5.786568515254576e-15 -7.000103872921897e-15 -6.690615534297707e-16
  hidden rotation_4 -0.1675377650796827 0.16753934189187486 0.9715254326009911 4.683494249759615
  hidden linearVelocity_4 -2.7750637939527918e-15 -6.56886307312882e-15 1.421153797100159e-16
  hidden angularVelocity_4 4.58834896174529e-15 4.2358839620386104e-17 -6.895951686019204e-16
  hidden rotation_5 0.1639879996558102 -0.16398299301579083 0.9727371248032375 4.684741341084222
  hidden linearVelocity_5 -9.847208450105825e-15 5.991701180627473e-15 1.421122482294909e-16
  hidden angularVelocity_5 8.292909785145842e-15 5.954444754739975e-15 -6.611004712887157e-16
  hidden rotation_6 0.07773614563926129 -0.07773195805855186 0.9939390496190071 4.70629955863249
  hidden linearVelocity_6 -1.0334401937299426e-14 -8.882325973395513e-15 -1.4211185292324147e-16
  hidden angularVelocity_6 1.112882869360054e-14 2.45388812111716e-15 -6.568145606147465e-16
  translation 14.25669999930407 5.304799941431266 -0.0023889310687114917
  rotation -2.473697494411647e-05 2.4823257166725702e-05 0.999999999385944 1.5554589191664303
  name "Pioneer 3-AT_1"
  controller "pioneer_controller_1"
}
DEF Pioneer_3-AT Pioneer3at {
  hidden position_0_0 17180.454441604397
  hidden position_0_1 14901.654045764108
  hidden position_0_2 17201.22296917797
  hidden position_0_3 14923.432880804112
  hidden linearVelocity_0 1.6267009835106578e-14 5.793373709289261e-15 -2.0670334131202914e-16
  hidden angularVelocity_0 -7.255793774649945e-16 1.367959101521758e-15 3.9762940813358656e-15
  hidden rotation_1 0.5773516024134749 -0.5773476024162304 -0.5773516027299337 2.094404999683543
  hidden translation_2 4.390430234023778e-13 2.1847962280823109e-13 0.04999999999999215
  hidden rotation_2 -0.42526537133496617 0.425258256650912 -0.7989397843977734 1.7934126943521096
  hidden rotation_3 0.7047397682761417 -0.7047327646752964 -0.08181435939493396 2.9783340102113183
  hidden linearVelocity_3 1.5934915857669193e-14 -2.4034001264121488e-14 1.421013656701206e-16
  hidden angularVelocity_3 -2.3515074408605754e-15 -4.016157789921107e-15 3.3333576012444e-15
  hidden rotation_4 -0.3244966544614053 0.3244963266431656 0.8884841333633636 4.594413538114177
  hidden linearVelocity_4 -1.6541462764126487e-14 -2.4109351927597634e-14 -5.684214262274238e-16
  hidden angularVelocity_4 -1.1757477832461985e-15 2.684318008470958e-16 3.2545119452927078e-15
  hidden rotation_5 0.05678641999375676 -0.056782439250735214 0.9967703131098102 4.7091439332841505
  hidden linearVelocity_5 1.5932159302425754e-14 2.4314834890300775e-14 -7.107056550020648e-17
  hidden angularVelocity_5 1.1757646181174363e-15 -4.1444108836785275e-15 2.8418108544681683e-15
  hidden rotation_6 -0.07888296156203892 0.07888553015814916 0.9937577931804458 4.706116647184425
  hidden linearVelocity_6 -1.717562432149822e-14 2.454343655673536e-14 2.131752311834303e-16
  hidden angularVelocity_6 -3.5271966672113846e-15 -8.447847795987292e-15 2.0988394982032913e-15
  translation 10.68229934696106 9.696709999979111 -0.0023889310679025
  rotation -0.007212864419137077 0.9999538025559105 -0.006353529794223109 4.918019805350901e-05
  name "Pioneer 3-AT_2"
  controller "pioneer_controller_2"
}
DEF Pioneer_3-AT Pioneer3at {
  hidden position_0_0 17180.45440498884
  hidden position_0_1 14901.65401096943
  hidden position_0_2 17201.22305705772
  hidden position_0_3 14923.43297021905
  hidden linearVelocity_0 6.5127819488429814e-15 1.3695598387462886e-14 -5.1675835328007286e-17
  hidden angularVelocity_0 1.8079669199713133e-15 6.839083339755179e-16 -3.828630811679174e-15
  hidden rotation_1 0.5773516024134749 -0.5773476024162304 -0.5773516027299337 2.094404999683543
  hidden translation_2 4.390430234023778e-13 2.1847962280823109e-13 0.04999999999999215
  hidden rotation_2 -0.42526537133496617 0.425258256650912 -0.7989397843977734 1.7934126943521096
  hidden rotation_3 0.7047405221775744 -0.7047335185247147 -0.08180137082381561 2.9783598144086745
  hidden linearVelocity_3 9.328984362726459e-15 -2.4778283437298384e-14 3.5527033193044577e-16
  hidden angularVelocity_3 1.1757272342205739e-15 -6.052698239486294e-15 -3.2512341452724704e-15
  hidden rotation_4 -0.32451048397344534 0.3245101559779086 0.8884740313923156 4.594402247128686
  hidden linearVelocity_4 -1.09294861601141e-14 -2.110526872221473e-14 3.552844120592154e-16
  hidden angularVelocity_4 -9.897770539643209e-21 1.7398777774384505e-15 -4.025785633994111e-15
  hidden rotation_5 0.056830076515776484 -0.05682609533859137 0.9967653371239292 4.709138941339283
  hidden linearVelocity_5 2.0610386795162926e-14 2.2824028586227007e-14 -8.526399032264589e-16
  hidden angularVelocity_5 1.814712541944483e-20 -3.713521161793219e-15 -2.8031232540911438e-15
  hidden rotation_6 -0.07883880931864894 0.07884137839485 0.9937648007441287 4.706123698755304
  hidden linearVelocity_6 -2.103176010647218e-14 2.2563514879167902e-14 2.1318578859494529e-16
  hidden angularVelocity_6 5.878787114143186e-15 -9.99892776347046e-15 -3.5474339573412147e-15
  translation 7.891711741444334 9.700530025627735 -0.0023889310679026388
  rotation -0.00721041639052947 0.9997153300874407 -0.022743541580737475 4.919192966093875e-05
  name "Pioneer 3-AT_3"
  controller "pioneer_controller_3"
}
SquareManhole {
  translation 25 19 0
}
SquareManhole {
  translation 19.092 9.85948 -0.04
  rotation 0 0 1 0.523602
  name "manhole(16)"
}
SquareManhole {
  translation 20.7736 10.6536 -0.04
  rotation 0 0 1 0.785401
  name "manhole(17)"
}
SquareManhole {
  translation 9.00273 10.7778 -0.02
  rotation 0 0 1 1.5708
  name "manhole(12)"
}
SquareManhole {
  translation 4.9337 9.8387 -0.04
  rotation 9.58978e-09 3.57898e-08 1 -0.523595307179586
  name "manhole(11)"
}
WoodenPallet {
  translation 6 8.7 0
  name "wooden pallet(7)"
  size 2 1 0.1
}
WoodenPallet {
  translation 12.72 8.7 0
  name "wooden pallet(8)"
  size 2 1 0.1
}
WoodenPallet {
  translation 15.74 8.7 0
  name "wooden pallet(9)"
  size 2 1 0.1
}
WoodenPallet {
  translation 13.93 11.89 0
  name "wooden pallet(10)"
  size 2 1 0.1
}
WoodenPallet {
  translation 20.37 11.89 0
  name "wooden pallet(11)"
  size 2 1 0.1
}
Robot {
  translation 1.6005464063897952 1.4133767194900337 -0.010403707020512715
  rotation -0.6703636575080674 0.6689109026349904 -0.32120207195541056 0.0047837403375133305
  children [
    Pose {
      translation 0.037646 0 0
      children [
        Shape {
          appearance DEF WHITE Plastic {
          }
          geometry Mesh {
            url [
              "https://raw.githubusercontent.com/cyberbotics/webots/R2025a/projects/robots/mir/mir100/protos/meshes/mir_100_base.obj"
            ]
          }
        }
        Shape {
          appearance USE WHITE
          geometry Mesh {
            url [
              "https://raw.githubusercontent.com/cyberbotics/webots/R2025a/projects/robots/mir/mir100/protos/meshes/mir_100_inside.obj"
            ]
          }
        }
        Shape {
          appearance Plastic {
            colorOverride 0.93 0.93 0.93
          }
          geometry Mesh {
            url [
              "https://raw.githubusercontent.com/cyberbotics/webots/R2025a/projects/robots/mir/mir100/protos/meshes/mir_100_logos.dae"
            ]
          }
        }
        Shape {
          appearance DEF BLACK Plastic {
            colorOverride 0 0 0
          }
          geometry Mesh {
            url [
              "https://raw.githubusercontent.com/cyberbotics/webots/R2025a/projects/robots/mir/mir100/protos/meshes/mir_100_base_corners.dae"
            ]
          }
        }
        Shape {
          appearance DEF BLACK Plastic {
            colorOverride 0 0 0
          }
          geometry Mesh {
            url [
              "https://raw.githubusercontent.com/cyberbotics/webots/R2025a/projects/robots/mir/mir100/protos/meshes/mir_100_top_plugs.dae"
            ]
          }
        }
      ]
    }
    DEF IMU Pose {
      translation 0 0 0.25
      children [
        Accelerometer {
          name "imu_data accelerometer"
          lookupTable [
            -100 -100 -0.002
            100 100 0.002
          ]
        }
        Gyro {
          name "imu_data gyro"
          lookupTable [
            -100 -100 -0.002
            100 100 0.002
          ]
        }
        Compass {
          name "imu_data compass"
          lookupTable [
            -1 -1 -0.2
            1 1 0.2
          ]
        }
      ]
    }
    Pose {
      translation 0.4288 0.2358 0.188
      rotation -0.9238797538373538 -0.38268289803626016 0 -3.14159
    }
    Pose {
      translation -0.3548 -0.2352 0.188
      rotation 0.38268289803626016 -0.9238797538373538 0 -3.14159
    }
    Pose {
      translation 0.037646 0 0.349
    }
    DEF CAMERA_RIGHT Transform {
      translation 0.448325 -0.063463 0.110114
      rotation 0.23089800552792925 -0.8463170202616761 -0.48003501149251837 -1.480875307179586
      scale 1.0003465485345713 0.92893 0.92893
      children [
        Shape {
          appearance Appearance {
            material Material {
              emissiveColor 1 1 1
            }
            texture ImageTexture {
              url [
                "https://raw.githubusercontent.com/cyberbotics/webots/R2025a/projects/robots/mir/mir100/protos/textures/camera.png"
              ]
            }
            textureTransform TextureTransform {
              rotation 3.1415926
            }
          }
          geometry Plane {
            size 0.08 0.015
          }
        }
      ]
    }
    DEF CAMERA_LEFT Transform {
      translation 0.448325 0.063463 0.110114
      rotation 0.6034542780292518 -0.1646370758531751 0.7802163594687759 2.48203
      scale 1.0003465485345713 0.92893 0.92893
      children [
        Shape {
          appearance Appearance {
            material Material {
              emissiveColor 1 1 1
            }
            texture ImageTexture {
              url [
                "https://raw.githubusercontent.com/cyberbotics/webots/R2025a/projects/robots/mir/mir100/protos/textures/camera.png"
              ]
            }
          }
          geometry Plane {
            size 0.08 0.015
          }
        }
      ]
    }
    Mir100UltrasonicSensor {
      translation 0.415448 -0.108238 0.08
      rotation 0.8628559982596194 -0.35740699927911007 -0.35740699927911007 1.71777
      name "ds0"
      lookupTable [
        0.2 1000 0
        0.3 0 0
      ]
    }
    Mir100UltrasonicSensor {
      translation -0.3844 -0.1328 0.156
      rotation 0 0 1 3.141592653589793
      name "ds1"
    }
    Mir100UltrasonicSensor {
      translation -0.3844 0.1328 0.156
      rotation 0 0 1 3.141592653589793
      name "ds2"
    }
    Mir100UltrasonicSensor {
      translation 0.415448 0.108238 0.08
      rotation 0.8628559982596194 0.35740699927911007 0.35740699927911007 1.71777
      name "ds3"
      lookupTable [
        0.2 1000 0
        0.3 0 0
      ]
    }
    RangeFinder {
      translation 0.004 -0.28 0.18
      rotation 0 0 1 -1.5707953071795862
      name "depth_camera"
      fieldOfView 2.05949
      width 1280
      height 720
      minRange 0.18
      maxRange 1.95
    }
    Pose {
      translation 0.03733 0.0005 0.2085
      children [
        DEF LIGHT_FRONT Pose {
          translation 0.392 0 0
          children [
            DEF LIGHT_WIDTH_SHAPE Shape {
              appearance PBRAppearance {
                transparency 0.5
                emissiveColor 0 0.9 1
              }
              geometry Box {
                size 0.001 0.4723 0.053
              }
            }
          ]
        }
        DEF LIGHT_BACK Pose {
          translation -0.392 0 0
          children [
            USE LIGHT_WIDTH_SHAPE
          ]
        }
        DEF LIGHT_LEFT Pose {
          translation 0 0.2355 0
          children [
            DEF LIGHT_WIDTH_SHAPE Shape {
              appearance PBRAppearance {
                transparency 0.5
                emissiveColor 0 0.9 1
              }
              geometry Box {
                size 0.783 0.001 0.053
              }
            }
          ]
        }
        DEF LIGHT_RIGHT Pose {
          translation 0 -0.2355 0
          children [
            USE LIGHT_WIDTH_SHAPE
          ]
        }
      ]
    }
    DEF US_1_FRAME Solid {
      translation 0.45 -0.12 0.16
      name "us_1_frame"
    }
    DEF US_2_FRAME Solid {
      translation 0.45 0.12 0.16
      name "us_2_frame"
    }
    DEF LEFT_WHEEL_JOINT HingeJoint {
      jointParameters HingeJointParameters {
        position -4.9139261620889955e-05
        axis 0 1 0
        anchor 0 0.222604 0.0625
      }
      device [
        RotationalMotor {
          name "middle_left_wheel_joint"
          maxVelocity 20
          maxTorque 100
        }
        PositionSensor {
          name "middle_left_wheel_joint_sensor"
        }
      ]
      endPoint DEF LEFT_WHEEL_LINK Solid {
        translation 0 0.222604 0.0625
        rotation -0.9999999993963357 -2.4569540551429665e-05 -2.4569630800557135e-05 1.5708000006036618
        children [
          Group {
            children [
              DEF RIM Shape {
                appearance CorrodedMetal {
                }
                geometry Cylinder {
                  height 0.032
                  radius 0.0465
                }
              }
              SolidTorus {
                translation 0 0 0
                majorRadius 0.0465
                minorRadius 0.016
                appearance DEF WHEEL_RUBBER PBRAppearance {
                  baseColor 0 0 0
                  roughness 1
                  metalness 0
                }
                enableBoundingObject FALSE
              }
            ]
          }
        ]
        name "left_wheel_link"
        contactMaterial "wheel"
        boundingObject DEF WHEEL_BO Cylinder {
          height 0.01
          radius 0.0625
        }
        physics Physics {
          density -1
          mass 1
          centerOfMass [
            0 0 0
          ]
          inertiaMatrix [
            0.001061895 0.001953125 0.001061895
            0 0 5.457207e-20
          ]
        }
        linearVelocity 3.8007790046133084e-06 2.4995329770809463e-06 -5.714376015587268e-06
        angularVelocity -2.072005465135119e-06 1.9399831628067245e-06 -7.103587368086862e-06
      }
    }
    DEF RIGHT_WHEEL_JOINT HingeJoint {
      jointParameters HingeJointParameters {
        position -2.2690954568862924e-05
        axis 0 1 0
        anchor 0 -0.222604 0.0625
      }
      device [
        RotationalMotor {
          name "middle_right_wheel_joint"
          maxVelocity 20
          maxTorque 100
        }
        PositionSensor {
          name "middle_right_wheel_joint_sensor"
        }
      ]
      endPoint DEF RIGHT_WHEEL_LINK Solid {
        translation 0 -0.222604 0.0625
        rotation -0.9999999998712804 -1.1345435609269373e-05 -1.1345477283457872e-05 1.5708000001287166
        children [
          Group {
            children [
              USE RIM
              SolidTorus {
                translation 0 0 0
                majorRadius 0.0465
                minorRadius 0.016
                appearance USE WHEEL_RUBBER
                enableBoundingObject FALSE
              }
            ]
          }
        ]
        name "right_wheel_link"
        contactMaterial "wheel"
        boundingObject USE WHEEL_BO
        physics Physics {
          density -1
          mass 1
          centerOfMass [
            0 0 0
          ]
          inertiaMatrix [
            0.001061895 0.001953125 0.001061895
            0 0 5.457207e-20
          ]
        }
        linearVelocity 6.539412853838834e-07 2.541207156609982e-06 -4.788825369703512e-06
        angularVelocity -2.0704650159743074e-06 1.5496694470074558e-06 -7.102334548969446e-06
      }
    }
    DEF FL_CASTER_ROTATION_JOINT HingeJoint {
      jointParameters HingeJointParameters {
        position 1.994601248400622
        axis 0 0 1
        anchor 0.341346 0.203 0.1565
        dampingConstant 0.01
      }
      device [
        PositionSensor {
          name "front_left_caster_joint_sensor"
        }
      ]
      endPoint DEF FL_CASTER_ROTATION_LINK Solid {
        translation 0.341346 0.203 0.1565
        rotation 0 0 1 1.9946012484006217
        children [
          DEF CASTER_WHEEL_BASE Shape {
            appearance PBRAppearance {
              baseColor 0.35 0.35 0.35
              roughness 1
              metalness 0
            }
            geometry Mesh {
              url [
                "https://raw.githubusercontent.com/cyberbotics/webots/R2025a/projects/robots/mir/mir100/protos/meshes/caster_wheel_base.dae"
              ]
            }
          }
          DEF FL_CASTER_WHEEL_JOINT HingeJoint {
            jointParameters HingeJointParameters {
              position -0.15105055177861826
              axis 0 1 0
              anchor -0.0382 0 -0.094
            }
            device [
              PositionSensor {
                name "front_left_wheel_joint_sensor"
              }
            ]
            endPoint DEF FL_CASTER_WHEEL_LINK Solid {
              translation -0.0382 0 -0.094
              rotation -0.994322905153074 -0.0752393470867102 -0.07523962345677142 1.5764932399849103
              children [
                Group {
                  children [
                    USE RIM
                    SolidTorus {
                      translation 0 0 0
                      majorRadius 0.0465
                      minorRadius 0.016
                      appearance USE WHEEL_RUBBER
                      enableBoundingObject FALSE
                    }
                  ]
                }
              ]
              name "fl_caster_wheel_link"
              contactMaterial "wheel"
              boundingObject USE WHEEL_BO
              physics Physics {
                density -1
                mass 1
                centerOfMass [
                  0 0 0
                ]
                inertiaMatrix [
                  0.001061895 0.001953125 0.001061895
                  0 0 5.457207e-20
                ]
              }
              linearVelocity -1.8357787569227186e-06 -2.3813969806549875e-06 -6.136883606474152e-06
              angularVelocity 1.9310597022799328e-05 1.0821210268385665e-05 -0.00015805081444456536
            }
          }
        ]
        name "fl_caster_rotation_link"
        boundingObject Pose {
          translation 0 0 -0.028
          children [
            DEF SWIVEL Cylinder {
              height 0.055
              radius 0.0298
            }
          ]
        }
        physics Physics {
          density -1
          mass 0.309754
          centerOfMass [
            0 0 -0.0425
          ]
          inertiaMatrix [
            0.0005287255 0.000517415 0.0002462724
            -7.734275e-21 -1.120566e-20 -0.0001505672
          ]
        }
        linearVelocity 3.741263458782396e-06 1.9511271872826997e-07 -6.178081464632265e-06
        angularVelocity -2.5536761841161975e-06 9.977003639311822e-07 -0.0001579492861342526
      }
    }
    DEF FR_CASTER_ROTATION_JOINT HingeJoint {
      jointParameters HingeJointParameters {
        position 0.2446146810016309
        axis 0 0 1
        anchor 0.341346 -0.203 0.1565
        dampingConstant 0.01
      }
      device [
        PositionSensor {
          name "front_right_caster_joint_sensor"
        }
      ]
      endPoint DEF FR_CASTER_ROTATION_LINK Solid {
        translation 0.341346 -0.203 0.1565
        rotation 0 0 1 0.24461468100163053
        children [
          USE CASTER_WHEEL_BASE
          DEF FR_CASTER_WHEEL_JOINT HingeJoint {
            jointParameters HingeJointParameters {
              position 0.07406478303953735
              axis 0 1 0
              anchor -0.0382 0 -0.094
            }
            device [
              PositionSensor {
                name "front_right_wheel_joint_sensor"
              }
            ]
            endPoint DEF FR_CASTER_WHEEL_LINK Solid {
              translation -0.0382 0 -0.094
              rotation -0.9986301720162243 0.036998442416001545 0.036998578319118604 1.5721707666230638
              children [
                Group {
                  children [
                    USE RIM
                    SolidTorus {
                      translation 0 0 0
                      majorRadius 0.0465
                      minorRadius 0.016
                      appearance USE WHEEL_RUBBER
                      enableBoundingObject FALSE
                    }
                  ]
                }
              ]
              name "fr_caster_wheel_link"
              contactMaterial "wheel"
              boundingObject USE WHEEL_BO
              physics Physics {
                density -1
                mass 1
                centerOfMass [
                  0 0 0
                ]
                inertiaMatrix [
                  0.001061895 0.001953125 0.001061895
                  0 0 5.457207e-20
                ]
              }
              linearVelocity 1.0636478429024323e-06 -1.0540225703601094e-06 -5.286116101046368e-06
              angularVelocity -4.478092425867204e-06 1.1800862395256095e-05 3.10942426473305e-05
            }
          }
        ]
        name "fr_caster_rotation_link"
        boundingObject Pose {
          translation 0 0 -0.028
          children [
            USE SWIVEL
          ]
        }
        physics Physics {
          density -1
          mass 0.309754
          centerOfMass [
            0 0 -0.0425
          ]
          inertiaMatrix [
            0.0005287255 0.000517415 0.0002462724
            -7.734275e-21 -1.120566e-20 -0.0001505672
          ]
        }
        linearVelocity 8.552969559997997e-07 2.028387944209927e-07 -5.333751439886919e-06
        angularVelocity -1.9489901884136505e-06 1.6023291340880202e-06 3.1118818341178915e-05
      }
    }
    DEF BL_CASTER_ROTATION_JOINT HingeJoint {
      jointParameters HingeJointParameters {
        position 1.9841055206218892
        axis 0 0 1
        anchor -0.270154 0.203 0.1565
        dampingConstant 0.01
      }
      device [
        PositionSensor {
          name "back_left_caster_joint_sensor"
        }
      ]
      endPoint DEF BL_CASTER_ROTATION_LINK Solid {
        translation -0.270154 0.203 0.1565
        rotation 0 0 1 1.9841055206218892
        children [
          USE CASTER_WHEEL_BASE
          DEF BL_CASTER_WHEEL_JOINT HingeJoint {
            jointParameters HingeJointParameters {
              position -0.14262524581532204
              axis 0 1 0
              anchor -0.0382 0 -0.094
            }
            device [
              PositionSensor {
                name "back_left_wheel_joint_sensor"
              }
            ]
            endPoint DEF BL_CASTER_WHEEL_LINK Solid {
              translation -0.0382 0 -0.094
              rotation -0.9949359653195793 -0.07107175179112515 -0.07107201285272585 1.5758768785005628
              children [
                Group {
                  children [
                    USE RIM
                    SolidTorus {
                      translation 0 0 0
                      majorRadius 0.0465
                      minorRadius 0.016
                      appearance USE WHEEL_RUBBER
                      enableBoundingObject FALSE
                    }
                  ]
                }
              ]
              name "bl_caster_wheel_link"
              contactMaterial "wheel"
              boundingObject USE WHEEL_BO
              physics Physics {
                density -1
                mass 1
                centerOfMass [
                  0 0 0
                ]
                inertiaMatrix [
                  0.001061895 0.001953125 0.001061895
                  0 0 5.457207e-20
                ]
              }
              linearVelocity -2.9872394168037663e-06 1.5275589599292727e-06 -5.208989321428971e-06
              angularVelocity -3.9544803702302714e-05 -1.521687421167257e-05 -0.00019026591316117066
            }
          }
        ]
        name "bl_caster_rotation_link"
        boundingObject Pose {
          translation 0 0 -0.028
          children [
            USE SWIVEL
          ]
        }
        physics Physics {
          density -1
          mass 0.309754
          centerOfMass [
            0 0 -0.0425
          ]
          inertiaMatrix [
            0.0005287255 0.000517415 0.0002462724
            -7.734275e-21 -1.120566e-20 -0.0001505672
          ]
        }
        linearVelocity 3.751862398282948e-06 4.542553435384621e-06 -5.2654954046082295e-06
        angularVelocity -2.657935806607533e-06 8.932002250521195e-07 -0.00019043560426855918
      }
    }
    DEF BR_CASTER_ROTATION_JOINT HingeJoint {
      jointParameters HingeJointParameters {
        position 0.017172435102168624
        axis 0 0 1
        anchor -0.270154 -0.203 0.1565
        dampingConstant 0.01
      }
      device [
        PositionSensor {
          name "back_right_caster_joint_sensor"
        }
      ]
      endPoint DEF BR_CASTER_ROTATION_LINK Solid {
        translation -0.270154 -0.203 0.1565
        rotation 0 0 1 0.017172435102175188
        children [
          USE CASTER_WHEEL_BASE
          DEF BR_CASTER_WHEEL_JOINT HingeJoint {
            jointParameters HingeJointParameters {
              position 0.09735661280786066
              axis 0 1 0
              anchor -0.0382 0 -0.094
            }
            device [
              PositionSensor {
                name "back_right_wheel_joint_sensor"
              }
            ]
            endPoint DEF BR_CASTER_WHEEL_LINK Solid {
              translation -0.0382 0 -0.094
              rotation -0.9976350985749314 0.04860140295502985 0.048601581478279074 1.573167699998514
              children [
                Group {
                  children [
                    USE RIM
                    SolidTorus {
                      translation 0 0 0
                      majorRadius 0.0465
                      minorRadius 0.016
                      appearance USE WHEEL_RUBBER
                      enableBoundingObject FALSE
                    }
                  ]
                }
              ]
              name "br_caster_wheel_link"
              contactMaterial "wheel"
              boundingObject USE WHEEL_BO
              physics Physics {
                density -1
                mass 1
                centerOfMass [
                  0 0 0
                ]
                inertiaMatrix [
                  0.001061895 0.001953125 0.001061895
                  0 0 5.457207e-20
                ]
              }
              linearVelocity 8.780815969384782e-07 -1.3041733496077556e-06 -4.365235581640531e-06
              angularVelocity -1.7563337533080385e-06 1.417136051814948e-05 0.0001506528159344842
            }
          }
        ]
        name "br_caster_rotation_link"
        boundingObject Pose {
          translation 0 0 -0.028
          children [
            USE SWIVEL
          ]
        }
        physics Physics {
          density -1
          mass 0.309754
          centerOfMass [
            0 0 -0.0425
          ]
          inertiaMatrix [
            0.0005287255 0.000517415 0.0002462724
            -7.734275e-21 -1.120566e-20 -0.0001505672
          ]
        }
        linearVelocity 8.654703966700145e-07 4.5523281140317465e-06 -4.421384997603614e-06
        angularVelocity -1.5658769899556111e-06 1.985766184331315e-06 0.00015069117352465786
      }
    }
    DEF SURFACE Solid {
      translation 0.037646 0 0.352
      name "surface"
    }
  ]
  name "Mir100"
  model "Mobile Industrial Robots' MiR100"
  boundingObject Group {
    children [
      DEF TOP Pose {
        translation 0.0375 0.0005 0.334
        children [
          Box {
            size 0.774 0.461 0.04
          }
        ]
      }
      DEF MIDDLE_CENTER Pose {
        translation 0.0375 0.0005 0.262
        children [
          Box {
            size 0.857 0.44 0.096
          }
        ]
      }
      DEF MIDDLE_RIGHT_SIDE Pose {
        translation 0.0375 -0.25 0.262
        children [
          Box {
            size 0.774 0.041 0.096
          }
        ]
      }
      DEF MIDDLE_LEFT_SIDE Pose {
        translation 0.0375 0.25 0.262
        children [
          Box {
            size 0.774 0.041 0.096
          }
        ]
      }
      DEF CYL_BR Pose {
        translation -0.3555 -0.2353 0.262
        children [
          Cylinder {
            height 0.096
            radius 0.054
          }
        ]
      }
      DEF CYL_FL Pose {
        translation 0.4306 0.2364 0.262
        children [
          Cylinder {
            height 0.096
            radius 0.054
          }
        ]
      }
      DEF CYL_FR Pose {
        translation 0.415 -0.221 0.262
        children [
          Cylinder {
            height 0.096
            radius 0.049
          }
        ]
      }
      DEF CYL_BL Pose {
        translation -0.341 0.222 0.262
        children [
          Cylinder {
            height 0.096
            radius 0.049
          }
        ]
      }
      DEF MIDLOW Pose {
        translation 0.03733 0.0005 0.204
        children [
          Box {
            size 0.7806 0.4665 0.04
          }
        ]
      }
      DEF LOW Pose {
        translation 0.0374 0.0005 0.16
        children [
          Box {
            size 0.85 0.536 0.039
          }
        ]
      }
      DEF BOTTOM_LEFT Pose {
        translation 0.0374 0.2486 0.09425
        children [
          Box {
            size 0.35 0.04 0.0925
          }
        ]
      }
      DEF BOTTOM_RIGHT Pose {
        translation 0.0374 -0.2476 0.09425
        children [
          Box {
            size 0.35 0.04 0.0925
          }
        ]
      }
      DEF BOTTOM_CENTER Pose {
        translation 0.0375 0.0005 0.094
        children [
          Box {
            size 0.857 0.2 0.092
          }
        ]
      }
    ]
  }
  physics Physics {
    density -1
    mass 70
  }
  controller "mir100"
  linearVelocity 2.463111580268936e-06 2.5732628175377525e-06 -5.278426765048087e-06
  angularVelocity -2.0715766373681117e-06 1.4806753567193703e-06 -7.102110664836079e-06
}
