#VRML_SIM R2025a utf8

EXTERNPROTO "https://raw.githubusercontent.com/cyberbotics/webots/R2025a/projects/objects/backgrounds/protos/TexturedBackground.proto"
EXTERNPROTO "https://raw.githubusercontent.com/cyberbotics/webots/R2025a/projects/objects/backgrounds/protos/TexturedBackgroundLight.proto"
EXTERNPROTO "https://raw.githubusercontent.com/cyberbotics/webots/R2025a/projects/objects/floors/protos/RectangleArena.proto"
EXTERNPROTO "https://raw.githubusercontent.com/cyberbotics/webots/R2025a/projects/appearances/protos/Parquetry.proto"
EXTERNPROTO "../protos/ConveyorBelt.proto"
EXTERNPROTO "../protos/Pioneer3at.proto"
EXTERNPROTO "../protos/WoodenPallet.proto"
EXTERNPROTO "https://raw.githubusercontent.com/cyberbotics/webots/R2025a/projects/objects/factory/containers/protos/CardboardBox.proto"
EXTERNPROTO "https://raw.githubusercontent.com/cyberbotics/webots/R2025a/projects/objects/factory/containers/protos/PlasticFruitBox.proto"
EXTERNPROTO "https://raw.githubusercontent.com/cyberbotics/webots/R2025a/projects/objects/factory/manhole/protos/SquareManhole.proto"
EXTERNPROTO "https://raw.githubusercontent.com/cyberbotics/webots/R2025a/projects/objects/traffic/protos/SignPole.proto"
EXTERNPROTO "https://raw.githubusercontent.com/cyberbotics/webots/R2025a/projects/objects/traffic/protos/DirectionPanel.proto"
EXTERNPROTO "https://raw.githubusercontent.com/cyberbotics/webots/R2025a/projects/humans/pedestrian/protos/Pedestrian.proto"
EXTERNPROTO "https://raw.githubusercontent.com/cyberbotics/webots/R2025a/projects/appearances/protos/Plastic.proto"
EXTERNPROTO "https://raw.githubusercontent.com/cyberbotics/webots/R2025a/projects/robots/mir/mir100/protos/Mir100UltrasonicSensor.proto"
EXTERNPROTO "https://raw.githubusercontent.com/cyberbotics/webots/R2025a/projects/appearances/protos/CorrodedMetal.proto"
EXTERNPROTO "https://raw.githubusercontent.com/cyberbotics/webots/R2025a/projects/objects/solids/protos/SolidTorus.proto"

WorldInfo {
}
Viewpoint {
  orientation -0.37843982941664256 0.5644353032565567 -0.7336184866460096 4.80227023621706
  position 1.9691411566625794 -2.500749778570412 -6.663575123076781
  follow "Pioneer 3-AT_0"
  followType "None"
}
TexturedBackground {
}
TexturedBackgroundLight {
}
DEF rectangle_arena RectangleArena {
  translation 15.1304 9.85552 -0.5
  floorSize 30 20
  floorTileSize 1 1
  floorAppearance Parquetry {
    type "dark strip"
  }
}
Pedestrian {
  translation 11.06 7.31002 1.27
  rotation 0 0 1 -3.1415853071795863
}
Pedestrian {
  translation 16.3842 17.72 1.28
  rotation 0 0 1 -0.523595307179586
  name "pedestrian(1)"
}
Pedestrian {
  translation 26.7331 5.34865 1.28
  rotation 0 0 -1 1.5708
  name "pedestrian(2)"
}
SignPole {
  translation 25.3498 15.6897 0
  rotation 0 0 1 3.14159
  height 1
  signBoards [
    DirectionPanel {
      translation 0 0 -0.86
      width 0.4
      height 0.2
    }
  ]
}
PlasticFruitBox {
  translation 28.2254 1.86879 0.63
  rotation 0 0 1 0.261799
  color 0.371527 0.966171 0.557473
}
DEF left_big_conveyor_belt_5 ConveyorBelt {
  hidden translation_1 0 0 1.1219163115120803
  translation 17.8 15 0
  rotation 0 0 -1 0
  size 1 5 1.5
}
DEF left_big_conveyor_belt_6 ConveyorBelt {
  hidden translation_1 7.105427357601002e-15 -3.552713678800501e-15 1.1219163115120787
  translation 21 15 0
  rotation 0 0 -1 0
  name "conveyor belt(11)"
  size 1 5 1.5
}
DEF left_big_conveyor_belt_6 ConveyorBelt {
  hidden translation_1 -0.0003848911937467392 2.1388581966874654e-05 1.1469607526386167
  hidden rotation_1 -0.007108017828594725 0.999974682844138 -0.0003312903771018675 0.006046461441891239
  translation 28.88 15 0
  rotation 0 0 -1 0
  name "conveyor belt(25)"
  size 1 5 1.5
}
DEF left_small_conveyor_belt_4 ConveyorBelt {
  hidden translation_1 0 0 0.7469163117035101
  translation 13.33 14.5 0
  rotation 0 0 -1 0
  name "conveyor belt(3)"
  size 1 4 1
}
DEF left_big_conveyor_belt_4 ConveyorBelt {
  hidden translation_1 0 0 1.1219163115120803
  translation 14.5 15 0
  rotation 0 0 -1 0
  name "conveyor belt(4)"
  size 1 5 1.5
}
DEF left_small_conveyor_belt_5 ConveyorBelt {
  hidden translation_1 0 0 0.7469163115123268
  translation 16.6 14.5 0
  rotation 0 0 -1 0
  name "conveyor belt(1)"
  size 1 4 1
}
DEF left_small_conveyor_belt_6 ConveyorBelt {
  hidden translation_1 0 0 0.7469163115120724
  translation 19.8 14.5 0
  rotation 0 0 -1 0
  name "conveyor belt(10)"
  size 1 4 1
}
DEF right_small_conveyor_belt_6 ConveyorBelt {
  hidden translation_1 0 0 0.7469163115120724
  translation 23 6 0
  rotation 0 0 -1 0
  name "conveyor belt(2)"
  size 1 4 1
}
DEF right_big_conveyor_belt_6 ConveyorBelt {
  hidden translation_1 0 0 1.1219163115120803
  translation 21.8 5.5 0
  rotation 0 0 -1 0
  name "conveyor belt(5)"
  size 1 5 1.5
}
ConveyorBelt {
  hidden translation_1 0 0 0.44691631151206695
  translation 27.8449 2.58127 0
  rotation 0 0 -1 0
  name "conveyor belt(12)"
  size 4 4 0.6
}
DEF right_small_conveyor_belt_5 ConveyorBelt {
  hidden translation_1 0 0 0.7469163115120724
  translation 19.8 6 0
  rotation 0 0 -1 0
  name "conveyor belt(6)"
  size 1 4 1
}
WoodenPallet {
  translation 22.5 8.7 0
  size 2 1 0.1
}
WoodenPallet {
  translation 19 8.7 0
  name "wooden pallet(1)"
  size 2 1 0.1
}
WoodenPallet {
  translation 9.4 8.7 0
  name "wooden pallet(6)"
  size 2 1 0.1
}
WoodenPallet {
  translation 17 11.9 0
  name "wooden pallet(2)"
  size 2 1 0.1
}
WoodenPallet {
  translation 10.73 11.9 0
  name "wooden pallet(3)"
  size 2 1 0.1
}
WoodenPallet {
  translation 7.5 11.9 0
  name "wooden pallet(5)"
  size 2 1 0.1
}
WoodenPallet {
  translation 4.5 11.9 0
  name "wooden pallet(4)"
  size 2 1 0.1
}
DEF right_big_conveyor_belt_5 ConveyorBelt {
  hidden translation_1 0 0 1.1219163115120803
  translation 18.5 5.5 0
  rotation 0 0 -1 0
  name "conveyor belt(7)"
  window "<none>"
  size 1 5 1.5
}
DEF right_small_conveyor_belt_4 ConveyorBelt {
  hidden translation_1 0 0 0.7469163115120724
  translation 16.46 6 0
  rotation 0 0 -1 0
  name "conveyor belt(8)"
  window "<none>"
  size 1 4 1
}
DEF right_small_conveyor_belt_3 ConveyorBelt {
  hidden translation_1 0 0 0.7469163116766864
  translation 13.22 6 0
  rotation 0 0 -1 0
  name "conveyor belt(14)"
  window "<none>"
  size 1 4 1
}
DEF left_small_conveyor_belt_2 ConveyorBelt {
  hidden translation_1 0 0 0.7469163115120724
  translation 6.9 14.5 0
  rotation 0 0 -1 0
  name "conveyor belt(21)"
  size 1 4 1
}
DEF left_small_conveyor_belt_1 ConveyorBelt {
  hidden translation_1 0 0 0.7469163115120724
  translation 3.7 14.5 0
  rotation 0 0 -1 0
  name "conveyor belt(23)"
  size 1 4 1
}
DEF left_small_conveyor_belt_3 ConveyorBelt {
  hidden translation_1 0 0 0.7469163115120724
  translation 10.1 14.5 0
  rotation 0 0 -1 0
  name "conveyor belt(19)"
  size 1 4 1
}
DEF right_small_conveyor_belt_2 ConveyorBelt {
  hidden translation_1 0 0 0.7469163115120724
  translation 10 6 0
  rotation 0 0 -1 0
  name "conveyor belt(15)"
  size 1 4 1
}
DEF right_small_conveyor_belt_1 ConveyorBelt {
  hidden translation_1 0 0 0.7469163115120724
  translation 7 6 0
  rotation 0 0 -1 0
  name "conveyor belt(17)"
  size 1 4 1
}
DEF right_big_conveyor_belt_4 ConveyorBelt {
  hidden translation_1 0 0 1.1219163115120803
  translation 15.3 5.5 0
  rotation 0 0 -1 0
  name "conveyor belt(9)"
  size 1 5 1.5
}
DEF right_big_conveyor_belt_3 ConveyorBelt {
  hidden translation_1 0 0 1.1219163115120803
  translation 12 5.5 0
  rotation 0 0 -1 0
  name "conveyor belt(13)"
  size 1 5 1.5
}
DEF left_big_conveyor_belt_3 ConveyorBelt {
  hidden translation_1 0 0 1.1219163115120803
  translation 11.3 15 0
  rotation 0 0 -1 0
  name "conveyor belt(20)"
  size 1 5 1.5
}
DEF left_big_conveyor_belt_2 ConveyorBelt {
  hidden translation_1 0 0 1.1219163115120803
  translation 8.1 15 0
  rotation 0 0 -1 0
  name "conveyor belt(22)"
  size 1 5 1.5
}
DEF left_big_conveyor_belt_1 ConveyorBelt {
  hidden translation_1 0 0 1.1219163115120803
  translation 4.9 15 0
  rotation 0 0 -1 0
  name "conveyor belt(24)"
  size 1 5 1.5
}
DEF right_big_conveyor_belt_2 ConveyorBelt {
  hidden translation_1 0 0 1.1219163115120803
  translation 8.8 5.5 0
  rotation 0 0 -1 0
  name "conveyor belt(16)"
  size 1 5 1.5
}
DEF right_big_conveyor_belt_1 ConveyorBelt {
  hidden translation_1 0 0 1.1219163115120803
  translation 5.8 5.5 0
  rotation 0 0 -1 0
  name "conveyor belt(18)"
  size 1 5 1.5
}
CardboardBox {
  translation 27.8384 3.01098 0.71
  rotation 0 0 1 0.261799
  size 0.2 0.2 0.2
}
CardboardBox {
  translation 28.0224 3.48865 0.71
  rotation 0 0 1 0.785398
  name "cardboard box(1)"
  size 0.2 0.2 0.2
}
CardboardBox {
  translation 21.6903 3.22499 1.6
  rotation 0 0 1 1.309
  name "cardboard box(6)"
  size 0.2 0.2 0.2
}
CardboardBox {
  translation 7.98736 14.1014 1.6
  rotation 0 0 1 1.309
  name "cardboard box(7)"
  size 0.2 0.2 0.2
}
CardboardBox {
  translation 15.3336 4.18682 1.6
  rotation 0 0 1 2.0944
  name "cardboard box(10)"
  size 0.2 0.2 0.2
}
CardboardBox {
  translation 11.2185 13.9355 1.6
  rotation 0 0 1 2.0944
  name "cardboard box(11)"
  size 0.2 0.2 0.2
}
CardboardBox {
  translation 4.6953 16.4739 1.6
  rotation 0 0 1 2.0944
  name "cardboard box(12)"
  size 0.2 0.2 0.2
}
CardboardBox {
  translation 5.94515 4.74132 1.6
  rotation 0 0 1 1.309
  name "cardboard box(9)"
  size 0.2 0.2 0.2
}
CardboardBox {
  translation 26.2061 1.6839 0.71
  rotation 0 0 1 1.309
  name "cardboard box(8)"
  size 0.2 0.2 0.2
}
CardboardBox {
  translation 28.3211 1.96902 0.77
  rotation 0 0 1 4.692820414042842e-06
  name "cardboard box(5)"
  size 0.2 0.2 0.2
}
CardboardBox {
  translation 28.0496 3.95362 0.71
  rotation 0 0 1 0.261803
  name "cardboard box(2)"
  size 0.2 0.2 0.2
}
CardboardBox {
  translation 18.9049 8.5223 0.11
  rotation 0 0 1 1.5708
  name "cardboard box(4)"
  size 0.2 0.2 0.2
}
CardboardBox {
  translation 20.9849 7.7223 0.11
  rotation 0 0 1 1.5708
  name "cardboard box(13)"
  size 0.2 0.2 0.2
}
CardboardBox {
  translation 17.3949 8.2323 0.11
  rotation 0 0 1 1.5708
  name "cardboard box(16)"
  size 0.2 0.2 0.2
}
CardboardBox {
  translation 18.6349 12.5223 0.11
  rotation 0 0 1 1.5708
  name "cardboard box(17)"
  size 0.2 0.2 0.2
}
CardboardBox {
  translation 17.0749 12.4123 0.11
  rotation 0 0 1 1.5708
  name "cardboard box(18)"
  size 0.2 0.2 0.2
}
CardboardBox {
  translation 24.9049 4.5023 0.11
  rotation 0 0 1 1.5708
  name "cardboard box(15)"
  size 0.2 0.2 0.2
}
CardboardBox {
  translation 24.3649 4.5123 0.11
  rotation 0 0 1 1.5708
  name "cardboard box(14)"
  size 0.2 0.2 0.2
}
CardboardBox {
  translation 22.6249 18.7445 0.15
  rotation 0 0 1 4.07987e-06
  name "cardboard box(3)"
  size 0.2 0.2 0.2
}
Pose {
}
DEF SUPERVISOR Robot {
  rotation 0 0 1 -2.8797853071795863
  controller "floor_mapper"
  supervisor TRUE
}
DEF Pioneer_3-AT Pioneer3at {
  hidden position_0_0 17181.67559809793
  hidden position_0_1 14901.686230776273
  hidden position_0_2 17201.27376671953
  hidden position_0_3 14922.746012854139
  hidden linearVelocity_0 3.059354178125098e-15 -8.670586882153043e-16 -3.1005501196804374e-16
  hidden angularVelocity_0 7.995131147705868e-15 2.8265517033447587e-14 1.2596163037158803e-16
  hidden rotation_1 0.5773516024134749 -0.5773476024162304 -0.5773516027299337 2.094404999683543
  hidden translation_2 4.390430234023778e-13 2.1847962280823109e-13 0.04999999999999215
  hidden rotation_2 -0.42526537133496617 0.425258256650912 -0.7989397843977734 1.7934126943521096
  hidden rotation_3 0.5988398296672657 -0.5988354524500358 -0.5317771707144274 2.164114403451273
  hidden linearVelocity_3 2.7571702327465028e-14 -1.5449024999955536e-15 3.573028410475331e-15
  hidden angularVelocity_3 7.012355610633255e-15 2.8770586025756184e-14 -1.3010046332952136e-15
  hidden rotation_4 -0.31157830343253645 0.31157814042936155 0.8976848128584349 4.604650244039555
  hidden linearVelocity_4 2.7517635501079883e-14 -1.4798308823532648e-15 3.676112119340069e-15
  hidden angularVelocity_4 8.32182255889965e-15 2.8559355766219275e-14 8.00646119364953e-16
  hidden rotation_5 0.08193834394784771 -0.08193411524610296 0.9932637658496973 4.705619954792564
  hidden linearVelocity_5 4.91605523187054e-15 -1.249176462971528e-14 -4.259111796590988e-15
  hidden angularVelocity_5 7.531515096946361e-15 2.858310128490071e-14 -9.549914063647884e-16
  hidden rotation_6 -0.3794923276835968 0.37949127938687927 0.8437842983242785 4.543329843370436
  hidden linearVelocity_6 4.887969824481643e-15 -1.2460373552398172e-14 -4.24063360424745e-15
  hidden angularVelocity_6 8.390343699284404e-15 2.8468801962763524e-14 2.541237985090688e-15
  translation 22.016309448421772 10.637760974509574 -0.21171455720660445
  rotation 0.9904945889682195 -0.1341866276110339 -0.030239348456203647 -3.133110634227484
  name "Pioneer 3-AT_0"
  controller "pioneer_controller"
}
DEF Pioneer_3-AT Pioneer3at {
  hidden position_0_0 17180.781321946775
  hidden position_0_1 14902.012854805262
  hidden position_0_2 17201.44317941472
  hidden position_0_3 14923.747408771429
  hidden linearVelocity_0 1.658386835123224e-14 6.544331049296304e-16 -5.1675835328007286e-17
  hidden angularVelocity_0 6.841236394399529e-16 9.318124982618342e-18 -3.790749736239057e-16
  hidden rotation_1 0.5773516024134749 -0.5773476024162304 -0.5773516027299337 2.094404999683543
  hidden translation_2 4.390430234023778e-13 2.1847962280823109e-13 0.04999999999999215
  hidden rotation_2 -0.42526537133496617 0.425258256650912 -0.7989397843977734 1.7934126943521096
  hidden rotation_3 0.6930327462872252 -0.6930262611204867 -0.19854524414083907 2.749608410457329
  hidden linearVelocity_3 5.593086190340033e-15 1.2872917288204584e-14 1.9215769602972854e-16
  hidden angularVelocity_3 4.2840083823077805e-15 2.5111151330680384e-15 1.8093138148137903e-16
  hidden rotation_4 -0.16753807427528816 0.1675396510839222 0.9715253259605772 4.683494140038329
  hidden linearVelocity_4 1.7487419637304165e-15 5.648652957586877e-15 2.1815882702457088e-16
  hidden angularVelocity_4 1.3147386473441542e-15 4.0144120240706533e-16 1.0738141539355997e-16
  hidden rotation_5 0.163988308897673 -0.1639833022548143 0.9727370205386898 4.684741233939556
  hidden linearVelocity_5 -5.9051028747263354e-15 -9.801414798632367e-15 -3.5001093543093674e-16
  hidden angularVelocity_5 1.0697406064938572e-14 -5.006816207257006e-15 9.93692234283337e-17
  hidden rotation_6 0.0777364689986103 -0.07773228141473272 0.9939389990405291 4.706299507747655
  hidden linearVelocity_6 -1.7386986910742975e-15 -1.1719679694401563e-14 -2.785480625816963e-16
  hidden angularVelocity_6 1.0903103239726654e-14 -1.0345359721600597e-15 1.1800321885074716e-16
  translation 14.256700055441339 5.3048028824907885 -0.5023889310687116
  rotation -2.4736974904103787e-05 2.482325628559809e-05 0.999999999385944 1.5554589558088148
  name "Pioneer 3-AT_1"
  controller "pioneer_controller_1"
}
DEF Pioneer_3-AT Pioneer3at {
  hidden position_0_0 17180.454440948437
  hidden position_0_1 14901.654045109359
  hidden position_0_2 17201.222969831968
  hidden position_0_3 14923.432881459421
  hidden linearVelocity_0 7.708815435739343e-15 2.181623547733706e-14 -1.5502750598402187e-16
  hidden angularVelocity_0 -7.255759497169552e-16 -8.794298011972395e-16 4.351579298169564e-15
  hidden rotation_1 0.5773516024134749 -0.5773476024162304 -0.5773516027299337 2.094404999683543
  hidden translation_2 4.390430234023778e-13 2.1847962280823109e-13 0.04999999999999215
  hidden rotation_2 -0.42526537133496617 0.425258256650912 -0.7989397843977734 1.7934126943521096
  hidden rotation_3 0.7047397817832001 -0.7047327781814235 -0.0818141267071902 2.9783344724880534
  hidden linearVelocity_3 2.0491765861720538e-14 3.250612042833368e-15 1.702163323751611e-16
  hidden angularVelocity_3 1.81199103090198e-15 -4.176911245914181e-15 4.171201275497539e-15
  hidden rotation_4 -0.32449691470099545 0.3244965868794198 0.8884839432725512 4.5944133256504855
  hidden linearVelocity_4 2.5658979493914057e-14 -6.499005344909622e-16 -9.746167879326208e-17
  hidden angularVelocity_4 3.569628538896194e-15 8.191723299350547e-15 4.00803498834972e-15
  hidden rotation_5 0.05678674488637778 -0.056782764140125425 0.9967702760926493 4.709143896148361
  hidden linearVelocity_5 -2.4646535380184174e-14 -3.885156173835011e-15 -4.4397844508506036e-16
  hidden angularVelocity_5 5.045859815471764e-15 -1.4064887278204257e-14 5.114915196576994e-15
  hidden rotation_6 -0.07888263797890388 0.07888520657853196 0.993757844551957 4.706116698878729
  hidden linearVelocity_6 -2.3862531863996105e-14 -1.4467393368356344e-16 -4.0674107910082654e-16
  hidden angularVelocity_6 3.4585633513909828e-15 -1.1120877539945643e-14 2.8354853355705838e-15
  translation 10.682302288535604 9.696709989615803 -0.5023889310679025
  rotation -0.0072129083420234335 0.9999578824115479 -0.005675152532101507 4.917999739149196e-05
  name "Pioneer 3-AT_2"
  controller "pioneer_controller_2"
}
DEF Pioneer_3-AT Pioneer3at {
  hidden position_0_0 17180.454404332457
  hidden position_0_1 14901.654010314682
  hidden position_0_2 17201.223057712134
  hidden position_0_3 14923.432970874357
  hidden linearVelocity_0 1.0425114843362867e-14 1.9640583832135373e-14 -2.583791766400364e-16
  hidden angularVelocity_0 -3.607670224926559e-15 -2.9281146144015754e-16 -1.9263675716491183e-15
  hidden rotation_1 0.5773516024134749 -0.5773476024162304 -0.5773516027299337 2.094404999683543
  hidden translation_2 4.390430234023778e-13 2.1847962280823109e-13 0.04999999999999215
  hidden rotation_2 -0.42526537133496617 0.425258256650912 -0.7989397843977734 1.7934126943521096
  hidden rotation_3 0.7047405356911483 -0.7047335320373567 -0.08180113798661628 2.978360276983304
  hidden linearVelocity_3 1.2443061615218906e-14 3.1047309080349527e-15 1.0335602220944255e-16
  hidden angularVelocity_3 -2.0146325238369813e-15 -5.937269656474225e-15 -2.9711924196169824e-15
  hidden rotation_4 -0.3245107442074663 0.32451041620859344 0.8884738412953089 4.594402034655941
  hidden linearVelocity_4 1.3026922303944825e-14 -6.444255724650994e-16 2.267573619676336e-17
  hidden angularVelocity_4 -3.173898465871748e-15 5.4220928150591235e-15 -3.560732502634534e-15
  hidden rotation_5 0.056830401611185674 -0.056826420430767764 0.9967653000550014 4.709138904151371
  hidden linearVelocity_5 -1.5836774543461123e-14 -1.1769264415840767e-15 1.3819363158474466e-16
  hidden angularVelocity_5 4.3749328780345165e-15 -1.2829045478273476e-14 -1.9626155499683915e-15
  hidden rotation_6 -0.0788384857318627 0.0788410548115817 0.9937648520871041 4.706123750420529
  hidden linearVelocity_6 -1.2102401515561066e-14 -9.30109029278153e-16 3.418244478019822e-16
  hidden angularVelocity_6 -1.8005970312938666e-15 -9.041192947181766e-15 -3.28827598731343e-15
  translation 7.891714683018901 9.700530015261823 -0.5023889310679026
  rotation -0.00721054045690285 0.9997305220771472 -0.022065614282731353 4.919118212997606e-05
  name "Pioneer 3-AT_3"
  controller "pioneer_controller_3"
}
SquareManhole {
  translation 25 19 0
}
SquareManhole {
  translation 19.092 9.85948 -0.04
  rotation 0 0 1 0.523602
  name "manhole(16)"
}
SquareManhole {
  translation 20.7736 10.6536 -0.04
  rotation 0 0 1 0.785401
  name "manhole(17)"
}
SquareManhole {
  translation 9.00273 10.7778 -0.02
  rotation 0 0 1 1.5708
  name "manhole(12)"
}
SquareManhole {
  translation 4.9337 9.8387 -0.04
  rotation 9.58978e-09 3.57898e-08 1 -0.523595307179586
  name "manhole(11)"
}
WoodenPallet {
  translation 6 8.7 0
  name "wooden pallet(7)"
  size 2 1 0.1
}
WoodenPallet {
  translation 12.72 8.7 0
  name "wooden pallet(8)"
  size 2 1 0.1
}
WoodenPallet {
  translation 15.74 8.7 0
  name "wooden pallet(9)"
  size 2 1 0.1
}
WoodenPallet {
  translation 13.93 11.89 0
  name "wooden pallet(10)"
  size 2 1 0.1
}
WoodenPallet {
  translation 20.37 11.89 0
  name "wooden pallet(11)"
  size 2 1 0.1
}
Robot {
  translation 5.574799049269629 1.0250023027572597 -0.5140765958187594
  rotation -0.002558349631548058 -0.005579585895149922 0.9999811613567535 -2.7027043440546765
  children [
    Pose {
      translation 0.037646 0 0
      children [
        Shape {
          appearance DEF WHITE Plastic {
          }
          geometry Mesh {
            url [
              "https://raw.githubusercontent.com/cyberbotics/webots/R2025a/projects/robots/mir/mir100/protos/meshes/mir_100_base.obj"
            ]
          }
        }
        Shape {
          appearance USE WHITE
          geometry Mesh {
            url [
              "https://raw.githubusercontent.com/cyberbotics/webots/R2025a/projects/robots/mir/mir100/protos/meshes/mir_100_inside.obj"
            ]
          }
        }
        Shape {
          appearance Plastic {
            colorOverride 0.93 0.93 0.93
          }
          geometry Mesh {
            url [
              "https://raw.githubusercontent.com/cyberbotics/webots/R2025a/projects/robots/mir/mir100/protos/meshes/mir_100_logos.dae"
            ]
          }
        }
        Shape {
          appearance DEF BLACK Plastic {
            colorOverride 0 0 0
          }
          geometry Mesh {
            url [
              "https://raw.githubusercontent.com/cyberbotics/webots/R2025a/projects/robots/mir/mir100/protos/meshes/mir_100_base_corners.dae"
            ]
          }
        }
        Shape {
          appearance DEF BLACK Plastic {
            colorOverride 0 0 0
          }
          geometry Mesh {
            url [
              "https://raw.githubusercontent.com/cyberbotics/webots/R2025a/projects/robots/mir/mir100/protos/meshes/mir_100_top_plugs.dae"
            ]
          }
        }
      ]
    }
    DEF IMU Pose {
      translation 0 0 0.25
      children [
        Accelerometer {
          name "imu_data accelerometer"
          lookupTable [
            -100 -100 -0.002
            100 100 0.002
          ]
        }
        Gyro {
          name "imu_data gyro"
          lookupTable [
            -100 -100 -0.002
            100 100 0.002
          ]
        }
        Compass {
          name "imu_data compass"
          lookupTable [
            -1 -1 -0.2
            1 1 0.2
          ]
        }
      ]
    }
    Pose {
      translation 0.4288 0.2358 0.188
      rotation -0.9238797538373538 -0.38268289803626016 0 -3.14159
    }
    Pose {
      translation -0.3548 -0.2352 0.188
      rotation 0.38268289803626016 -0.9238797538373538 0 -3.14159
    }
    Pose {
      translation 0.037646 0 0.349
    }
    DEF DEPTH_CAMERA Transform {
      translation 0.042224 -0.273014 0.141194
      rotation 1 0 0 1.5708
      scale 4.00035 3.92893 3.92893
      children [
        Shape {
          appearance Appearance {
            material Material {
              emissiveColor 1 1 1
            }
            texture ImageTexture {
              url [
                "https://raw.githubusercontent.com/cyberbotics/webots/R2025a/projects/robots/mir/mir100/protos/textures/camera.png"
              ]
            }
            textureTransform TextureTransform {
              rotation 3.1415926
            }
          }
          geometry Plane {
            size 0.08 0.015
          }
        }
      ]
    }
    Mir100UltrasonicSensor {
      translation 0.415448 -0.108238 0.08
      rotation 0.8628559982596194 -0.35740699927911007 -0.35740699927911007 1.71777
      name "ds0"
      lookupTable [
        0.2 1000 0
        0.3 0 0
      ]
    }
    Mir100UltrasonicSensor {
      translation -0.3844 -0.1328 0.156
      rotation 0 0 1 3.141592653589793
      name "ds1"
    }
    Mir100UltrasonicSensor {
      translation -0.3844 0.1328 0.156
      rotation 0 0 1 3.141592653589793
      name "ds2"
    }
    Mir100UltrasonicSensor {
      translation 0.415448 0.108238 0.08
      rotation 0.8628559982596194 0.35740699927911007 0.35740699927911007 1.71777
      name "ds3"
      lookupTable [
        0.2 1000 0
        0.3 0 0
      ]
    }
    RangeFinder {
      translation 0.044 -0.28 0.18
      rotation 0 0 1 -1.5707953071795862
      name "depth_camera"
      fieldOfView 2.05949
      width 1280
      height 720
      minRange 0.18
      maxRange 1.95
    }
    Pose {
      translation 0.03733 0.0005 0.2085
      children [
        DEF LIGHT_FRONT Pose {
          translation 0.392 0 0
          children [
            DEF LIGHT_WIDTH_SHAPE Shape {
              appearance PBRAppearance {
                transparency 0.5
                emissiveColor 0 0.9 1
              }
              geometry Box {
                size 0.001 0.4723 0.053
              }
            }
          ]
        }
        DEF LIGHT_BACK Pose {
          translation -0.392 0 0
          children [
            USE LIGHT_WIDTH_SHAPE
          ]
        }
        DEF LIGHT_LEFT Pose {
          translation 0 0.2355 0
          children [
            DEF LIGHT_WIDTH_SHAPE Shape {
              appearance PBRAppearance {
                transparency 0.5
                emissiveColor 0 0.9 1
              }
              geometry Box {
                size 0.783 0.001 0.053
              }
            }
          ]
        }
        DEF LIGHT_RIGHT Pose {
          translation 0 -0.2355 0
          children [
            USE LIGHT_WIDTH_SHAPE
          ]
        }
      ]
    }
    DEF US_1_FRAME Solid {
      translation 0.45 -0.12 0.16
      name "us_1_frame"
    }
    DEF US_2_FRAME Solid {
      translation 0.45 0.12 0.16
      name "us_2_frame"
    }
    DEF LEFT_WHEEL_JOINT HingeJoint {
      jointParameters HingeJointParameters {
        position 48.99762520441625
        axis 0 1 0
        anchor 0 0.222604 0.0625
      }
      device [
        PositionSensor {
          name "middle_left_wheel_joint_sensor"
        }
      ]
      endPoint DEF LEFT_WHEEL_LINK Solid {
        translation -0.005197652495645506 0.2225758854174258 0.06405720015490605
        rotation -0.6932267911640488 -0.5096242544337556 -0.509627055115047 1.9292663775206105
        children [
          Group {
          }
        ]
        name "left_wheel_link"
        contactMaterial "wheel"
        boundingObject DEF WHEEL_BO Cylinder {
          height 0.01
          radius 0.0625
        }
        physics Physics {
          density -1
          mass 1
          centerOfMass [
            0 0 0
          ]
          inertiaMatrix [
            0.001061895 0.001953125 0.001061895
            0 0 5.457207e-20
          ]
        }
        linearVelocity -2.1307486674186053e-05 -4.263445332107476e-05 2.5314408997761784e-05
        angularVelocity 0.0006726799370022135 -0.0016189952992032562 -4.013497541384e-05
      }
    }
    DEF RIGHT_WHEEL_JOINT HingeJoint {
      jointParameters HingeJointParameters {
        position -14.897307575600147
        axis 0 1 0
        anchor 0 -0.222604 0.0625
      }
      device [
        PositionSensor {
          name "middle_right_wheel_joint_sensor"
        }
      ]
      endPoint DEF RIGHT_WHEEL_LINK Solid {
        translation -0.0030583566840410286 -0.22269587362031196 0.05955938976116058
        rotation -0.2903403860418303 -0.6766440366290737 -0.6766500631252419 2.576454652537355
        children [
          Group {
          }
        ]
        name "right_wheel_link"
        contactMaterial "wheel"
        boundingObject USE WHEEL_BO
        physics Physics {
          density -1
          mass 1
          centerOfMass [
            0 0 0
          ]
          inertiaMatrix [
            0.001061895 0.001953125 0.001061895
            0 0 5.457207e-20
          ]
        }
        linearVelocity -8.413224076246458e-06 -3.242308793469549e-05 -1.4447163261778378e-05
        angularVelocity 0.00035006560171697637 -0.0009315186537130098 -3.2801070623700755e-05
      }
    }
    DEF FL_CASTER_ROTATION_JOINT HingeJoint {
      jointParameters HingeJointParameters {
        position 378.71345457540616
        axis 0 0 1
        anchor 0.341346 0.203 0.1565
        dampingConstant 0.01
      }
      device [
        RotationalMotor {
          name "front_left_wheel_joint"
          maxVelocity 100
          maxTorque 20
        }
        PositionSensor {
          name "front_left_caster_joint_sensor"
        }
      ]
      endPoint DEF FL_CASTER_ROTATION_LINK Solid {
        translation 0.3415437737439415 0.20263170784352702 0.16390625039509987
        rotation 0 0 -1 4.412828840139878
        children [
          DEF CASTER_WHEEL_BASE Shape {
            appearance PBRAppearance {
              baseColor 0.35 0.35 0.35
              roughness 1
              metalness 0
            }
            geometry Mesh {
              url [
                "https://raw.githubusercontent.com/cyberbotics/webots/R2025a/projects/robots/mir/mir100/protos/meshes/caster_wheel_base.dae"
              ]
            }
          }
          DEF FL_CASTER_WHEEL_JOINT HingeJoint {
            jointParameters HingeJointParameters {
              position 261.36197632685895
              axis 0 1 0
              anchor -0.0382 0 -0.094
            }
            device [
              RotationalMotor {
                name "front_left_wheel"
                maxVelocity 100
                maxTorque 20
              }
              PositionSensor {
                name "front_left_wheel_joint_sensor"
              }
            ]
            endPoint DEF FL_CASTER_WHEEL_LINK Solid {
              translation -0.03794855256517403 -4.7259524189602256e-05 -0.09397523861036983
              rotation -0.6202372458281648 0.5546642742423626 0.5546650356446545 2.0312625955605594
              children [
                Group {
                  children [
                    DEF RIM Shape {
                      appearance CorrodedMetal {
                      }
                      geometry Cylinder {
                        height 0.032
                        radius 0.0465
                      }
                    }
                    SolidTorus {
                      translation 0 0 0
                      majorRadius 0.0465
                      minorRadius 0.016
                      appearance DEF WHEEL_RUBBER PBRAppearance {
                        baseColor 0 0 0
                        roughness 1
                        metalness 0
                      }
                      enableBoundingObject FALSE
                    }
                  ]
                }
              ]
              name "fl_caster_wheel_link"
              contactMaterial "wheel"
              boundingObject USE WHEEL_BO
              physics Physics {
                density -1
                mass 1
                centerOfMass [
                  0 0 0
                ]
                inertiaMatrix [
                  0.001061895 0.001953125 0.001061895
                  0 0 5.457207e-20
                ]
              }
              linearVelocity -1.3509552608057576e-05 -2.7739575624869406e-06 1.0893899669273833e-05
              angularVelocity -6.850812575734807e-05 -3.824170444740845e-05 -2.4958621381486403e-05
            }
          }
        ]
        name "fl_caster_rotation_link"
        boundingObject Pose {
          translation 0 0 -0.028
          children [
            DEF SWIVEL Cylinder {
              height 0.055
              radius 0.0298
            }
          ]
        }
        physics Physics {
          density -1
          mass 0.309754
          centerOfMass [
            0 0 -0.0425
          ]
          inertiaMatrix [
            0.0005287255 0.000517415 0.0002462724
            -7.734275e-21 -1.120566e-20 -0.0001505672
          ]
        }
        linearVelocity -2.5350300843233822e-05 -3.471725807134032e-06 1.4028641469974091e-05
        angularVelocity -6.849777669585321e-05 -3.7385857331799685e-05 -2.4927556495112643e-05
      }
    }
    DEF FR_CASTER_ROTATION_JOINT HingeJoint {
      jointParameters HingeJointParameters {
        position 479.9196171397085
        axis 0 0 1
        anchor 0.341346 -0.203 0.1565
        dampingConstant 0.01
      }
      device [
        RotationalMotor {
          name "front_right_wheel_joint"
          maxVelocity 100
          maxTorque 20
        }
        PositionSensor {
          name "front_right_caster_joint_sensor"
        }
      ]
      endPoint DEF FR_CASTER_ROTATION_LINK Solid {
        translation 0.34119247892986 -0.20307586194556038 0.163633783048641
        rotation 0 0 -1 4.412583234939405
        children [
          USE CASTER_WHEEL_BASE
          DEF FR_CASTER_WHEEL_JOINT HingeJoint {
            jointParameters HingeJointParameters {
              position 310.3033000694972
              axis 0 1 0
              anchor -0.0382 0 -0.094
            }
            device [
              RotationalMotor {
                name "front_right_wheel"
                maxVelocity 100
                maxTorque 20
              }
              PositionSensor {
                name "front_right_wheel_joint_sensor"
              }
            ]
            endPoint DEF FR_CASTER_WHEEL_LINK Solid {
              translation -0.0382 0 -0.094
              rotation 0.2551538517983527 -0.683700620829706 -0.6837031322069098 3.6412377619178518
              children [
                Group {
                  children [
                    USE RIM
                    SolidTorus {
                      translation 0 0 0
                      majorRadius 0.0465
                      minorRadius 0.016
                      appearance USE WHEEL_RUBBER
                      enableBoundingObject FALSE
                    }
                  ]
                }
              ]
              name "fr_caster_wheel_link"
              contactMaterial "wheel"
              boundingObject USE WHEEL_BO
              physics Physics {
                density -1
                mass 1
                centerOfMass [
                  0 0 0
                ]
                inertiaMatrix [
                  0.001061895 0.001953125 0.001061895
                  0 0 5.457207e-20
                ]
              }
              linearVelocity -5.229417990727037e-05 3.400760762901244e-05 -1.936179141601911e-05
              angularVelocity -7.104350273040904e-05 -3.869259047618445e-05 -2.5132131780526994e-05
            }
          }
        ]
        name "fr_caster_rotation_link"
        boundingObject Pose {
          translation 0 0 -0.028
          children [
            USE SWIVEL
          ]
        }
        physics Physics {
          density -1
          mass 0.309754
          centerOfMass [
            0 0 -0.0425
          ]
          inertiaMatrix [
            0.0005287255 0.000517415 0.0002462724
            -7.734275e-21 -1.120566e-20 -0.0001505672
          ]
        }
        linearVelocity -4.046234861872833e-05 1.7032507591234055e-05 -1.6950892626437838e-05
        angularVelocity -6.606977722296884e-05 -3.386496738321501e-05 -2.5036701700282646e-05
      }
    }
    DEF BL_CASTER_ROTATION_JOINT HingeJoint {
      jointParameters HingeJointParameters {
        position -50.411446170772805
        axis 0 0 1
        anchor -0.270154 0.203 0.1565
        dampingConstant 0.01
      }
      device [
        RotationalMotor {
          name "back_left_wheel_joint"
          maxVelocity 100
          maxTorque 20
        }
        PositionSensor {
          name "back_left_caster_joint_sensor"
        }
      ]
      endPoint DEF BL_CASTER_ROTATION_LINK Solid {
        translation -0.270164354203423 0.20299800956289307 0.16145995620363154
        rotation 0 0 -1 4.412836471319993
        children [
          USE CASTER_WHEEL_BASE
          DEF BL_CASTER_WHEEL_JOINT HingeJoint {
            jointParameters HingeJointParameters {
              position 359.4881046118515
              axis 0 1 0
              anchor -0.0382 0 -0.094
            }
            device [
              RotationalMotor {
                name "back_left_wheel"
                maxVelocity 100
                maxTorque 20
              }
              PositionSensor {
                name "back_left_wheel_joint_sensor"
              }
            ]
            endPoint DEF BL_CASTER_WHEEL_LINK Solid {
              translation -0.0382 0 -0.094
              rotation 0.6633870291079247 -0.52911038211275 -0.5291123256472686 4.313046563624316
              children [
                Group {
                  children [
                    USE RIM
                    SolidTorus {
                      translation 0 0 0
                      majorRadius 0.0465
                      minorRadius 0.016
                      appearance USE WHEEL_RUBBER
                      enableBoundingObject FALSE
                    }
                  ]
                }
              ]
              name "bl_caster_wheel_link"
              contactMaterial "wheel"
              boundingObject USE WHEEL_BO
              physics Physics {
                density -1
                mass 1
                centerOfMass [
                  0 0 0
                ]
                inertiaMatrix [
                  0.001061895 0.001953125 0.001061895
                  0 0 5.457207e-20
                ]
              }
              linearVelocity -3.445394794470829e-05 -2.5425974527697636e-05 1.2863099760337453e-05
              angularVelocity -6.932788716548826e-05 -3.517158921587521e-05 -2.7174497186236108e-05
            }
          }
        ]
        name "bl_caster_rotation_link"
        boundingObject Pose {
          translation 0 0 -0.028
          children [
            USE SWIVEL
          ]
        }
        physics Physics {
          density -1
          mass 0.309754
          centerOfMass [
            0 0 -0.0425
          ]
          inertiaMatrix [
            0.0005287255 0.000517415 0.0002462724
            -7.734275e-21 -1.120566e-20 -0.0001505672
          ]
        }
        linearVelocity -3.2833128281786976e-05 -2.1252767245034076e-05 1.6019024927413585e-05
        angularVelocity -6.922249655172325e-05 -3.534576977779204e-05 -2.714701185089631e-05
      }
    }
    DEF BR_CASTER_ROTATION_JOINT HingeJoint {
      jointParameters HingeJointParameters {
        position -37.98780868132912
        axis 0 0 1
        anchor -0.270154 -0.203 0.1565
        dampingConstant 0.01
      }
      device [
        RotationalMotor {
          name "back_right_wheel_joint"
          maxVelocity 100
          maxTorque 20
        }
        PositionSensor {
          name "back_right_caster_joint_sensor"
        }
      ]
      endPoint DEF BR_CASTER_ROTATION_LINK Solid {
        translation -0.270171953197899 -0.20300672592450603 0.1604163962969258
        rotation 0 0 -1 4.412865694358907
        children [
          USE CASTER_WHEEL_BASE
          DEF BR_CASTER_WHEEL_JOINT HingeJoint {
            jointParameters HingeJointParameters {
              position 361.16753885208294
              axis 0 1 0
              anchor -0.0382 0 -0.094
            }
            device [
              RotationalMotor {
                name "back_right_wheel"
                maxVelocity 100
                maxTorque 20
              }
              PositionSensor {
                name "back_right_wheel_joint_sensor"
              }
            ]
            endPoint DEF BR_CASTER_WHEEL_LINK Solid {
              translation -0.0382 0 -0.094
              rotation 0.04088798653684997 -0.7065141560835287 -0.7065167512596862 3.2233228006718453
              children [
                Group {
                  children [
                    USE RIM
                    SolidTorus {
                      translation 0 0 0
                      majorRadius 0.0465
                      minorRadius 0.016
                      appearance USE WHEEL_RUBBER
                      enableBoundingObject FALSE
                    }
                  ]
                }
              ]
              name "br_caster_wheel_link"
              contactMaterial "wheel"
              boundingObject USE WHEEL_BO
              physics Physics {
                density -1
                mass 1
                centerOfMass [
                  0 0 0
                ]
                inertiaMatrix [
                  0.001061895 0.001953125 0.001061895
                  0 0 5.457207e-20
                ]
              }
              linearVelocity -3.888299676920896e-05 2.274117820158915e-05 -1.7420370927958083e-05
              angularVelocity -6.91290930472316e-05 -3.7907623828605324e-05 -2.486704400217067e-05
            }
          }
        ]
        name "br_caster_rotation_link"
        boundingObject Pose {
          translation 0 0 -0.028
          children [
            USE SWIVEL
          ]
        }
        physics Physics {
          density -1
          mass 0.309754
          centerOfMass [
            0 0 -0.0425
          ]
          inertiaMatrix [
            0.0005287255 0.000517415 0.0002462724
            -7.734275e-21 -1.120566e-20 -0.0001505672
          ]
        }
        linearVelocity -3.0735213734571765e-05 4.952583820068972e-06 -1.4973227751868795e-05
        angularVelocity -6.588440149800488e-05 -3.438204934732507e-05 -2.479258378284073e-05
      }
    }
    DEF SURFACE Solid {
      translation 0.037646 0 0.352
      name "surface"
    }
  ]
  name "Mir100"
  model "Mobile Industrial Robots' MiR100"
  boundingObject Group {
    children [
      DEF TOP Pose {
        translation 0.0375 0.0005 0.334
        children [
          Box {
            size 0.774 0.461 0.04
          }
        ]
      }
      DEF MIDDLE_CENTER Pose {
        translation 0.0375 0.0005 0.262
        children [
          Box {
            size 0.857 0.44 0.096
          }
        ]
      }
      DEF MIDDLE_RIGHT_SIDE Pose {
        translation 0.0375 -0.25 0.262
        children [
          Box {
            size 0.774 0.041 0.096
          }
        ]
      }
      DEF MIDDLE_LEFT_SIDE Pose {
        translation 0.0375 0.25 0.262
        children [
          Box {
            size 0.774 0.041 0.096
          }
        ]
      }
      DEF CYL_BR Pose {
        translation -0.3555 -0.2353 0.262
        children [
          Cylinder {
            height 0.096
            radius 0.054
          }
        ]
      }
      DEF CYL_FL Pose {
        translation 0.4306 0.2364 0.262
        children [
          Cylinder {
            height 0.096
            radius 0.054
          }
        ]
      }
      DEF CYL_FR Pose {
        translation 0.415 -0.221 0.262
        children [
          Cylinder {
            height 0.096
            radius 0.049
          }
        ]
      }
      DEF CYL_BL Pose {
        translation -0.341 0.222 0.262
        children [
          Cylinder {
            height 0.096
            radius 0.049
          }
        ]
      }
      DEF MIDLOW Pose {
        translation 0.03733 0.0005 0.204
        children [
          Box {
            size 0.7806 0.4665 0.04
          }
        ]
      }
      DEF LOW Pose {
        translation 0.0374 0.0005 0.16
        children [
          Box {
            size 0.85 0.536 0.039
          }
        ]
      }
      DEF BOTTOM_LEFT Pose {
        translation 0.0374 0.2586 0.09425
        children [
          Box {
            size 0.35 0.04 0.0925
          }
        ]
      }
      DEF BOTTOM_RIGHT Pose {
        translation 0.0374 -0.2476 0.09425
        children [
          Box {
            size 0.35 0.04 0.0925
          }
        ]
      }
      DEF BOTTOM_CENTER Pose {
        translation 0.0375 0.0005 0.094
        children [
          Box {
            size 0.857 0.2 0.092
          }
        ]
      }
    ]
  }
  physics Physics {
    density -1
    mass 70
  }
  controller "mir100"
  linearVelocity -3.09781722617345e-05 -4.4710681929291495e-06 -4.095091245204662e-07
  angularVelocity -6.902254818237064e-05 -3.602093119652722e-05 -2.3485598343762906e-05
}
