#VRML_SIM R2025a utf8

EXTERNPROTO "https://raw.githubusercontent.com/cyberbotics/webots/R2025a/projects/objects/backgrounds/protos/TexturedBackground.proto"
EXTERNPROTO "https://raw.githubusercontent.com/cyberbotics/webots/R2025a/projects/objects/backgrounds/protos/TexturedBackgroundLight.proto"
EXTERNPROTO "https://raw.githubusercontent.com/cyberbotics/webots/R2025a/projects/objects/floors/protos/RectangleArena.proto"
EXTERNPROTO "https://raw.githubusercontent.com/cyberbotics/webots/R2025a/projects/appearances/protos/Parquetry.proto"
EXTERNPROTO "../protos/ConveyorBelt.proto"
EXTERNPROTO "../protos/Pioneer3at.proto"
EXTERNPROTO "../protos/WoodenPallet.proto"
EXTERNPROTO "https://raw.githubusercontent.com/cyberbotics/webots/R2025a/projects/objects/factory/containers/protos/CardboardBox.proto"
EXTERNPROTO "https://raw.githubusercontent.com/cyberbotics/webots/R2025a/projects/objects/factory/containers/protos/PlasticFruitBox.proto"
EXTERNPROTO "https://raw.githubusercontent.com/cyberbotics/webots/R2025a/projects/objects/factory/manhole/protos/SquareManhole.proto"
EXTERNPROTO "https://raw.githubusercontent.com/cyberbotics/webots/R2025a/projects/objects/traffic/protos/SignPole.proto"
EXTERNPROTO "https://raw.githubusercontent.com/cyberbotics/webots/R2025a/projects/objects/traffic/protos/DirectionPanel.proto"
EXTERNPROTO "https://raw.githubusercontent.com/cyberbotics/webots/R2025a/projects/humans/pedestrian/protos/Pedestrian.proto"
EXTERNPROTO "https://raw.githubusercontent.com/cyberbotics/webots/R2025a/projects/appearances/protos/Plastic.proto"
EXTERNPROTO "https://raw.githubusercontent.com/cyberbotics/webots/R2025a/projects/robots/mir/mir100/protos/Mir100UltrasonicSensor.proto"
EXTERNPROTO "https://raw.githubusercontent.com/cyberbotics/webots/R2025a/projects/appearances/protos/CorrodedMetal.proto"
EXTERNPROTO "https://raw.githubusercontent.com/cyberbotics/webots/R2025a/projects/objects/solids/protos/SolidTorus.proto"
EXTERNPROTO "https://raw.githubusercontent.com/cyberbotics/webots/R2025a/projects/appearances/protos/CorrugatedMetal.proto"
EXTERNPROTO "https://raw.githubusercontent.com/cyberbotics/webots/R2025a/projects/appearances/protos/Rubber.proto"

WorldInfo {
  FPS 30
}
Viewpoint {
  orientation 6.990192168468815e-05 -0.9999999827315605 -0.0001721934966195328 5.511935295142907
  position 3.4532013185196204 5.572292593052866 1.620655117564171
  followType "None"
}
TexturedBackground {
}
TexturedBackgroundLight {
}
DEF rectangle_arena RectangleArena {
  translation 15.1304 9.85552 0
  floorSize 30 20
  floorTileSize 1 1
  floorAppearance Parquetry {
    type "dark strip"
  }
}
Pedestrian {
  translation 11.06 7.31002 1.27
  rotation 0 0 1 -3.1415853071795863
}
Pedestrian {
  translation 16.3842 17.72 1.28
  rotation 0 0 1 -0.523595307179586
  name "pedestrian(1)"
}
Pedestrian {
  translation 26.7331 5.34865 1.28
  rotation 0 0 -1 1.5708
  name "pedestrian(2)"
}
SignPole {
  translation 25.3498 15.6897 0
  rotation 0 0 1 3.14159
  height 1
  signBoards [
    DirectionPanel {
      translation 0 0 -0.86
      width 0.4
      height 0.2
    }
  ]
}
PlasticFruitBox {
  translation 28.2254 1.86879 0.63
  rotation 0 0 1 0.261799
  color 0.371527 0.966171 0.557473
}
DEF left_big_conveyor_belt_5 ConveyorBelt {
  hidden translation_1 0 0 1.121124005434286
  translation 17.8 15 0
  rotation 0 0 -1 0
  size 1 5 1.5
}
DEF left_big_conveyor_belt_6 ConveyorBelt {
  hidden translation_1 7.105427357601002e-15 -3.552713678800501e-15 1.1211240054342844
  translation 21 15 0
  rotation 0 0 -1 0
  name "conveyor belt(11)"
  size 1 5 1.5
}
DEF left_big_conveyor_belt_6 ConveyorBelt {
  hidden translation_1 -0.0003848911937467392 2.1388581966874654e-05 1.1461684465608224
  hidden rotation_1 -0.007108017828594725 0.999974682844138 -0.0003312903771018675 0.006046461441891239
  translation 28.88 15 0
  rotation 0 0 -1 0
  name "conveyor belt(25)"
  size 1 5 1.5
}
DEF left_small_conveyor_belt_4 ConveyorBelt {
  hidden translation_1 0 0 0.7461240056257148
  translation 13.33 14.5 0
  rotation 0 0 -1 0
  name "conveyor belt(3)"
  size 1 4 1
}
DEF left_big_conveyor_belt_4 ConveyorBelt {
  hidden translation_1 0 0 1.121124005434286
  translation 14.5 15 0
  rotation 0 0 -1 0
  name "conveyor belt(4)"
  size 1 5 1.5
}
DEF left_small_conveyor_belt_5 ConveyorBelt {
  hidden translation_1 0 0 0.7461240054345315
  translation 16.6 14.5 0
  rotation 0 0 -1 0
  name "conveyor belt(1)"
  size 1 4 1
}
DEF left_small_conveyor_belt_6 ConveyorBelt {
  hidden translation_1 0 0 0.746124005434277
  translation 19.8 14.5 0
  rotation 0 0 -1 0
  name "conveyor belt(10)"
  size 1 4 1
}
DEF right_small_conveyor_belt_6 ConveyorBelt {
  hidden translation_1 0 0 0.746124005434277
  translation 23 6 0
  rotation 0 0 -1 0
  name "conveyor belt(2)"
  size 1 4 1
}
DEF right_big_conveyor_belt_6 ConveyorBelt {
  hidden translation_1 0 0 1.121124005434286
  translation 21.8 5.5 0
  rotation 0 0 -1 0
  name "conveyor belt(5)"
  size 1 5 1.5
}
ConveyorBelt {
  hidden translation_1 0 0 0.44612400543427116
  translation 27.8449 2.58127 0
  rotation 0 0 -1 0
  name "conveyor belt(12)"
  size 4 4 0.6
}
DEF right_small_conveyor_belt_5 ConveyorBelt {
  hidden translation_1 0 0 0.746124005434277
  translation 19.8 6 0
  rotation 0 0 -1 0
  name "conveyor belt(6)"
  size 1 4 1
}
WoodenPallet {
  translation 22.5 8.7 0
  size 2 1 0.1
}
WoodenPallet {
  translation 19 8.7 0
  name "wooden pallet(1)"
  size 2 1 0.1
}
WoodenPallet {
  translation 9.4 8.7 0
  name "wooden pallet(6)"
  size 2 1 0.1
}
WoodenPallet {
  translation 17 11.9 0
  name "wooden pallet(2)"
  size 2 1 0.1
}
WoodenPallet {
  translation 10.73 11.9 0
  name "wooden pallet(3)"
  size 2 1 0.1
}
WoodenPallet {
  translation 7.5 11.9 0
  name "wooden pallet(5)"
  size 2 1 0.1
}
WoodenPallet {
  translation 4.5 11.9 0
  name "wooden pallet(4)"
  size 2 1 0.1
}
DEF right_big_conveyor_belt_5 ConveyorBelt {
  hidden translation_1 0 0 1.121124005434286
  translation 18.5 5.5 0
  rotation 0 0 -1 0
  name "conveyor belt(7)"
  window "<none>"
  size 1 5 1.5
}
DEF right_small_conveyor_belt_4 ConveyorBelt {
  hidden translation_1 0 0 0.746124005434277
  translation 16.46 6 0
  rotation 0 0 -1 0
  name "conveyor belt(8)"
  window "<none>"
  size 1 4 1
}
DEF right_small_conveyor_belt_3 ConveyorBelt {
  hidden translation_1 0 0 0.746124005598891
  translation 13.22 6 0
  rotation 0 0 -1 0
  name "conveyor belt(14)"
  window "<none>"
  size 1 4 1
}
DEF left_small_conveyor_belt_2 ConveyorBelt {
  hidden translation_1 0 0 0.746124005434277
  translation 6.9 14.5 0
  rotation 0 0 -1 0
  name "conveyor belt(21)"
  size 1 4 1
}
DEF left_small_conveyor_belt_1 ConveyorBelt {
  hidden translation_1 0 0 0.746124005434277
  translation 3.7 14.5 0
  rotation 0 0 -1 0
  name "conveyor belt(23)"
  size 1 4 1
}
DEF left_small_conveyor_belt_3 ConveyorBelt {
  hidden translation_1 0 0 0.746124005434277
  translation 10.1 14.5 0
  rotation 0 0 -1 0
  name "conveyor belt(19)"
  size 1 4 1
}
DEF right_small_conveyor_belt_2 ConveyorBelt {
  hidden translation_1 0 0 0.746124005434277
  translation 10 6 0
  rotation 0 0 -1 0
  name "conveyor belt(15)"
  size 1 4 1
}
DEF right_small_conveyor_belt_1 ConveyorBelt {
  hidden translation_1 1.7763568394002505e-15 1.7763568394002505e-15 0.7461240054342766
  translation 7 6 0
  rotation 0 0 -1 0
  name "conveyor belt(17)"
  size 1 4 1
}
DEF right_big_conveyor_belt_4 ConveyorBelt {
  hidden translation_1 0 0 1.121124005434286
  translation 15.3 5.5 0
  rotation 0 0 -1 0
  name "conveyor belt(9)"
  size 1 5 1.5
}
DEF right_big_conveyor_belt_3 ConveyorBelt {
  hidden translation_1 0 0 1.121124005434286
  translation 12 5.5 0
  rotation 0 0 -1 0
  name "conveyor belt(13)"
  size 1 5 1.5
}
DEF left_big_conveyor_belt_3 ConveyorBelt {
  hidden translation_1 0 0 1.121124005434286
  translation 11.3 15 0
  rotation 0 0 -1 0
  name "conveyor belt(20)"
  size 1 5 1.5
}
DEF left_big_conveyor_belt_2 ConveyorBelt {
  hidden translation_1 0 0 1.121124005434286
  translation 8.1 15 0
  rotation 0 0 -1 0
  name "conveyor belt(22)"
  size 1 5 1.5
}
DEF left_big_conveyor_belt_1 ConveyorBelt {
  hidden translation_1 0 0 1.121124005434286
  translation 4.9 15 0
  rotation 0 0 -1 0
  name "conveyor belt(24)"
  size 1 5 1.5
}
DEF right_big_conveyor_belt_2 ConveyorBelt {
  hidden translation_1 0 0 1.121124005434286
  translation 8.8 5.5 0
  rotation 0 0 -1 0
  name "conveyor belt(16)"
  size 1 5 1.5
}
DEF right_big_conveyor_belt_1 Robot {
  translation 5.8 5.5 0
  rotation 0 0 -1 0
  children [
    Track {
      translation -9.488717160177629e-05 -0.0008011680417192579 1.1290515528820535
      rotation 0.9966346016118166 -0.08196245748030113 0.0012753171548224409 0.007025254798688431
      children [
        Shape {
          appearance Rubber {
            type "dotted"
            textureTransform TextureTransform {
              scale 4 20
            }
          }
          geometry DEF BELT_BO Box {
            size 1 5 0.75
          }
        }
      ]
      boundingObject USE BELT_BO
      physics Physics {
        density -1
        mass 1
      }
      device [
        LinearMotor {
          name "belt_motor"
          maxVelocity 0.5
          sound ""
        }
      ]
      textureAnimation 1 0
      linearVelocity 0 0 -3.069544618483621e-15
    }
    Shape {
      appearance CorrugatedMetal {
        textureTransform TextureTransform {
          scale 2 2
        }
      }
      geometry IndexedFaceSet {
        coord Coordinate {
          point [
            0.53 -2.53 0
            0.53 -2.53 1.51
            -0.53 -2.53 1.51
            -0.53 -2.53 0
            0.53 2.53 0
            0.53 2.53 1.51
            -0.53 2.53 1.51
            -0.53 2.53 0
            0.5 -2.5 1.51
            0.5 2.5 1.51
            -0.5 2.5 1.51
            -0.5 -2.5 1.51
            0.5 -2.5 1.5
            0.5 2.5 1.5
            -0.5 2.5 1.5
            -0.5 -2.5 1.5
          ]
        }
        texCoord TextureCoordinate {
          point [
            0 0
            1 0
            1 1
            0 1
            0 2.849056603773585
            1 2.849056603773585
            0 2.849056603773585
            4.7735849056603765 2.849056603773585
            4.7735849056603765 0
            0 0
            0.001 0
            0.001 0.001
            0 0.001
          ]
        }
        coordIndex [
          0, 1, 2, 3, -1, 4, 7, 6, 5, -1, 0, 4, 5, 1, -1, 7, 3, 2, 6, -1, 1, 5, 9, 8, -1, 5, 6, 10, 9, -1, 6, 2, 11, 10, -1, 2, 1, 8, 11, -1, 0, 3, 7, 4, -1, 8, 9, 13, 12, -1, 9, 10, 14, 13, -1, 10, 11, 15, 14, -1, 11, 8, 12, 15, -1
        ]
        texCoordIndex [
          1, 5, 4, 0, -1, 0, 1, 5, 4, -1, 0, 8, 7, 6, -1, 0, 8, 7, 6, -1, 9, 10, 11, 12, -1, 9, 10, 11, 12, -1, 9, 10, 11, 12, -1, 9, 10, 11, 12, -1, 9, 10, 11, 12, -1, 9, 10, 11, 12, -1, 9, 10, 11, 12, -1, 9, 10, 11, 12, -1, 9, 10, 11, 12, -1
        ]
      }
    }
    Pose {
      translation -0.53 -2.93845e-06 0.173
      rotation 0 0 1 -3.14159
      children [
        Shape {
          appearance Appearance {
            material Material {
              diffuseColor 1 1 1
            }
            texture ImageTexture {
              url [
                "/Users/nguyenquangnhat/Documents/ARM_project/protos/textures/april_tag.png"
              ]
              repeatS FALSE
              repeatT FALSE
            }
          }
          geometry Box {
            size 0.0005 0.05 0.05
          }
        }
      ]
    }
  ]
  name "conveyor belt(18)"
  boundingObject Group {
    children [
      Pose {
        translation 0.515 0 0.755
        children [
          Box {
            size 0.03 5.06 1.51
          }
        ]
      }
      Pose {
        translation -0.515 0 0.755
        children [
          Box {
            size 0.03 5.06 1.51
          }
        ]
      }
      Pose {
        translation 0 -2.515 0.755
        children [
          Box {
            size 1 0.03 1.51
          }
        ]
      }
      Pose {
        translation 0 2.515 0.755
        children [
          Box {
            size 1 0.03 1.51
          }
        ]
      }
    ]
  }
  controllerArgs [
    "0.5"
    "0"
  ]
}
CardboardBox {
  translation 27.8384 3.01098 0.71
  rotation 0 0 1 0.261799
  size 0.2 0.2 0.2
}
CardboardBox {
  translation 28.0224 3.48865 0.71
  rotation 0 0 1 0.785398
  name "cardboard box(1)"
  size 0.2 0.2 0.2
}
CardboardBox {
  translation 21.6903 3.22499 1.6
  rotation 0 0 1 1.309
  name "cardboard box(6)"
  size 0.2 0.2 0.2
}
CardboardBox {
  translation 7.98736 14.1014 1.6
  rotation 0 0 1 1.309
  name "cardboard box(7)"
  size 0.2 0.2 0.2
}
CardboardBox {
  translation 15.3336 4.18682 1.6
  rotation 0 0 1 2.0944
  name "cardboard box(10)"
  size 0.2 0.2 0.2
}
CardboardBox {
  translation 11.2185 13.9355 1.6
  rotation 0 0 1 2.0944
  name "cardboard box(11)"
  size 0.2 0.2 0.2
}
CardboardBox {
  translation 4.6953 16.4739 1.6
  rotation 0 0 1 2.0944
  name "cardboard box(12)"
  size 0.2 0.2 0.2
}
CardboardBox {
  translation 5.94515 4.74132 1.6
  rotation 0 0 1 1.309
  name "cardboard box(9)"
  size 0.2 0.2 0.2
}
CardboardBox {
  translation 26.2061 1.6839 0.71
  rotation 0 0 1 1.309
  name "cardboard box(8)"
  size 0.2 0.2 0.2
}
CardboardBox {
  translation 28.3211 1.96902 0.77
  rotation 0 0 1 4.692820414042842e-06
  name "cardboard box(5)"
  size 0.2 0.2 0.2
}
CardboardBox {
  translation 28.0496 3.95362 0.71
  rotation 0 0 1 0.261803
  name "cardboard box(2)"
  size 0.2 0.2 0.2
}
CardboardBox {
  translation 18.9049 8.5223 0.11
  rotation 0 0 1 1.5708
  name "cardboard box(4)"
  size 0.2 0.2 0.2
}
CardboardBox {
  translation 20.9849 7.7223 0.11
  rotation 0 0 1 1.5708
  name "cardboard box(13)"
  size 0.2 0.2 0.2
}
CardboardBox {
  translation 17.3949 8.2323 0.11
  rotation 0 0 1 1.5708
  name "cardboard box(16)"
  size 0.2 0.2 0.2
}
CardboardBox {
  translation 18.6349 12.5223 0.11
  rotation 0 0 1 1.5708
  name "cardboard box(17)"
  size 0.2 0.2 0.2
}
CardboardBox {
  translation 17.0749 12.4123 0.11
  rotation 0 0 1 1.5708
  name "cardboard box(18)"
  size 0.2 0.2 0.2
}
CardboardBox {
  translation 24.9049 4.5023 0.11
  rotation 0 0 1 1.5708
  name "cardboard box(15)"
  size 0.2 0.2 0.2
}
CardboardBox {
  translation 24.3649 4.5123 0.11
  rotation 0 0 1 1.5708
  name "cardboard box(14)"
  size 0.2 0.2 0.2
}
CardboardBox {
  translation 22.6249 18.7445 0.15
  rotation 0 0 1 4.07987e-06
  name "cardboard box(3)"
  size 0.2 0.2 0.2
}
Pose {
}
DEF SUPERVISOR Robot {
  rotation 0 0 1 -2.8797853071795863
  controller "floor_mapper"
  supervisor TRUE
}
DEF Pioneer_3-AT Pioneer3at {
  hidden position_0_0 17180.781317375877
  hidden position_0_1 14902.012851970921
  hidden position_0_2 17201.44317647442
  hidden position_0_3 14923.747407567666
  hidden linearVelocity_0 2.5205947072004047e-14 -3.5514102706615054e-15 2.0670334131202914e-16
  hidden angularVelocity_0 2.0571070955115534e-16 1.4495925620875672e-15 -3.893621589253485e-15
  hidden rotation_1 0.5773516024134749 -0.5773476024162304 -0.5773516027299337 2.094404999683543
  hidden translation_2 4.390430234023778e-13 2.1847962280823109e-13 0.04999999999999215
  hidden rotation_2 -0.42526537133496617 0.425258256650912 -0.7989397843977734 1.7934126943521096
  hidden rotation_3 0.6930329821173109 -0.6930264969425303 -0.1985435978145658 2.7496115782105313
  hidden linearVelocity_3 1.8799014757959116e-14 8.857242150917068e-16 3.552835711846739e-16
  hidden angularVelocity_3 6.781915502949606e-15 -3.464215784788206e-15 -1.4375253900393882e-15
  hidden rotation_4 -0.1675394124454849 0.16754098923872202 0.9715248644282513 4.68349366517206
  hidden linearVelocity_4 -1.3747600038444178e-14 -1.6952406407401582e-15 -8.08181819183298e-21
  hidden angularVelocity_4 3.530408506110926e-15 3.559314886505772e-15 -1.4418193078346008e-15
  hidden rotation_5 0.16398691728294837 -0.16398191065287496 0.9727374897363974 4.6847417160979035
  hidden linearVelocity_5 -2.460536090454112e-15 7.275012142039749e-16 1.4207157525140817e-16
  hidden angularVelocity_5 9.080233686421425e-15 1.2593484200094284e-15 -1.4587702351433638e-15
  hidden rotation_6 0.07773587437966444 -0.07773168680161999 0.9939390920481014 4.7062996013185865
  hidden linearVelocity_6 -2.0955761531149517e-15 -3.091557085564694e-15 -7.107549546228401e-17
  hidden angularVelocity_6 9.829990906758079e-15 5.968591311409098e-15 -1.4396950691341335e-15
  translation 12.981299877670352 1.13463999594598 -0.0023889310687115473
  rotation -2.473697390064555e-05 2.4823054967731392e-05 0.9999999993859491 1.5554670101767032
  name "Pioneer 3-AT_1"
  controller "pioneer_controller_1"
}
DEF Pioneer_3-AT Pioneer3at {
  hidden position_0_0 17180.78131738147
  hidden position_0_1 14902.01285196449
  hidden position_0_2 17201.44317648295
  hidden position_0_3 14923.747407564484
  hidden linearVelocity_0 1.6280759305123185e-14 -1.7211847477574791e-15 -1.5502750598402187e-16
  hidden angularVelocity_0 6.687437868237665e-16 -2.1591516983440667e-15 3.1010765076384523e-15
  hidden rotation_1 0.5773516024134749 -0.5773476024162304 -0.5773516027299337 2.094404999683543
  hidden translation_2 4.390430234023778e-13 2.1847962280823109e-13 0.04999999999999215
  hidden rotation_2 -0.42526537133496617 0.425258256650912 -0.7989397843977734 1.7934126943521096
  hidden rotation_3 0.6930329818288219 -0.6930264966540503 -0.1985435998285146 2.7496115743354195
  hidden linearVelocity_3 2.0541393081926927e-14 -4.3597935700689424e-16 1.4211088321278606e-16
  hidden angularVelocity_3 7.761075803332521e-15 1.2471323477535491e-15 5.697006758404919e-16
  hidden rotation_4 -0.16753941548218249 0.1675409922753852 0.9715248633808956 4.683493664094447
  hidden linearVelocity_4 -1.660753694117745e-14 -8.66036620471445e-16 1.4210825454179887e-16
  hidden angularVelocity_4 3.865682706012077e-15 3.566852107185718e-17 5.983105503878034e-16
  hidden rotation_5 0.16398692132061446 -0.16398191469050316 0.9727374883750616 4.6847417146989665
  hidden linearVelocity_5 -2.263143024076732e-15 8.610684956120502e-16 -4.263162775683241e-16
  hidden angularVelocity_5 9.066683316832094e-15 -1.0919365536797754e-15 5.985044094623503e-16
  hidden rotation_6 0.07773587280815276 -0.07773168523012376 0.993939092293909 4.70629960156588
  hidden linearVelocity_6 -2.526693846813406e-15 -2.9044276284714244e-15 -8.637835256219136e-21
  hidden angularVelocity_6 9.663715479085246e-15 -6.964322875823599e-15 6.124763559193453e-16
  translation 14.481299987271571 1.1131699973750653 -0.0023889310687115195
  rotation -2.4736973900548638e-05 2.482305495098348e-05 0.999999999385949 1.55546701084041
  name "Pioneer 3-AT_1(1)"
  controller "pioneer_controller_2"
}
DEF Pioneer_3-AT Pioneer3at {
  hidden position_0_0 17180.781317380788
  hidden position_0_1 14902.012851963003
  hidden position_0_2 17201.44317648763
  hidden position_0_3 14923.747407568473
  hidden linearVelocity_0 3.871760743254679e-14 -2.2263362239619254e-15 -5.1675835328007286e-17
  hidden angularVelocity_0 4.063379944881056e-16 2.1675169949768476e-15 3.435332191894441e-15
  hidden rotation_1 0.5773516024134749 -0.5773476024162304 -0.5773516027299337 2.094404999683543
  hidden translation_2 4.390430234023778e-13 2.1847962280823109e-13 0.04999999999999215
  hidden rotation_2 -0.42526537133496617 0.425258256650912 -0.7989397843977734 1.7934126943521096
  hidden rotation_3 0.6930329818639206 -0.6930264966891494 -0.19854359958348466 2.749611574806888
  hidden linearVelocity_3 3.54143860231783e-14 -8.186819008624468e-16 -4.973802568034626e-16
  hidden angularVelocity_3 7.501948321012822e-15 6.91630960233332e-17 5.058756134095217e-16
  hidden rotation_4 -0.16753941618381768 0.1675409929770127 0.971524863138902 4.68349366384546
  hidden linearVelocity_4 -3.1428401155827534e-14 -1.0055321207877863e-15 2.1316900575706846e-16
  hidden angularVelocity_4 3.8542118829871074e-15 3.556267476368788e-17 5.220278520077573e-16
  hidden rotation_5 0.16398692353659353 -0.16398191690646452 0.9727374876279236 4.684741713931185
  hidden linearVelocity_5 -2.2334948926297158e-15 1.1478786780287998e-15 -7.107722743889949e-17
  hidden angularVelocity_5 9.002556240871418e-15 -2.2681082008755114e-15 6.056634141969602e-16
  hidden rotation_6 0.07773587477860765 -0.07773168720055816 0.9939390919857007 4.706299601255803
  hidden linearVelocity_6 -2.3960645071576526e-15 -2.5831417816695958e-15 -2.8421085489205955e-16
  hidden angularVelocity_6 9.273705987494412e-15 -6.967921105554737e-15 5.709470542768609e-16
  translation 16.431299991034358 1.0847899972813133 -0.0023889310687115195
  rotation -2.473697390036113e-05 2.4823054909319153e-05 0.999999999385949 1.5554670125049672
  name "Pioneer 3-AT_1(2)"
  controller "pioneer_controller_3"
}
SquareManhole {
  translation 25 19 0
}
SquareManhole {
  translation 19.092 9.85948 -0.04
  rotation 0 0 1 0.523602
  name "manhole(16)"
}
SquareManhole {
  translation 19.2812 12.146 -0.04
  rotation 0 0 1 0.785401
  name "manhole(17)"
}
SquareManhole {
  translation 9.00273 12.0778 -0.02
  rotation 0 0 1 1.5708
  name "manhole(12)"
}
SquareManhole {
  translation 6.19714 8.34714 -0.04
  rotation 9.58978e-09 3.57898e-08 1 -0.523595307179586
  name "manhole(11)"
}
WoodenPallet {
  translation 6.46 8.7 0
  name "wooden pallet(7)"
  size 2 1 0.1
}
WoodenPallet {
  translation 12.72 8.7 0
  name "wooden pallet(8)"
  size 2 1 0.1
}
WoodenPallet {
  translation 15.74 8.7 0
  name "wooden pallet(9)"
  size 2 1 0.1
}
WoodenPallet {
  translation 13.93 11.89 0
  name "wooden pallet(10)"
  size 2 1 0.1
}
WoodenPallet {
  translation 20.37 11.89 0
  name "wooden pallet(11)"
  size 2 1 0.1
}
Robot {
  translation 4.961931863924217 5.453761456044593 -0.0063145853259105045
  rotation 0.0004377581314966077 0.0005930949464133876 0.9999997283030645 1.585537195290184
  children [
    Camera {
      translation 0.044 -0.28 0.18
      rotation 0 0 1 -1.5707953071795862
      fieldOfView 2.05949
      width 1280
      height 720
    }
    InertialUnit {
      rotation 0 0 1 -1.5707953071795862
    }
    GPS {
      rotation 0 0 -1 -5.307179586466759e-06
    }
    Pose {
      translation 0.037646 0 0
      children [
        Shape {
          appearance DEF WHITE Plastic {
          }
          geometry Mesh {
            url [
              "https://raw.githubusercontent.com/cyberbotics/webots/R2025a/projects/robots/mir/mir100/protos/meshes/mir_100_base.obj"
            ]
          }
        }
        Shape {
          appearance USE WHITE
          geometry Mesh {
            url [
              "https://raw.githubusercontent.com/cyberbotics/webots/R2025a/projects/robots/mir/mir100/protos/meshes/mir_100_inside.obj"
            ]
          }
        }
        Shape {
          appearance Plastic {
            colorOverride 0.93 0.93 0.93
          }
          geometry Mesh {
            url [
              "https://raw.githubusercontent.com/cyberbotics/webots/R2025a/projects/robots/mir/mir100/protos/meshes/mir_100_logos.dae"
            ]
          }
        }
        Shape {
          appearance DEF BLACK Plastic {
            colorOverride 0 0 0
          }
          geometry Mesh {
            url [
              "https://raw.githubusercontent.com/cyberbotics/webots/R2025a/projects/robots/mir/mir100/protos/meshes/mir_100_base_corners.dae"
            ]
          }
        }
        Shape {
          appearance DEF BLACK Plastic {
            colorOverride 0 0 0
          }
          geometry Mesh {
            url [
              "https://raw.githubusercontent.com/cyberbotics/webots/R2025a/projects/robots/mir/mir100/protos/meshes/mir_100_top_plugs.dae"
            ]
          }
        }
      ]
    }
    DEF IMU Pose {
      translation 0 0 0.25
      children [
        Accelerometer {
          name "imu_data accelerometer"
          lookupTable [
            -100 -100 -0.002
            100 100 0.002
          ]
        }
        Gyro {
          name "imu_data gyro"
          lookupTable [
            -100 -100 -0.002
            100 100 0.002
          ]
        }
        Compass {
          name "imu_data compass"
          lookupTable [
            -1 -1 -0.2
            1 1 0.2
          ]
        }
      ]
    }
    Pose {
      translation 0.4288 0.2358 0.188
      rotation -0.9238797538373538 -0.38268289803626016 0 -3.14159
    }
    Pose {
      translation -0.3548 -0.2352 0.188
      rotation 0.38268289803626016 -0.9238797538373538 0 -3.14159
    }
    Pose {
      translation 0.037646 0 0.349
    }
    DEF DEPTH_CAMERA Transform {
      translation 0.042224 -0.273014 0.141194
      rotation 1 0 0 1.5708
      scale 4.00035 3.92893 3.92893
      children [
        Shape {
          appearance Appearance {
            material Material {
              emissiveColor 1 1 1
            }
            texture ImageTexture {
              url [
                "https://raw.githubusercontent.com/cyberbotics/webots/R2025a/projects/robots/mir/mir100/protos/textures/camera.png"
              ]
            }
            textureTransform TextureTransform {
              rotation 3.1415926
            }
          }
          geometry Plane {
            size 0.08 0.015
          }
        }
      ]
    }
    Mir100UltrasonicSensor {
      translation -0.3844 -0.1328 0.156
      rotation 0 0 1 3.141592653589793
      name "ds1"
    }
    Mir100UltrasonicSensor {
      translation -0.3844 0.1328 0.156
      rotation 0 0 1 3.141592653589793
      name "ds2"
    }
    RangeFinder {
      translation 0.044 -0.28 0.18
      rotation 0 0 1 -1.5707953071795862
      name "depth_camera"
      fieldOfView 2.05949
      near 0.001
      maxRange 1.95
    }
    Pose {
      translation 0.03733 0.0005 0.2085
      children [
        DEF LIGHT_FRONT Pose {
          translation 0.392 0 0
          children [
            DEF LIGHT_WIDTH_SHAPE Shape {
              appearance PBRAppearance {
                transparency 0.5
                emissiveColor 0 0.9 1
              }
              geometry Box {
                size 0.001 0.4723 0.053
              }
            }
          ]
        }
        DEF LIGHT_BACK Pose {
          translation -0.392 0 0
          children [
            USE LIGHT_WIDTH_SHAPE
          ]
        }
        DEF LIGHT_LEFT Pose {
          translation 0 0.2355 0
          children [
            DEF LIGHT_WIDTH_SHAPE Shape {
              appearance PBRAppearance {
                transparency 0.5
                emissiveColor 0 0.9 1
              }
              geometry Box {
                size 0.783 0.001 0.053
              }
            }
          ]
        }
        DEF LIGHT_RIGHT Pose {
          translation 0 -0.2355 0
          children [
            USE LIGHT_WIDTH_SHAPE
          ]
        }
      ]
    }
    DEF US_1_FRAME Solid {
      translation 0.45 -0.12 0.16
      name "us_1_frame"
    }
    DEF US_2_FRAME Solid {
      translation 0.45 0.12 0.16
      name "us_2_frame"
    }
    DEF FRONT_WHEEL HingeJoint {
      jointParameters HingeJointParameters {
        position -1.5551810065876144
        axis 0 0 1
        anchor 0.341 -0.203 0.161
        dampingConstant 0.01
      }
      device [
        RotationalMotor {
          name "front_wheel_joint"
          maxVelocity 100
          maxTorque 20
        }
        PositionSensor {
          name "front_caster_joint_sensor"
        }
      ]
      endPoint DEF FL_CASTER_ROTATION_LINK Solid {
        translation 0.34100001736723734 -0.2030000038097304 0.16101939884163602
        rotation 0 0 -0.9999999999999999 1.5551810065876144
        children [
          DEF UP_RIM Shape {
            appearance CorrodedMetal {
            }
            geometry Cylinder {
              height 0.2
              radius 0.03
            }
          }
          DEF FL_CASTER_WHEEL_JOINT HingeJoint {
            jointParameters HingeJointParameters {
              position 19.025736389667056
              axis 0 1 0
              anchor 0 0 -0.094
            }
            device [
              RotationalMotor {
                name "front_wheel"
                maxVelocity 100
                maxTorque 20
              }
              PositionSensor {
                name "front_left_wheel_joint_sensor"
              }
            ]
            endPoint DEF FL_CASTER_WHEEL_LINK Solid {
              translation -7.85913265479497e-05 2.1689599999999898e-05 -0.09398601223647657
              rotation -0.06112767599900182 -0.7057672651541076 -0.7058016539112476 3.0187005991486666
              children [
                Group {
                  children [
                    DEF RIM Shape {
                      appearance CorrodedMetal {
                      }
                      geometry Cylinder {
                        height 0.032
                        radius 0.0465
                      }
                    }
                    SolidTorus {
                      translation 0 0 0
                      majorRadius 0.0465
                      minorRadius 0.016
                      appearance DEF WHEEL_RUBBER PBRAppearance {
                        baseColor 0 0 0
                        roughness 1
                        metalness 0
                      }
                      enableBoundingObject FALSE
                    }
                  ]
                }
              ]
              name "fl_caster_wheel_link"
              contactMaterial "wheel"
              boundingObject DEF WHEEL_BO Cylinder {
                height 0.01
                radius 0.0625
              }
              physics Physics {
                density -1
                mass 1
                centerOfMass [
                  0 0 0
                ]
                inertiaMatrix [
                  0.001061895 0.001953125 0.001061895
                  0 0 5.457207e-20
                ]
              }
              linearVelocity 4.694313307602876e-10 -9.427090575699668e-11 -2.216702935269609e-15
              angularVelocity -3.625218388374262e-10 1.1888921629695952e-08 -7.722868522585677e-10
            }
          }
        ]
        name "fl_caster_rotation_link"
        boundingObject Pose {
          translation 0 0 -0.028
          children [
            DEF SWIVEL Cylinder {
              height 0.055
              radius 0.0298
            }
          ]
        }
        physics Physics {
          density -1
          mass 0.309754
          centerOfMass [
            0 0 -0.0425
          ]
          inertiaMatrix [
            0.0005287255 0.000517415 0.0002462724
            -7.734275e-21 -1.120566e-20 -0.0001505672
          ]
        }
        linearVelocity 4.693042596909691e-10 -9.429843520808662e-11 -9.368720472992767e-13
        angularVelocity -1.5480915110960937e-12 1.1501268575117995e-12 -7.707085110793427e-10
      }
    }
    DEF MIDDLE_WHEEL HingeJoint {
      jointParameters HingeJointParameters {
        position -1.5551770604099262
        axis 0 0 1
        anchor 0.04 0.203 0.161
        dampingConstant 0.01
      }
      device [
        RotationalMotor {
          name "middle_wheel_joint"
          maxVelocity 100
          maxTorque 20
        }
        PositionSensor {
          name "middle_caster_joint_sensor"
        }
      ]
      endPoint DEF BL_CASTER_ROTATION_LINK Solid {
        translation 0.0400020338128303 0.20300002513744714 0.16154839624725909
        rotation 0 0 -1 1.555177060409926
        children [
          DEF UP_RIM Shape {
            appearance CorrodedMetal {
            }
            geometry Cylinder {
              height 0.2
              radius 0.03
            }
          }
          DEF BL_CASTER_WHEEL_JOINT HingeJoint {
            jointParameters HingeJointParameters {
              position 1.4953837681933284
              axis 0 1 0
              anchor 0 0 -0.096
            }
            device [
              RotationalMotor {
                name "middle_wheel"
                maxVelocity 100
                maxTorque 20
              }
              PositionSensor {
                name "middle_wheel_joint_sensor"
              }
            ]
            endPoint DEF BL_CASTER_WHEEL_LINK Solid {
              translation 1.7382644941939804e-06 6.762419999999964e-06 -0.0960230254304172
              rotation -0.6063670210041235 0.5622794183177166 0.5622818613247942 2.051420535187573
              children [
                Group {
                  children [
                    USE RIM
                    SolidTorus {
                      translation 0 0 0
                      majorRadius 0.0465
                      minorRadius 0.016
                      appearance USE WHEEL_RUBBER
                      enableBoundingObject FALSE
                    }
                  ]
                }
              ]
              name "bl_caster_wheel_link"
              contactMaterial "wheel"
              boundingObject USE WHEEL_BO
              physics Physics {
                density -1
                mass 1
                centerOfMass [
                  0 0 0
                ]
                inertiaMatrix [
                  0.001061895 0.001953125 0.001061895
                  0 0 5.457207e-20
                ]
              }
              linearVelocity 2.3129938563869347e-10 2.1695399162294237e-10 1.193513567324413e-15
              angularVelocity 1.1852646182286002e-11 -4.402604787930545e-10 -7.756145831964455e-10
            }
          }
        ]
        name "bl_caster_rotation_link"
        boundingObject Pose {
          translation 0 0 -0.028
          children [
            USE SWIVEL
          ]
        }
        physics Physics {
          density -1
          mass 0.309754
          centerOfMass [
            0 0 -0.0425
          ]
          inertiaMatrix [
            0.0005287255 0.000517415 0.0002462724
            -7.734275e-21 -1.120566e-20 -0.0001505672
          ]
        }
        linearVelocity 2.3133450578389415e-10 2.1700455152199822e-10 -4.587787313546235e-17
        angularVelocity -1.5546709618144676e-12 1.1452943690317682e-12 -7.756723593693867e-10
      }
    }
    DEF BACK_WHEEL HingeJoint {
      jointParameters HingeJointParameters {
        position -1.555180850060889
        axis 0 0 1
        anchor -0.27 -0.203 0.161
        dampingConstant 0.01
      }
      device [
        RotationalMotor {
          name "back_wheel_joint"
          maxVelocity 100
          maxTorque 20
        }
        PositionSensor {
          name "back_caster_joint_sensor"
        }
      ]
      endPoint DEF BR_CASTER_ROTATION_LINK Solid {
        translation -0.2699999823005179 -0.2030000030536263 0.16101986770820237
        rotation 0 0 -1 1.555180850060889
        children [
          DEF UP_RIM Shape {
            appearance CorrodedMetal {
            }
            geometry Cylinder {
              height 0.2
              radius 0.03
            }
          }
          DEF BR_CASTER_WHEEL_JOINT HingeJoint {
            jointParameters HingeJointParameters {
              position 788.0555910920948
              axis 0 1 0
              anchor 0 0 -0.094
            }
            device [
              RotationalMotor {
                name "back_wheel"
                maxVelocity 100
                maxTorque 20
              }
              PositionSensor {
                name "back_wheel_joint_sensor"
              }
            ]
            endPoint DEF BR_CASTER_WHEEL_LINK Solid {
              translation 2.086987428172966e-06 -1.2047399999999962e-05 -0.09410039431029434
              rotation -0.26667258741907646 0.6814996297060665 0.6815012735349137 2.6203861950807896
              children [
                Group {
                  children [
                    USE RIM
                    SolidTorus {
                      translation 0 0 0
                      majorRadius 0.0465
                      minorRadius 0.016
                      appearance USE WHEEL_RUBBER
                      enableBoundingObject FALSE
                    }
                  ]
                }
              ]
              name "br_caster_wheel_link"
              contactMaterial "wheel"
              boundingObject USE WHEEL_BO
              physics Physics {
                density -1
                mass 1
                centerOfMass [
                  0 0 0
                ]
                inertiaMatrix [
                  0.001061895 0.001953125 0.001061895
                  0 0 5.457207e-20
                ]
              }
              linearVelocity -4.371132603758846e-12 -1.0129536219650609e-10 1.1368369921824698e-15
              angularVelocity 7.70111109018231e-12 -3.0370897771717635e-10 -7.789267550118677e-10
            }
          }
        ]
        name "br_caster_rotation_link"
        boundingObject Pose {
          translation 0 0 -0.028
          children [
            USE SWIVEL
          ]
        }
        physics Physics {
          density -1
          mass 0.309754
          centerOfMass [
            0 0 -0.0425
          ]
          inertiaMatrix [
            0.0005287255 0.000517415 0.0002462724
            -7.734275e-21 -1.120566e-20 -0.0001505672
          ]
        }
        linearVelocity -4.344849755715439e-12 -1.0126778368086992e-10 3.2114511194823646e-16
        angularVelocity -1.5562025998300589e-12 1.1486366891026147e-12 -7.789661028722447e-10
      }
    }
    DEF SURFACE Solid {
      translation 0.037646 0 0.352
      name "surface"
    }
  ]
  name "Mir100"
  model "Mobile Industrial Robots' MiR100"
  boundingObject Group {
    children [
      DEF TOP Pose {
        translation 0.0375 0.0005 0.334
        children [
          Box {
            size 0.774 0.461 0.04
          }
        ]
      }
      DEF MIDDLE_CENTER Pose {
        translation 0.0375 0.0005 0.262
        children [
          Box {
            size 0.857 0.44 0.096
          }
        ]
      }
      DEF MIDDLE_RIGHT_SIDE Pose {
        translation 0.0375 -0.25 0.262
        children [
          Box {
            size 0.774 0.041 0.096
          }
        ]
      }
      DEF MIDDLE_LEFT_SIDE Pose {
        translation 0.0375 0.25 0.262
        children [
          Box {
            size 0.774 0.041 0.096
          }
        ]
      }
      DEF CYL_BR Pose {
        translation -0.3555 -0.2353 0.262
        children [
          Cylinder {
            height 0.096
            radius 0.054
          }
        ]
      }
      DEF CYL_FL Pose {
        translation 0.4306 0.2364 0.262
        children [
          Cylinder {
            height 0.096
            radius 0.054
          }
        ]
      }
      DEF CYL_FR Pose {
        translation 0.415 -0.221 0.262
        children [
          Cylinder {
            height 0.096
            radius 0.049
          }
        ]
      }
      DEF CYL_BL Pose {
        translation -0.341 0.222 0.262
        children [
          Cylinder {
            height 0.096
            radius 0.049
          }
        ]
      }
      DEF MIDLOW Pose {
        translation 0.03733 0.0005 0.204
        children [
          Box {
            size 0.7806 0.4665 0.04
          }
        ]
      }
      DEF LOW Pose {
        translation 0.0374 0.0005 0.16
        children [
          Box {
            size 0.85 0.536 0.039
          }
        ]
      }
      DEF BOTTOM_LEFT Pose {
        translation 0.0374 0.2586 0.09425
        children [
          Box {
            size 0.35 0.04 0.0925
          }
        ]
      }
      DEF BOTTOM_RIGHT Pose {
        translation 0.0374 -0.2476 0.09425
        children [
          Box {
            size 0.35 0.04 0.0925
          }
        ]
      }
      DEF BOTTOM_CENTER Pose {
        translation 0.0375 0.0005 0.094
        children [
          Box {
            size 0.857 0.2 0.092
          }
        ]
      }
    ]
  }
  physics Physics {
    density -1
    mass 5
  }
  controller "mir100"
  linearVelocity 2.3068850419636226e-10 6.012694835217739e-11 -2.312712509042881e-13
  angularVelocity -1.5518921211460827e-12 1.1465245550556447e-12 -7.752847696915778e-10
}
