#VRML_SIM R2025a utf8

EXTERNPROTO "https://raw.githubusercontent.com/cyberbotics/webots/R2025a/projects/objects/backgrounds/protos/TexturedBackground.proto"
EXTERNPROTO "https://raw.githubusercontent.com/cyberbotics/webots/R2025a/projects/objects/backgrounds/protos/TexturedBackgroundLight.proto"
EXTERNPROTO "https://raw.githubusercontent.com/cyberbotics/webots/R2025a/projects/objects/floors/protos/RectangleArena.proto"
EXTERNPROTO "https://raw.githubusercontent.com/cyberbotics/webots/R2025a/projects/appearances/protos/Parquetry.proto"
EXTERNPROTO "../protos/ConveyorBelt.proto"
EXTERNPROTO "../protos/Pioneer3at.proto"
EXTERNPROTO "../protos/WoodenPallet.proto"
EXTERNPROTO "https://raw.githubusercontent.com/cyberbotics/webots/R2025a/projects/objects/factory/containers/protos/CardboardBox.proto"
EXTERNPROTO "https://raw.githubusercontent.com/cyberbotics/webots/R2025a/projects/objects/factory/containers/protos/PlasticFruitBox.proto"
EXTERNPROTO "https://raw.githubusercontent.com/cyberbotics/webots/R2025a/projects/objects/factory/manhole/protos/SquareManhole.proto"
EXTERNPROTO "https://raw.githubusercontent.com/cyberbotics/webots/R2025a/projects/objects/traffic/protos/SignPole.proto"
EXTERNPROTO "https://raw.githubusercontent.com/cyberbotics/webots/R2025a/projects/objects/traffic/protos/DirectionPanel.proto"
EXTERNPROTO "https://raw.githubusercontent.com/cyberbotics/webots/R2025a/projects/humans/pedestrian/protos/Pedestrian.proto"
EXTERNPROTO "https://raw.githubusercontent.com/cyberbotics/webots/R2025a/projects/appearances/protos/Plastic.proto"
EXTERNPROTO "https://raw.githubusercontent.com/cyberbotics/webots/R2025a/projects/robots/mir/mir100/protos/Mir100UltrasonicSensor.proto"
EXTERNPROTO "https://raw.githubusercontent.com/cyberbotics/webots/R2025a/projects/appearances/protos/CorrodedMetal.proto"
EXTERNPROTO "https://raw.githubusercontent.com/cyberbotics/webots/R2025a/projects/objects/solids/protos/SolidTorus.proto"
EXTERNPROTO "https://raw.githubusercontent.com/cyberbotics/webots/R2025a/projects/appearances/protos/CorrugatedMetal.proto"
EXTERNPROTO "https://raw.githubusercontent.com/cyberbotics/webots/R2025a/projects/appearances/protos/Rubber.proto"

WorldInfo {
  FPS 30
}
Viewpoint {
  orientation -0.020058698147999682 0.9993075667089126 -0.031337449591820735 5.14380619204132
  position 1.3257953734185701 5.682813550605046 -6.696131509550521
  followType "None"
}
TexturedBackground {
}
TexturedBackgroundLight {
}
DEF rectangle_arena RectangleArena {
  translation 15.1304 9.85552 0
  floorSize 30 20
  floorTileSize 1 1
  floorAppearance Parquetry {
    type "dark strip"
  }
}
Pedestrian {
  translation 11.06 7.31002 1.27
  rotation 0 0 1 -3.1415853071795863
}
Pedestrian {
  translation 16.3842 17.72 1.28
  rotation 0 0 1 -0.523595307179586
  name "pedestrian(1)"
}
Pedestrian {
  translation 26.7331 5.34865 1.28
  rotation 0 0 -1 1.5708
  name "pedestrian(2)"
}
SignPole {
  translation 25.3498 15.6897 0
  rotation 0 0 1 3.14159
  height 1
  signBoards [
    DirectionPanel {
      translation 0 0 -0.86
      width 0.4
      height 0.2
    }
  ]
}
PlasticFruitBox {
  translation 28.2254 1.86879 0.63
  rotation 0 0 1 0.261799
  color 0.371527 0.966171 0.557473
}
DEF left_big_conveyor_belt_5 ConveyorBelt {
  hidden translation_1 0 0 1.1210769174343023
  translation 17.8 15 0
  rotation 0 0 -1 0
  size 1 5 1.5
}
DEF left_big_conveyor_belt_6 ConveyorBelt {
  hidden translation_1 7.105427357601002e-15 -3.552713678800501e-15 1.1210769174343007
  translation 21 15 0
  rotation 0 0 -1 0
  name "conveyor belt(11)"
  size 1 5 1.5
}
DEF left_big_conveyor_belt_6 ConveyorBelt {
  hidden translation_1 -0.0003848911937467392 2.1388581966874654e-05 1.1461213585608387
  hidden rotation_1 -0.007108017828594725 0.999974682844138 -0.0003312903771018675 0.006046461441891239
  translation 28.88 15 0
  rotation 0 0 -1 0
  name "conveyor belt(25)"
  size 1 5 1.5
}
DEF left_small_conveyor_belt_4 ConveyorBelt {
  hidden translation_1 0 0 0.7460769176257306
  translation 13.33 14.5 0
  rotation 0 0 -1 0
  name "conveyor belt(3)"
  size 1 4 1
}
DEF left_big_conveyor_belt_4 ConveyorBelt {
  hidden translation_1 0 0 1.1210769174343023
  translation 14.5 15 0
  rotation 0 0 -1 0
  name "conveyor belt(4)"
  size 1 5 1.5
}
DEF left_small_conveyor_belt_5 ConveyorBelt {
  hidden translation_1 0 0 0.7460769174345473
  translation 16.6 14.5 0
  rotation 0 0 -1 0
  name "conveyor belt(1)"
  size 1 4 1
}
DEF left_small_conveyor_belt_6 ConveyorBelt {
  hidden translation_1 0 0 0.7460769174342928
  translation 19.8 14.5 0
  rotation 0 0 -1 0
  name "conveyor belt(10)"
  size 1 4 1
}
DEF right_small_conveyor_belt_6 ConveyorBelt {
  hidden translation_1 0 0 0.7460769174342928
  translation 23 6 0
  rotation 0 0 -1 0
  name "conveyor belt(2)"
  size 1 4 1
}
DEF right_big_conveyor_belt_6 ConveyorBelt {
  hidden translation_1 0 0 1.1210769174343023
  translation 21.8 5.5 0
  rotation 0 0 -1 0
  name "conveyor belt(5)"
  size 1 5 1.5
}
ConveyorBelt {
  hidden translation_1 0 0 0.44607691743428657
  translation 27.8449 2.58127 0
  rotation 0 0 -1 0
  name "conveyor belt(12)"
  size 4 4 0.6
}
DEF right_small_conveyor_belt_5 ConveyorBelt {
  hidden translation_1 0 0 0.7460769174342928
  translation 19.8 6 0
  rotation 0 0 -1 0
  name "conveyor belt(6)"
  size 1 4 1
}
WoodenPallet {
  translation 22.5 8.7 0
  size 2 1 0.1
}
WoodenPallet {
  translation 19 8.7 0
  name "wooden pallet(1)"
  size 2 1 0.1
}
WoodenPallet {
  translation 9.4 8.7 0
  name "wooden pallet(6)"
  size 2 1 0.1
}
WoodenPallet {
  translation 17 11.9 0
  name "wooden pallet(2)"
  size 2 1 0.1
}
WoodenPallet {
  translation 10.73 11.9 0
  name "wooden pallet(3)"
  size 2 1 0.1
}
WoodenPallet {
  translation 7.5 11.9 0
  name "wooden pallet(5)"
  size 2 1 0.1
}
WoodenPallet {
  translation 4.5 11.9 0
  name "wooden pallet(4)"
  size 2 1 0.1
}
DEF right_big_conveyor_belt_5 ConveyorBelt {
  hidden translation_1 0 0 1.1210769174343023
  translation 18.5 5.5 0
  rotation 0 0 -1 0
  name "conveyor belt(7)"
  window "<none>"
  size 1 5 1.5
}
DEF right_small_conveyor_belt_4 ConveyorBelt {
  hidden translation_1 0 0 0.7460769174342928
  translation 16.46 6 0
  rotation 0 0 -1 0
  name "conveyor belt(8)"
  window "<none>"
  size 1 4 1
}
DEF right_small_conveyor_belt_3 ConveyorBelt {
  hidden translation_1 0 0 0.7460769175989068
  translation 13.22 6 0
  rotation 0 0 -1 0
  name "conveyor belt(14)"
  window "<none>"
  size 1 4 1
}
DEF left_small_conveyor_belt_2 ConveyorBelt {
  hidden translation_1 0 0 0.7460769174342928
  translation 6.9 14.5 0
  rotation 0 0 -1 0
  name "conveyor belt(21)"
  size 1 4 1
}
DEF left_small_conveyor_belt_1 ConveyorBelt {
  hidden translation_1 0 0 0.7460769174342928
  translation 3.7 14.5 0
  rotation 0 0 -1 0
  name "conveyor belt(23)"
  size 1 4 1
}
DEF left_small_conveyor_belt_3 ConveyorBelt {
  hidden translation_1 0 0 0.7460769174342928
  translation 10.1 14.5 0
  rotation 0 0 -1 0
  name "conveyor belt(19)"
  size 1 4 1
}
DEF right_small_conveyor_belt_2 ConveyorBelt {
  hidden translation_1 0 0 0.7460769174342928
  translation 10 6 0
  rotation 0 0 -1 0
  name "conveyor belt(15)"
  size 1 4 1
}
DEF right_small_conveyor_belt_1 ConveyorBelt {
  hidden translation_1 1.7763568394002505e-15 1.7763568394002505e-15 0.7460769174342924
  translation 7 6 0
  rotation 0 0 -1 0
  name "conveyor belt(17)"
  size 1 4 1
}
DEF right_big_conveyor_belt_4 ConveyorBelt {
  hidden translation_1 0 0 1.1210769174343023
  translation 15.3 5.5 0
  rotation 0 0 -1 0
  name "conveyor belt(9)"
  size 1 5 1.5
}
DEF right_big_conveyor_belt_3 ConveyorBelt {
  hidden translation_1 0 0 1.1210769174343023
  translation 12 5.5 0
  rotation 0 0 -1 0
  name "conveyor belt(13)"
  size 1 5 1.5
}
DEF left_big_conveyor_belt_3 ConveyorBelt {
  hidden translation_1 0 0 1.1210769174343023
  translation 11.3 15 0
  rotation 0 0 -1 0
  name "conveyor belt(20)"
  size 1 5 1.5
}
DEF left_big_conveyor_belt_2 ConveyorBelt {
  hidden translation_1 0 0 1.1210769174343023
  translation 8.1 15 0
  rotation 0 0 -1 0
  name "conveyor belt(22)"
  size 1 5 1.5
}
DEF left_big_conveyor_belt_1 ConveyorBelt {
  hidden translation_1 0 0 1.1210769174343023
  translation 4.9 15 0
  rotation 0 0 -1 0
  name "conveyor belt(24)"
  size 1 5 1.5
}
DEF right_big_conveyor_belt_2 ConveyorBelt {
  hidden translation_1 0 0 1.1210769174343023
  translation 8.8 5.5 0
  rotation 0 0 -1 0
  name "conveyor belt(16)"
  size 1 5 1.5
}
DEF right_big_conveyor_belt_1 Robot {
  translation 5.8 5.5 0
  rotation 0 0 -1 0
  children [
    Track {
      translation -9.488717160177629e-05 -0.0008011680417192579 1.1290044648820698
      rotation 0.9966346016118167 -0.08196245748030113 0.001275317154822441 0.007025254798688432
      children [
        Shape {
          appearance Rubber {
            type "dotted"
            textureTransform TextureTransform {
              scale 4 20
            }
          }
          geometry DEF BELT_BO Box {
            size 1 5 0.75
          }
        }
      ]
      boundingObject USE BELT_BO
      physics Physics {
        density -1
        mass 1
      }
      device [
        LinearMotor {
          name "belt_motor"
          maxVelocity 0.5
          sound ""
        }
      ]
      textureAnimation 1 0
      linearVelocity 0 0 -1.1959855328312992e-13
    }
    Shape {
      appearance CorrugatedMetal {
        textureTransform TextureTransform {
          scale 2 2
        }
      }
      geometry IndexedFaceSet {
        coord Coordinate {
          point [
            0.53 -2.53 0
            0.53 -2.53 1.51
            -0.53 -2.53 1.51
            -0.53 -2.53 0
            0.53 2.53 0
            0.53 2.53 1.51
            -0.53 2.53 1.51
            -0.53 2.53 0
            0.5 -2.5 1.51
            0.5 2.5 1.51
            -0.5 2.5 1.51
            -0.5 -2.5 1.51
            0.5 -2.5 1.5
            0.5 2.5 1.5
            -0.5 2.5 1.5
            -0.5 -2.5 1.5
          ]
        }
        texCoord TextureCoordinate {
          point [
            0 0
            1 0
            1 1
            0 1
            0 2.849056603773585
            1 2.849056603773585
            0 2.849056603773585
            4.7735849056603765 2.849056603773585
            4.7735849056603765 0
            0 0
            0.001 0
            0.001 0.001
            0 0.001
          ]
        }
        coordIndex [
          0, 1, 2, 3, -1, 4, 7, 6, 5, -1, 0, 4, 5, 1, -1, 7, 3, 2, 6, -1, 1, 5, 9, 8, -1, 5, 6, 10, 9, -1, 6, 2, 11, 10, -1, 2, 1, 8, 11, -1, 0, 3, 7, 4, -1, 8, 9, 13, 12, -1, 9, 10, 14, 13, -1, 10, 11, 15, 14, -1, 11, 8, 12, 15, -1
        ]
        texCoordIndex [
          1, 5, 4, 0, -1, 0, 1, 5, 4, -1, 0, 8, 7, 6, -1, 0, 8, 7, 6, -1, 9, 10, 11, 12, -1, 9, 10, 11, 12, -1, 9, 10, 11, 12, -1, 9, 10, 11, 12, -1, 9, 10, 11, 12, -1, 9, 10, 11, 12, -1, 9, 10, 11, 12, -1, 9, 10, 11, 12, -1, 9, 10, 11, 12, -1
        ]
      }
    }
    Pose {
      translation -0.53 -2.93845e-06 0.174
      rotation 0 0 1 -3.14159
      children [
        Shape {
          appearance Appearance {
            material Material {
              diffuseColor 1 1 1
            }
            texture ImageTexture {
              url [
                "/Users/nguyenquangnhat/Documents/ARM_project/protos/textures/april_tag.png"
              ]
              repeatS FALSE
              repeatT FALSE
            }
          }
          geometry Box {
            size 0.0005 0.05 0.05
          }
        }
      ]
    }
  ]
  name "conveyor belt(18)"
  boundingObject Group {
    children [
      Pose {
        translation 0.515 0 0.755
        children [
          Box {
            size 0.03 5.06 1.51
          }
        ]
      }
      Pose {
        translation -0.515 0 0.755
        children [
          Box {
            size 0.03 5.06 1.51
          }
        ]
      }
      Pose {
        translation 0 -2.515 0.755
        children [
          Box {
            size 1 0.03 1.51
          }
        ]
      }
      Pose {
        translation 0 2.515 0.755
        children [
          Box {
            size 1 0.03 1.51
          }
        ]
      }
    ]
  }
  controllerArgs [
    "0.5"
    "0"
  ]
}
CardboardBox {
  translation 27.8384 3.01098 0.71
  rotation 0 0 1 0.261799
  size 0.2 0.2 0.2
}
CardboardBox {
  translation 28.0224 3.48865 0.71
  rotation 0 0 1 0.785398
  name "cardboard box(1)"
  size 0.2 0.2 0.2
}
CardboardBox {
  translation 21.6903 3.22499 1.6
  rotation 0 0 1 1.309
  name "cardboard box(6)"
  size 0.2 0.2 0.2
}
CardboardBox {
  translation 7.98736 14.1014 1.6
  rotation 0 0 1 1.309
  name "cardboard box(7)"
  size 0.2 0.2 0.2
}
CardboardBox {
  translation 15.3336 4.18682 1.6
  rotation 0 0 1 2.0944
  name "cardboard box(10)"
  size 0.2 0.2 0.2
}
CardboardBox {
  translation 11.2185 13.9355 1.6
  rotation 0 0 1 2.0944
  name "cardboard box(11)"
  size 0.2 0.2 0.2
}
CardboardBox {
  translation 4.6953 16.4739 1.6
  rotation 0 0 1 2.0944
  name "cardboard box(12)"
  size 0.2 0.2 0.2
}
CardboardBox {
  translation 5.94515 4.74132 1.6
  rotation 0 0 1 1.309
  name "cardboard box(9)"
  size 0.2 0.2 0.2
}
CardboardBox {
  translation 26.2061 1.6839 0.71
  rotation 0 0 1 1.309
  name "cardboard box(8)"
  size 0.2 0.2 0.2
}
CardboardBox {
  translation 28.3211 1.96902 0.77
  rotation 0 0 1 4.692820414042842e-06
  name "cardboard box(5)"
  size 0.2 0.2 0.2
}
CardboardBox {
  translation 28.0496 3.95362 0.71
  rotation 0 0 1 0.261803
  name "cardboard box(2)"
  size 0.2 0.2 0.2
}
CardboardBox {
  translation 18.9049 8.5223 0.11
  rotation 0 0 1 1.5708
  name "cardboard box(4)"
  size 0.2 0.2 0.2
}
CardboardBox {
  translation 20.9849 7.7223 0.11
  rotation 0 0 1 1.5708
  name "cardboard box(13)"
  size 0.2 0.2 0.2
}
CardboardBox {
  translation 17.3949 8.2323 0.11
  rotation 0 0 1 1.5708
  name "cardboard box(16)"
  size 0.2 0.2 0.2
}
CardboardBox {
  translation 18.6349 12.5223 0.11
  rotation 0 0 1 1.5708
  name "cardboard box(17)"
  size 0.2 0.2 0.2
}
CardboardBox {
  translation 17.0749 12.4123 0.11
  rotation 0 0 1 1.5708
  name "cardboard box(18)"
  size 0.2 0.2 0.2
}
CardboardBox {
  translation 24.9049 4.5023 0.11
  rotation 0 0 1 1.5708
  name "cardboard box(15)"
  size 0.2 0.2 0.2
}
CardboardBox {
  translation 24.3649 4.5123 0.11
  rotation 0 0 1 1.5708
  name "cardboard box(14)"
  size 0.2 0.2 0.2
}
CardboardBox {
  translation 22.6249 18.7445 0.15
  rotation 0 0 1 4.07987e-06
  name "cardboard box(3)"
  size 0.2 0.2 0.2
}
Pose {
}
DEF SUPERVISOR Robot {
  rotation 0 0 1 -2.8797853071795863
  controller "floor_mapper"
  supervisor TRUE
}
DEF Pioneer_3-AT Pioneer3at {
  hidden position_0_0 17180.781317376728
  hidden position_0_1 14902.01285197073
  hidden position_0_2 17201.44317647468
  hidden position_0_3 14923.74740756701
  hidden linearVelocity_0 1.9176740594198193e-14 -3.0486377311511605e-15 -1.5502750598402187e-16
  hidden angularVelocity_0 1.2730693516387133e-15 3.8055040491265157e-16 -3.380511800061083e-15
  hidden rotation_1 0.5773516024134749 -0.5773476024162304 -0.5773516027299337 2.094404999683543
  hidden translation_2 4.390430234023778e-13 2.1847962280823109e-13 0.04999999999999215
  hidden rotation_2 -0.42526537133496617 0.425258256650912 -0.7989397843977734 1.7934126943521096
  hidden rotation_3 0.6930329820733898 -0.6930264968986108 -0.19854359812117847 2.7496115776205667
  hidden linearVelocity_3 2.0851392533942964e-14 9.656381914047473e-16 2.1315748540136933e-16
  hidden angularVelocity_3 7.885188227414191e-15 -1.102883895626341e-15 1.768288188122845e-17
  hidden rotation_4 -0.16753941253565838 0.1675409893288947 0.9715248643971505 4.683493665140061
  hidden linearVelocity_4 -1.5966125221155676e-14 -1.5260981119893723e-15 -2.8418951090249393e-16
  hidden angularVelocity_4 4.443923576197226e-15 -1.134576063750642e-15 1.3579718683680431e-17
  hidden rotation_5 0.16398691740691915 -0.16398191077684504 0.9727374896945994 4.684741716054951
  hidden linearVelocity_5 -4.7829331400523315e-15 3.407059861368147e-16 1.421070676639105e-16
  hidden angularVelocity_5 1.0085517618325279e-14 -3.433697553121481e-15 1.0819822860662033e-17
  hidden rotation_6 0.07773587405619731 -0.07773168647815612 0.9939390920986962 4.706299601369489
  hidden linearVelocity_6 -8.41369110570536e-16 -3.3598222261392877e-15 -4.2632286518503706e-16
  hidden angularVelocity_6 1.0277898919323311e-14 9.482366725984625e-17 -2.5538374813914826e-17
  translation 12.981299877691752 1.1346399959456264 -0.0023889310687115473
  rotation -2.4736973900514553e-05 2.4823054971116024e-05 0.999999999385949 1.5554670100436643
  name "Pioneer 3-AT_1"
  controller "pioneer_controller_1"
}
DEF Pioneer_3-AT Pioneer3at {
  hidden position_0_0 17180.78131738232
  hidden position_0_1 14902.012851964299
  hidden position_0_2 17201.44317648321
  hidden position_0_3 14923.74740756383
  hidden linearVelocity_0 2.2087444708110635e-14 -2.6434686195059792e-15 -1.5502750598402187e-16
  hidden angularVelocity_0 1.1804949187755387e-15 1.0957007382629917e-15 2.7261650662121017e-15
  hidden rotation_1 0.5773516024134749 -0.5773476024162304 -0.5773516027299337 2.094404999683543
  hidden translation_2 4.390430234023778e-13 2.1847962280823109e-13 0.04999999999999215
  hidden rotation_2 -0.42526537133496617 0.425258256650912 -0.7989397843977734 1.7934126943521096
  hidden rotation_3 0.6930329817849009 -0.693026496610131 -0.19854360013512745 2.749611573745455
  hidden linearVelocity_3 1.833288543639476e-14 -4.3776712041267635e-16 1.4213220804722542e-16
  hidden angularVelocity_3 7.444591816170466e-15 6.863436756903331e-17 -3.07059319351809e-16
  hidden rotation_4 -0.1675394155723562 0.1675409923655577 0.9715248633497948 4.683493664062447
  hidden linearVelocity_4 -1.488989126272198e-14 -1.2351629368584794e-15 1.4210665334753423e-16
  hidden angularVelocity_4 4.414208188922708e-15 -2.3104302382378925e-15 -3.494345891904178e-16
  hidden rotation_5 0.16398692144458524 -0.16398191481447316 0.9727374883332636 4.684741714656014
  hidden linearVelocity_5 -3.933020565274898e-15 1.013274478666282e-15 1.2494788780292315e-20
  hidden angularVelocity_5 9.750239547601425e-15 8.994949029704114e-17 -3.34085659737945e-16
  hidden rotation_6 0.07773587248468548 -0.0777316849066599 0.9939390923445041 4.706299601616781
  hidden linearVelocity_6 -1.3559866401936358e-16 -2.8182238393505746e-15 -4.2632108027188697e-16
  hidden angularVelocity_6 1.0057877720908734e-14 -2.2583663066192785e-15 -3.5644251698116734e-16
  translation 14.48129998729297 1.1131699973747136 -0.0023889310687114917
  rotation -2.4736973900840817e-05 2.4823054954113694e-05 0.999999999385949 1.5554670107073634
  name "Pioneer 3-AT_1(1)"
  controller "pioneer_controller_2"
}
DEF Pioneer_3-AT Pioneer3at {
  hidden position_0_0 17180.78131738164
  hidden position_0_1 14902.012851962812
  hidden position_0_2 17201.443176487894
  hidden position_0_3 14923.747407567818
  hidden linearVelocity_0 3.886921160713263e-14 -2.89560358014317e-15 5.1675835328007286e-17
  hidden angularVelocity_0 -8.821429914727819e-16 -3.7495162547187826e-16 2.8490460404105926e-15
  hidden rotation_1 0.5773516024134749 -0.5773476024162304 -0.5773516027299337 2.094404999683543
  hidden translation_2 4.390430234023778e-13 2.1847962280823109e-13 0.04999999999999215
  hidden rotation_2 -0.42526537133496617 0.425258256650912 -0.7989397843977734 1.7934126943521096
  hidden rotation_3 0.6930329818199995 -0.69302649664523 -0.19854359989009743 2.749611574216923
  hidden linearVelocity_3 3.549853438200495e-14 -4.841504203215648e-16 -2.1316178209458586e-16
  hidden angularVelocity_3 6.1848632502636794e-15 2.4081809670458905e-15 1.1573833915420608e-16
  hidden rotation_4 -0.16753941627399108 0.16754099306718498 0.9715248631078014 4.6834936638134606
  hidden linearVelocity_4 -3.117655773901607e-14 -1.0223680951340374e-15 7.103625024243599e-17
  hidden angularVelocity_4 3.1289271306900942e-15 3.555610451212603e-15 9.541966405561655e-17
  hidden rotation_5 0.1639869236605646 -0.16398191703043444 0.9727374875861255 4.684741713888233
  hidden linearVelocity_5 -1.819442906497599e-15 9.879981969426731e-16 -3.5526227760164617e-16
  hidden angularVelocity_5 8.329925135315604e-15 2.4280066762762282e-15 1.0523043577994868e-16
  hidden rotation_6 0.07773587445514045 -0.07773168687709453 0.9939390920362957 4.706299601306705
  hidden linearVelocity_6 -2.140289409345699e-15 -2.349084317425103e-15 -2.1316028519632423e-16
  hidden angularVelocity_6 8.599001012686628e-15 -4.6229858986629294e-15 1.0994407745906732e-16
  translation 16.431299991055756 1.0847899972809587 -0.0023889310687115473
  rotation -2.4736973900594737e-05 2.482305491279679e-05 0.9999999993859491 1.5554670123717598
  name "Pioneer 3-AT_1(2)"
  controller "pioneer_controller_3"
}
SquareManhole {
  translation 25 19 0
}
SquareManhole {
  translation 19.092 9.85948 -0.04
  rotation 0 0 1 0.523602
  name "manhole(16)"
}
SquareManhole {
  translation 19.2812 12.146 -0.04
  rotation 0 0 1 0.785401
  name "manhole(17)"
}
SquareManhole {
  translation 9.00273 12.0778 -0.02
  rotation 0 0 1 1.5708
  name "manhole(12)"
}
SquareManhole {
  translation 6.19714 8.34714 -0.04
  rotation 9.58978e-09 3.57898e-08 1 -0.523595307179586
  name "manhole(11)"
}
WoodenPallet {
  translation 6.46 8.7 0
  name "wooden pallet(7)"
  size 2 1 0.1
}
WoodenPallet {
  translation 12.72 8.7 0
  name "wooden pallet(8)"
  size 2 1 0.1
}
WoodenPallet {
  translation 15.74 8.7 0
  name "wooden pallet(9)"
  size 2 1 0.1
}
WoodenPallet {
  translation 13.93 11.89 0
  name "wooden pallet(10)"
  size 2 1 0.1
}
WoodenPallet {
  translation 20.37 11.89 0
  name "wooden pallet(11)"
  size 2 1 0.1
}
Robot {
  translation 4.9620485244464385 5.455067594742928 -0.006313646597225553
  rotation 0.0004473354494645951 0.0005837500868908287 0.9999997295633793 1.5707390647652297
  children [
    Camera {
      translation 0.044 -0.28 0.18
      rotation 0 0 1 -1.5707953071795862
      fieldOfView 2.05949
      width 1280
      height 720
    }
    InertialUnit {
      rotation 0 0 1 -1.5707953071795862
    }
    GPS {
      rotation 0 0 -1 -5.307179586466759e-06
    }
    Pose {
      translation 0.037646 0 0
      children [
        Shape {
          appearance DEF WHITE Plastic {
          }
          geometry Mesh {
            url [
              "https://raw.githubusercontent.com/cyberbotics/webots/R2025a/projects/robots/mir/mir100/protos/meshes/mir_100_base.obj"
            ]
          }
        }
        Shape {
          appearance USE WHITE
          geometry Mesh {
            url [
              "https://raw.githubusercontent.com/cyberbotics/webots/R2025a/projects/robots/mir/mir100/protos/meshes/mir_100_inside.obj"
            ]
          }
        }
        Shape {
          appearance Plastic {
            colorOverride 0.93 0.93 0.93
          }
          geometry Mesh {
            url [
              "https://raw.githubusercontent.com/cyberbotics/webots/R2025a/projects/robots/mir/mir100/protos/meshes/mir_100_logos.dae"
            ]
          }
        }
        Shape {
          appearance DEF BLACK Plastic {
            colorOverride 0 0 0
          }
          geometry Mesh {
            url [
              "https://raw.githubusercontent.com/cyberbotics/webots/R2025a/projects/robots/mir/mir100/protos/meshes/mir_100_base_corners.dae"
            ]
          }
        }
        Shape {
          appearance DEF BLACK Plastic {
            colorOverride 0 0 0
          }
          geometry Mesh {
            url [
              "https://raw.githubusercontent.com/cyberbotics/webots/R2025a/projects/robots/mir/mir100/protos/meshes/mir_100_top_plugs.dae"
            ]
          }
        }
      ]
    }
    DEF IMU Pose {
      translation 0 0 0.25
      children [
        Accelerometer {
          name "imu_data accelerometer"
          lookupTable [
            -100 -100 -0.002
            100 100 0.002
          ]
        }
        Gyro {
          name "imu_data gyro"
          lookupTable [
            -100 -100 -0.002
            100 100 0.002
          ]
        }
        Compass {
          name "imu_data compass"
          lookupTable [
            -1 -1 -0.2
            1 1 0.2
          ]
        }
      ]
    }
    Pose {
      translation 0.4288 0.2358 0.188
      rotation -0.9238797538373538 -0.38268289803626016 0 -3.14159
    }
    Pose {
      translation -0.3548 -0.2352 0.188
      rotation 0.38268289803626016 -0.9238797538373538 0 -3.14159
    }
    Pose {
      translation 0.037646 0 0.349
    }
    DEF DEPTH_CAMERA Transform {
      translation 0.042224 -0.273014 0.141194
      rotation 1 0 0 1.5708
      scale 4.00035 3.92893 3.92893
      children [
        Shape {
          appearance Appearance {
            material Material {
              emissiveColor 1 1 1
            }
            texture ImageTexture {
              url [
                "https://raw.githubusercontent.com/cyberbotics/webots/R2025a/projects/robots/mir/mir100/protos/textures/camera.png"
              ]
            }
            textureTransform TextureTransform {
              rotation 3.1415926
            }
          }
          geometry Plane {
            size 0.08 0.015
          }
        }
      ]
    }
    Mir100UltrasonicSensor {
      translation -0.3844 -0.1328 0.156
      rotation 0 0 1 3.141592653589793
      name "ds1"
    }
    Mir100UltrasonicSensor {
      translation -0.3844 0.1328 0.156
      rotation 0 0 1 3.141592653589793
      name "ds2"
    }
    RangeFinder {
      translation 0.044 -0.28 0.18
      rotation 0 0 1 -1.5707953071795862
      name "depth_camera"
      fieldOfView 2.05949
      near 0.001
      maxRange 1.95
    }
    Pose {
      translation 0.03733 0.0005 0.2085
      children [
        DEF LIGHT_FRONT Pose {
          translation 0.392 0 0
          children [
            DEF LIGHT_WIDTH_SHAPE Shape {
              appearance PBRAppearance {
                transparency 0.5
                emissiveColor 0 0.9 1
              }
              geometry Box {
                size 0.001 0.4723 0.053
              }
            }
          ]
        }
        DEF LIGHT_BACK Pose {
          translation -0.392 0 0
          children [
            USE LIGHT_WIDTH_SHAPE
          ]
        }
        DEF LIGHT_LEFT Pose {
          translation 0 0.2355 0
          children [
            DEF LIGHT_WIDTH_SHAPE Shape {
              appearance PBRAppearance {
                transparency 0.5
                emissiveColor 0 0.9 1
              }
              geometry Box {
                size 0.783 0.001 0.053
              }
            }
          ]
        }
        DEF LIGHT_RIGHT Pose {
          translation 0 -0.2355 0
          children [
            USE LIGHT_WIDTH_SHAPE
          ]
        }
      ]
    }
    DEF US_1_FRAME Solid {
      translation 0.45 -0.12 0.16
      name "us_1_frame"
    }
    DEF US_2_FRAME Solid {
      translation 0.45 0.12 0.16
      name "us_2_frame"
    }
    DEF FRONT_WHEEL HingeJoint {
      jointParameters HingeJointParameters {
        position -7.852709330089572
        axis 0 0 1
        anchor 0.341 -0.203 0.161
        dampingConstant 0.01
      }
      device [
        RotationalMotor {
          name "front_wheel_joint"
          maxVelocity 100
          maxTorque 20
        }
        PositionSensor {
          name "front_caster_joint_sensor"
        }
      ]
      endPoint DEF FL_CASTER_ROTATION_LINK Solid {
        translation 0.3410000173108097 -0.20300000405842855 0.16101939884163602
        rotation 0 0 1 4.713661284269601
        children [
          DEF UP_RIM Shape {
            appearance CorrodedMetal {
            }
            geometry Cylinder {
              height 0.2
              radius 0.03
            }
          }
          DEF FL_CASTER_WHEEL_JOINT HingeJoint {
            jointParameters HingeJointParameters {
              position 31.50547151157377
              axis 0 1 0
              anchor 0 0 -0.094
            }
            device [
              RotationalMotor {
                name "front_wheel"
                maxVelocity 100
                maxTorque 20
              }
              PositionSensor {
                name "front_left_wheel_joint_sensor"
              }
            ]
            endPoint DEF FL_CASTER_WHEEL_LINK Solid {
              translation -7.950689058585008e-05 2.1689599999999844e-05 -0.09399286498168717
              rotation -0.03046308098387628 -0.7067700114958446 -0.7067872038648786 3.0798933566272466
              children [
                Group {
                  children [
                    DEF RIM Shape {
                      appearance CorrodedMetal {
                      }
                      geometry Cylinder {
                        height 0.032
                        radius 0.0465
                      }
                    }
                    SolidTorus {
                      translation 0 0 0
                      majorRadius 0.0465
                      minorRadius 0.016
                      appearance DEF WHEEL_RUBBER PBRAppearance {
                        baseColor 0 0 0
                        roughness 1
                        metalness 0
                      }
                      enableBoundingObject FALSE
                    }
                  ]
                }
              ]
              name "fl_caster_wheel_link"
              contactMaterial "wheel"
              boundingObject DEF WHEEL_BO Cylinder {
                height 0.01
                radius 0.0625
              }
              physics Physics {
                density -1
                mass 1
                centerOfMass [
                  0 0 0
                ]
                inertiaMatrix [
                  0.001061895 0.001953125 0.001061895
                  0 0 5.457207e-20
                ]
              }
              linearVelocity 4.616717359626912e-10 -1.1997227113142028e-10 -1.7621059033334285e-15
              angularVelocity -1.614950049061294e-11 1.2032180289967726e-08 -8.86702953189642e-10
            }
          }
        ]
        name "fl_caster_rotation_link"
        boundingObject Pose {
          translation 0 0 -0.028
          children [
            DEF SWIVEL Cylinder {
              height 0.055
              radius 0.0298
            }
          ]
        }
        physics Physics {
          density -1
          mass 0.309754
          centerOfMass [
            0 0 -0.0425
          ]
          inertiaMatrix [
            0.0005287255 0.000517415 0.0002462724
            -7.734275e-21 -1.120566e-20 -0.0001505672
          ]
        }
        linearVelocity 4.616258485536041e-10 -1.2001230444737065e-10 -9.585264034192148e-13
        angularVelocity -1.5285062265949389e-12 1.2144814866757298e-12 -8.850783462882178e-10
      }
    }
    DEF MIDDLE_WHEEL HingeJoint {
      jointParameters HingeJointParameters {
        position -7.852683678133839
        axis 0 0 1
        anchor 0.04 0.203 0.161
        dampingConstant 0.01
      }
      device [
        RotationalMotor {
          name "middle_wheel_joint"
          maxVelocity 100
          maxTorque 20
        }
        PositionSensor {
          name "middle_caster_joint_sensor"
        }
      ]
      endPoint DEF BL_CASTER_ROTATION_LINK Solid {
        translation 0.04000203396425531 0.202999996009 0.16154839624725909
        rotation 0 0 0.9999999999999999 4.713686936225335
        children [
          DEF UP_RIM Shape {
            appearance CorrodedMetal {
            }
            geometry Cylinder {
              height 0.2
              radius 0.03
            }
          }
          DEF BL_CASTER_WHEEL_JOINT HingeJoint {
            jointParameters HingeJointParameters {
              position 13.97470792319908
              axis 0 1 0
              anchor 0 0 -0.096
            }
            device [
              RotationalMotor {
                name "middle_wheel"
                maxVelocity 100
                maxTorque 20
              }
              PositionSensor {
                name "middle_wheel_joint_sensor"
              }
            ]
            endPoint DEF BL_CASTER_WHEEL_LINK Solid {
              translation 3.7334352100521634e-06 6.762419999999961e-06 -0.09602278713388912
              rotation -0.6397787924937651 0.5434521737357529 0.5434545349310326 2.0032841065851312
              children [
                Group {
                  children [
                    USE RIM
                    SolidTorus {
                      translation 0 0 0
                      majorRadius 0.0465
                      minorRadius 0.016
                      appearance USE WHEEL_RUBBER
                      enableBoundingObject FALSE
                    }
                  ]
                }
              ]
              name "bl_caster_wheel_link"
              contactMaterial "wheel"
              boundingObject USE WHEEL_BO
              physics Physics {
                density -1
                mass 1
                centerOfMass [
                  0 0 0
                ]
                inertiaMatrix [
                  0.001061895 0.001953125 0.001061895
                  0 0 5.457207e-20
                ]
              }
              linearVelocity 1.940030159037731e-10 2.4092373584576775e-10 5.68265521103796e-16
              angularVelocity -3.0172159718686286e-13 -9.942264222779706e-10 -8.894086349789022e-10
            }
          }
        ]
        name "bl_caster_rotation_link"
        boundingObject Pose {
          translation 0 0 -0.028
          children [
            USE SWIVEL
          ]
        }
        physics Physics {
          density -1
          mass 0.309754
          centerOfMass [
            0 0 -0.0425
          ]
          inertiaMatrix [
            0.0005287255 0.000517415 0.0002462724
            -7.734275e-21 -1.120566e-20 -0.0001505672
          ]
        }
        linearVelocity 1.9405836058978183e-10 2.409553159418286e-10 -4.4501536941398474e-15
        angularVelocity -1.5342655524337125e-12 1.2160306602260635e-12 -8.895445562600229e-10
      }
    }
    DEF BACK_WHEEL HingeJoint {
      jointParameters HingeJointParameters {
        position -7.852693634778555
        axis 0 0 1
        anchor -0.27 -0.203 0.161
        dampingConstant 0.01
      }
      device [
        RotationalMotor {
          name "back_wheel_joint"
          maxVelocity 100
          maxTorque 20
        }
        PositionSensor {
          name "back_caster_joint_sensor"
        }
      ]
      endPoint DEF BR_CASTER_ROTATION_LINK Solid {
        translation -0.26999998234608386 -0.20300000330689316 0.16101986770820237
        rotation 0 0 1 4.713676979580617
        children [
          DEF UP_RIM Shape {
            appearance CorrodedMetal {
            }
            geometry Cylinder {
              height 0.2
              radius 0.03
            }
          }
          DEF BR_CASTER_WHEEL_JOINT HingeJoint {
            jointParameters HingeJointParameters {
              position 800.5220027048275
              axis 0 1 0
              anchor 0 0 -0.094
            }
            device [
              RotationalMotor {
                name "back_wheel"
                maxVelocity 100
                maxTorque 20
              }
              PositionSensor {
                name "back_wheel_joint_sensor"
              }
            ]
            endPoint DEF BR_CASTER_WHEEL_LINK Solid {
              translation 1.2095181283838478e-05 -1.2047399999999955e-05 -0.09409968490179416
              rotation -0.303299644222786 0.6737979791453302 0.6737993834324876 2.5526396138577967
              children [
                Group {
                  children [
                    USE RIM
                    SolidTorus {
                      translation 0 0 0
                      majorRadius 0.0465
                      minorRadius 0.016
                      appearance USE WHEEL_RUBBER
                      enableBoundingObject FALSE
                    }
                  ]
                }
              ]
              name "br_caster_wheel_link"
              contactMaterial "wheel"
              boundingObject USE WHEEL_BO
              physics Physics {
                density -1
                mass 1
                centerOfMass [
                  0 0 0
                ]
                inertiaMatrix [
                  0.001061895 0.001953125 0.001061895
                  0 0 5.457207e-20
                ]
              }
              linearVelocity -8.14746493362926e-11 -1.200172281300022e-10 1.0801202504259173e-15
              angularVelocity 7.367552713780537e-13 -1.848235369619424e-09 -8.926624329495089e-10
            }
          }
        ]
        name "br_caster_rotation_link"
        boundingObject Pose {
          translation 0 0 -0.028
          children [
            USE SWIVEL
          ]
        }
        physics Physics {
          density -1
          mass 0.309754
          centerOfMass [
            0 0 -0.0425
          ]
          inertiaMatrix [
            0.0005287255 0.000517415 0.0002462724
            -7.734275e-21 -1.120566e-20 -0.0001505672
          ]
        }
        linearVelocity -8.155993060098974e-11 -1.1997579953866345e-10 -2.151672250053184e-14
        angularVelocity -1.5381343148360044e-12 1.2151910187434405e-12 -8.929124090554757e-10
      }
    }
    DEF SURFACE Solid {
      translation 0.037646 0 0.352
      name "surface"
    }
  ]
  name "Mir100"
  model "Mobile Industrial Robots' MiR100"
  boundingObject Group {
    children [
      DEF TOP Pose {
        translation 0.0375 0.0005 0.334
        children [
          Box {
            size 0.774 0.461 0.04
          }
        ]
      }
      DEF MIDDLE_CENTER Pose {
        translation 0.0375 0.0005 0.262
        children [
          Box {
            size 0.857 0.44 0.096
          }
        ]
      }
      DEF MIDDLE_RIGHT_SIDE Pose {
        translation 0.0375 -0.25 0.262
        children [
          Box {
            size 0.774 0.041 0.096
          }
        ]
      }
      DEF MIDDLE_LEFT_SIDE Pose {
        translation 0.0375 0.25 0.262
        children [
          Box {
            size 0.774 0.041 0.096
          }
        ]
      }
      DEF CYL_BR Pose {
        translation -0.3555 -0.2353 0.262
        children [
          Cylinder {
            height 0.096
            radius 0.054
          }
        ]
      }
      DEF CYL_FL Pose {
        translation 0.4306 0.2364 0.262
        children [
          Cylinder {
            height 0.096
            radius 0.054
          }
        ]
      }
      DEF CYL_FR Pose {
        translation 0.415 -0.221 0.262
        children [
          Cylinder {
            height 0.096
            radius 0.049
          }
        ]
      }
      DEF CYL_BL Pose {
        translation -0.341 0.222 0.262
        children [
          Cylinder {
            height 0.096
            radius 0.049
          }
        ]
      }
      DEF MIDLOW Pose {
        translation 0.03733 0.0005 0.204
        children [
          Box {
            size 0.7806 0.4665 0.04
          }
        ]
      }
      DEF LOW Pose {
        translation 0.0374 0.0005 0.16
        children [
          Box {
            size 0.85 0.536 0.039
          }
        ]
      }
      DEF BOTTOM_LEFT Pose {
        translation 0.0374 0.2586 0.09425
        children [
          Box {
            size 0.35 0.04 0.0925
          }
        ]
      }
      DEF BOTTOM_RIGHT Pose {
        translation 0.0374 -0.2476 0.09425
        children [
          Box {
            size 0.35 0.04 0.0925
          }
        ]
      }
      DEF BOTTOM_CENTER Pose {
        translation 0.0375 0.0005 0.094
        children [
          Box {
            size 0.857 0.2 0.092
          }
        ]
      }
    ]
  }
  physics Physics {
    density -1
    mass 5
  }
  controller "mir100"
  linearVelocity 1.9062219715254054e-10 6.107015313411201e-11 -2.434171837364161e-13
  angularVelocity -1.534768613413013e-12 1.2158729995156929e-12 -8.890243393316166e-10
}
