#VRML_SIM R2025a utf8

EXTERNPROTO "https://raw.githubusercontent.com/cyberbotics/webots/R2025a/projects/objects/backgrounds/protos/TexturedBackground.proto"
EXTERNPROTO "https://raw.githubusercontent.com/cyberbotics/webots/R2025a/projects/objects/backgrounds/protos/TexturedBackgroundLight.proto"
EXTERNPROTO "https://raw.githubusercontent.com/cyberbotics/webots/R2025a/projects/objects/floors/protos/RectangleArena.proto"
EXTERNPROTO "https://raw.githubusercontent.com/cyberbotics/webots/R2025a/projects/appearances/protos/Parquetry.proto"
EXTERNPROTO "../protos/ConveyorBelt.proto"
EXTERNPROTO "../protos/Pioneer3at.proto"
EXTERNPROTO "../protos/WoodenPallet.proto"
EXTERNPROTO "https://raw.githubusercontent.com/cyberbotics/webots/R2025a/projects/objects/factory/containers/protos/CardboardBox.proto"
EXTERNPROTO "https://raw.githubusercontent.com/cyberbotics/webots/R2025a/projects/objects/factory/containers/protos/PlasticFruitBox.proto"
EXTERNPROTO "https://raw.githubusercontent.com/cyberbotics/webots/R2025a/projects/objects/factory/manhole/protos/SquareManhole.proto"
EXTERNPROTO "https://raw.githubusercontent.com/cyberbotics/webots/R2025a/projects/objects/traffic/protos/SignPole.proto"
EXTERNPROTO "https://raw.githubusercontent.com/cyberbotics/webots/R2025a/projects/objects/traffic/protos/DirectionPanel.proto"
EXTERNPROTO "https://raw.githubusercontent.com/cyberbotics/webots/R2025a/projects/humans/pedestrian/protos/Pedestrian.proto"
EXTERNPROTO "https://raw.githubusercontent.com/cyberbotics/webots/R2025a/projects/appearances/protos/Plastic.proto"
EXTERNPROTO "https://raw.githubusercontent.com/cyberbotics/webots/R2025a/projects/robots/mir/mir100/protos/Mir100UltrasonicSensor.proto"
EXTERNPROTO "https://raw.githubusercontent.com/cyberbotics/webots/R2025a/projects/appearances/protos/CorrodedMetal.proto"
EXTERNPROTO "https://raw.githubusercontent.com/cyberbotics/webots/R2025a/projects/objects/solids/protos/SolidTorus.proto"

WorldInfo {
}
Viewpoint {
  orientation -0.4364079049293709 0.43590276290576574 0.7871066775261643 1.809059125887584
  position 16.735067784676367 0.9044930067293002 17.48287205977164
  followType "None"
}
TexturedBackground {
}
TexturedBackgroundLight {
}
DEF rectangle_arena RectangleArena {
  translation 15.1304 9.85552 0
  floorSize 30 20
  floorTileSize 1 1
  floorAppearance Parquetry {
    type "dark strip"
  }
}
Pedestrian {
  translation 11.06 7.31002 1.27
  rotation 0 0 1 -3.1415853071795863
}
Pedestrian {
  translation 16.3842 17.72 1.28
  rotation 0 0 1 -0.523595307179586
  name "pedestrian(1)"
}
Pedestrian {
  translation 26.7331 5.34865 1.28
  rotation 0 0 -1 1.5708
  name "pedestrian(2)"
}
SignPole {
  translation 25.3498 15.6897 0
  rotation 0 0 1 3.14159
  height 1
  signBoards [
    DirectionPanel {
      translation 0 0 -0.86
      width 0.4
      height 0.2
    }
  ]
}
PlasticFruitBox {
  translation 28.2254 1.86879 0.63
  rotation 0 0 1 0.261799
  color 0.371527 0.966171 0.557473
}
DEF left_big_conveyor_belt_5 ConveyorBelt {
  hidden translation_1 0 0 1.1214770255503845
  translation 17.8 15 0
  rotation 0 0 -1 0
  size 1 5 1.5
}
DEF left_big_conveyor_belt_6 ConveyorBelt {
  hidden translation_1 7.105427357601002e-15 -3.552713678800501e-15 1.121477025550383
  translation 21 15 0
  rotation 0 0 -1 0
  name "conveyor belt(11)"
  size 1 5 1.5
}
DEF left_big_conveyor_belt_6 ConveyorBelt {
  hidden translation_1 -0.0003848911937467392 2.1388581966874654e-05 1.146521466676921
  hidden rotation_1 -0.007108017828594725 0.999974682844138 -0.0003312903771018675 0.006046461441891239
  translation 28.88 15 0
  rotation 0 0 -1 0
  name "conveyor belt(25)"
  size 1 5 1.5
}
DEF left_small_conveyor_belt_4 ConveyorBelt {
  hidden translation_1 0 0 0.7464770257418142
  translation 13.33 14.5 0
  rotation 0 0 -1 0
  name "conveyor belt(3)"
  size 1 4 1
}
DEF left_big_conveyor_belt_4 ConveyorBelt {
  hidden translation_1 0 0 1.1214770255503845
  translation 14.5 15 0
  rotation 0 0 -1 0
  name "conveyor belt(4)"
  size 1 5 1.5
}
DEF left_small_conveyor_belt_5 ConveyorBelt {
  hidden translation_1 0 0 0.7464770255506309
  translation 16.6 14.5 0
  rotation 0 0 -1 0
  name "conveyor belt(1)"
  size 1 4 1
}
DEF left_small_conveyor_belt_6 ConveyorBelt {
  hidden translation_1 0 0 0.7464770255503764
  translation 19.8 14.5 0
  rotation 0 0 -1 0
  name "conveyor belt(10)"
  size 1 4 1
}
DEF right_small_conveyor_belt_6 ConveyorBelt {
  hidden translation_1 0 0 0.7464770255503764
  translation 23 6 0
  rotation 0 0 -1 0
  name "conveyor belt(2)"
  size 1 4 1
}
DEF right_big_conveyor_belt_6 ConveyorBelt {
  hidden translation_1 0 0 1.1214770255503845
  translation 21.8 5.5 0
  rotation 0 0 -1 0
  name "conveyor belt(5)"
  size 1 5 1.5
}
ConveyorBelt {
  hidden translation_1 0 0 0.44647702555037094
  translation 27.8449 2.58127 0
  rotation 0 0 -1 0
  name "conveyor belt(12)"
  size 4 4 0.6
}
DEF right_small_conveyor_belt_5 ConveyorBelt {
  hidden translation_1 0 0 0.7464770255503764
  translation 19.8 6 0
  rotation 0 0 -1 0
  name "conveyor belt(6)"
  size 1 4 1
}
WoodenPallet {
  translation 22.5 8.7 0
  size 2 1 0.1
}
WoodenPallet {
  translation 19 8.7 0
  name "wooden pallet(1)"
  size 2 1 0.1
}
WoodenPallet {
  translation 9.4 8.7 0
  name "wooden pallet(6)"
  size 2 1 0.1
}
WoodenPallet {
  translation 17 11.9 0
  name "wooden pallet(2)"
  size 2 1 0.1
}
WoodenPallet {
  translation 10.73 11.9 0
  name "wooden pallet(3)"
  size 2 1 0.1
}
WoodenPallet {
  translation 7.5 11.9 0
  name "wooden pallet(5)"
  size 2 1 0.1
}
WoodenPallet {
  translation 4.5 11.9 0
  name "wooden pallet(4)"
  size 2 1 0.1
}
DEF right_big_conveyor_belt_5 ConveyorBelt {
  hidden translation_1 0 0 1.1214770255503845
  translation 18.5 5.5 0
  rotation 0 0 -1 0
  name "conveyor belt(7)"
  window "<none>"
  size 1 5 1.5
}
DEF right_small_conveyor_belt_4 ConveyorBelt {
  hidden translation_1 0 0 0.7464770255503764
  translation 16.46 6 0
  rotation 0 0 -1 0
  name "conveyor belt(8)"
  window "<none>"
  size 1 4 1
}
DEF right_small_conveyor_belt_3 ConveyorBelt {
  hidden translation_1 0 0 0.7464770257149904
  translation 13.22 6 0
  rotation 0 0 -1 0
  name "conveyor belt(14)"
  window "<none>"
  size 1 4 1
}
DEF left_small_conveyor_belt_2 ConveyorBelt {
  hidden translation_1 0 0 0.7464770255503764
  translation 6.9 14.5 0
  rotation 0 0 -1 0
  name "conveyor belt(21)"
  size 1 4 1
}
DEF left_small_conveyor_belt_1 ConveyorBelt {
  hidden translation_1 0 0 0.7464770255503764
  translation 3.7 14.5 0
  rotation 0 0 -1 0
  name "conveyor belt(23)"
  size 1 4 1
}
DEF left_small_conveyor_belt_3 ConveyorBelt {
  hidden translation_1 0 0 0.7464770255503764
  translation 10.1 14.5 0
  rotation 0 0 -1 0
  name "conveyor belt(19)"
  size 1 4 1
}
DEF right_small_conveyor_belt_2 ConveyorBelt {
  hidden translation_1 0 0 0.7464770255503764
  translation 10 6 0
  rotation 0 0 -1 0
  name "conveyor belt(15)"
  size 1 4 1
}
DEF right_small_conveyor_belt_1 ConveyorBelt {
  hidden translation_1 1.7763568394002505e-15 1.7763568394002505e-15 0.746477025550376
  translation 7 6 0
  rotation 0 0 -1 0
  name "conveyor belt(17)"
  size 1 4 1
}
DEF right_big_conveyor_belt_4 ConveyorBelt {
  hidden translation_1 0 0 1.1214770255503845
  translation 15.3 5.5 0
  rotation 0 0 -1 0
  name "conveyor belt(9)"
  size 1 5 1.5
}
DEF right_big_conveyor_belt_3 ConveyorBelt {
  hidden translation_1 0 0 1.1214770255503845
  translation 12 5.5 0
  rotation 0 0 -1 0
  name "conveyor belt(13)"
  size 1 5 1.5
}
DEF left_big_conveyor_belt_3 ConveyorBelt {
  hidden translation_1 0 0 1.1214770255503845
  translation 11.3 15 0
  rotation 0 0 -1 0
  name "conveyor belt(20)"
  size 1 5 1.5
}
DEF left_big_conveyor_belt_2 ConveyorBelt {
  hidden translation_1 0 0 1.1214770255503845
  translation 8.1 15 0
  rotation 0 0 -1 0
  name "conveyor belt(22)"
  size 1 5 1.5
}
DEF left_big_conveyor_belt_1 ConveyorBelt {
  hidden translation_1 0 0 1.1214770255503845
  translation 4.9 15 0
  rotation 0 0 -1 0
  name "conveyor belt(24)"
  size 1 5 1.5
}
DEF right_big_conveyor_belt_2 ConveyorBelt {
  hidden translation_1 0 0 1.1214770255503845
  translation 8.8 5.5 0
  rotation 0 0 -1 0
  name "conveyor belt(16)"
  size 1 5 1.5
}
DEF right_big_conveyor_belt_1 ConveyorBelt {
  hidden translation_1 -9.488717160177629e-05 -0.0008011680417192579 1.1294045729981548
  hidden rotation_1 0.9966346016118167 -0.08196245748030113 0.001275317154822441 0.007025254798688432
  translation 5.8 5.5 0
  rotation 0 0 -1 0
  name "conveyor belt(18)"
  size 1 5 1.5
}
CardboardBox {
  translation 27.8384 3.01098 0.71
  rotation 0 0 1 0.261799
  size 0.2 0.2 0.2
}
CardboardBox {
  translation 28.0224 3.48865 0.71
  rotation 0 0 1 0.785398
  name "cardboard box(1)"
  size 0.2 0.2 0.2
}
CardboardBox {
  translation 21.6903 3.22499 1.6
  rotation 0 0 1 1.309
  name "cardboard box(6)"
  size 0.2 0.2 0.2
}
CardboardBox {
  translation 7.98736 14.1014 1.6
  rotation 0 0 1 1.309
  name "cardboard box(7)"
  size 0.2 0.2 0.2
}
CardboardBox {
  translation 15.3336 4.18682 1.6
  rotation 0 0 1 2.0944
  name "cardboard box(10)"
  size 0.2 0.2 0.2
}
CardboardBox {
  translation 11.2185 13.9355 1.6
  rotation 0 0 1 2.0944
  name "cardboard box(11)"
  size 0.2 0.2 0.2
}
CardboardBox {
  translation 4.6953 16.4739 1.6
  rotation 0 0 1 2.0944
  name "cardboard box(12)"
  size 0.2 0.2 0.2
}
CardboardBox {
  translation 5.94515 4.74132 1.6
  rotation 0 0 1 1.309
  name "cardboard box(9)"
  size 0.2 0.2 0.2
}
CardboardBox {
  translation 26.2061 1.6839 0.71
  rotation 0 0 1 1.309
  name "cardboard box(8)"
  size 0.2 0.2 0.2
}
CardboardBox {
  translation 28.3211 1.96902 0.77
  rotation 0 0 1 4.692820414042842e-06
  name "cardboard box(5)"
  size 0.2 0.2 0.2
}
CardboardBox {
  translation 28.0496 3.95362 0.71
  rotation 0 0 1 0.261803
  name "cardboard box(2)"
  size 0.2 0.2 0.2
}
CardboardBox {
  translation 18.9049 8.5223 0.11
  rotation 0 0 1 1.5708
  name "cardboard box(4)"
  size 0.2 0.2 0.2
}
CardboardBox {
  translation 20.9849 7.7223 0.11
  rotation 0 0 1 1.5708
  name "cardboard box(13)"
  size 0.2 0.2 0.2
}
CardboardBox {
  translation 17.3949 8.2323 0.11
  rotation 0 0 1 1.5708
  name "cardboard box(16)"
  size 0.2 0.2 0.2
}
CardboardBox {
  translation 18.6349 12.5223 0.11
  rotation 0 0 1 1.5708
  name "cardboard box(17)"
  size 0.2 0.2 0.2
}
CardboardBox {
  translation 17.0749 12.4123 0.11
  rotation 0 0 1 1.5708
  name "cardboard box(18)"
  size 0.2 0.2 0.2
}
CardboardBox {
  translation 24.9049 4.5023 0.11
  rotation 0 0 1 1.5708
  name "cardboard box(15)"
  size 0.2 0.2 0.2
}
CardboardBox {
  translation 24.3649 4.5123 0.11
  rotation 0 0 1 1.5708
  name "cardboard box(14)"
  size 0.2 0.2 0.2
}
CardboardBox {
  translation 22.6249 18.7445 0.15
  rotation 0 0 1 4.07987e-06
  name "cardboard box(3)"
  size 0.2 0.2 0.2
}
Pose {
}
DEF SUPERVISOR Robot {
  rotation 0 0 1 -2.8797853071795863
  controller "floor_mapper"
  supervisor TRUE
}
DEF Pioneer_3-AT Pioneer3at {
  hidden position_0_0 17180.78131737236
  hidden position_0_1 14902.01285197265
  hidden position_0_2 17201.443176471188
  hidden position_0_3 14923.74740757245
  hidden linearVelocity_0 1.363051922702607e-14 -2.8996825458437283e-15 1.5502750598402187e-16
  hidden angularVelocity_0 -9.722055195957235e-16 7.121439697587558e-16 -3.606869073679626e-15
  hidden rotation_1 0.5773516024134749 -0.5773476024162304 -0.5773516027299337 2.094404999683543
  hidden translation_2 4.390430234023778e-13 2.1847962280823109e-13 0.04999999999999215
  hidden rotation_2 -0.42526537133496617 0.425258256650912 -0.7989397843977734 1.7934126943521096
  hidden rotation_3 0.6930329822988137 -0.6930264971240263 -0.1985435965474945 2.749611580648548
  hidden linearVelocity_3 1.889834792890968e-14 1.0779027233450733e-15 -1.4209084404916364e-16
  hidden angularVelocity_3 6.931040393928344e-15 -3.4628410434338215e-15 -7.016966275700105e-17
  hidden rotation_4 -0.16753941162962985 0.16754098842287693 0.9715248647096393 4.683493665461578
  hidden linearVelocity_4 -1.4215120938159862e-14 -1.4384670527694317e-15 7.104725745001969e-17
  hidden angularVelocity_4 3.613323920669401e-15 3.3340006604921206e-17 -9.45823445924426e-18
  hidden rotation_5 0.16398691575397292 -0.16398190912391195 0.9727374902519057 4.684741716627653
  hidden linearVelocity_5 -2.8166522693873214e-15 4.680734623113401e-16 4.973619794260848e-16
  hidden angularVelocity_5 8.830494876698218e-15 -2.2696955626326645e-15 -6.171853442398011e-17
  hidden rotation_6 0.07773587674277287 -0.07773168916470367 0.9939390916784762 4.70629960094672
  hidden linearVelocity_6 -2.8615672703774472e-15 -3.275285908067182e-15 4.973694244486222e-16
  hidden angularVelocity_6 9.470787369379411e-15 -4.614942819084124e-15 -6.308974845408844e-17
  translation 12.981299877519625 1.134639997552859 -0.0023889310687115195
  rotation -2.4736973900066588e-05 2.4823054942818625e-05 0.9999999993859491 1.5554670111994422
  name "Pioneer 3-AT_1"
  controller "pioneer_controller_1"
}
DEF Pioneer_3-AT Pioneer3at {
  hidden position_0_0 17180.78131737795
  hidden position_0_1 14902.012851966218
  hidden position_0_2 17201.44317647972
  hidden position_0_3 14923.747407569268
  hidden linearVelocity_0 2.250408409967819e-14 -2.440300960042259e-15 -5.1675835328007286e-17
  hidden angularVelocity_0 6.995279397655993e-16 2.1727053890039998e-15 1.9114212595824464e-15
  hidden rotation_1 0.5773516024134749 -0.5773476024162304 -0.5773516027299337 2.094404999683543
  hidden translation_2 4.390430234023778e-13 2.1847962280823109e-13 0.04999999999999215
  hidden rotation_2 -0.42526537133496617 0.425258256650912 -0.7989397843977734 1.7934126943521096
  hidden rotation_3 0.6930329820103248 -0.6930264968355463 -0.19854359856144324 2.7496115767734386
  hidden linearVelocity_3 1.846545710973636e-14 -5.611118658379453e-16 7.104983312475247e-17
  hidden angularVelocity_3 7.752239622827532e-15 -2.2796898442052193e-15 -3.066170906305588e-16
  hidden rotation_4 -0.167539414666328 0.16754099145954013 0.9715248636622834 4.683493664383962
  hidden linearVelocity_4 -1.4344768253153904e-14 -1.17859858060543e-15 2.1318688006532605e-16
  hidden angularVelocity_4 3.828650462987101e-15 3.5620667673710805e-15 -3.656660280052378e-16
  hidden rotation_5 0.16398691979163835 -0.16398191316154043 0.97273748889057 4.684741715228714
  hidden linearVelocity_5 -3.3771447920089473e-15 1.179812162847905e-15 -3.5526998294594875e-16
  hidden angularVelocity_5 9.343511661025756e-15 7.139677529509604e-15 -3.5421394399348983e-16
  hidden rotation_6 0.07773587517126132 -0.0777316875932071 0.9939390919242839 4.706299601194017
  hidden linearVelocity_6 2.4202667095500105e-16 -2.7913566297539723e-15 4.2634901702817977e-16
  hidden angularVelocity_6 9.933226425302909e-15 5.969543806769232e-15 -3.1902813847493985e-16
  translation 14.48129998712085 1.1131699989819348 -0.0023889310687115195
  rotation -2.4736973900348603e-05 2.4823054925794266e-05 0.999999999385949 1.5554670118631664
  name "Pioneer 3-AT_1(1)"
  controller "pioneer_controller_2"
}
DEF Pioneer_3-AT Pioneer3at {
  hidden position_0_0 17180.78131737727
  hidden position_0_1 14902.012851964731
  hidden position_0_2 17201.4431764844
  hidden position_0_3 14923.747407573257
  hidden linearVelocity_0 3.875598281772384e-14 -2.0178563681083615e-15 0
  hidden angularVelocity_0 -2.0315349711315925e-16 -1.0869364231263265e-15 1.8971292615391495e-15
  hidden rotation_1 0.5773516024134749 -0.5773476024162304 -0.5773516027299337 2.094404999683543
  hidden translation_2 4.390430234023778e-13 2.1847962280823109e-13 0.04999999999999215
  hidden rotation_2 -0.42526537133496617 0.425258256650912 -0.7989397843977734 1.7934126943521096
  hidden rotation_3 0.6930329820454235 -0.6930264968706449 -0.19854359831641438 2.749611577244907
  hidden linearVelocity_3 3.4428366097348656e-14 -3.852660029482973e-16 5.684235790225596e-16
  hidden angularVelocity_3 6.791893803317771e-15 -1.1693185669774393e-14 -7.655706825562251e-16
  hidden rotation_4 -0.16753941536796296 0.16754099216116694 0.9715248634202897 4.683493664134979
  hidden linearVelocity_4 -3.120648158954402e-14 -1.027952886052283e-15 -4.973940254541158e-16
  hidden angularVelocity_4 3.574214735550696e-15 1.2085591167418603e-15 -7.88030963013287e-16
  hidden rotation_5 0.1639869220076191 -0.16398191537750167 0.9727374881434319 4.684741714460935
  hidden linearVelocity_5 -1.6576436941205824e-15 8.342449733379303e-16 4.263247344444126e-16
  hidden angularVelocity_5 9.403490873790427e-15 3.6134906922949535e-15 -7.990231386248304e-16
  hidden rotation_6 0.07773587714171569 -0.0777316895636417 0.9939390916160756 4.70629960088394
  hidden linearVelocity_6 -1.8707020312984444e-15 -2.6141628047327167e-15 7.107790041468167e-17
  hidden angularVelocity_6 9.350835444865414e-15 2.4374305830546766e-15 -7.89260032570893e-16
  translation 16.431299990883634 1.0847899988881944 -0.0023889310687115195
  rotation -2.473697389997578e-05 2.4823054884237203e-05 0.9999999993859491 1.5554670135287851
  name "Pioneer 3-AT_1(2)"
  controller "pioneer_controller_3"
}
SquareManhole {
  translation 25 19 0
}
SquareManhole {
  translation 19.092 9.85948 -0.04
  rotation 0 0 1 0.523602
  name "manhole(16)"
}
SquareManhole {
  translation 19.2812 12.146 -0.04
  rotation 0 0 1 0.785401
  name "manhole(17)"
}
SquareManhole {
  translation 9.00273 10.7778 -0.02
  rotation 0 0 1 1.5708
  name "manhole(12)"
}
SquareManhole {
  translation 4.9337 9.8387 -0.04
  rotation 9.58978e-09 3.57898e-08 1 -0.523595307179586
  name "manhole(11)"
}
WoodenPallet {
  translation 6 8.7 0
  name "wooden pallet(7)"
  size 2 1 0.1
}
WoodenPallet {
  translation 12.72 8.7 0
  name "wooden pallet(8)"
  size 2 1 0.1
}
WoodenPallet {
  translation 15.74 8.7 0
  name "wooden pallet(9)"
  size 2 1 0.1
}
WoodenPallet {
  translation 13.93 11.89 0
  name "wooden pallet(10)"
  size 2 1 0.1
}
WoodenPallet {
  translation 20.37 11.89 0
  name "wooden pallet(11)"
  size 2 1 0.1
}
Robot {
  translation 20.256218826760854 11.044569304372114 -0.008594793443434168
  rotation 0.0009121265740000768 -0.0015267013367879917 0.9999984186028203 3.1415569906481564
  children [
    Camera {
      translation 0.044 -0.28 0.18
      rotation 0 0 1 -1.5707953071795862
      fieldOfView 2.05949
      width 1280
      height 720
    }
    InertialUnit {
      rotation 0 0 1 -1.5707953071795862
    }
    GPS {
      rotation 0 0 -1 -5.307179586466759e-06
    }
    Pose {
      translation 0.037646 0 0
      children [
        Shape {
          appearance DEF WHITE Plastic {
          }
          geometry Mesh {
            url [
              "https://raw.githubusercontent.com/cyberbotics/webots/R2025a/projects/robots/mir/mir100/protos/meshes/mir_100_base.obj"
            ]
          }
        }
        Shape {
          appearance USE WHITE
          geometry Mesh {
            url [
              "https://raw.githubusercontent.com/cyberbotics/webots/R2025a/projects/robots/mir/mir100/protos/meshes/mir_100_inside.obj"
            ]
          }
        }
        Shape {
          appearance Plastic {
            colorOverride 0.93 0.93 0.93
          }
          geometry Mesh {
            url [
              "https://raw.githubusercontent.com/cyberbotics/webots/R2025a/projects/robots/mir/mir100/protos/meshes/mir_100_logos.dae"
            ]
          }
        }
        Shape {
          appearance DEF BLACK Plastic {
            colorOverride 0 0 0
          }
          geometry Mesh {
            url [
              "https://raw.githubusercontent.com/cyberbotics/webots/R2025a/projects/robots/mir/mir100/protos/meshes/mir_100_base_corners.dae"
            ]
          }
        }
        Shape {
          appearance DEF BLACK Plastic {
            colorOverride 0 0 0
          }
          geometry Mesh {
            url [
              "https://raw.githubusercontent.com/cyberbotics/webots/R2025a/projects/robots/mir/mir100/protos/meshes/mir_100_top_plugs.dae"
            ]
          }
        }
      ]
    }
    DEF IMU Pose {
      translation 0 0 0.25
      children [
        Accelerometer {
          name "imu_data accelerometer"
          lookupTable [
            -100 -100 -0.002
            100 100 0.002
          ]
        }
        Gyro {
          name "imu_data gyro"
          lookupTable [
            -100 -100 -0.002
            100 100 0.002
          ]
        }
        Compass {
          name "imu_data compass"
          lookupTable [
            -1 -1 -0.2
            1 1 0.2
          ]
        }
      ]
    }
    Pose {
      translation 0.4288 0.2358 0.188
      rotation -0.9238797538373538 -0.38268289803626016 0 -3.14159
    }
    Pose {
      translation -0.3548 -0.2352 0.188
      rotation 0.38268289803626016 -0.9238797538373538 0 -3.14159
    }
    Pose {
      translation 0.037646 0 0.349
    }
    DEF DEPTH_CAMERA Transform {
      translation 0.042224 -0.273014 0.141194
      rotation 1 0 0 1.5708
      scale 4.00035 3.92893 3.92893
      children [
        Shape {
          appearance Appearance {
            material Material {
              emissiveColor 1 1 1
            }
            texture ImageTexture {
              url [
                "https://raw.githubusercontent.com/cyberbotics/webots/R2025a/projects/robots/mir/mir100/protos/textures/camera.png"
              ]
            }
            textureTransform TextureTransform {
              rotation 3.1415926
            }
          }
          geometry Plane {
            size 0.08 0.015
          }
        }
      ]
    }
    Mir100UltrasonicSensor {
      translation 0.415448 -0.108238 0.08
      rotation 0.8628559982596194 -0.35740699927911007 -0.35740699927911007 1.71777
      name "ds0"
      lookupTable [
        0.2 1000 0
        0.3 0 0
      ]
    }
    Mir100UltrasonicSensor {
      translation -0.3844 -0.1328 0.156
      rotation 0 0 1 3.141592653589793
      name "ds1"
    }
    Mir100UltrasonicSensor {
      translation -0.3844 0.1328 0.156
      rotation 0 0 1 3.141592653589793
      name "ds2"
    }
    Mir100UltrasonicSensor {
      translation 0.415448 0.108238 0.08
      rotation 0.8628559982596194 0.35740699927911007 0.35740699927911007 1.71777
      name "ds3"
      lookupTable [
        0.2 1000 0
        0.3 0 0
      ]
    }
    RangeFinder {
      translation 0.044 -0.28 0.18
      rotation 0 0 1 -1.5707953071795862
      name "depth_camera"
      fieldOfView 2.05949
      width 1280
      height 720
      minRange 0.18
      maxRange 1.95
    }
    Pose {
      translation 0.03733 0.0005 0.2085
      children [
        DEF LIGHT_FRONT Pose {
          translation 0.392 0 0
          children [
            DEF LIGHT_WIDTH_SHAPE Shape {
              appearance PBRAppearance {
                transparency 0.5
                emissiveColor 0 0.9 1
              }
              geometry Box {
                size 0.001 0.4723 0.053
              }
            }
          ]
        }
        DEF LIGHT_BACK Pose {
          translation -0.392 0 0
          children [
            USE LIGHT_WIDTH_SHAPE
          ]
        }
        DEF LIGHT_LEFT Pose {
          translation 0 0.2355 0
          children [
            DEF LIGHT_WIDTH_SHAPE Shape {
              appearance PBRAppearance {
                transparency 0.5
                emissiveColor 0 0.9 1
              }
              geometry Box {
                size 0.783 0.001 0.053
              }
            }
          ]
        }
        DEF LIGHT_RIGHT Pose {
          translation 0 -0.2355 0
          children [
            USE LIGHT_WIDTH_SHAPE
          ]
        }
      ]
    }
    DEF US_1_FRAME Solid {
      translation 0.45 -0.12 0.16
      name "us_1_frame"
    }
    DEF US_2_FRAME Solid {
      translation 0.45 0.12 0.16
      name "us_2_frame"
    }
    DEF FL_CASTER_ROTATION_JOINT HingeJoint {
      jointParameters HingeJointParameters {
        position 4.0277748450680675e-06
        axis 0 0 1
        anchor 0.341346 0 0.154
        dampingConstant 0.01
      }
      device [
        RotationalMotor {
          name "front_wheel_joint"
          maxVelocity 100
          maxTorque 20
        }
        PositionSensor {
          name "front_caster_joint_sensor"
        }
      ]
      endPoint DEF FL_CASTER_ROTATION_LINK Solid {
        translation 0.3408593731842644 0.0005417789481489707 0.16104314252205185
        rotation 0 0 1 2.1018561938412506e-06
        children [
          DEF CASTER_WHEEL_BASE Shape {
            appearance PBRAppearance {
              baseColor 0.35 0.35 0.35
              roughness 1
              metalness 0
            }
            geometry Mesh {
              url [
                "https://raw.githubusercontent.com/cyberbotics/webots/R2025a/projects/robots/mir/mir100/protos/meshes/caster_wheel_base.dae"
              ]
            }
          }
          DEF FL_CASTER_WHEEL_JOINT HingeJoint {
            jointParameters HingeJointParameters {
              position 657.0119040384378
              axis 0 1 0
              anchor -0.0382 0 -0.094
            }
            device [
              RotationalMotor {
                name "front_wheel"
                maxVelocity 100
                maxTorque 20
              }
              PositionSensor {
                name "front_left_wheel_joint_sensor"
              }
            ]
            endPoint DEF FL_CASTER_WHEEL_LINK Solid {
              translation -0.03784277247947904 -5.553783064016232e-05 -0.09390075955928237
              rotation 0.8124153160861717 -0.4122993719349982 -0.41229914151088376 4.506119593660061
              children [
                Group {
                  children [
                    DEF RIM Shape {
                      appearance CorrodedMetal {
                      }
                      geometry Cylinder {
                        height 0.032
                        radius 0.0465
                      }
                    }
                    SolidTorus {
                      translation 0 0 0
                      majorRadius 0.0465
                      minorRadius 0.016
                      appearance DEF WHEEL_RUBBER PBRAppearance {
                        baseColor 0 0 0
                        roughness 1
                        metalness 0
                      }
                      enableBoundingObject FALSE
                    }
                  ]
                }
              ]
              name "fl_caster_wheel_link"
              contactMaterial "wheel"
              boundingObject DEF WHEEL_BO Cylinder {
                height 0.01
                radius 0.0625
              }
              physics Physics {
                density -1
                mass 1
                centerOfMass [
                  0 0 0
                ]
                inertiaMatrix [
                  0.001061895 0.001953125 0.001061895
                  0 0 5.457207e-20
                ]
              }
              linearVelocity 2.0822223640913987e-09 -5.468059192392798e-10 8.184316100626937e-13
              angularVelocity 1.1636234956146999e-10 1.1170219662558866e-07 3.9704613661030576e-08
            }
          }
        ]
        name "fl_caster_rotation_link"
        boundingObject Pose {
          translation 0 0 -0.028
          children [
            DEF SWIVEL Cylinder {
              height 0.055
              radius 0.0298
            }
          ]
        }
        physics Physics {
          density -1
          mass 0.309754
          centerOfMass [
            0 0 -0.0425
          ]
          inertiaMatrix [
            0.0005287255 0.000517415 0.0002462724
            -7.734275e-21 -1.120566e-20 -0.0001505672
          ]
        }
        linearVelocity 2.078012865966936e-09 -2.03263534414311e-09 -4.563091254437416e-11
        angularVelocity 1.1251725763601028e-10 -1.7213441548594072e-10 3.936301025875997e-08
      }
    }
    DEF BL_CASTER_ROTATION_JOINT HingeJoint {
      jointParameters HingeJointParameters {
        position 1.6868654202243212e-06
        axis 0 0 1
        anchor -0.270154 0.203 0.1565
        dampingConstant 0.01
      }
      device [
        RotationalMotor {
          name "back_left_wheel_joint"
          maxVelocity 100
          maxTorque 20
        }
        PositionSensor {
          name "back_left_caster_joint_sensor"
        }
      ]
      endPoint DEF BL_CASTER_ROTATION_LINK Solid {
        translation -0.2701497508167207 0.20300711304599908 0.16440597262302642
        rotation 0 0 0.9999999999999999 8.57561503049032e-07
        children [
          USE CASTER_WHEEL_BASE
          DEF BL_CASTER_WHEEL_JOINT HingeJoint {
            jointParameters HingeJointParameters {
              position 742.7851721047062
              axis 0 1 0
              anchor -0.0382 0 -0.094
            }
            device [
              RotationalMotor {
                name "back_left_wheel"
                maxVelocity 100
                maxTorque 20
              }
              PositionSensor {
                name "back_left_wheel_joint_sensor"
              }
            ]
            endPoint DEF BL_CASTER_WHEEL_LINK Solid {
              translation -0.03808994971191833 -2.9480967995709537e-06 -0.09404284357561686
              rotation -0.6547049744459474 0.5344900080753782 0.5344921212733764 1.9822447637983456
              children [
                Group {
                  children [
                    USE RIM
                    SolidTorus {
                      translation 0 0 0
                      majorRadius 0.0465
                      minorRadius 0.016
                      appearance USE WHEEL_RUBBER
                      enableBoundingObject FALSE
                    }
                  ]
                }
              ]
              name "bl_caster_wheel_link"
              contactMaterial "wheel"
              boundingObject USE WHEEL_BO
              physics Physics {
                density -1
                mass 1
                centerOfMass [
                  0 0 0
                ]
                inertiaMatrix [
                  0.001061895 0.001953125 0.001061895
                  0 0 5.457207e-20
                ]
              }
              linearVelocity 2.5874498322873852e-09 2.6554749772398396e-10 -1.1444228667648375e-11
              angularVelocity 7.647427863766949e-11 1.5106746056133266e-08 1.8554283722961936e-08
            }
          }
        ]
        name "bl_caster_rotation_link"
        boundingObject Pose {
          translation 0 0 -0.028
          children [
            USE SWIVEL
          ]
        }
        physics Physics {
          density -1
          mass 0.309754
          centerOfMass [
            0 0 -0.0425
          ]
          inertiaMatrix [
            0.0005287255 0.000517415 0.0002462724
            -7.734275e-21 -1.120566e-20 -0.0001505672
          ]
        }
        linearVelocity 2.5903270541467478e-09 -4.44255041038238e-10 -1.7495664553827973e-11
        angularVelocity 7.572522873609189e-11 -1.088332267685739e-10 1.8507822268588237e-08
      }
    }
    DEF BR_CASTER_ROTATION_JOINT HingeJoint {
      jointParameters HingeJointParameters {
        position 1.6434634372469413e-06
        axis 0 0 1
        anchor -0.270154 -0.203 0.1565
        dampingConstant 0.01
      }
      device [
        RotationalMotor {
          name "back_right_wheel_joint"
          maxVelocity 100
          maxTorque 20
        }
        PositionSensor {
          name "back_right_caster_joint_sensor"
        }
      ]
      endPoint DEF BR_CASTER_ROTATION_LINK Solid {
        translation -0.27014431983140563 -0.20305818996506764 0.16301604855217966
        rotation 0 0 0.9999999999999999 8.248300852238027e-07
        children [
          USE CASTER_WHEEL_BASE
          DEF BR_CASTER_WHEEL_JOINT HingeJoint {
            jointParameters HingeJointParameters {
              position 728.8493115377615
              axis 0 1 0
              anchor -0.0382 0 -0.094
            }
            device [
              RotationalMotor {
                name "back_right_wheel"
                maxVelocity 100
                maxTorque 20
              }
              PositionSensor {
                name "back_right_wheel_joint_sensor"
              }
            ]
            endPoint DEF BR_CASTER_WHEEL_LINK Solid {
              translation -0.03840694615022995 -1.0658529570051058e-07 -0.0938701263546828
              rotation -0.9999999915272824 -9.204533486965519e-05 -9.20493962654989e-05 1.570800010638266
              children [
                Group {
                  children [
                    USE RIM
                    SolidTorus {
                      translation 0 0 0
                      majorRadius 0.0465
                      minorRadius 0.016
                      appearance USE WHEEL_RUBBER
                      enableBoundingObject FALSE
                    }
                  ]
                }
              ]
              name "br_caster_wheel_link"
              contactMaterial "wheel"
              boundingObject USE WHEEL_BO
              physics Physics {
                density -1
                mass 1
                centerOfMass [
                  0 0 0
                ]
                inertiaMatrix [
                  0.001061895 0.001953125 0.001061895
                  0 0 5.457207e-20
                ]
              }
              linearVelocity 1.5565323984334352e-09 2.6566986848972466e-10 1.0582539291852427e-11
              angularVelocity 7.462930761795391e-11 -2.7392303774328823e-08 1.825440619064746e-08
            }
          }
        ]
        name "br_caster_rotation_link"
        boundingObject Pose {
          translation 0 0 -0.028
          children [
            USE SWIVEL
          ]
        }
        physics Physics {
          density -1
          mass 0.309754
          centerOfMass [
            0 0 -0.0425
          ]
          inertiaMatrix [
            0.0005287255 0.000517415 0.0002462724
            -7.734275e-21 -1.120566e-20 -0.0001505672
          ]
        }
        linearVelocity 1.5447603548374135e-09 -4.4387983965582905e-10 8.81543332297909e-13
        angularVelocity 7.548091271209264e-11 -1.1090242335224552e-10 1.8337711383902174e-08
      }
    }
    DEF SURFACE Solid {
      translation 0.037646 0 0.352
      name "surface"
    }
  ]
  name "Mir100"
  model "Mobile Industrial Robots' MiR100"
  boundingObject Group {
    children [
      DEF TOP Pose {
        translation 0.0375 0.0005 0.334
        children [
          Box {
            size 0.774 0.461 0.04
          }
        ]
      }
      DEF MIDDLE_CENTER Pose {
        translation 0.0375 0.0005 0.262
        children [
          Box {
            size 0.857 0.44 0.096
          }
        ]
      }
      DEF MIDDLE_RIGHT_SIDE Pose {
        translation 0.0375 -0.25 0.262
        children [
          Box {
            size 0.774 0.041 0.096
          }
        ]
      }
      DEF MIDDLE_LEFT_SIDE Pose {
        translation 0.0375 0.25 0.262
        children [
          Box {
            size 0.774 0.041 0.096
          }
        ]
      }
      DEF CYL_BR Pose {
        translation -0.3555 -0.2353 0.262
        children [
          Cylinder {
            height 0.096
            radius 0.054
          }
        ]
      }
      DEF CYL_FL Pose {
        translation 0.4306 0.2364 0.262
        children [
          Cylinder {
            height 0.096
            radius 0.054
          }
        ]
      }
      DEF CYL_FR Pose {
        translation 0.415 -0.221 0.262
        children [
          Cylinder {
            height 0.096
            radius 0.049
          }
        ]
      }
      DEF CYL_BL Pose {
        translation -0.341 0.222 0.262
        children [
          Cylinder {
            height 0.096
            radius 0.049
          }
        ]
      }
      DEF MIDLOW Pose {
        translation 0.03733 0.0005 0.204
        children [
          Box {
            size 0.7806 0.4665 0.04
          }
        ]
      }
      DEF LOW Pose {
        translation 0.0374 0.0005 0.16
        children [
          Box {
            size 0.85 0.536 0.039
          }
        ]
      }
      DEF BOTTOM_LEFT Pose {
        translation 0.0374 0.2586 0.09425
        children [
          Box {
            size 0.35 0.04 0.0925
          }
        ]
      }
      DEF BOTTOM_RIGHT Pose {
        translation 0.0374 -0.2476 0.09425
        children [
          Box {
            size 0.35 0.04 0.0925
          }
        ]
      }
      DEF BOTTOM_CENTER Pose {
        translation 0.0375 0.0005 0.094
        children [
          Box {
            size 0.857 0.2 0.092
          }
        ]
      }
    ]
  }
  physics Physics {
    density -1
    mass 5
  }
  controller "mir100"
  linearVelocity 2.0605403359604476e-09 -1.2549659784473794e-09 -2.7110223129218133e-11
  angularVelocity 4.633806059739545e-11 -6.103217715272741e-11 2.615240288658521e-09
}
