#VRML_SIM R2025a utf8

EXTERNPROTO "https://raw.githubusercontent.com/cyberbotics/webots/R2025a/projects/objects/backgrounds/protos/TexturedBackground.proto"
EXTERNPROTO "https://raw.githubusercontent.com/cyberbotics/webots/R2025a/projects/objects/backgrounds/protos/TexturedBackgroundLight.proto"
EXTERNPROTO "https://raw.githubusercontent.com/cyberbotics/webots/R2025a/projects/objects/floors/protos/RectangleArena.proto"
EXTERNPROTO "https://raw.githubusercontent.com/cyberbotics/webots/R2025a/projects/appearances/protos/Parquetry.proto"
EXTERNPROTO "../protos/ConveyorBelt.proto"
EXTERNPROTO "../protos/Pioneer3at.proto"
EXTERNPROTO "../protos/WoodenPallet.proto"
EXTERNPROTO "https://raw.githubusercontent.com/cyberbotics/webots/R2025a/projects/objects/factory/containers/protos/CardboardBox.proto"
EXTERNPROTO "https://raw.githubusercontent.com/cyberbotics/webots/R2025a/projects/objects/factory/containers/protos/PlasticFruitBox.proto"
EXTERNPROTO "https://raw.githubusercontent.com/cyberbotics/webots/R2025a/projects/objects/factory/manhole/protos/SquareManhole.proto"
EXTERNPROTO "https://raw.githubusercontent.com/cyberbotics/webots/R2025a/projects/objects/traffic/protos/SignPole.proto"
EXTERNPROTO "https://raw.githubusercontent.com/cyberbotics/webots/R2025a/projects/objects/traffic/protos/DirectionPanel.proto"
EXTERNPROTO "https://raw.githubusercontent.com/cyberbotics/webots/R2025a/projects/humans/pedestrian/protos/Pedestrian.proto"
EXTERNPROTO "https://raw.githubusercontent.com/cyberbotics/webots/R2025a/projects/appearances/protos/Plastic.proto"
EXTERNPROTO "https://raw.githubusercontent.com/cyberbotics/webots/R2025a/projects/robots/mir/mir100/protos/Mir100UltrasonicSensor.proto"
EXTERNPROTO "https://raw.githubusercontent.com/cyberbotics/webots/R2025a/projects/appearances/protos/CorrodedMetal.proto"
EXTERNPROTO "https://raw.githubusercontent.com/cyberbotics/webots/R2025a/projects/objects/solids/protos/SolidTorus.proto"

WorldInfo {
}
Viewpoint {
  orientation 0.6750774008206842 0.1896932240613553 0.7129424827055812 3.5370243366982503
  position 2.4353391497839727 3.4761377448141095 -2.604358822885368
  follow "Pioneer 3-AT_0"
  followType "None"
}
TexturedBackground {
}
TexturedBackgroundLight {
}
DEF rectangle_arena RectangleArena {
  translation 15.1304 9.85552 0
  floorSize 30 20
  floorTileSize 1 1
  floorAppearance Parquetry {
    type "dark strip"
  }
}
Pedestrian {
  translation 11.06 7.31002 1.27
  rotation 0 0 1 -3.1415853071795863
}
Pedestrian {
  translation 16.3842 17.72 1.28
  rotation 0 0 1 -0.523595307179586
  name "pedestrian(1)"
}
Pedestrian {
  translation 26.7331 5.34865 1.28
  rotation 0 0 -1 1.5708
  name "pedestrian(2)"
}
SignPole {
  translation 25.3498 15.6897 0
  rotation 0 0 1 3.14159
  height 1
  signBoards [
    DirectionPanel {
      translation 0 0 -0.86
      width 0.4
      height 0.2
    }
  ]
}
PlasticFruitBox {
  translation 28.2254 1.86879 0.63
  rotation 0 0 1 0.261799
  color 0.371527 0.966171 0.557473
}
DEF left_big_conveyor_belt_5 ConveyorBelt {
  hidden translation_1 0 0 1.1218692545854252
  translation 17.8 15 0
  rotation 0 0 -1 0
  size 1 5 1.5
}
DEF left_big_conveyor_belt_6 ConveyorBelt {
  hidden translation_1 7.105427357601002e-15 -3.552713678800501e-15 1.1218692545854236
  translation 21 15 0
  rotation 0 0 -1 0
  name "conveyor belt(11)"
  size 1 5 1.5
}
DEF left_big_conveyor_belt_6 ConveyorBelt {
  hidden translation_1 -0.0003848911937467392 2.1388581966874654e-05 1.1469136957119617
  hidden rotation_1 -0.007108017828594725 0.999974682844138 -0.0003312903771018675 0.006046461441891239
  translation 28.88 15 0
  rotation 0 0 -1 0
  name "conveyor belt(25)"
  size 1 5 1.5
}
DEF left_small_conveyor_belt_4 ConveyorBelt {
  hidden translation_1 0 0 0.7468692547768551
  translation 13.33 14.5 0
  rotation 0 0 -1 0
  name "conveyor belt(3)"
  size 1 4 1
}
DEF left_big_conveyor_belt_4 ConveyorBelt {
  hidden translation_1 0 0 1.1218692545854252
  translation 14.5 15 0
  rotation 0 0 -1 0
  name "conveyor belt(4)"
  size 1 5 1.5
}
DEF left_small_conveyor_belt_5 ConveyorBelt {
  hidden translation_1 0 0 0.7468692545856718
  translation 16.6 14.5 0
  rotation 0 0 -1 0
  name "conveyor belt(1)"
  size 1 4 1
}
DEF left_small_conveyor_belt_6 ConveyorBelt {
  hidden translation_1 0 0 0.7468692545854173
  translation 19.8 14.5 0
  rotation 0 0 -1 0
  name "conveyor belt(10)"
  size 1 4 1
}
DEF right_small_conveyor_belt_6 ConveyorBelt {
  hidden translation_1 0 0 0.7468692545854173
  translation 23 6 0
  rotation 0 0 -1 0
  name "conveyor belt(2)"
  size 1 4 1
}
DEF right_big_conveyor_belt_6 ConveyorBelt {
  hidden translation_1 0 0 1.1218692545854252
  translation 21.8 5.5 0
  rotation 0 0 -1 0
  name "conveyor belt(5)"
  size 1 5 1.5
}
ConveyorBelt {
  hidden translation_1 0 0 0.44686925458541193
  translation 27.8449 2.58127 0
  rotation 0 0 -1 0
  name "conveyor belt(12)"
  size 4 4 0.6
}
DEF right_small_conveyor_belt_5 ConveyorBelt {
  hidden translation_1 0 0 0.7468692545854173
  translation 19.8 6 0
  rotation 0 0 -1 0
  name "conveyor belt(6)"
  size 1 4 1
}
WoodenPallet {
  translation 22.5 8.7 0
  size 2 1 0.1
}
WoodenPallet {
  translation 19 8.7 0
  name "wooden pallet(1)"
  size 2 1 0.1
}
WoodenPallet {
  translation 9.4 8.7 0
  name "wooden pallet(6)"
  size 2 1 0.1
}
WoodenPallet {
  translation 17 11.9 0
  name "wooden pallet(2)"
  size 2 1 0.1
}
WoodenPallet {
  translation 10.73 11.9 0
  name "wooden pallet(3)"
  size 2 1 0.1
}
WoodenPallet {
  translation 7.5 11.9 0
  name "wooden pallet(5)"
  size 2 1 0.1
}
WoodenPallet {
  translation 4.5 11.9 0
  name "wooden pallet(4)"
  size 2 1 0.1
}
DEF right_big_conveyor_belt_5 ConveyorBelt {
  hidden translation_1 0 0 1.1218692545854252
  translation 18.5 5.5 0
  rotation 0 0 -1 0
  name "conveyor belt(7)"
  window "<none>"
  size 1 5 1.5
}
DEF right_small_conveyor_belt_4 ConveyorBelt {
  hidden translation_1 0 0 0.7468692545854173
  translation 16.46 6 0
  rotation 0 0 -1 0
  name "conveyor belt(8)"
  window "<none>"
  size 1 4 1
}
DEF right_small_conveyor_belt_3 ConveyorBelt {
  hidden translation_1 0 0 0.7468692547500313
  translation 13.22 6 0
  rotation 0 0 -1 0
  name "conveyor belt(14)"
  window "<none>"
  size 1 4 1
}
DEF left_small_conveyor_belt_2 ConveyorBelt {
  hidden translation_1 0 0 0.7468692545854173
  translation 6.9 14.5 0
  rotation 0 0 -1 0
  name "conveyor belt(21)"
  size 1 4 1
}
DEF left_small_conveyor_belt_1 ConveyorBelt {
  hidden translation_1 0 0 0.7468692545854173
  translation 3.7 14.5 0
  rotation 0 0 -1 0
  name "conveyor belt(23)"
  size 1 4 1
}
DEF left_small_conveyor_belt_3 ConveyorBelt {
  hidden translation_1 0 0 0.7468692545854173
  translation 10.1 14.5 0
  rotation 0 0 -1 0
  name "conveyor belt(19)"
  size 1 4 1
}
DEF right_small_conveyor_belt_2 ConveyorBelt {
  hidden translation_1 0 0 0.7468692545854173
  translation 10 6 0
  rotation 0 0 -1 0
  name "conveyor belt(15)"
  size 1 4 1
}
DEF right_small_conveyor_belt_1 ConveyorBelt {
  hidden translation_1 1.7763568394002505e-15 1.7763568394002505e-15 0.7468692545854169
  translation 7 6 0
  rotation 0 0 -1 0
  name "conveyor belt(17)"
  size 1 4 1
}
DEF right_big_conveyor_belt_4 ConveyorBelt {
  hidden translation_1 0 0 1.1218692545854252
  translation 15.3 5.5 0
  rotation 0 0 -1 0
  name "conveyor belt(9)"
  size 1 5 1.5
}
DEF right_big_conveyor_belt_3 ConveyorBelt {
  hidden translation_1 0 0 1.1218692545854252
  translation 12 5.5 0
  rotation 0 0 -1 0
  name "conveyor belt(13)"
  size 1 5 1.5
}
DEF left_big_conveyor_belt_3 ConveyorBelt {
  hidden translation_1 0 0 1.1218692545854252
  translation 11.3 15 0
  rotation 0 0 -1 0
  name "conveyor belt(20)"
  size 1 5 1.5
}
DEF left_big_conveyor_belt_2 ConveyorBelt {
  hidden translation_1 0 0 1.1218692545854252
  translation 8.1 15 0
  rotation 0 0 -1 0
  name "conveyor belt(22)"
  size 1 5 1.5
}
DEF left_big_conveyor_belt_1 ConveyorBelt {
  hidden translation_1 0 0 1.1218692545854252
  translation 4.9 15 0
  rotation 0 0 -1 0
  name "conveyor belt(24)"
  size 1 5 1.5
}
DEF right_big_conveyor_belt_2 ConveyorBelt {
  hidden translation_1 0 0 1.1218692545854252
  translation 8.8 5.5 0
  rotation 0 0 -1 0
  name "conveyor belt(16)"
  size 1 5 1.5
}
DEF right_big_conveyor_belt_1 ConveyorBelt {
  hidden translation_1 -9.488717160177629e-05 -0.0008011680417192579 1.1297968020331954
  hidden rotation_1 0.9966346016118166 -0.08196245748030113 0.001275317154822441 0.007025254798688431
  translation 5.8 5.5 0
  rotation 0 0 -1 0
  name "conveyor belt(18)"
  size 1 5 1.5
}
CardboardBox {
  translation 27.8384 3.01098 0.71
  rotation 0 0 1 0.261799
  size 0.2 0.2 0.2
}
CardboardBox {
  translation 28.0224 3.48865 0.71
  rotation 0 0 1 0.785398
  name "cardboard box(1)"
  size 0.2 0.2 0.2
}
CardboardBox {
  translation 21.6903 3.22499 1.6
  rotation 0 0 1 1.309
  name "cardboard box(6)"
  size 0.2 0.2 0.2
}
CardboardBox {
  translation 7.98736 14.1014 1.6
  rotation 0 0 1 1.309
  name "cardboard box(7)"
  size 0.2 0.2 0.2
}
CardboardBox {
  translation 15.3336 4.18682 1.6
  rotation 0 0 1 2.0944
  name "cardboard box(10)"
  size 0.2 0.2 0.2
}
CardboardBox {
  translation 11.2185 13.9355 1.6
  rotation 0 0 1 2.0944
  name "cardboard box(11)"
  size 0.2 0.2 0.2
}
CardboardBox {
  translation 4.6953 16.4739 1.6
  rotation 0 0 1 2.0944
  name "cardboard box(12)"
  size 0.2 0.2 0.2
}
CardboardBox {
  translation 5.94515 4.74132 1.6
  rotation 0 0 1 1.309
  name "cardboard box(9)"
  size 0.2 0.2 0.2
}
CardboardBox {
  translation 26.2061 1.6839 0.71
  rotation 0 0 1 1.309
  name "cardboard box(8)"
  size 0.2 0.2 0.2
}
CardboardBox {
  translation 28.3211 1.96902 0.77
  rotation 0 0 1 4.692820414042842e-06
  name "cardboard box(5)"
  size 0.2 0.2 0.2
}
CardboardBox {
  translation 28.0496 3.95362 0.71
  rotation 0 0 1 0.261803
  name "cardboard box(2)"
  size 0.2 0.2 0.2
}
CardboardBox {
  translation 18.9049 8.5223 0.11
  rotation 0 0 1 1.5708
  name "cardboard box(4)"
  size 0.2 0.2 0.2
}
CardboardBox {
  translation 20.9849 7.7223 0.11
  rotation 0 0 1 1.5708
  name "cardboard box(13)"
  size 0.2 0.2 0.2
}
CardboardBox {
  translation 17.3949 8.2323 0.11
  rotation 0 0 1 1.5708
  name "cardboard box(16)"
  size 0.2 0.2 0.2
}
CardboardBox {
  translation 18.6349 12.5223 0.11
  rotation 0 0 1 1.5708
  name "cardboard box(17)"
  size 0.2 0.2 0.2
}
CardboardBox {
  translation 17.0749 12.4123 0.11
  rotation 0 0 1 1.5708
  name "cardboard box(18)"
  size 0.2 0.2 0.2
}
CardboardBox {
  translation 24.9049 4.5023 0.11
  rotation 0 0 1 1.5708
  name "cardboard box(15)"
  size 0.2 0.2 0.2
}
CardboardBox {
  translation 24.3649 4.5123 0.11
  rotation 0 0 1 1.5708
  name "cardboard box(14)"
  size 0.2 0.2 0.2
}
CardboardBox {
  translation 22.6249 18.7445 0.15
  rotation 0 0 1 4.07987e-06
  name "cardboard box(3)"
  size 0.2 0.2 0.2
}
Pose {
}
DEF SUPERVISOR Robot {
  rotation 0 0 1 -2.8797853071795863
  controller "floor_mapper"
  supervisor TRUE
}
DEF Pioneer_3-AT Pioneer3at {
  hidden position_0_0 17181.67559809793
  hidden position_0_1 14901.686230776273
  hidden position_0_2 17201.27376671953
  hidden position_0_3 14922.746012854139
  hidden linearVelocity_0 2.4707773146064783e-15 -7.201901194949197e-16 -6.201100239360875e-16
  hidden angularVelocity_0 6.452871828255895e-15 2.294478874205686e-14 -3.6672539574362586e-19
  hidden rotation_1 0.5773516024134749 -0.5773476024162304 -0.5773516027299337 2.094404999683543
  hidden translation_2 4.390430234023778e-13 2.1847962280823109e-13 0.04999999999999215
  hidden rotation_2 -0.42526537133496617 0.425258256650912 -0.7989397843977734 1.7934126943521096
  hidden rotation_3 0.5988398296672657 -0.5988354524500358 -0.5317771707144274 2.164114403451273
  hidden linearVelocity_3 4.343192474113233e-15 -1.2867484851803274e-15 2.522431401161742e-15
  hidden angularVelocity_3 6.8273387235816924e-15 2.3292771730681934e-14 3.0837041138178813e-15
  hidden rotation_4 -0.31157830343253634 0.31157814042936155 0.8976848128584349 4.604650244039555
  hidden linearVelocity_4 4.314326677295917e-15 -1.2357892487044761e-14 2.7711107241356093e-15
  hidden angularVelocity_4 6.5706065605445605e-15 2.3481021336411744e-14 1.062428686439461e-15
  hidden rotation_5 0.08193834394784771 -0.08193411524610296 0.9932637658496973 4.705619954792564
  hidden linearVelocity_5 3.954614412739284e-15 -1.1690648445261208e-15 -4.192211812194625e-15
  hidden angularVelocity_5 6.549062035918629e-15 2.331289200858154e-14 3.4290143920002054e-16
  hidden rotation_6 -0.37949232768359653 0.37949127938687893 0.8437842983242787 4.543329843370436
  hidden linearVelocity_6 3.954614411251747e-15 -1.1590728369590726e-15 -3.4461359099901676e-15
  hidden angularVelocity_6 7.142252227336979e-15 2.315794811058125e-14 1.7512737986056797e-15
  translation 22.01631079215965 10.637760023902711 0.2882854427933956
  rotation 0.9904942647239363 -0.1341890232982286 -0.0302393382079711 -3.1331104879515514
  name "Pioneer 3-AT_0"
  controller "pioneer_controller"
}
DEF Pioneer_3-AT Pioneer3at {
  hidden position_0_0 17180.781321947627
  hidden position_0_1 14902.01285480507
  hidden position_0_2 17201.443179414982
  hidden position_0_3 14923.747408770774
  hidden linearVelocity_0 1.4046434063530423e-14 -7.0213721200832165e-16 -5.1675835328007286e-17
  hidden angularVelocity_0 -5.94108086678947e-16 -1.0875917894869038e-15 -3.198793649313463e-15
  hidden rotation_1 0.5773516024134749 -0.5773476024162304 -0.5773516027299337 2.094404999683543
  hidden translation_2 4.390430234023778e-13 2.1847962280823109e-13 0.04999999999999215
  hidden rotation_2 -0.42526537133496617 0.425258256650912 -0.7989397843977734 1.7934126943521096
  hidden rotation_3 0.6930327462433039 -0.6930262610765671 -0.198545244447452 2.7496084098673648
  hidden linearVelocity_3 2.3397279353754248e-14 5.12638773394294e-15 -2.1316914731066522e-16
  hidden angularVelocity_3 5.498692389526887e-15 4.7530413591544525e-15 2.9214718105286966e-16
  hidden rotation_4 -0.1675380743654616 0.1675396511740949 0.9715253259294765 4.683494140006329
  hidden linearVelocity_4 -2.803485789855869e-15 -8.183680044220022e-15 2.1314042685646933e-16
  hidden angularVelocity_4 4.601903093240715e-15 2.3936435057933134e-15 3.744468041218418e-16
  hidden rotation_5 0.163988309021644 -0.16398330237878428 0.9727370204968916 4.684741233896604
  hidden linearVelocity_5 -1.012632018609256e-14 6.8335559812667786e-15 -3.552618089486457e-16
  hidden angularVelocity_5 7.350745702387809e-15 -2.283310811284546e-15 3.533042307529979e-16
  hidden rotation_6 0.07773646867514306 -0.07773228109126905 0.9939389990911246 4.706299507798557
  hidden linearVelocity_6 -9.846196122818766e-15 -6.722845010746028e-15 -2.131412206656129e-16
  hidden angularVelocity_6 9.718438648907805e-15 -3.437030358223372e-15 3.888222649280744e-16
  translation 14.25670005546277 5.3048028824899545 -0.0023889310687115473
  rotation -2.473697490435673e-05 2.4823256289216306e-05 0.9999999993859441 1.5554589556763545
  name "Pioneer 3-AT_1"
  controller "pioneer_controller_1"
}
DEF Pioneer_3-AT Pioneer3at {
  hidden position_0_0 17180.45444094907
  hidden position_0_1 14901.65404510919
  hidden position_0_2 17201.222969832175
  hidden position_0_3 14923.432881459044
  hidden linearVelocity_0 4.903039779735607e-15 5.3119760624547205e-15 5.1675835328007286e-17
  hidden angularVelocity_0 -2.999636780218424e-18 -1.1726114014653636e-15 3.610465866076209e-15
  hidden rotation_1 0.5773516024134749 -0.5773476024162304 -0.5773516027299337 2.094404999683543
  hidden translation_2 4.390430234023778e-13 2.1847962280823109e-13 0.04999999999999215
  hidden rotation_2 -0.42526537133496617 0.425258256650912 -0.7989397843977734 1.7934126943521096
  hidden rotation_3 0.7047397817701656 -0.70473277816839 -0.08181412693173613 2.9783344720419516
  hidden linearVelocity_3 1.5845395843414833e-14 -2.4603249952572287e-14 -7.103459112687361e-17
  hidden angularVelocity_3 2.3514750320736773e-15 -4.824843574095176e-15 4.642665346886387e-15
  hidden rotation_4 -0.3244969147682329 0.3244965869466565 0.8884839432234378 4.594413325595592
  hidden linearVelocity_4 -1.6726925817421507e-14 -2.412292621817666e-14 -7.10572473651969e-17
  hidden angularVelocity_4 -2.351485144141137e-15 -1.4711894088674524e-15 5.665885786013452e-15
  hidden rotation_5 0.05678674498939195 -0.05678276424313892 0.9967702760809123 4.709143896136586
  hidden linearVelocity_5 1.5796931744664932e-14 2.4173513417400622e-14 -6.394809650834001e-16
  hidden angularVelocity_5 2.528840713145124e-20 -5.77345281290895e-15 3.947599104176994e-15
  hidden rotation_6 -0.07888263816483002 0.07888520676445579 0.9937578445224396 4.706116698849027
  hidden linearVelocity_6 -1.732979055361818e-14 2.391551105057317e-14 -4.2631473590076354e-16
  hidden angularVelocity_6 2.351541661891122e-15 -9.748950202250662e-15 5.040053838021626e-15
  translation 10.682302288535084 9.696709989610238 -0.0023889310679025
  rotation -0.007212908200199894 0.999957869285015 -0.005677465127019252 4.917999803718067e-05
  name "Pioneer 3-AT_2"
  controller "pioneer_controller_2"
}
DEF Pioneer_3-AT Pioneer3at {
  hidden position_0_0 17180.45440433309
  hidden position_0_1 14901.654010314513
  hidden position_0_2 17201.223057712756
  hidden position_0_3 14923.43297087398
  hidden linearVelocity_0 9.058512305159072e-15 -5.7475005920428006e-15 1.0335167065601457e-16
  hidden angularVelocity_0 -2.1651111793317456e-15 1.8544969708638532e-19 -6.06495037472125e-16
  hidden rotation_1 0.5773516024134749 -0.5773476024162304 -0.5773516027299337 2.094404999683543
  hidden translation_2 4.390430234023778e-13 2.1847962280823109e-13 0.04999999999999215
  hidden rotation_2 -0.42526537133496617 0.425258256650912 -0.7989397843977734 1.7934126943521096
  hidden rotation_3 0.7047405356781159 -0.7047335320243253 -0.08180113821116208 2.9783602765372024
  hidden linearVelocity_3 9.9889129387689e-15 -2.4548090608465165e-14 1.4210603328771304e-16
  hidden angularVelocity_3 7.054458073442969e-15 -6.361322058811443e-15 -8.872268884763939e-16
  hidden rotation_4 -0.3245107442747025 0.3245104162758289 0.8884738412461939 4.594402034601044
  hidden linearVelocity_4 -9.91893583704873e-15 -2.3920435773162284e-14 1.4210177340980088e-16
  hidden angularVelocity_4 -2.351495759881151e-15 5.27096060802429e-16 -1.6362022919475369e-15
  hidden rotation_5 0.05683040192022518 -0.05682642073980483 0.9967653000197632 4.7091389041160205
  hidden linearVelocity_5 2.1228075613875894e-14 2.399721189422777e-14 7.815763553059548e-16
  hidden angularVelocity_5 2.2716480219246085e-20 -4.666759013056638e-15 -1.1465997446483698e-15
  hidden rotation_6 -0.07883848591779133 0.0788410549975084 0.9937648520576032 4.706123750390843
  hidden linearVelocity_6 -2.3794270720120017e-14 2.3680246668395632e-14 -2.1315688365841672e-16
  hidden angularVelocity_6 2.351558426248688e-15 -1.1941867436487941e-14 2.8935977729652267e-16
  translation 7.891714683018399 9.70053001525625 -0.0023889310679026388
  rotation -0.007210540047359765 0.9997304710636026 -0.022067925574755873 4.919118464048144e-05
  name "Pioneer 3-AT_3"
  controller "pioneer_controller_3"
}
SquareManhole {
  translation 25 19 0
}
SquareManhole {
  translation 19.092 9.85948 -0.04
  rotation 0 0 1 0.523602
  name "manhole(16)"
}
SquareManhole {
  translation 20.7736 10.6536 -0.04
  rotation 0 0 1 0.785401
  name "manhole(17)"
}
SquareManhole {
  translation 9.00273 10.7778 -0.02
  rotation 0 0 1 1.5708
  name "manhole(12)"
}
SquareManhole {
  translation 4.9337 9.8387 -0.04
  rotation 9.58978e-09 3.57898e-08 1 -0.523595307179586
  name "manhole(11)"
}
WoodenPallet {
  translation 6 8.7 0
  name "wooden pallet(7)"
  size 2 1 0.1
}
WoodenPallet {
  translation 12.72 8.7 0
  name "wooden pallet(8)"
  size 2 1 0.1
}
WoodenPallet {
  translation 15.74 8.7 0
  name "wooden pallet(9)"
  size 2 1 0.1
}
WoodenPallet {
  translation 13.93 11.89 0
  name "wooden pallet(10)"
  size 2 1 0.1
}
WoodenPallet {
  translation 20.37 11.89 0
  name "wooden pallet(11)"
  size 2 1 0.1
}
Robot {
  translation 2.286230558698363 3.420916810110604 -0.013703896563691392
  rotation -0.0008258978501502972 0.018754048060925465 0.999823786261394 0.5987433103183056
  children [
    Pose {
      translation 0.037646 0 0
      children [
        Shape {
          appearance DEF WHITE Plastic {
          }
          geometry Mesh {
            url [
              "https://raw.githubusercontent.com/cyberbotics/webots/R2025a/projects/robots/mir/mir100/protos/meshes/mir_100_base.obj"
            ]
          }
        }
        Shape {
          appearance USE WHITE
          geometry Mesh {
            url [
              "https://raw.githubusercontent.com/cyberbotics/webots/R2025a/projects/robots/mir/mir100/protos/meshes/mir_100_inside.obj"
            ]
          }
        }
        Shape {
          appearance Plastic {
            colorOverride 0.93 0.93 0.93
          }
          geometry Mesh {
            url [
              "https://raw.githubusercontent.com/cyberbotics/webots/R2025a/projects/robots/mir/mir100/protos/meshes/mir_100_logos.dae"
            ]
          }
        }
        Shape {
          appearance DEF BLACK Plastic {
            colorOverride 0 0 0
          }
          geometry Mesh {
            url [
              "https://raw.githubusercontent.com/cyberbotics/webots/R2025a/projects/robots/mir/mir100/protos/meshes/mir_100_base_corners.dae"
            ]
          }
        }
        Shape {
          appearance DEF BLACK Plastic {
            colorOverride 0 0 0
          }
          geometry Mesh {
            url [
              "https://raw.githubusercontent.com/cyberbotics/webots/R2025a/projects/robots/mir/mir100/protos/meshes/mir_100_top_plugs.dae"
            ]
          }
        }
      ]
    }
    DEF IMU Pose {
      translation 0 0 0.25
      children [
        Accelerometer {
          name "imu_data accelerometer"
          lookupTable [
            -100 -100 -0.002
            100 100 0.002
          ]
        }
        Gyro {
          name "imu_data gyro"
          lookupTable [
            -100 -100 -0.002
            100 100 0.002
          ]
        }
        Compass {
          name "imu_data compass"
          lookupTable [
            -1 -1 -0.2
            1 1 0.2
          ]
        }
      ]
    }
    Pose {
      translation 0.4288 0.2358 0.188
      rotation -0.9238797538373538 -0.38268289803626016 0 -3.14159
    }
    Pose {
      translation -0.3548 -0.2352 0.188
      rotation 0.38268289803626016 -0.9238797538373538 0 -3.14159
    }
    Pose {
      translation 0.037646 0 0.349
    }
    DEF DEPTH_CAMERA Transform {
      translation 0.042224 -0.273014 0.141194
      rotation 1 0 0 1.5708
      scale 4.00035 3.92893 3.92893
      children [
        Shape {
          appearance Appearance {
            material Material {
              emissiveColor 1 1 1
            }
            texture ImageTexture {
              url [
                "https://raw.githubusercontent.com/cyberbotics/webots/R2025a/projects/robots/mir/mir100/protos/textures/camera.png"
              ]
            }
            textureTransform TextureTransform {
              rotation 3.1415926
            }
          }
          geometry Plane {
            size 0.08 0.015
          }
        }
      ]
    }
    Mir100UltrasonicSensor {
      translation 0.415448 -0.108238 0.08
      rotation 0.8628559982596194 -0.35740699927911007 -0.35740699927911007 1.71777
      name "ds0"
      lookupTable [
        0.2 1000 0
        0.3 0 0
      ]
    }
    Mir100UltrasonicSensor {
      translation -0.3844 -0.1328 0.156
      rotation 0 0 1 3.141592653589793
      name "ds1"
    }
    Mir100UltrasonicSensor {
      translation -0.3844 0.1328 0.156
      rotation 0 0 1 3.141592653589793
      name "ds2"
    }
    Mir100UltrasonicSensor {
      translation 0.415448 0.108238 0.08
      rotation 0.8628559982596194 0.35740699927911007 0.35740699927911007 1.71777
      name "ds3"
      lookupTable [
        0.2 1000 0
        0.3 0 0
      ]
    }
    RangeFinder {
      translation 0.044 -0.28 0.18
      rotation 0 0 1 -1.5707953071795862
      name "depth_camera"
      fieldOfView 2.05949
      width 1280
      height 720
      minRange 0.18
      maxRange 1.95
    }
    Pose {
      translation 0.03733 0.0005 0.2085
      children [
        DEF LIGHT_FRONT Pose {
          translation 0.392 0 0
          children [
            DEF LIGHT_WIDTH_SHAPE Shape {
              appearance PBRAppearance {
                transparency 0.5
                emissiveColor 0 0.9 1
              }
              geometry Box {
                size 0.001 0.4723 0.053
              }
            }
          ]
        }
        DEF LIGHT_BACK Pose {
          translation -0.392 0 0
          children [
            USE LIGHT_WIDTH_SHAPE
          ]
        }
        DEF LIGHT_LEFT Pose {
          translation 0 0.2355 0
          children [
            DEF LIGHT_WIDTH_SHAPE Shape {
              appearance PBRAppearance {
                transparency 0.5
                emissiveColor 0 0.9 1
              }
              geometry Box {
                size 0.783 0.001 0.053
              }
            }
          ]
        }
        DEF LIGHT_RIGHT Pose {
          translation 0 -0.2355 0
          children [
            USE LIGHT_WIDTH_SHAPE
          ]
        }
      ]
    }
    DEF US_1_FRAME Solid {
      translation 0.45 -0.12 0.16
      name "us_1_frame"
    }
    DEF US_2_FRAME Solid {
      translation 0.45 0.12 0.16
      name "us_2_frame"
    }
    DEF LEFT_WHEEL_JOINT HingeJoint {
      jointParameters HingeJointParameters {
        position 122.53318010652302
        axis 0 1 0
        anchor 0 0.222604 0.0625
      }
      device [
        PositionSensor {
          name "middle_left_wheel_joint_sensor"
        }
      ]
      endPoint DEF LEFT_WHEEL_LINK Solid {
        translation 4.262561869171978e-06 0.2225758854174258 0.05707409494936599
        rotation -0.003911362492962478 -0.7070994311978304 -0.7071033132740602 3.133770005765406
        children [
          Group {
          }
        ]
        name "left_wheel_link"
        contactMaterial "wheel"
        boundingObject DEF WHEEL_BO Cylinder {
          height 0.01
          radius 0.0625
        }
        physics Physics {
          density -1
          mass 1
          centerOfMass [
            0 0 0
          ]
          inertiaMatrix [
            0.001061895 0.001953125 0.001061895
            0 0 5.457207e-20
          ]
        }
        linearVelocity -7.694312803812409e-05 9.863955989430906e-05 5.8122091567895495e-05
        angularVelocity 0.000290829846450909 6.061885495662706e-05 -2.363606578826624e-05
      }
    }
    DEF RIGHT_WHEEL_JOINT HingeJoint {
      jointParameters HingeJointParameters {
        position 39.27027170174256
        axis 0 1 0
        anchor 0 -0.222604 0.0625
      }
      device [
        PositionSensor {
          name "middle_right_wheel_joint_sensor"
        }
      ]
      endPoint DEF RIGHT_WHEEL_LINK Solid {
        translation 0.004242668322712093 -0.22269587362031196 0.06252235368070355
        rotation -0.5772138021654347 0.5774159257624097 0.5774210554401891 2.0946075350981697
        children [
          Group {
          }
        ]
        name "right_wheel_link"
        contactMaterial "wheel"
        boundingObject USE WHEEL_BO
        physics Physics {
          density -1
          mass 1
          centerOfMass [
            0 0 0
          ]
          inertiaMatrix [
            0.001061895 0.001953125 0.001061895
            0 0 5.457207e-20
          ]
        }
        linearVelocity -5.654316288808105e-05 4.914693620607856e-05 -5.335846689399639e-05
        angularVelocity 0.0009040466690242328 -0.000845098589303569 -2.6434782267763954e-05
      }
    }
    DEF FL_CASTER_ROTATION_JOINT HingeJoint {
      jointParameters HingeJointParameters {
        position 425.18352372158705
        axis 0 0 1
        anchor 0.341346 0.203 0.1565
        dampingConstant 0.01
      }
      device [
        RotationalMotor {
          name "front_left_wheel_joint"
          maxVelocity 100
          maxTorque 20
        }
        PositionSensor {
          name "front_left_caster_joint_sensor"
        }
      ]
      endPoint DEF FL_CASTER_ROTATION_LINK Solid {
        translation 0.34139549560250176 0.20341126876792426 0.1645007810335874
        rotation 0 0 -1 6.135139503665329
        children [
          DEF CASTER_WHEEL_BASE Shape {
            appearance PBRAppearance {
              baseColor 0.35 0.35 0.35
              roughness 1
              metalness 0
            }
            geometry Mesh {
              url [
                "https://raw.githubusercontent.com/cyberbotics/webots/R2025a/projects/robots/mir/mir100/protos/meshes/caster_wheel_base.dae"
              ]
            }
          }
          DEF FL_CASTER_WHEEL_JOINT HingeJoint {
            jointParameters HingeJointParameters {
              position 358.613360593196
              axis 0 1 0
              anchor -0.0382 0 -0.094
            }
            device [
              RotationalMotor {
                name "front_left_wheel"
                maxVelocity 100
                maxTorque 20
              }
              PositionSensor {
                name "front_left_wheel_joint_sensor"
              }
            ]
            endPoint DEF FL_CASTER_WHEEL_LINK Solid {
              translation -0.03844565142303016 -4.7259524189602216e-05 -0.09405911275040313
              rotation -0.48160145710731733 -0.619700194846149 -0.6197029167429776 2.243952044666369
              children [
                Group {
                  children [
                    DEF RIM Shape {
                      appearance CorrodedMetal {
                      }
                      geometry Cylinder {
                        height 0.032
                        radius 0.0465
                      }
                    }
                    SolidTorus {
                      translation 0 0 0
                      majorRadius 0.0465
                      minorRadius 0.016
                      appearance DEF WHEEL_RUBBER PBRAppearance {
                        baseColor 0 0 0
                        roughness 1
                        metalness 0
                      }
                      enableBoundingObject FALSE
                    }
                  ]
                }
              ]
              name "fl_caster_wheel_link"
              contactMaterial "wheel"
              boundingObject USE WHEEL_BO
              physics Physics {
                density -1
                mass 1
                centerOfMass [
                  0 0 0
                ]
                inertiaMatrix [
                  0.001061895 0.001953125 0.001061895
                  0 0 5.457207e-20
                ]
              }
              linearVelocity 1.0311866307673778e-05 -8.967837158161273e-05 4.860399341106358e-05
              angularVelocity 0.00021224463409443781 0.00014863929361746622 -2.7712204814331146e-05
            }
          }
        ]
        name "fl_caster_rotation_link"
        boundingObject Pose {
          translation 0 0 -0.028
          children [
            DEF SWIVEL Cylinder {
              height 0.055
              radius 0.0298
            }
          ]
        }
        physics Physics {
          density -1
          mass 0.309754
          centerOfMass [
            0 0 -0.0425
          ]
          inertiaMatrix [
            0.0005287255 0.000517415 0.0002462724
            -7.734275e-21 -1.120566e-20 -0.0001505672
          ]
        }
        linearVelocity 8.548665238803924e-06 -5.731394395671684e-05 5.067916525546884e-05
        angularVelocity 0.00020985396406436428 0.00015483544817585917 -2.7695454748600035e-05
      }
    }
    DEF FR_CASTER_ROTATION_JOINT HingeJoint {
      jointParameters HingeJointParameters {
        position 526.3896593639514
        axis 0 0 1
        anchor 0.341346 -0.203 0.1565
        dampingConstant 0.01
      }
      device [
        RotationalMotor {
          name "front_right_wheel_joint"
          maxVelocity 100
          maxTorque 20
        }
        PositionSensor {
          name "front_right_caster_joint_sensor"
        }
      ]
      endPoint DEF FR_CASTER_ROTATION_LINK Solid {
        translation 0.34150699166871157 -0.20303529844287763 0.16409093943828093
        rotation 0 0 -0.9999999999999999 6.135106297313539
        children [
          USE CASTER_WHEEL_BASE
          DEF FR_CASTER_WHEEL_JOINT HingeJoint {
            jointParameters HingeJointParameters {
              position 407.55500581447905
              axis 0 1 0
              anchor -0.0382 0 -0.094
            }
            device [
              RotationalMotor {
                name "front_right_wheel"
                maxVelocity 100
                maxTorque 20
              }
              PositionSensor {
                name "front_right_wheel_joint_sensor"
              }
            ]
            endPoint DEF FR_CASTER_WHEEL_LINK Solid {
              translation -0.0382 0 -0.094
              rotation 0.8415882459810549 0.38192155781342346 0.38192296069220494 4.5407696173737495
              children [
                Group {
                  children [
                    USE RIM
                    SolidTorus {
                      translation 0 0 0
                      majorRadius 0.0465
                      minorRadius 0.016
                      appearance USE WHEEL_RUBBER
                      enableBoundingObject FALSE
                    }
                  ]
                }
              ]
              name "fr_caster_wheel_link"
              contactMaterial "wheel"
              boundingObject USE WHEEL_BO
              physics Physics {
                density -1
                mass 1
                centerOfMass [
                  0 0 0
                ]
                inertiaMatrix [
                  0.001061895 0.001953125 0.001061895
                  0 0 5.457207e-20
                ]
              }
              linearVelocity 6.199955620766673e-05 -8.403295523197585e-05 -5.574361078123502e-05
              angularVelocity 0.00020880417016558512 0.00014724906365472723 -2.9984199275276987e-05
            }
          }
        ]
        name "fr_caster_rotation_link"
        boundingObject Pose {
          translation 0 0 -0.028
          children [
            USE SWIVEL
          ]
        }
        physics Physics {
          density -1
          mass 0.309754
          centerOfMass [
            0 0 -0.0425
          ]
          inertiaMatrix [
            0.0005287255 0.000517415 0.0002462724
            -7.734275e-21 -1.120566e-20 -0.0001505672
          ]
        }
        linearVelocity 3.0344571488428056e-05 -5.7022417876033165e-05 -5.5669208438741776e-05
        angularVelocity 0.00021054634321956414 0.00015047181453126246 -2.99814351522324e-05
      }
    }
    DEF BL_CASTER_ROTATION_JOINT HingeJoint {
      jointParameters HingeJointParameters {
        position -3.941490333040969
        axis 0 0 1
        anchor -0.270154 0.203 0.1565
        dampingConstant 0.01
      }
      device [
        RotationalMotor {
          name "back_left_wheel_joint"
          maxVelocity 100
          maxTorque 20
        }
        PositionSensor {
          name "back_left_caster_joint_sensor"
        }
      ]
      endPoint DEF BL_CASTER_ROTATION_LINK Solid {
        translation -0.270159304153634 0.20298101972028404 0.16198790307477856
        rotation 0 0 -1 6.13509777324223
        children [
          USE CASTER_WHEEL_BASE
          DEF BL_CASTER_WHEEL_JOINT HingeJoint {
            jointParameters HingeJointParameters {
              position 456.7406597959681
              axis 0 1 0
              anchor -0.0382 0 -0.094
            }
            device [
              RotationalMotor {
                name "back_left_wheel"
                maxVelocity 100
                maxTorque 20
              }
              PositionSensor {
                name "back_left_wheel_joint_sensor"
              }
            ]
            endPoint DEF BL_CASTER_WHEEL_LINK Solid {
              translation -0.0382 0 -0.094
              rotation 0.43916246969371575 0.6352689825716574 0.6352713160492038 3.9691998964656006
              children [
                Group {
                  children [
                    USE RIM
                    SolidTorus {
                      translation 0 0 0
                      majorRadius 0.0465
                      minorRadius 0.016
                      appearance USE WHEEL_RUBBER
                      enableBoundingObject FALSE
                    }
                  ]
                }
              ]
              name "bl_caster_wheel_link"
              contactMaterial "wheel"
              boundingObject USE WHEEL_BO
              physics Physics {
                density -1
                mass 1
                centerOfMass [
                  0 0 0
                ]
                inertiaMatrix [
                  0.001061895 0.001953125 0.001061895
                  0 0 5.457207e-20
                ]
              }
              linearVelocity 1.1979686218866803e-05 -3.090069694435016e-05 5.264581660941303e-05
              angularVelocity 0.0002131021219001718 0.00015217661081269815 -2.4435151408660876e-05
            }
          }
        ]
        name "bl_caster_rotation_link"
        boundingObject Pose {
          translation 0 0 -0.028
          children [
            USE SWIVEL
          ]
        }
        physics Physics {
          density -1
          mass 0.309754
          centerOfMass [
            0 0 -0.0425
          ]
          inertiaMatrix [
            0.0005287255 0.000517415 0.0002462724
            -7.734275e-21 -1.120566e-20 -0.0001505672
          ]
        }
        linearVelocity 5.625568909945788e-06 -2.245615057118483e-05 5.489430341592248e-05
        angularVelocity 0.0002133774117692389 0.00015415557733984212 -2.4429798366223344e-05
      }
    }
    DEF BR_CASTER_ROTATION_JOINT HingeJoint {
      jointParameters HingeJointParameters {
        position 8.482170901401094
        axis 0 0 1
        anchor -0.270154 -0.203 0.1565
        dampingConstant 0.01
      }
      device [
        RotationalMotor {
          name "back_right_wheel_joint"
          maxVelocity 100
          maxTorque 20
        }
        PositionSensor {
          name "back_right_caster_joint_sensor"
        }
      ]
      endPoint DEF BR_CASTER_ROTATION_LINK Solid {
        translation -0.2700940927347334 -0.20299251295386214 0.16089369854269187
        rotation 0 0 -1 6.135090102062543
        children [
          USE CASTER_WHEEL_BASE
          DEF BR_CASTER_WHEEL_JOINT HingeJoint {
            jointParameters HingeJointParameters {
              position 458.42012123476286
              axis 0 1 0
              anchor -0.0382 0 -0.094
            }
            device [
              RotationalMotor {
                name "back_right_wheel"
                maxVelocity 100
                maxTorque 20
              }
              PositionSensor {
                name "back_right_wheel_joint_sensor"
              }
            ]
            endPoint DEF BR_CASTER_WHEEL_LINK Solid {
              translation -0.0382 0 -0.094
              rotation 0.9842807475332558 0.12488253573444368 0.12488299445445045 4.696541860415688
              children [
                Group {
                  children [
                    USE RIM
                    SolidTorus {
                      translation 0 0 0
                      majorRadius 0.0465
                      minorRadius 0.016
                      appearance USE WHEEL_RUBBER
                      enableBoundingObject FALSE
                    }
                  ]
                }
              ]
              name "br_caster_wheel_link"
              contactMaterial "wheel"
              boundingObject USE WHEEL_BO
              physics Physics {
                density -1
                mass 1
                centerOfMass [
                  0 0 0
                ]
                inertiaMatrix [
                  0.001061895 0.001953125 0.001061895
                  0 0 5.457207e-20
                ]
              }
              linearVelocity 3.730758988245952e-05 -7.025587548764634e-05 -5.1464633503371716e-05
              angularVelocity 0.000209968167289365 0.00014791490972452972 -2.792447256577823e-05
            }
          }
        ]
        name "br_caster_rotation_link"
        boundingObject Pose {
          translation 0 0 -0.028
          children [
            USE SWIVEL
          ]
        }
        physics Physics {
          density -1
          mass 0.309754
          centerOfMass [
            0 0 -0.0425
          ]
          inertiaMatrix [
            0.0005287255 0.000517415 0.0002462724
            -7.734275e-21 -1.120566e-20 -0.0001505672
          ]
        }
        linearVelocity 1.4236753118579265e-05 -4.459035835523618e-05 -5.133401999091282e-05
        angularVelocity 0.00021065474249057527 0.00015165058535331942 -2.7915810402581633e-05
      }
    }
    DEF SURFACE Solid {
      translation 0.037646 0 0.352
      name "surface"
    }
  ]
  name "Mir100"
  model "Mobile Industrial Robots' MiR100"
  boundingObject Group {
    children [
      DEF TOP Pose {
        translation 0.0375 0.0005 0.334
        children [
          Box {
            size 0.774 0.461 0.04
          }
        ]
      }
      DEF MIDDLE_CENTER Pose {
        translation 0.0375 0.0005 0.262
        children [
          Box {
            size 0.857 0.44 0.096
          }
        ]
      }
      DEF MIDDLE_RIGHT_SIDE Pose {
        translation 0.0375 -0.25 0.262
        children [
          Box {
            size 0.774 0.041 0.096
          }
        ]
      }
      DEF MIDDLE_LEFT_SIDE Pose {
        translation 0.0375 0.25 0.262
        children [
          Box {
            size 0.774 0.041 0.096
          }
        ]
      }
      DEF CYL_BR Pose {
        translation -0.3555 -0.2353 0.262
        children [
          Cylinder {
            height 0.096
            radius 0.054
          }
        ]
      }
      DEF CYL_FL Pose {
        translation 0.4306 0.2364 0.262
        children [
          Cylinder {
            height 0.096
            radius 0.054
          }
        ]
      }
      DEF CYL_FR Pose {
        translation 0.415 -0.221 0.262
        children [
          Cylinder {
            height 0.096
            radius 0.049
          }
        ]
      }
      DEF CYL_BL Pose {
        translation -0.341 0.222 0.262
        children [
          Cylinder {
            height 0.096
            radius 0.049
          }
        ]
      }
      DEF MIDLOW Pose {
        translation 0.03733 0.0005 0.204
        children [
          Box {
            size 0.7806 0.4665 0.04
          }
        ]
      }
      DEF LOW Pose {
        translation 0.0374 0.0005 0.16
        children [
          Box {
            size 0.85 0.536 0.039
          }
        ]
      }
      DEF BOTTOM_LEFT Pose {
        translation 0.0374 0.2586 0.09425
        children [
          Box {
            size 0.35 0.04 0.0925
          }
        ]
      }
      DEF BOTTOM_RIGHT Pose {
        translation 0.0374 -0.2476 0.09425
        children [
          Box {
            size 0.35 0.04 0.0925
          }
        ]
      }
      DEF BOTTOM_CENTER Pose {
        translation 0.0375 0.0005 0.094
        children [
          Box {
            size 0.857 0.2 0.092
          }
        ]
      }
    ]
  }
  physics Physics {
    density -1
    mass 70
  }
  controller "mir100"
  linearVelocity 6.140581556009908e-06 -3.144526760046291e-05 -3.4668203163362764e-07
  angularVelocity 0.00021642962971766183 0.00015636822206804225 -2.3305258037799713e-05
}
