#VRML_SIM R2025a utf8

EXTERNPROTO "https://raw.githubusercontent.com/cyberbotics/webots/R2025a/projects/objects/backgrounds/protos/TexturedBackground.proto"
EXTERNPROTO "https://raw.githubusercontent.com/cyberbotics/webots/R2025a/projects/objects/backgrounds/protos/TexturedBackgroundLight.proto"
EXTERNPROTO "https://raw.githubusercontent.com/cyberbotics/webots/R2025a/projects/objects/floors/protos/RectangleArena.proto"
EXTERNPROTO "https://raw.githubusercontent.com/cyberbotics/webots/R2025a/projects/appearances/protos/Parquetry.proto"
EXTERNPROTO "../protos/ConveyorBelt.proto"
EXTERNPROTO "../protos/Pioneer3at.proto"
EXTERNPROTO "../protos/WoodenPallet.proto"
EXTERNPROTO "https://raw.githubusercontent.com/cyberbotics/webots/R2025a/projects/objects/factory/containers/protos/CardboardBox.proto"
EXTERNPROTO "https://raw.githubusercontent.com/cyberbotics/webots/R2025a/projects/objects/factory/containers/protos/PlasticFruitBox.proto"
EXTERNPROTO "https://raw.githubusercontent.com/cyberbotics/webots/R2025a/projects/objects/factory/manhole/protos/SquareManhole.proto"
EXTERNPROTO "https://raw.githubusercontent.com/cyberbotics/webots/R2025a/projects/objects/traffic/protos/SignPole.proto"
EXTERNPROTO "https://raw.githubusercontent.com/cyberbotics/webots/R2025a/projects/objects/traffic/protos/DirectionPanel.proto"
EXTERNPROTO "https://raw.githubusercontent.com/cyberbotics/webots/R2025a/projects/humans/pedestrian/protos/Pedestrian.proto"
EXTERNPROTO "https://raw.githubusercontent.com/cyberbotics/webots/R2025a/projects/appearances/protos/Plastic.proto"
EXTERNPROTO "https://raw.githubusercontent.com/cyberbotics/webots/R2025a/projects/robots/mir/mir100/protos/Mir100UltrasonicSensor.proto"
EXTERNPROTO "https://raw.githubusercontent.com/cyberbotics/webots/R2025a/projects/appearances/protos/CorrodedMetal.proto"
EXTERNPROTO "https://raw.githubusercontent.com/cyberbotics/webots/R2025a/projects/objects/solids/protos/SolidTorus.proto"
EXTERNPROTO "https://raw.githubusercontent.com/cyberbotics/webots/R2025a/projects/appearances/protos/CorrugatedMetal.proto"
EXTERNPROTO "https://raw.githubusercontent.com/cyberbotics/webots/R2025a/projects/appearances/protos/Rubber.proto"

WorldInfo {
  FPS 30
}
Viewpoint {
  orientation -0.09703389685447253 -0.9677833724924503 0.2323354617538503 5.468376596712878
  position -7.772012478524073 7.861720089113583 14.41423507722695
  followType "None"
}
TexturedBackground {
}
TexturedBackgroundLight {
}
DEF rectangle_arena RectangleArena {
  translation 15.1304 9.85552 0
  floorSize 30 20
  floorTileSize 1 1
  floorAppearance Parquetry {
    type "dark strip"
  }
}
Pedestrian {
  translation 11.06 7.31002 1.27
  rotation 0 0 1 -3.1415853071795863
}
Pedestrian {
  translation 16.3842 17.72 1.28
  rotation 0 0 1 -0.523595307179586
  name "pedestrian(1)"
}
Pedestrian {
  translation 26.7331 5.34865 1.28
  rotation 0 0 -1 1.5708
  name "pedestrian(2)"
}
SignPole {
  translation 25.3498 15.6897 0
  rotation 0 0 1 3.14159
  height 1
  signBoards [
    DirectionPanel {
      translation 0 0 -0.86
      width 0.4
      height 0.2
    }
  ]
}
PlasticFruitBox {
  translation 28.2254 1.86879 0.63
  rotation 0 0 1 0.261799
  color 0.371527 0.966171 0.557473
}
DEF left_big_conveyor_belt_5 ConveyorBelt {
  hidden translation_1 0 0 1.121092613434287
  translation 17.8 15 0
  rotation 0 0 -1 0
  size 1 5 1.5
}
DEF left_big_conveyor_belt_6 ConveyorBelt {
  hidden translation_1 7.105427357601002e-15 -3.552713678800501e-15 1.1210926134342853
  translation 21 15 0
  rotation 0 0 -1 0
  name "conveyor belt(11)"
  size 1 5 1.5
}
DEF left_big_conveyor_belt_6 ConveyorBelt {
  hidden translation_1 -0.0003848911937467392 2.1388581966874654e-05 1.1461370545608234
  hidden rotation_1 -0.007108017828594725 0.999974682844138 -0.0003312903771018675 0.006046461441891239
  translation 28.88 15 0
  rotation 0 0 -1 0
  name "conveyor belt(25)"
  size 1 5 1.5
}
DEF left_small_conveyor_belt_4 ConveyorBelt {
  hidden translation_1 0 0 0.7460926136257153
  translation 13.33 14.5 0
  rotation 0 0 -1 0
  name "conveyor belt(3)"
  size 1 4 1
}
DEF left_big_conveyor_belt_4 ConveyorBelt {
  hidden translation_1 0 0 1.121092613434287
  translation 14.5 15 0
  rotation 0 0 -1 0
  name "conveyor belt(4)"
  size 1 5 1.5
}
DEF left_small_conveyor_belt_5 ConveyorBelt {
  hidden translation_1 0 0 0.746092613434532
  translation 16.6 14.5 0
  rotation 0 0 -1 0
  name "conveyor belt(1)"
  size 1 4 1
}
DEF left_small_conveyor_belt_6 ConveyorBelt {
  hidden translation_1 0 0 0.7460926134342776
  translation 19.8 14.5 0
  rotation 0 0 -1 0
  name "conveyor belt(10)"
  size 1 4 1
}
DEF right_small_conveyor_belt_6 ConveyorBelt {
  hidden translation_1 0 0 0.7460926134342776
  translation 23 6 0
  rotation 0 0 -1 0
  name "conveyor belt(2)"
  size 1 4 1
}
DEF right_big_conveyor_belt_6 ConveyorBelt {
  hidden translation_1 0 0 1.121092613434287
  translation 21.8 5.5 0
  rotation 0 0 -1 0
  name "conveyor belt(5)"
  size 1 5 1.5
}
ConveyorBelt {
  hidden translation_1 0 0 0.44609261343427137
  translation 27.8449 2.58127 0
  rotation 0 0 -1 0
  name "conveyor belt(12)"
  size 4 4 0.6
}
DEF right_small_conveyor_belt_5 ConveyorBelt {
  hidden translation_1 0 0 0.7460926134342776
  translation 19.8 6 0
  rotation 0 0 -1 0
  name "conveyor belt(6)"
  size 1 4 1
}
WoodenPallet {
  translation 22.5 8.7 0
  size 2 1 0.1
}
WoodenPallet {
  translation 19 8.7 0
  name "wooden pallet(1)"
  size 2 1 0.1
}
WoodenPallet {
  translation 9.4 8.7 0
  name "wooden pallet(6)"
  size 2 1 0.1
}
WoodenPallet {
  translation 17 11.9 0
  name "wooden pallet(2)"
  size 2 1 0.1
}
WoodenPallet {
  translation 10.73 11.9 0
  name "wooden pallet(3)"
  size 2 1 0.1
}
WoodenPallet {
  translation 7.5 11.9 0
  name "wooden pallet(5)"
  size 2 1 0.1
}
WoodenPallet {
  translation 4.5 11.9 0
  name "wooden pallet(4)"
  size 2 1 0.1
}
DEF right_big_conveyor_belt_5 ConveyorBelt {
  hidden translation_1 0 0 1.121092613434287
  translation 18.5 5.5 0
  rotation 0 0 -1 0
  name "conveyor belt(7)"
  window "<none>"
  size 1 5 1.5
}
DEF right_small_conveyor_belt_4 ConveyorBelt {
  hidden translation_1 0 0 0.7460926134342776
  translation 16.46 6 0
  rotation 0 0 -1 0
  name "conveyor belt(8)"
  window "<none>"
  size 1 4 1
}
DEF right_small_conveyor_belt_3 ConveyorBelt {
  hidden translation_1 0 0 0.7460926135988916
  translation 13.22 6 0
  rotation 0 0 -1 0
  name "conveyor belt(14)"
  window "<none>"
  size 1 4 1
}
DEF left_small_conveyor_belt_2 ConveyorBelt {
  hidden translation_1 0 0 0.7460926134342776
  translation 6.9 14.5 0
  rotation 0 0 -1 0
  name "conveyor belt(21)"
  size 1 4 1
}
DEF left_small_conveyor_belt_1 ConveyorBelt {
  hidden translation_1 0 0 0.7460926134342776
  translation 3.7 14.5 0
  rotation 0 0 -1 0
  name "conveyor belt(23)"
  size 1 4 1
}
DEF left_small_conveyor_belt_3 ConveyorBelt {
  hidden translation_1 0 0 0.7460926134342776
  translation 10.1 14.5 0
  rotation 0 0 -1 0
  name "conveyor belt(19)"
  size 1 4 1
}
DEF right_small_conveyor_belt_2 ConveyorBelt {
  hidden translation_1 0 0 0.7460926134342776
  translation 10 6 0
  rotation 0 0 -1 0
  name "conveyor belt(15)"
  size 1 4 1
}
DEF right_small_conveyor_belt_1 ConveyorBelt {
  hidden translation_1 1.7763568394002505e-15 1.7763568394002505e-15 0.7460926134342771
  translation 7 6 0
  rotation 0 0 -1 0
  name "conveyor belt(17)"
  size 1 4 1
}
DEF right_big_conveyor_belt_4 ConveyorBelt {
  hidden translation_1 0 0 1.121092613434287
  translation 15.3 5.5 0
  rotation 0 0 -1 0
  name "conveyor belt(9)"
  size 1 5 1.5
}
DEF right_big_conveyor_belt_3 ConveyorBelt {
  hidden translation_1 0 0 1.121092613434287
  translation 12 5.5 0
  rotation 0 0 -1 0
  name "conveyor belt(13)"
  size 1 5 1.5
}
DEF left_big_conveyor_belt_3 ConveyorBelt {
  hidden translation_1 0 0 1.121092613434287
  translation 11.3 15 0
  rotation 0 0 -1 0
  name "conveyor belt(20)"
  size 1 5 1.5
}
DEF left_big_conveyor_belt_2 ConveyorBelt {
  hidden translation_1 0 0 1.121092613434287
  translation 8.1 15 0
  rotation 0 0 -1 0
  name "conveyor belt(22)"
  size 1 5 1.5
}
DEF left_big_conveyor_belt_1 ConveyorBelt {
  hidden translation_1 0 0 1.121092613434287
  translation 4.9 15 0
  rotation 0 0 -1 0
  name "conveyor belt(24)"
  size 1 5 1.5
}
DEF right_big_conveyor_belt_2 ConveyorBelt {
  hidden translation_1 0 0 1.121092613434287
  translation 8.8 5.5 0
  rotation 0 0 -1 0
  name "conveyor belt(16)"
  size 1 5 1.5
}
DEF right_big_conveyor_belt_1 Robot {
  translation 5.8 5.5 0
  rotation 0 0 -1 0
  children [
    Track {
      translation -9.488717160177629e-05 -0.0008011680417192579 1.1290201608820545
      rotation 0.9966346016118166 -0.08196245748030113 0.0012753171548224409 0.007025254798688431
      children [
        Shape {
          appearance Rubber {
            type "dotted"
            textureTransform TextureTransform {
              scale 4 20
            }
          }
          geometry DEF BELT_BO Box {
            size 1 5 0.75
          }
        }
      ]
      boundingObject USE BELT_BO
      physics Physics {
        density -1
        mass 1
      }
      device [
        LinearMotor {
          name "belt_motor"
          maxVelocity 0.5
          sound ""
        }
      ]
      textureAnimation 1 0
      linearVelocity 0 0 -3.0695446184836328e-15
    }
    Shape {
      appearance CorrugatedMetal {
        textureTransform TextureTransform {
          scale 2 2
        }
      }
      geometry IndexedFaceSet {
        coord Coordinate {
          point [
            0.53 -2.53 0
            0.53 -2.53 1.51
            -0.53 -2.53 1.51
            -0.53 -2.53 0
            0.53 2.53 0
            0.53 2.53 1.51
            -0.53 2.53 1.51
            -0.53 2.53 0
            0.5 -2.5 1.51
            0.5 2.5 1.51
            -0.5 2.5 1.51
            -0.5 -2.5 1.51
            0.5 -2.5 1.5
            0.5 2.5 1.5
            -0.5 2.5 1.5
            -0.5 -2.5 1.5
          ]
        }
        texCoord TextureCoordinate {
          point [
            0 0
            1 0
            1 1
            0 1
            0 2.849056603773585
            1 2.849056603773585
            0 2.849056603773585
            4.7735849056603765 2.849056603773585
            4.7735849056603765 0
            0 0
            0.001 0
            0.001 0.001
            0 0.001
          ]
        }
        coordIndex [
          0, 1, 2, 3, -1, 4, 7, 6, 5, -1, 0, 4, 5, 1, -1, 7, 3, 2, 6, -1, 1, 5, 9, 8, -1, 5, 6, 10, 9, -1, 6, 2, 11, 10, -1, 2, 1, 8, 11, -1, 0, 3, 7, 4, -1, 8, 9, 13, 12, -1, 9, 10, 14, 13, -1, 10, 11, 15, 14, -1, 11, 8, 12, 15, -1
        ]
        texCoordIndex [
          1, 5, 4, 0, -1, 0, 1, 5, 4, -1, 0, 8, 7, 6, -1, 0, 8, 7, 6, -1, 9, 10, 11, 12, -1, 9, 10, 11, 12, -1, 9, 10, 11, 12, -1, 9, 10, 11, 12, -1, 9, 10, 11, 12, -1, 9, 10, 11, 12, -1, 9, 10, 11, 12, -1, 9, 10, 11, 12, -1, 9, 10, 11, 12, -1
        ]
      }
    }
    Pose {
      translation -0.53 -2.93845e-06 0.173
      rotation 0 0 1 -3.14159
      children [
        Shape {
          appearance Appearance {
            material Material {
              diffuseColor 1 1 1
            }
            texture ImageTexture {
              url [
                "/Users/nguyenquangnhat/Documents/ARM_project/protos/textures/april_tag.png"
              ]
              repeatS FALSE
              repeatT FALSE
            }
          }
          geometry Box {
            size 0.0005 0.05 0.05
          }
        }
      ]
    }
  ]
  name "conveyor belt(18)"
  boundingObject Group {
    children [
      Pose {
        translation 0.515 0 0.755
        children [
          Box {
            size 0.03 5.06 1.51
          }
        ]
      }
      Pose {
        translation -0.515 0 0.755
        children [
          Box {
            size 0.03 5.06 1.51
          }
        ]
      }
      Pose {
        translation 0 -2.515 0.755
        children [
          Box {
            size 1 0.03 1.51
          }
        ]
      }
      Pose {
        translation 0 2.515 0.755
        children [
          Box {
            size 1 0.03 1.51
          }
        ]
      }
    ]
  }
  controllerArgs [
    "0.5"
    "0"
  ]
}
CardboardBox {
  translation 27.8384 3.01098 0.71
  rotation 0 0 1 0.261799
  size 0.2 0.2 0.2
}
CardboardBox {
  translation 28.0224 3.48865 0.71
  rotation 0 0 1 0.785398
  name "cardboard box(1)"
  size 0.2 0.2 0.2
}
CardboardBox {
  translation 21.6903 3.22499 1.6
  rotation 0 0 1 1.309
  name "cardboard box(6)"
  size 0.2 0.2 0.2
}
CardboardBox {
  translation 7.98736 14.1014 1.6
  rotation 0 0 1 1.309
  name "cardboard box(7)"
  size 0.2 0.2 0.2
}
CardboardBox {
  translation 15.3336 4.18682 1.6
  rotation 0 0 1 2.0944
  name "cardboard box(10)"
  size 0.2 0.2 0.2
}
CardboardBox {
  translation 11.2185 13.9355 1.6
  rotation 0 0 1 2.0944
  name "cardboard box(11)"
  size 0.2 0.2 0.2
}
CardboardBox {
  translation 4.6953 16.4739 1.6
  rotation 0 0 1 2.0944
  name "cardboard box(12)"
  size 0.2 0.2 0.2
}
CardboardBox {
  translation 5.94515 4.74132 1.6
  rotation 0 0 1 1.309
  name "cardboard box(9)"
  size 0.2 0.2 0.2
}
CardboardBox {
  translation 26.2061 1.6839 0.71
  rotation 0 0 1 1.309
  name "cardboard box(8)"
  size 0.2 0.2 0.2
}
CardboardBox {
  translation 28.3211 1.96902 0.77
  rotation 0 0 1 4.692820414042842e-06
  name "cardboard box(5)"
  size 0.2 0.2 0.2
}
CardboardBox {
  translation 28.0496 3.95362 0.71
  rotation 0 0 1 0.261803
  name "cardboard box(2)"
  size 0.2 0.2 0.2
}
CardboardBox {
  translation 18.9049 8.5223 0.11
  rotation 0 0 1 1.5708
  name "cardboard box(4)"
  size 0.2 0.2 0.2
}
CardboardBox {
  translation 20.9849 7.7223 0.11
  rotation 0 0 1 1.5708
  name "cardboard box(13)"
  size 0.2 0.2 0.2
}
CardboardBox {
  translation 17.3949 8.2323 0.11
  rotation 0 0 1 1.5708
  name "cardboard box(16)"
  size 0.2 0.2 0.2
}
CardboardBox {
  translation 18.6349 12.5223 0.11
  rotation 0 0 1 1.5708
  name "cardboard box(17)"
  size 0.2 0.2 0.2
}
CardboardBox {
  translation 17.0749 12.4123 0.11
  rotation 0 0 1 1.5708
  name "cardboard box(18)"
  size 0.2 0.2 0.2
}
CardboardBox {
  translation 24.9049 4.5023 0.11
  rotation 0 0 1 1.5708
  name "cardboard box(15)"
  size 0.2 0.2 0.2
}
CardboardBox {
  translation 24.3649 4.5123 0.11
  rotation 0 0 1 1.5708
  name "cardboard box(14)"
  size 0.2 0.2 0.2
}
CardboardBox {
  translation 22.6249 18.7445 0.15
  rotation 0 0 1 4.07987e-06
  name "cardboard box(3)"
  size 0.2 0.2 0.2
}
Pose {
}
DEF SUPERVISOR Robot {
  rotation 0 0 1 -2.8797853071795863
  controller "floor_mapper"
  supervisor TRUE
}
DEF Pioneer_3-AT Pioneer3at {
  hidden position_0_0 17180.781317376444
  hidden position_0_1 14902.012851970794
  hidden position_0_2 17201.44317647442
  hidden position_0_3 14923.747407567229
  hidden linearVelocity_0 1.9581273242206688e-14 -2.9553600728265458e-15 -2.583791766400364e-16
  hidden angularVelocity_0 5.940735427750491e-16 1.0938301445155095e-15 -3.901554070308293e-15
  hidden rotation_1 0.5773516024134749 -0.5773476024162304 -0.5773516027299337 2.094404999683543
  hidden translation_2 4.390430234023778e-13 2.1847962280823109e-13 0.04999999999999215
  hidden rotation_2 -0.42526537133496617 0.425258256650912 -0.7989397843977734 1.7934126943521096
  hidden rotation_3 0.6930329820880304 -0.6930264969132508 -0.1985435980189743 2.7496115778172214
  hidden linearVelocity_3 2.1199560718518157e-14 6.015671615332487e-16 3.5528663963706464e-16
  hidden angularVelocity_3 7.49517686088958e-15 -1.106479501796137e-15 -7.118209428075089e-16
  hidden rotation_4 -0.1675394125056006 0.1675409892988371 0.9715248644075174 4.683493665150727
  hidden linearVelocity_4 -1.5979892057243438e-14 -1.5210134648941376e-15 1.420904002911465e-16
  hidden angularVelocity_4 4.042443476911267e-15 -1.1382805152332557e-15 -6.398492296019814e-16
  hidden rotation_5 0.16398691728294834 -0.16398191065287526 0.9727374897363973 4.6847417160979035
  hidden linearVelocity_5 -4.34841726179912e-15 9.046310928278023e-16 -6.394897388061195e-16
  hidden angularVelocity_5 9.32581802323091e-15 8.603403360556884e-17 -5.944389454547799e-16
  hidden rotation_6 0.07773587416401968 -0.07773168658597751 0.9939390920818311 4.706299601352522
  hidden linearVelocity_6 -2.7679775821099194e-16 -3.3519880109884418e-15 4.973985216340835e-16
  hidden angularVelocity_6 9.972337387967031e-15 4.79432461787891e-15 -6.06114261368208e-16
  translation 12.981299877684622 1.134639995945744 -0.0023889310687114917
  rotation -2.473697390061377e-05 2.482305496996215e-05 0.999999999385949 1.5554670100880081
  name "Pioneer 3-AT_1"
  controller "pioneer_controller_1"
}
DEF Pioneer_3-AT Pioneer3at {
  hidden position_0_0 17180.781317382036
  hidden position_0_1 14902.012851964362
  hidden position_0_2 17201.44317648295
  hidden position_0_3 14923.747407564048
  hidden linearVelocity_0 1.9389876999818748e-14 -2.747829583820744e-15 1.0335167065601457e-16
  hidden angularVelocity_0 -4.012080515695304e-16 -1.4453875140130335e-15 -3.8079824191809734e-15
  hidden rotation_1 0.5773516024134749 -0.5773476024162304 -0.5773516027299337 2.094404999683543
  hidden translation_2 4.390430234023778e-13 2.1847962280823109e-13 0.04999999999999215
  hidden rotation_2 -0.42526537133496617 0.425258256650912 -0.7989397843977734 1.7934126943521096
  hidden rotation_3 0.6930329817995412 -0.6930264966247707 -0.19854360003292326 2.7496115739421096
  hidden linearVelocity_3 2.0879590212766502e-14 2.8467536216199565e-16 4.973899009750579e-16
  hidden angularVelocity_3 5.987791103170119e-15 5.5203617293094805e-17 -5.378766325021337e-16
  hidden rotation_4 -0.16753941554229818 0.1675409923355001 0.9715248633601616 4.683493664073114
  hidden linearVelocity_4 -1.6079145854446553e-14 -1.4055914297197112e-15 -7.105225134943399e-17
  hidden angularVelocity_4 3.0538718149566286e-15 -3.4985620013022897e-15 -5.091246954484018e-16
  hidden rotation_5 0.16398692132061432 -0.1639819146905033 0.9727374883750617 4.6847417146989665
  hidden linearVelocity_5 -4.181422849374249e-15 1.4975776782339065e-15 -2.1319545558672666e-16
  hidden angularVelocity_5 8.18080537869201e-15 2.4266309633390975e-15 -5.012049470497552e-16
  hidden rotation_6 0.0777358725925078 -0.07773168501448109 0.9939390923276391 4.706299601599814
  hidden linearVelocity_6 -7.67129809922853e-16 -3.2212898707062044e-15 -7.104376322312104e-17
  hidden angularVelocity_6 8.717861659569485e-15 8.043077108417914e-17 -4.9021184463002e-16
  translation 14.481299987285835 1.1131699973748304 -0.0023889310687115473
  rotation -2.4736973900688053e-05 2.48230549532143e-05 0.9999999993859491 1.5554670107517148
  name "Pioneer 3-AT_1(1)"
  controller "pioneer_controller_2"
}
DEF Pioneer_3-AT Pioneer3at {
  hidden position_0_0 17180.781317381356
  hidden position_0_1 14902.012851962876
  hidden position_0_2 17201.44317648763
  hidden position_0_3 14923.747407568037
  hidden linearVelocity_0 3.925855604884163e-14 -2.940711910093263e-15 -5.1675835328007286e-17
  hidden angularVelocity_0 7.741764196937362e-16 -1.0758136534401454e-15 3.837749933931249e-15
  hidden rotation_1 0.5773516024134749 -0.5773476024162304 -0.5773516027299337 2.094404999683543
  hidden translation_2 4.390430234023778e-13 2.1847962280823109e-13 0.04999999999999215
  hidden rotation_2 -0.42526537133496617 0.425258256650912 -0.7989397843977734 1.7934126943521096
  hidden rotation_3 0.6930329818346399 -0.6930264966598698 -0.19854359978789315 2.749611574413578
  hidden linearVelocity_3 3.641477556007703e-14 -6.362684039657103e-16 -3.552640794268718e-16
  hidden angularVelocity_3 7.62698543517244e-15 1.1826118452541476e-14 5.775590375358636e-16
  hidden rotation_4 -0.1675394162439333 0.16754099303712758 0.9715248631181681 4.683493663824127
  hidden linearVelocity_4 -3.112880933344195e-14 -7.779268022248283e-16 7.103230004278779e-17
  hidden angularVelocity_4 4.021577926296291e-15 1.2126869405396228e-15 4.714795818946284e-16
  hidden rotation_5 0.16398692353659353 -0.16398191690646452 0.9727374876279236 4.684741713931185
  hidden linearVelocity_5 -1.9602718485864653e-15 8.656029885639687e-16 2.8419564314691343e-16
  hidden angularVelocity_5 9.387867747638848e-15 -1.088973522276526e-15 5.355751818557027e-16
  hidden rotation_6 0.07773587456296283 -0.0777316869849157 0.9939390920194309 4.7062996012897385
  hidden linearVelocity_6 -1.5385750660506755e-15 -2.8486544797470902e-15 -6.395003314319653e-16
  hidden angularVelocity_6 1.0057328928510009e-14 3.619528769146171e-15 5.085503809380657e-16
  translation 16.431299991048622 1.0847899972810766 -0.0023889310687116028
  rotation -2.4736973900490823e-05 2.4823054911684387e-05 0.999999999385949 1.5554670124161656
  name "Pioneer 3-AT_1(2)"
  controller "pioneer_controller_3"
}
SquareManhole {
  translation 25 19 0
}
SquareManhole {
  translation 19.092 9.85948 -0.04
  rotation 0 0 1 0.523602
  name "manhole(16)"
}
SquareManhole {
  translation 19.2812 12.146 -0.04
  rotation 0 0 1 0.785401
  name "manhole(17)"
}
SquareManhole {
  translation 9.00273 12.0778 -0.02
  rotation 0 0 1 1.5708
  name "manhole(12)"
}
SquareManhole {
  translation 6.19714 8.34714 -0.04
  rotation 9.58978e-09 3.57898e-08 1 -0.523595307179586
  name "manhole(11)"
}
WoodenPallet {
  translation 6.46 8.7 0
  name "wooden pallet(7)"
  size 2 1 0.1
}
WoodenPallet {
  translation 12.72 8.7 0
  name "wooden pallet(8)"
  size 2 1 0.1
}
WoodenPallet {
  translation 15.74 8.7 0
  name "wooden pallet(9)"
  size 2 1 0.1
}
WoodenPallet {
  translation 13.93 11.89 0
  name "wooden pallet(10)"
  size 2 1 0.1
}
WoodenPallet {
  translation 20.37 11.89 0
  name "wooden pallet(11)"
  size 2 1 0.1
}
Robot {
  translation 4.582490223750587 5.470899039688194 -0.0063212872677554655
  rotation 0.0005399714559014933 0.0004652443018960513 0.9999997459892509 1.5095452747596783
  children [
    Camera {
      translation 0.044 -0.28 0.18
      rotation 0 0 1 -1.5707953071795862
      fieldOfView 2.05949
      width 1280
      height 720
    }
    InertialUnit {
      rotation 0 0 1 -1.5707953071795862
    }
    GPS {
      rotation 0 0 -1 -5.307179586466759e-06
    }
    Pose {
      translation 0.037646 0 0
      children [
        Shape {
          appearance DEF WHITE Plastic {
          }
          geometry Mesh {
            url [
              "https://raw.githubusercontent.com/cyberbotics/webots/R2025a/projects/robots/mir/mir100/protos/meshes/mir_100_base.obj"
            ]
          }
        }
        Shape {
          appearance USE WHITE
          geometry Mesh {
            url [
              "https://raw.githubusercontent.com/cyberbotics/webots/R2025a/projects/robots/mir/mir100/protos/meshes/mir_100_inside.obj"
            ]
          }
        }
        Shape {
          appearance Plastic {
            colorOverride 0.93 0.93 0.93
          }
          geometry Mesh {
            url [
              "https://raw.githubusercontent.com/cyberbotics/webots/R2025a/projects/robots/mir/mir100/protos/meshes/mir_100_logos.dae"
            ]
          }
        }
        Shape {
          appearance DEF BLACK Plastic {
            colorOverride 0 0 0
          }
          geometry Mesh {
            url [
              "https://raw.githubusercontent.com/cyberbotics/webots/R2025a/projects/robots/mir/mir100/protos/meshes/mir_100_base_corners.dae"
            ]
          }
        }
        Shape {
          appearance DEF BLACK Plastic {
            colorOverride 0 0 0
          }
          geometry Mesh {
            url [
              "https://raw.githubusercontent.com/cyberbotics/webots/R2025a/projects/robots/mir/mir100/protos/meshes/mir_100_top_plugs.dae"
            ]
          }
        }
      ]
    }
    DEF IMU Pose {
      translation 0 0 0.25
      children [
        Accelerometer {
          name "imu_data accelerometer"
          lookupTable [
            -100 -100 -0.002
            100 100 0.002
          ]
        }
        Gyro {
          name "imu_data gyro"
          lookupTable [
            -100 -100 -0.002
            100 100 0.002
          ]
        }
        Compass {
          name "imu_data compass"
          lookupTable [
            -1 -1 -0.2
            1 1 0.2
          ]
        }
      ]
    }
    Pose {
      translation 0.4288 0.2358 0.188
      rotation -0.9238797538373538 -0.38268289803626016 0 -3.14159
    }
    Pose {
      translation -0.3548 -0.2352 0.188
      rotation 0.38268289803626016 -0.9238797538373538 0 -3.14159
    }
    Pose {
      translation 0.037646 0 0.349
    }
    DEF DEPTH_CAMERA Transform {
      translation 0.042224 -0.273014 0.141194
      rotation 1 0 0 1.5708
      scale 4.00035 3.92893 3.92893
      children [
        Shape {
          appearance Appearance {
            material Material {
              emissiveColor 1 1 1
            }
            texture ImageTexture {
              url [
                "https://raw.githubusercontent.com/cyberbotics/webots/R2025a/projects/robots/mir/mir100/protos/textures/camera.png"
              ]
            }
            textureTransform TextureTransform {
              rotation 3.1415926
            }
          }
          geometry Plane {
            size 0.08 0.015
          }
        }
      ]
    }
    Mir100UltrasonicSensor {
      translation -0.3844 -0.1328 0.156
      rotation 0 0 1 3.141592653589793
      name "ds1"
    }
    Mir100UltrasonicSensor {
      translation -0.3844 0.1328 0.156
      rotation 0 0 1 3.141592653589793
      name "ds2"
    }
    RangeFinder {
      translation 0.044 -0.28 0.18
      rotation 0 0 1 -1.5707953071795862
      name "depth_camera"
      fieldOfView 2.05949
      near 0.001
      maxRange 1.95
    }
    Pose {
      translation 0.03733 0.0005 0.2085
      children [
        DEF LIGHT_FRONT Pose {
          translation 0.392 0 0
          children [
            DEF LIGHT_WIDTH_SHAPE Shape {
              appearance PBRAppearance {
                transparency 0.5
                emissiveColor 0 0.9 1
              }
              geometry Box {
                size 0.001 0.4723 0.053
              }
            }
          ]
        }
        DEF LIGHT_BACK Pose {
          translation -0.392 0 0
          children [
            USE LIGHT_WIDTH_SHAPE
          ]
        }
        DEF LIGHT_LEFT Pose {
          translation 0 0.2355 0
          children [
            DEF LIGHT_WIDTH_SHAPE Shape {
              appearance PBRAppearance {
                transparency 0.5
                emissiveColor 0 0.9 1
              }
              geometry Box {
                size 0.783 0.001 0.053
              }
            }
          ]
        }
        DEF LIGHT_RIGHT Pose {
          translation 0 -0.2355 0
          children [
            USE LIGHT_WIDTH_SHAPE
          ]
        }
      ]
    }
    DEF US_1_FRAME Solid {
      translation 0.45 -0.12 0.16
      name "us_1_frame"
    }
    DEF US_2_FRAME Solid {
      translation 0.45 0.12 0.16
      name "us_2_frame"
    }
    DEF FRONT_WHEEL HingeJoint {
      jointParameters HingeJointParameters {
        position -7.843103225025809
        axis 0 0 1
        anchor 0.341 -0.203 0.161
        dampingConstant 0.01
      }
      device [
        RotationalMotor {
          name "front_wheel_joint"
          maxVelocity 100
          maxTorque 20
        }
        PositionSensor {
          name "front_caster_joint_sensor"
        }
      ]
      endPoint DEF FL_CASTER_ROTATION_LINK Solid {
        translation 0.3410000173489962 -0.2030000038919544 0.16101939884163602
        rotation 0 0 1 4.723267389333364
        children [
          DEF UP_RIM Shape {
            appearance CorrodedMetal {
            }
            geometry Cylinder {
              height 0.2
              radius 0.03
            }
          }
          DEF FL_CASTER_WHEEL_JOINT HingeJoint {
            jointParameters HingeJointParameters {
              position 24.337624411063373
              axis 0 1 0
              anchor 0 0 -0.094
            }
            device [
              RotationalMotor {
                name "front_wheel"
                maxVelocity 100
                maxTorque 20
              }
              PositionSensor {
                name "front_left_wheel_joint_sensor"
              }
            ]
            endPoint DEF FL_CASTER_WHEEL_LINK Solid {
              translation -5.5892055704952627e-05 2.1689599999999874e-05 -0.09405699414220803
              rotation -0.28585772752063493 0.6776807755627446 0.6775205724178529 2.5854307611345555
              children [
                Group {
                  children [
                    DEF RIM Shape {
                      appearance CorrodedMetal {
                      }
                      geometry Cylinder {
                        height 0.032
                        radius 0.0465
                      }
                    }
                    SolidTorus {
                      translation 0 0 0
                      majorRadius 0.0465
                      minorRadius 0.016
                      appearance DEF WHEEL_RUBBER PBRAppearance {
                        baseColor 0 0 0
                        roughness 1
                        metalness 0
                      }
                      enableBoundingObject FALSE
                    }
                  ]
                }
              ]
              name "fl_caster_wheel_link"
              contactMaterial "wheel"
              boundingObject DEF WHEEL_BO Cylinder {
                height 0.01
                radius 0.0625
              }
              physics Physics {
                density -1
                mass 1
                centerOfMass [
                  0 0 0
                ]
                inertiaMatrix [
                  0.001061895 0.001953125 0.001061895
                  0 0 5.457207e-20
                ]
              }
              linearVelocity 1.9661005796315102e-10 -2.007944506592608e-10 1.42109820307696e-15
              angularVelocity 4.264634205148196e-10 8.438436847943093e-09 -1.376105562233656e-09
            }
          }
        ]
        name "fl_caster_rotation_link"
        boundingObject Pose {
          translation 0 0 -0.028
          children [
            DEF SWIVEL Cylinder {
              height 0.055
              radius 0.0298
            }
          ]
        }
        physics Physics {
          density -1
          mass 0.309754
          centerOfMass [
            0 0 -0.0425
          ]
          inertiaMatrix [
            0.0005287255 0.000517415 0.0002462724
            -7.734275e-21 -1.120566e-20 -0.0001505672
          ]
        }
        linearVelocity 1.9714093941534813e-10 -2.010159657817272e-10 -4.711198792280629e-13
        angularVelocity 1.1144615657022712e-12 1.5799388161022463e-12 -1.376556232414315e-09
      }
    }
    DEF MIDDLE_WHEEL HingeJoint {
      jointParameters HingeJointParameters {
        position -7.843085119337595
        axis 0 0 1
        anchor 0.04 0.203 0.161
        dampingConstant 0.01
      }
      device [
        RotationalMotor {
          name "middle_wheel_joint"
          maxVelocity 100
          maxTorque 20
        }
        PositionSensor {
          name "middle_caster_joint_sensor"
        }
      ]
      endPoint DEF BL_CASTER_ROTATION_LINK Solid {
        translation 0.040002033908866357 0.20300001553200955 0.16154839624725909
        rotation 0 0 1 4.723285495021578
        children [
          DEF UP_RIM Shape {
            appearance CorrodedMetal {
            }
            geometry Cylinder {
              height 0.2
              radius 0.03
            }
          }
          DEF BL_CASTER_WHEEL_JOINT HingeJoint {
            jointParameters HingeJointParameters {
              position 6.806869364823029
              axis 0 1 0
              anchor 0 0 -0.096
            }
            device [
              RotationalMotor {
                name "middle_wheel"
                maxVelocity 100
                maxTorque 20
              }
              PositionSensor {
                name "middle_wheel_joint_sensor"
              }
            ]
            endPoint DEF BL_CASTER_WHEEL_LINK Solid {
              translation 1.9995646553039522e-05 6.762419999999964e-06 -0.0960115484253591
              rotation 0.9350928970849735 -0.25060000815309474 -0.2506010968349905 4.645325562081495
              children [
                Group {
                  children [
                    USE RIM
                    SolidTorus {
                      translation 0 0 0
                      majorRadius 0.0465
                      minorRadius 0.016
                      appearance USE WHEEL_RUBBER
                      enableBoundingObject FALSE
                    }
                  ]
                }
              ]
              name "bl_caster_wheel_link"
              contactMaterial "wheel"
              boundingObject USE WHEEL_BO
              physics Physics {
                density -1
                mass 1
                centerOfMass [
                  0 0 0
                ]
                inertiaMatrix [
                  0.001061895 0.001953125 0.001061895
                  0 0 5.457207e-20
                ]
              }
              linearVelocity -1.818192878455211e-10 3.8168223252744046e-10 1.3073817335903965e-15
              angularVelocity -2.766220361997885e-10 -5.509419738240599e-09 -1.3718465087318512e-09
            }
          }
        ]
        name "bl_caster_rotation_link"
        boundingObject Pose {
          translation 0 0 -0.028
          children [
            USE SWIVEL
          ]
        }
        physics Physics {
          density -1
          mass 0.309754
          centerOfMass [
            0 0 -0.0425
          ]
          inertiaMatrix [
            0.0005287255 0.000517415 0.0002462724
            -7.734275e-21 -1.120566e-20 -0.0001505672
          ]
        }
        linearVelocity -1.8181753125723603e-10 3.8159574799476447e-10 -1.086846814579103e-13
        angularVelocity 1.1167013173790782e-12 1.5861257464125231e-12 -1.3715504554620773e-09
      }
    }
    DEF BACK_WHEEL HingeJoint {
      jointParameters HingeJointParameters {
        position -7.8430908332386995
        axis 0 0 1
        anchor -0.27 -0.203 0.161
        dampingConstant 0.01
      }
      device [
        RotationalMotor {
          name "back_wheel_joint"
          maxVelocity 100
          maxTorque 20
        }
        PositionSensor {
          name "back_caster_joint_sensor"
        }
      ]
      endPoint DEF BR_CASTER_ROTATION_LINK Solid {
        translation -0.2699999823151429 -0.20300000313721625 0.16101986770820237
        rotation 0 0 1 4.723279781120473
        children [
          DEF UP_RIM Shape {
            appearance CorrodedMetal {
            }
            geometry Cylinder {
              height 0.2
              radius 0.03
            }
          }
          DEF BR_CASTER_WHEEL_JOINT HingeJoint {
            jointParameters HingeJointParameters {
              position 793.3669473076559
              axis 0 1 0
              anchor 0 0 -0.094
            }
            device [
              RotationalMotor {
                name "back_wheel"
                maxVelocity 100
                maxTorque 20
              }
              PositionSensor {
                name "back_wheel_joint_sensor"
              }
            ]
            endPoint DEF BR_CASTER_WHEEL_LINK Solid {
              translation 8.409412206259804e-05 -1.2047399999999931e-05 -0.09405487760645763
              rotation 0.6338567592391628 -0.5469125733103725 -0.5469115521927219 4.271469918889291
              children [
                Group {
                  children [
                    USE RIM
                    SolidTorus {
                      translation 0 0 0
                      majorRadius 0.0465
                      minorRadius 0.016
                      appearance USE WHEEL_RUBBER
                      enableBoundingObject FALSE
                    }
                  ]
                }
              ]
              name "br_caster_wheel_link"
              contactMaterial "wheel"
              boundingObject USE WHEEL_BO
              physics Physics {
                density -1
                mass 1
                centerOfMass [
                  0 0 0
                ]
                inertiaMatrix [
                  0.001061895 0.001953125 0.001061895
                  0 0 5.457207e-20
                ]
              }
              linearVelocity -6.408890500711893e-10 -1.4960668158004283e-10 -2.7285070977240104e-15
              angularVelocity -6.516821827911954e-10 -1.2949981181677077e-08 -1.376266161376458e-09
            }
          }
        ]
        name "br_caster_rotation_link"
        boundingObject Pose {
          translation 0 0 -0.028
          children [
            USE SWIVEL
          ]
        }
        physics Physics {
          density -1
          mass 0.309754
          centerOfMass [
            0 0 -0.0425
          ]
          inertiaMatrix [
            0.0005287255 0.000517415 0.0002462724
            -7.734275e-21 -1.120566e-20 -0.0001505672
          ]
        }
        linearVelocity -6.415014433079199e-10 -1.495887999365244e-10 -1.0926733044673067e-12
        angularVelocity 1.1195351596708657e-12 1.5812768012398626e-12 -1.3755770744860756e-09
      }
    }
    DEF SURFACE Solid {
      translation 0.037646 0 0.352
      name "surface"
    }
  ]
  name "Mir100"
  model "Mobile Industrial Robots' MiR100"
  boundingObject Group {
    children [
      DEF TOP Pose {
        translation 0.0375 0.0005 0.334
        children [
          Box {
            size 0.774 0.461 0.04
          }
        ]
      }
      DEF MIDDLE_CENTER Pose {
        translation 0.0375 0.0005 0.262
        children [
          Box {
            size 0.857 0.44 0.096
          }
        ]
      }
      DEF MIDDLE_RIGHT_SIDE Pose {
        translation 0.0375 -0.25 0.262
        children [
          Box {
            size 0.774 0.041 0.096
          }
        ]
      }
      DEF MIDDLE_LEFT_SIDE Pose {
        translation 0.0375 0.25 0.262
        children [
          Box {
            size 0.774 0.041 0.096
          }
        ]
      }
      DEF CYL_BR Pose {
        translation -0.3555 -0.2353 0.262
        children [
          Cylinder {
            height 0.096
            radius 0.054
          }
        ]
      }
      DEF CYL_FL Pose {
        translation 0.4306 0.2364 0.262
        children [
          Cylinder {
            height 0.096
            radius 0.054
          }
        ]
      }
      DEF CYL_FR Pose {
        translation 0.415 -0.221 0.262
        children [
          Cylinder {
            height 0.096
            radius 0.049
          }
        ]
      }
      DEF CYL_BL Pose {
        translation -0.341 0.222 0.262
        children [
          Cylinder {
            height 0.096
            radius 0.049
          }
        ]
      }
      DEF MIDLOW Pose {
        translation 0.03733 0.0005 0.204
        children [
          Box {
            size 0.7806 0.4665 0.04
          }
        ]
      }
      DEF LOW Pose {
        translation 0.0374 0.0005 0.16
        children [
          Box {
            size 0.85 0.536 0.039
          }
        ]
      }
      DEF BOTTOM_LEFT Pose {
        translation 0.0374 0.2586 0.09425
        children [
          Box {
            size 0.35 0.04 0.0925
          }
        ]
      }
      DEF BOTTOM_RIGHT Pose {
        translation 0.0374 -0.2476 0.09425
        children [
          Box {
            size 0.35 0.04 0.0925
          }
        ]
      }
      DEF BOTTOM_CENTER Pose {
        translation 0.0375 0.0005 0.094
        children [
          Box {
            size 0.857 0.2 0.092
          }
        ]
      }
    ]
  }
  physics Physics {
    density -1
    mass 5
  }
  controller "mir100"
  linearVelocity -2.0420557050655628e-10 1.0384665151665875e-10 -4.4636303158070413e-13
  angularVelocity 1.1159890805755754e-12 1.5814618207055285e-12 -1.3751512702395706e-09
}
